Workbook
Name \0: #REF!
Name _1: #REF!
Name _2: #REF!
Name _A655555: #REF!
Name _CFR1: #REF!
Name _cia1: #REF!
Name _XL250: #REF!
Name A: #REF!
Name ADM: [1]!ADM
Name ADM: [1]!ADM
Name ADM: [1]!ADM
Name ADM: [1]!ADM
Name ADM: [1]!ADM
Name ADM_: [1]!ADM
Name ADM_: [1]!ADM
Name ADM_: [1]!ADM
Name ADM_: [1]!ADM
Name ADM_: [1]!ADM
Name AI: #REF!
Name Air: #REF!
Name AP: '[2]TARIFA no aforos'!$C$12
Name Bancos: [3]Fx!$C$1:$C$23
Name CBL: #REF!
Name CCS: #REF!
Name CDT_p: [4]CDT!$C$3
Name CFR: #REF!
Name cia: #REF!
Name COM: #REF!
Name CRT: #REF!
Name CRT___CTEp___CDTp___CMRv: #REF!
Name CRT_aislados: '[4]COSTOS AJUSTADOS'!$C$13
Name CRT_costas: #REF!
Name CTE_p: [4]CTE!$C$5
Name Denominador: #REF!
Name dg: [1]!ADM
Name dg: [1]!ADM
Name dg: [1]!ADM
Name dg: [1]!ADM
Name dg: [1]!ADM
Name DIAS: [5]CONTRA!#REF!
Name Fmerc: #REF!
Name FPS: #REF!
Name InformacionGeneral: [1]!InformacionGeneral
Name InformacionGeneral: [1]!InformacionGeneral
Name InformacionGeneral: [1]!InformacionGeneral
Name InformacionGeneral: [1]!InformacionGeneral
Name InformacionGeneral: [1]!InformacionGeneral
Name INTFIN: #REF!
Name INV: [1]!INV
Name INV: [1]!INV
Name INV: [1]!INV
Name INV: [1]!INV
Name INV: [1]!INV
Name K: #REF!
Name N: '[4]COSTOS AJUSTADOS'!#REF!
Name Na: '[2]TARIFA no aforos'!$C$39
Name nfc: '[4]COSTOS AJUSTADOS'!#REF!
Name OYM: [1]!OYM
Name OYM: [1]!OYM
Name OYM: [1]!OYM

Sheet Recaudo EAAB Reciprocidad
B2: OPORTUNO | C2: ASE | D2: VALOR 1° Q | E2: NUMERO REG. 1°Q | F2: VALOR 2° Q | G2: NUMERO REG. 2°Q
C3: 1 | D3: 0 | E3: 0 | F3: 0 | G3: 0
C4: 2 | D4: 11627730 | E4: 116 | F4: 4390091 | G4: 56
C5: 3 | D5: 0 | E5: 0 | F5: 0 | G5: 0
C6: 4 | D6: 7382710 | E6: 66 | F6: 1814000 | G6: 24
C7: 5 | D7: 0 | E7: 0 | F7: 0 | G7: 0
C8: X
D9: 19010440 | E9: 182 | F9: 6204091 | G9: 80
C11: ASE | D11: VALOR 1° Q | E11: NUMERO REG. 1°Q | F11: VALOR 2° Q | G11: NUMERO REG. 2°Q
B12: EXTEMP. | C12: 1 | D12: 0 | E12: 0 | F12: 0 | G12: 0
C13: 2 | D13: 0 | E13: 0 | F13: 0 | G13: 0
C14: 3 | D14: 0 | E14: 0 | F14: 0 | G14: 0
C15: 4 | D15: 0 | E15: 0 | F15: 0 | G15: 0
C16: 5 | D16: 0 | E16: 0 | F16: 0 | G16: 0
C17: X
D18: 0 | E18: 0 | F18: 0 | G18: 0
C20: ASE | D20: VALOR 1° Q | E20: NUMERO REG. 1°Q | F20: VALOR 2° Q | G20: NUMERO REG. 2°Q | I20: VALOR TOTAL MES | J20: NUMERO REGISTROS MES
B21: TOTAL | C21: 1 | D21: 0 | E21: 0 | F21: 0 | G21: 0 | I21: 0 | J21: 0
C22: 2 | D22: 11627730 | E22: 116 | F22: 4390091 | G22: 56 | I22: 16017821 | J22: 172
C23: 3 | D23: 0 | E23: 0 | F23: 0 | G23: 0 | I23: 0 | J23: 0
C24: 4 | D24: 7382710 | E24: 66 | F24: 1814000 | G24: 24 | I24: 9196710 | J24: 90
C25: 5 | D25: 0 | E25: 0 | F25: 0 | G25: 0 | I25: 0 | J25: 0
C26: X | I26: 0 | J26: 0
D27: 19010440 | E27: 182 | F27: 6204091 | G27: 80 | I27: 25214531 | J27: 262
B31: OPORTUNO | D31: =D9=SUM(D3:D8) -> TRUE | E31: =E9=SUM(E3:E8) -> TRUE | F31: =F9=SUM(F3:F8) -> TRUE | G31: =G9=SUM(G3:G8) -> TRUE
B33: EXTEMP. | D33: =D18=SUM(D12:D17) -> TRUE | E33: =E18=SUM(E12:E17) -> TRUE | F33: =F18=SUM(F12:F17) -> TRUE | G33: =G18=SUM(G12:G17) -> TRUE
B35: TOTAL | D35: =D27=SUM(D21:D26) -> TRUE | E35: =E27=SUM(E21:E26) -> TRUE | F35: =F27=SUM(F21:F26) -> TRUE | G35: =G27=SUM(G21:G26) -> TRUE | I35: =I27=SUM(I21:I26) -> TRUE | J35: =J27=SUM(J21:J26) -> TRUE
E69: =C69-G17 -> 0

Sheet Recaudo ENEL
B2: OPORTUNO | C2: ASE | D2: VALOR 1° Q | E2: NUMERO REG. 1°Q | F2: VALOR 2° Q | G2: NUMERO REG. 2°Q
C3: 1 | D3: 16745673525 | E3: 356945 | F3: 15131451516 | G3: 257196
C4: 2 | D4: 12677941411 | E4: 247628 | F4: 20191843481 | G4: 415819
C5: 3 | D5: 10157711962 | E5: 233934 | F5: 13824429136 | G5: 269019
C6: 4 | D6: 10972037248 | E6: 193770 | F6: 6638974137 | G6: 116956
C7: 5 | D7: 8639656940 | E7: 172542 | F7: 12022816376 | G7: 242887
C8: X
D9: 59193021086 | E9: 1204819 | F9: 67809514646 | G9: 1301877
C11: ASE | D11: VALOR 1° Q | E11: NUMERO REG. 1°Q | F11: VALOR 2° Q | G11: NUMERO REG. 2°Q
B12: EXTEMP. | C12: 1 | D12: 202711553 | E12: 2558 | F12: 175327928 | G12: 2824
C13: 2 | D13: 73096641 | E13: 1473 | F13: 49072267 | G13: 722
C14: 3 | D14: 51248640 | E14: 963 | F14: 67822789 | G14: 1184
C15: 4 | D15: 62236830 | E15: 857 | F15: 72481595 | G15: 1595
C16: 5 | D16: 158575115 | E16: 2854 | F16: 25848890 | G16: 515
C17: X
D18: 547868779 | E18: 8705 | F18: 390553469 | G18: 6840
C20: ASE | D20: VALOR 1° Q | E20: NUMERO REG. 1°Q | F20: VALOR 2° Q | G20: NUMERO REG. 2°Q | I20: VALOR TOTAL MES | J20: NUMERO REGISTROS MES
B21: TOTAL | C21: 1 | D21: 16948385078 | E21: 359503 | F21: 15306779444 | G21: 260020 | I21: 32255164522 | J21: 619523
C22: 2 | D22: 12751038052 | E22: 249101 | F22: 20240915748 | G22: 416541 | I22: 32991953800 | J22: 665642
C23: 3 | D23: 10208960602 | E23: 234897 | F23: 13892251925 | G23: 270203 | I23: 24101212527 | J23: 505100
C24: 4 | D24: 11034274078 | E24: 194627 | F24: 6711455732 | G24: 118551 | I24: 17745729810 | J24: 313178
C25: 5 | D25: 8798232055 | E25: 175396 | F25: 12048665266 | G25: 243402 | I25: 20846897321 | J25: 418798
C26: X | I26: 0 | J26: 0
D27: 59740889865 | E27: 1213524 | F27: 68200068115 | G27: 1308717 | I27: 127940957980 | J27: 2522241
B31: OPORTUNO | D31: =D9=SUM(D3:D8) -> TRUE | E31: =E9=SUM(E3:E8) -> TRUE | F31: =F9=SUM(F3:F8) -> TRUE | G31: =G9=SUM(G3:G8) -> TRUE
B33: EXTEMP. | D33: =D18=SUM(D12:D17) -> TRUE | E33: =E18=SUM(E12:E17) -> TRUE | F33: =F18=SUM(F12:F17) -> TRUE | G33: =G18=SUM(G12:G17) -> TRUE
B35: TOTAL | D35: =D27=SUM(D21:D26) -> TRUE | E35: =E27=SUM(E21:E26) -> TRUE | F35: =F27=SUM(F21:F26) -> TRUE | G35: =G27=SUM(G21:G26) -> TRUE | I35: =I27=SUM(I21:I26) -> TRUE | J35: =J27=SUM(J21:J26) -> TRUE
E69: =C69-G17 -> 0

Sheet Recaudo ENERBIT
B2: OPORTUNO | C2: ASE | D2: VALOR 1° Q | E2: NUMERO REG. 1°Q | F2: VALOR 2° Q | G2: NUMERO REG. 2°Q
C3: 1 | D3: 0 | E3: 0 | F3: 0 | G3: 0
C4: 2 | D4: 0 | E4: 0 | F4: 0 | G4: 0
C5: 3 | D5: 0 | E5: 0 | F5: 0 | G5: 0
C6: 4 | D6: 0 | E6: 0 | F6: 0 | G6: 0
C7: 5 | D7: 137371512 | E7: 3020 | F7: 33627704 | G7: 521
C8: X
D9: 137371512 | E9: 3020 | F9: 33627704 | G9: 521
C11: ASE | D11: VALOR 1° Q | E11: NUMERO REG. 1°Q | F11: VALOR 2° Q | G11: NUMERO REG. 2°Q
B12: EXTEMP. | C12: 1 | D12: 0 | E12: 0 | F12: 0 | G12: 0
C13: 2 | D13: 0 | E13: 0 | F13: 0 | G13: 0
C14: 3 | D14: 0 | E14: 0 | F14: 0 | G14: 0
C15: 4 | D15: 0 | E15: 0 | F15: 0 | G15: 0
C16: 5 | D16: 1179300 | E16: 6 | F16: 5242682 | G16: 76
C17: X
D18: 1179300 | E18: 6 | F18: 5242682 | G18: 76
C20: ASE | D20: VALOR 1° Q | E20: NUMERO REG. 1°Q | F20: VALOR 2° Q | G20: NUMERO REG. 2°Q | I20: VALOR TOTAL MES | J20: NUMERO REGISTROS MES
B21: TOTAL | C21: 1 | D21: 0 | E21: 0 | F21: 0 | G21: 0 | I21: 0 | J21: 0
C22: 2 | D22: 0 | E22: 0 | F22: 0 | G22: 0 | I22: 0 | J22: 0
C23: 3 | D23: 0 | E23: 0 | F23: 0 | G23: 0 | I23: 0 | J23: 0
C24: 4 | D24: 0 | E24: 0 | F24: 0 | G24: 0 | I24: 0 | J24: 0
C25: 5 | D25: 138550812 | E25: 3026 | F25: 38870386 | G25: 597 | I25: 177421198 | J25: 3623
C26: X | I26: 0 | J26: 0
D27: 138550812 | E27: 3026 | F27: 38870386 | G27: 597 | I27: 177421198 | J27: 3623
B31: OPORTUNO | D31: =D9=SUM(D3:D8) -> TRUE | E31: =E9=SUM(E3:E8) -> TRUE | F31: =F9=SUM(F3:F8) -> TRUE | G31: =G9=SUM(G3:G8) -> TRUE
B33: EXTEMP. | D33: =D18=SUM(D12:D17) -> TRUE | E33: =E18=SUM(E12:E17) -> TRUE | F33: =F18=SUM(F12:F17) -> TRUE | G33: =G18=SUM(G12:G17) -> TRUE
B35: TOTAL | D35: =D27=SUM(D21:D26) -> TRUE | E35: =E27=SUM(E21:E26) -> TRUE | F35: =F27=SUM(F21:F26) -> TRUE | G35: =G27=SUM(G21:G26) -> TRUE | I35: =I27=SUM(I21:I26) -> TRUE | J35: =J27=SUM(J21:J26) -> TRUE
E69: =C69-G17 -> 0

Sheet Recaudo EAAB + Ciud Limp
B2: Ciudad Limpia - Prestador | C2: ASE | D2: VALOR 1° Q | E2: NUMERO REG. 1°Q | F2: VALOR 2° Q | G2: NUMERO REG. 2°Q
C3: 1 | D3: 0 | E3: 0 | F3: 0 | G3: 0
C4: 2 | D4: 0 | E4: 0 | F4: 0 | G4: 0
C5: 3 | D5: 0 | E5: 0 | F5: 0 | G5: 0
C6: 4 | D6: 0 | E6: 0 | F6: 0 | G6: 0
C7: 5 | D7: 0 | E7: 0 | F7: 0 | G7: 0
C8: X
D9: 0 | E9: 0 | F9: 0 | G9: 0
C11: ASE | D11: VALOR 1° Q | E11: NUMERO REG. 1°Q | F11: VALOR 2° Q | G11: NUMERO REG. 2°Q
B12: EAAB - Prestador | C12: 1 | D12: 0 | E12: 0 | F12: 0 | G12: 0
C13: 2 | D13: 0 | E13: 0 | F13: 0 | G13: 0
C14: 3 | D14: 0 | E14: 0 | F14: 0 | G14: 0
C15: 4 | D15: 0 | E15: 0 | F15: 0 | G15: 0
C16: 5 | D16: 0 | E16: 0 | F16: 0 | G16: 0
C17: X
D18: 0 | E18: 0 | F18: 0 | G18: 0
C20: ASE | D20: VALOR 1° Q | E20: NUMERO REG. 1°Q | F20: VALOR 2° Q | G20: NUMERO REG. 2°Q | I20: VALOR TOTAL MES | J20: NUMERO REGISTROS MES
B21: TOTAL | C21: 1 | D21: 0 | E21: 0 | F21: 0 | G21: 0 | I21: 0 | J21: 0
C22: 2 | D22: 0 | E22: 0 | F22: 0 | G22: 0 | I22: 0 | J22: 0
C23: 3 | D23: 0 | E23: 0 | F23: 0 | G23: 0 | I23: 0 | J23: 0
C24: 4 | D24: 0 | E24: 0 | F24: 0 | G24: 0 | I24: 0 | J24: 0
C25: 5 | D25: 0 | E25: 0 | F25: 0 | G25: 0 | I25: 0 | J25: 0
C26: X | I26: 0 | J26: 0
D27: 0 | E27: 0 | F27: 0 | G27: 0 | I27: 0 | J27: 0
B31: OPORTUNO | D31: =D9=SUM(D3:D8) -> TRUE | E31: =E9=SUM(E3:E8) -> TRUE | F31: =F9=SUM(F3:F8) -> TRUE | G31: =G9=SUM(G3:G8) -> TRUE
B33: EXTEMP. | D33: =D18=SUM(D12:D17) -> TRUE | E33: =E18=SUM(E12:E17) -> TRUE | F33: =F18=SUM(F12:F17) -> TRUE | G33: =G18=SUM(G12:G17) -> TRUE
B35: TOTAL | D35: =D27=SUM(D21:D26) -> TRUE | E35: =E27=SUM(E21:E26) -> TRUE | F35: =F27=SUM(F21:F26) -> TRUE | G35: =G27=SUM(G21:G26) -> TRUE | I35: =I27=SUM(I21:I26) -> TRUE | J35: =J27=SUM(J21:J26) -> TRUE

Sheet Recaudo Directa Occidente
B2: OPORTUNO | C2: ASE | D2: VALOR 1° Q | E2: NUMERO REG. 1°Q | F2: VALOR 2° Q | G2: NUMERO REG. 2°Q
C3: 1 | D3: 510782327 | E3: 2083 | F3: 659215777 | G3: 2359
C4: 2 | D4: 1360190364 | E4: 4795 | F4: 1939956060 | G4: 8702
C5: 3 | D5: 650826874 | E5: 1469 | F5: 1048706515 | G5: 1996
C6: 4 | D6: 515587332 | E6: 3012 | F6: 920907421 | G6: 4189
C7: 5 | D7: 224557157 | E7: 1221 | F7: 278031281 | G7: 1447
C8: X | D8: 0 | E8: 0 | F8: 437900 | G8: 1
D9: 3261944054 | E9: 12580 | F9: 4847254954 | G9: 18694
C11: ASE | D11: VALOR 1° Q | E11: NUMERO REG. 1°Q | F11: VALOR 2° Q | G11: NUMERO REG. 2°Q
B12: EXTEMP. | C12: 1 | D12: 23795111 | E12: 50 | F12: 118038698 | G12: 431
C13: 2 | D13: 62759499 | E13: 134 | F13: 234466650 | G13: 488
C14: 3 | D14: 48196023 | E14: 55 | F14: 422530889 | G14: 69
C15: 4 | D15: 5014320 | E15: 32 | F15: 111430406 | G15: 150
C16: 5 | D16: 14004529 | E16: 30 | F16: 2852410 | G16: 32
C17: X | D17: 0 | E17: 0 | F17: 0 | G17: 0
D18: 153769482 | E18: 301 | F18: 889319053 | G18: 1170
C20: ASE | D20: VALOR 1° Q | E20: NUMERO REG. 1°Q | F20: VALOR 2° Q | G20: NUMERO REG. 2°Q | I20: VALOR TOTAL MES | J20: NUMERO REGISTROS MES
B21: TOTAL | C21: 1 | D21: 534577438 | E21: 2133 | F21: 777254475 | G21: 2790 | I21: 1311831913 | J21: 4923
C22: 2 | D22: 1422949863 | E22: 4929 | F22: 2174422710 | G22: 9190 | I22: 3597372573 | J22: 14119
C23: 3 | D23: 699022897 | E23: 1524 | F23: 1471237404 | G23: 2065 | I23: 2170260301 | J23: 3589
C24: 4 | D24: 520601652 | E24: 3044 | F24: 1032337827 | G24: 4339 | I24: 1552939479 | J24: 7383
C25: 5 | D25: 238561686 | E25: 1251 | F25: 280883691 | G25: 1479 | I25: 519445377 | J25: 2730
C26: X | D26: 0 | E26: 0 | F26: 437900 | G26: 1 | I26: 437900 | J26: 1
D27: 3415713536 | E27: 12881 | F27: 5736574007 | G27: 19864 | I27: 9152287543 | J27: 32745
B31: OPORTUNO | D31: =D9=SUM(D3:D8) -> TRUE | E31: =E9=SUM(E3:E8) -> TRUE | F31: =F9=SUM(F3:F8) -> TRUE | G31: =G9=SUM(G3:G8) -> TRUE
B33: EXTEMP. | D33: =D18=SUM(D12:D17) -> TRUE | E33: =E18=SUM(E12:E17) -> TRUE | F33: =F18=SUM(F12:F17) -> TRUE | G33: =G18=SUM(G12:G17) -> TRUE
B35: TOTAL | D35: =D27=SUM(D21:D26) -> TRUE | E35: =E27=SUM(E21:E26) -> TRUE | F35: =F27=SUM(F21:F26) -> TRUE | G35: =G27=SUM(G21:G26) -> TRUE | I35: =I27=SUM(I21:I26) -> TRUE | J35: =J27=SUM(J21:J26) -> TRUE
E69: =C69-G17 -> 0

Sheet REPORTE RECAUDO x BANCO
C1: ENEL | D1: CIUDAD LIMPIA | E1: EAB | F1: NUEVO ESQUEMA | G1: ENERBIT | H1: OCCIDENTE | I1: Total
B2: 1-APLICADOS A FACTURACION | C2: =C13+C23+C32+C41+C51 -> 68070277487 | D2: =D13+D23+D32+D41+D51 -> 0 | E2: =E13+E23+E32+E41+E51 -> 0 | F2: =F13+F23+F32+F41+F51 -> 2329750 | G2: =G13+G23+G32+G41+G51 -> 34785208 | H2: =H13+H23+H32+H41+H51 -> 5.3054052e+09 | I2: =SUM(C2:H2) -> 7.3412798e+10
B3: 2-SALDOS A FAVOR GENERADOS | C3: =C14+C24+C33+C42+C52 -> 135065158 | D3: =D14+D24+D33+D42+D52 -> 0 | E3: =E14+E24+E33+E42+E52 -> 0 | F3: =F14+F24+F33+F42+F52 -> 3874341 | G3: =G14+G24+G33+G42+G52 -> 4085178 | H3: =H14+H24+H33+H42+H52 -> 3.811974e+08 | I3: =SUM(C3:H3) -> 5.2422208e+08
B4: 3-APLICADOS A FINANCIACIONES NUEVAS | C4: =C15+C25+C34+C43+C53 -> 0 | D4: =D15+D25+D34+D43+D53 -> 0 | E4: =E15+E25+E34+E43+E53 -> 0 | F4: =F15+F25+F34+F43+F53 -> 0 | G4: =G15+G25+G34+G43+G53 -> 0 | H4: =H15+H25+H34+H43+H53 -> 49533469 | I4: =SUM(C4:H4) -> 49533469
B5: 7-APLICADOS A RECIBOS SERVICIOS ESPECIALES | C5: =C16+C26+C35+C44+C54 -> 0 | D5: =D16+D26+D35+D44+D54 -> 0 | E5: =E16+E26+E35+E44+E54 -> 0 | F5: =F16+F26+F35+F44+F54 -> 0 | G5: =G16+G26+G35+G44+G54 -> 0 | H5: =H16+H26+H35+H44+H54 -> 0 | I5: =SUM(C5:H5) -> 0
B6: Total | C6: =SUM(C2:C5) -> 68205342645 | D6: =SUM(D2:D5) -> 0 | E6: =SUM(E2:E5) -> 0 | F6: =SUM(F2:F5) -> 6204091 | G6: =SUM(G2:G5) -> 38870386 | H6: =SUM(H2:H5) -> 5.7361361e+09 | I6: =SUM(I2:I5) -> 73986553229
C7: =C6=(C17+C27+C36+C45+C55) -> TRUE | D7: =D6=(D17+D27+D36+D45+D55) -> TRUE | E7: =E6=(E17+E27+E36+E45+E55) -> TRUE | F7: =F6=(F17+F27+F36+F45+F55) -> TRUE | H7: =H6=(H17+H27+H36+H45+H55) -> TRUE | I7: =I6=(I17+I27+I36+I45+I55) -> TRUE
B10: ASE 1
B11: Resumen Recaudo Aplicado Por Servicio
C12: ENEL | D12: CIUDAD LIMPIA | E12: EAB | F12: NUEVO ESQUEMA | G12: ENERBIT | H12: OCCIDENTE | I12: Total
B13: 1-APLICADOS A FACTURACION | C13: 15275852337 | H13: 7.2951372e+08 | I13: =SUM(C13:H13) -> 1.6005366e+10 | J13: =SUM(C13:H13)=I13 -> TRUE
B14: 2-SALDOS A FAVOR GENERADOS | C14: 30927107 | H14: 34356276 | I14: =SUM(C14:H14) -> 65283383 | J14: =SUM(C14:H14)=I14 -> TRUE
B15: 3-APLICADOS A FINANCIACIONES NUEVAS | C15: 0 | H15: 13384481 | I15: =SUM(C15:H15) -> 13384481 | J15: =SUM(C15:H15)=I15 -> TRUE
B16: 7-APLICADOS A RECIBOS SERVICIOS ESPECIALES | C16: 0 | I16: =SUM(C16:H16) -> 0 | J16: =SUM(C16:H16)=I16 -> TRUE
B17: Total | C17: =SUM(C13:C16) -> 15306779444 | D17: =SUM(D13:D16) -> 0 | E17: =SUM(E13:E16) -> 0 | F17: =SUM(F13:F16) -> 0 | G17: =SUM(G13:G16) -> 0 | H17: =SUM(H13:H16) -> 7.7725448e+08 | I17: =SUM(I13:I16) -> 1.6084034e+10 | J17: =SUM(C17:H17)=I17 -> TRUE
B20: ASE 2
B21: Resumen Recaudo Aplicado Por Servicio
C22: ENEL | D22: CIUDAD LIMPIA | E22: EAB | F22: NUEVO ESQUEMA | G22: ENERBIT | H22: OCCIDENTE | I22: Total
B23: 1-APLICADOS A FACTURACION | C23: 20206354631 | E23: 0 | F23: 1778140 | H23: 2.049434e+09 | I23: =SUM(C23:H23) -> 2.2257567e+10 | J23: =SUM(C23:H23)=I23 -> TRUE
B24: 2-SALDOS A FAVOR GENERADOS | C24: 37168207 | E24: 0 | F24: 2611951 | H24: 1.1706611e+08 | I24: =SUM(C24:H24) -> 1.5684627e+08 | J24: =SUM(C24:H24)=I24 -> TRUE
B25: 3-APLICADOS A FINANCIACIONES NUEVAS | C25: 0 | E25: 0 | F25: 0 | H25: 7922640.9 | I25: =SUM(C25:H25) -> 7922640.9 | J25: =SUM(C25:H25)=I25 -> TRUE
B26: 7-APLICADOS A RECIBOS SERVICIOS ESPECIALES | F26: 0 | H26: 0 | I26: =SUM(C26:H26) -> 0 | J26: =SUM(C26:H26)=I26 -> TRUE
B27: Total | C27: =SUM(C23:C26) -> 20243522838 | D27: =SUM(D23:D26) -> 0 | E27: =SUM(E23:E26) -> 0 | F27: =SUM(F23:F26) -> 4390091 | G27: =SUM(G23:G26) -> 0 | H27: =SUM(H23:H26) -> 2174422710 | I27: =SUM(I23:I26) -> 2.2422336e+10 | J27: =SUM(C27:H27)=I27 -> TRUE
B29: ASE 3
B30: Resumen Recaudo Aplicado Por Servicio
C31: ENEL | D31: CIUDAD LIMPIA | E31: EAB | F31: NUEVO ESQUEMA | G31: ENERBIT | H31: OCCIDENTE | I31: Total
B32: 1-APLICADOS A FACTURACION | C32: 13883027309 | F32: 0 | H32: 1.2760545e+09 | I32: =SUM(C32:H32) -> 1.5159082e+10 | J32: =SUM(C32:H32)=I32 -> TRUE
B33: 2-SALDOS A FAVOR GENERADOS | C33: 10762026 | F33: 0 | H33: 1.9018313e+08 | I33: =SUM(C33:H33) -> 2.0094516e+08 | J33: =SUM(C33:H33)=I33 -> TRUE
B34: 3-APLICADOS A FINANCIACIONES NUEVAS | C34: 0 | F34: 0 | H34: 4999782.5 | I34: =SUM(C34:H34) -> 4999782.5 | J34: =SUM(C34:H34)=I34 -> TRUE
B35: 7-APLICADOS A RECIBOS SERVICIOS ESPECIALES | C35: 0 | F35: 0 | I35: =SUM(C35:H35) -> 0 | J35: =SUM(C35:H35)=I35 -> TRUE
B36: Total | C36: =SUM(C32:C35) -> 13893789335 | D36: =SUM(D32:D35) -> 0 | E36: =SUM(E32:E35) -> 0 | F36: =SUM(F32:F35) -> 0 | G36: =SUM(G32:G35) -> 0 | H36: =SUM(H32:H35) -> 1471237404 | I36: =SUM(I32:I35) -> 1.5365027e+10 | J36: =SUM(C36:H36)=I36 -> TRUE
B38: ASE 4
B39: Resumen Recaudo Aplicado Por Servicio
C40: ENEL | D40: CIUDAD LIMPIA | E40: EAB | F40: NUEVO ESQUEMA | G40: ENERBIT | H40: OCCIDENTE | I40: Total
B41: 1-APLICADOS A FACTURACION | C41: 6664014596 | E41: 0 | F41: 551610 | H41: 9.857407e+08 | I41: =SUM(C41:H41) -> 7.6503069e+09 | J41: =SUM(C41:H41)=I41 -> TRUE
B42: 2-SALDOS A FAVOR GENERADOS | C42: 48073886 | E42: 0 | F42: 1262390 | H42: 24854028 | I42: =SUM(C42:H42) -> 74190304 | J42: =SUM(C42:H42)=I42 -> TRUE
B43: 3-APLICADOS A FINANCIACIONES NUEVAS | C43: 0 | E43: 0 | F43: 0 | H43: 21743103 | I43: =SUM(C43:H43) -> 21743103 | J43: =SUM(C43:H43)=I43 -> TRUE
B44: 7-APLICADOS A RECIBOS SERVICIOS ESPECIALES | I44: =SUM(C44:H44) -> 0 | J44: =SUM(C44:H44)=I44 -> TRUE
B45: Total | C45: =SUM(C41:C44) -> 6712088482 | D45: =SUM(D41:D44) -> 0 | E45: =SUM(E41:E44) -> 0 | F45: =SUM(F41:F44) -> 1814000 | G45: =SUM(G41:G44) -> 0 | H45: =SUM(H41:H44) -> 1032337827 | I45: =SUM(I41:I44) -> 7.7462403e+09 | J45: =SUM(C45:H45)=I45 -> TRUE
B48: ASE 5
...

Sheet ANT EXT-REV
C1: ASE 1 | E1: ASE 2 | G1: ASE 3 | I1: ASE 4 | K1: ASE 5 | M1: TOTAL
C2: REPORTE 3 | D2: REPORTE 4 | E2: REPORTE 3 | F2: REPORTE 4 | G2: REPORTE 3 | H2: REPORTE 4 | I2: REPORTE 3 | J2: REPORTE 4 | K2: REPORTE 3 | L2: REPORTE 4 | M2: REPORTE 3 | N2: REPORTE 4
B3: APLICADO | C3: =C11+C19+C27+C35+C43 -> 40070 | D3: =D11+D19+D27+D35+D43 -> -1285060 | E3: =E11+E19+E27+E35+E43 -> 18014168 | F3: =F11+F19+F27+F35+F43 -> -45230052 | G3: =G11+G19+G27+G35+G43 -> 388550 | H3: =H11+H19+H27+H35+H43 -> -7715664 | I3: =I11+I19+I27+I35+I43 -> 83364801 | J3: =J11+J19+J27+J35+J43 -> -1.7861971e+08 | ... L3: =L11+L19+L27+L35+L43 -> -4790099 | M3: =C3+E3+G3+I3+K3 -> 1.0180759e+08 | N3: =D3+F3+H3+J3+L3 -> -2.3764058e+08 | P3: =N3=(-VALIDACION_TOTAL!M9) -> TRUE
B4: ANTICIPOS | C4: =C12+C20+C28+C36+C44 -> 691640 | D4: =D12+D20+D28+D36+D44 -> -137440 | E4: =E12+E20+E28+E36+E44 -> 12142859 | F4: =F12+F20+F28+F36+F44 -> -139792 | G4: =G12+G20+G28+G36+G44 -> 1272990 | H4: =H12+H20+H28+H36+H44 -> -541790 | I4: =I12+I20+I28+I36+I44 -> 91642042 | J4: =J12+J20+J28+J36+J44 -> -780507.47 | ... L4: =L12+L20+L28+L36+L44 -> 0 | M4: =C4+E4+G4+I4+K4 -> 1.0574953e+08 | N4: =D4+F4+H4+J4+L4 -> -1599529.5 | P4: =N4=(-'CONSOLIDADO_TOTAL RECAUDO'!L131) -> TRUE
B5: TOTAL | C5: =SUM(C3:C4) -> 731710 | D5: =SUM(D3:D4) -> -1422500 | E5: =SUM(E3:E4) -> 30157027 | F5: =SUM(F3:F4) -> -45369844 | G5: =SUM(G3:G4) -> 1661540 | H5: =SUM(H3:H4) -> -8257454 | I5: =SUM(I3:I4) -> 175006843 | J5: =SUM(J3:J4) -> -179400217 | ... N5: =SUM(N3:N4) -> -239240114
C6: =C5=(C13+C21+C29+C37+C45) -> TRUE | D6: =D5=(D13+D21+D29+D37+D45) -> TRUE | E6: =E5=(E13+E21+E29+E37+E45) -> TRUE | F6: =F5=(F13+F21+F29+F37+F45) -> TRUE | G6: =G5=(G13+G21+G29+G37+G45) -> TRUE | H6: =H5=(H13+H21+H29+H37+H45) -> TRUE | I6: =I5=(I13+I21+I29+I37+I45) -> TRUE | J6: =J5=(J13+J21+J29+J37+J45) -> TRUE | ... N6: =N5=(N13+N21+N29+N37+N45) -> TRUE
B8: BANCO DE OCCIDENTE
C9: ASE 1 | E9: ASE 2 | G9: ASE 3 | I9: ASE 4 | K9: ASE 5 | M9: TOTAL
C10: REPORTE 3 | D10: REPORTE 4 | E10: REPORTE 3 | F10: REPORTE 4 | G10: REPORTE 3 | H10: REPORTE 4 | I10: REPORTE 3 | J10: REPORTE 4 | K10: REPORTE 3 | L10: REPORTE 4 | M10: REPORTE 3 | N10: REPORTE 4
B11: APLICADO | C11: 40070 | D11: -40070 | E11: 1003966 | F11: -3643056 | G11: 0 | H11: 0 | I11: 5075866 | J11: -9398936.9 | K11: 0 | L11: 0 | M11: =C11+E11+G11+I11+K11 -> 6119902 | N11: =D11+F11+H11+J11+L11 -> -13082063
B12: ANTICIPOS | C12: 0 | D12: 0 | E12: 2673592 | F12: -34502 | G12: 0 | H12: 0 | I12: 4396815 | J12: -73744.13 | K12: 0 | L12: 0 | M12: =C12+E12+G12+I12+K12 -> 7070407 | N12: =D12+F12+H12+J12+L12 -> -108246.13
B13: TOTAL | C13: =SUM(C11:C12) -> 40070 | D13: =SUM(D11:D12) -> -40070 | E13: =SUM(E11:E12) -> 3677558 | F13: =SUM(F11:F12) -> -3677558 | G13: =SUM(G11:G12) -> 0 | H13: =SUM(H11:H12) -> 0 | I13: =SUM(I11:I12) -> 9472681 | J13: =SUM(J11:J12) -> -9472681 | ... N13: =SUM(N11:N12) -> -13190309
B16: EAAB RECIPROCIDAD
C17: ASE 1 | E17: ASE 2 | G17: ASE 3 | I17: ASE 4 | K17: ASE 5 | M17: TOTAL
C18: REPORTE 3 | D18: REPORTE 4 | E18: REPORTE 3 | F18: REPORTE 4 | G18: REPORTE 3 | H18: REPORTE 4 | I18: REPORTE 3 | J18: REPORTE 4 | K18: REPORTE 3 | L18: REPORTE 4 | M18: REPORTE 3 | N18: REPORTE 4
B19: APLICADO | C19: 0 | D19: 0 | E19: 0 | F19: -46130 | G19: 0 | H19: 0 | I19: 477310 | J19: -1564160 | K19: 0 | L19: 0 | M19: =C19+E19+G19+I19+K19 -> 477310 | N19: =D19+F19+H19+J19+L19 -> -1610290
B20: ANTICIPOS | C20: 0 | D20: 0 | E20: 46130 | F20: 0 | G20: 0 | H20: 0 | I20: 1086850 | K20: 0 | L20: 0 | M20: =C20+E20+G20+I20+K20 -> 1132980 | N20: =D20+F20+H20+J20+L20 -> 0
B21: TOTAL | C21: =SUM(C19:C20) -> 0 | D21: =SUM(D19:D20) -> 0 | E21: =SUM(E19:E20) -> 46130 | F21: =SUM(F19:F20) -> -46130 | G21: =SUM(G19:G20) -> 0 | H21: =SUM(H19:H20) -> 0 | I21: =SUM(I19:I20) -> 1564160 | J21: =SUM(J19:J20) -> -1564160 | ... L21: =SUM(L19:L20) -> 0 | M21: =C21+E21+G21+I21+K21 -> 1610290 | N21: =SUM(N19:N20) -> -1610290
B24: EAAB CIUDAD LIMPIA
C25: ASE 1 | E25: ASE 2 | G25: ASE 3 | I25: ASE 4 | K25: ASE 5 | M25: TOTAL
C26: REPORTE 3 | D26: REPORTE 4 | E26: REPORTE 3 | F26: REPORTE 4 | G26: REPORTE 3 | H26: REPORTE 4 | I26: REPORTE 3 | J26: REPORTE 4 | K26: REPORTE 3 | L26: REPORTE 4 | M26: REPORTE 3 | N26: REPORTE 4
B27: APLICADO | C27: 0 | D27: 0 | E27: 0 | F27: 0 | G27: 0 | H27: 0 | I27: 0 | J27: 0 | K27: 0 | L27: 0 | M27: =C27+E27+G27+I27+K27 -> 0 | N27: =D27+F27+H27+J27+L27 -> 0
B28: ANTICIPOS | C28: 0 | D28: 0 | E28: 0 | F28: 0 | G28: 0 | H28: 0 | I28: 0 | J28: 0 | K28: 0 | L28: 0 | M28: =C28+E28+G28+I28+K28 -> 0 | N28: =D28+F28+H28+J28+L28 -> 0
B29: TOTAL | C29: =SUM(C27:C28) -> 0 | D29: =SUM(D27:D28) -> 0 | E29: =SUM(E27:E28) -> 0 | F29: =SUM(F27:F28) -> 0 | G29: =SUM(G27:G28) -> 0 | H29: =SUM(H27:H28) -> 0 | I29: =SUM(I27:I28) -> 0 | J29: =SUM(J27:J28) -> 0 | ... N29: =SUM(N27:N28) -> 0
B32: ENEL
C33: ASE 1 | E33: ASE 2 | G33: ASE 3 | I33: ASE 4 | K33: ASE 5 | M33: TOTAL
C34: REPORTE 3 | D34: REPORTE 4 | E34: REPORTE 3 | F34: REPORTE 4 | G34: REPORTE 3 | H34: REPORTE 4 | I34: REPORTE 3 | J34: REPORTE 4 | K34: REPORTE 3 | L34: REPORTE 4 | M34: REPORTE 3 | N34: REPORTE 4
B35: APLICADO | C35: 0 | D35: -1244990 | E35: 17010202 | F35: -41540866 | G35: 388550 | H35: -7715664 | I35: 77811625 | J35: -1.6765661e+08 | K35: 0 | L35: -4790099 | M35: =C35+E35+G35+I35+K35 -> 95210377 | N35: =D35+F35+H35+J35+L35 -> -2.2294823e+08
B36: ANTICIPOS | C36: 691640 | D36: -137440 | E36: 9423137 | F36: -105290 | G36: 1272990 | H36: -541790 | I36: 86158377 | J36: -706763.34 | K36: 0 | L36: 0 | M36: =C36+E36+G36+I36+K36 -> 97546144 | N36: =D36+F36+H36+J36+L36 -> -1491283.3
B37: TOTAL | C37: =SUM(C35:C36) -> 691640 | D37: =SUM(D35:D36) -> -1382430 | E37: =SUM(E35:E36) -> 26433339 | F37: =SUM(F35:F36) -> -41646156 | G37: =SUM(G35:G36) -> 1661540 | H37: =SUM(H35:H36) -> -8257454 | I37: =SUM(I35:I36) -> 163970002 | J37: =SUM(J35:J36) -> -168363376 | ... N37: =SUM(N35:N36) -> -224439515
B40: ENERBIT
C41: ASE 1 | E41: ASE 2 | G41: ASE 3 | I41: ASE 4 | K41: ASE 5 | M41: TOTAL
C42: REPORTE 3 | D42: REPORTE 4 | E42: REPORTE 3 | F42: REPORTE 4 | G42: REPORTE 3 | H42: REPORTE 4 | I42: REPORTE 3 | J42: REPORTE 4 | K42: REPORTE 3 | L42: REPORTE 4 | M42: REPORTE 3 | N42: REPORTE 4
B43: APLICADO | C43: 0 | D43: 0 | E43: 0 | F43: 0 | G43: 0 | H43: 0 | I43: 0 | J43: 0 | K43: 0 | L43: 0 | M43: =C43+E43+G43+I43+K43 -> 0 | N43: =D43+F43+H43+J43+L43 -> 0
B44: ANTICIPOS | C44: 0 | D44: 0 | E44: 0 | F44: 0 | G44: 0 | H44: 0 | I44: 0 | J44: 0 | K44: 0 | L44: 0 | M44: =C44+E44+G44+I44+K44 -> 0 | N44: =D44+F44+H44+J44+L44 -> 0
B45: TOTAL | C45: =SUM(C43:C44) -> 0 | D45: =SUM(D43:D44) -> 0 | E45: =SUM(E43:E44) -> 0 | F45: =SUM(F43:F44) -> 0 | G45: =SUM(G43:G44) -> 0 | H45: =SUM(H43:H44) -> 0 | I45: =SUM(I43:I44) -> 0 | J45: =SUM(J43:J44) -> 0 | ... N45: =SUM(N43:N44) -> 0

Sheet ANTICIPOS USUARIOS
B1: TOTAL | E1: RECIPRCIDAD | H1: ENEL | K1: ENERBIT | N1: OCCIDENTE | Q1: EAAB-CIUDADLIMPIA
B2: ASE | C2: ANTICIPOS GENERADOS POR PAGO | E2: ASE | F2: ANTICIPOS GENERADOS POR PAGO | H2: ASE | I2: ANTICIPOS GENERADOS POR PAGO | K2: ASE | L2: ANTICIPOS GENERADOS POR PAGO | N2: ASE | O2: ANTICIPOS GENERADOS POR PAGO | Q2: ASE | R2: ANTICIPOS GENERADOS POR PAGO | T2: Anticipos generados por pago
B3: 1 | C3: ='REPORTE RECAUDO x BANCO'!I14 -> 65283383 | E3: 1 | F3: ='REPORTE RECAUDO x BANCO'!F14 -> 0 | H3: 1 | I3: ='REPORTE RECAUDO x BANCO'!C14 -> 30927107 | K3: 1 | L3: ='REPORTE RECAUDO x BANCO'!G14 -> 0 | N3: 1 | O3: ='REPORTE RECAUDO x BANCO'!H14 -> 34356276 | Q3: 1 | R3: ='REPORTE RECAUDO x BANCO'!D14+'REPORTE RECAUDO x BANCO'!E14 -> 0 | T3: Sale del reporte Recaudo por Bancos.
B4: 2 | C4: ='REPORTE RECAUDO x BANCO'!I24 -> 1.5684627e+08 | E4: 2 | F4: ='REPORTE RECAUDO x BANCO'!F24 -> 2611951 | H4: 2 | I4: ='REPORTE RECAUDO x BANCO'!C24 -> 37168207 | K4: 2 | L4: ='REPORTE RECAUDO x BANCO'!G24 -> 0 | N4: 2 | O4: ='REPORTE RECAUDO x BANCO'!H24 -> 1.1706611e+08 | Q4: 2 | R4: ='REPORTE RECAUDO x BANCO'!D24+'REPORTE RECAUDO x BANCO'!E24 -> 0
B5: 3 | C5: ='REPORTE RECAUDO x BANCO'!I33 -> 2.0094516e+08 | E5: 3 | F5: ='REPORTE RECAUDO x BANCO'!F33 -> 0 | H5: 3 | I5: ='REPORTE RECAUDO x BANCO'!C33 -> 10762026 | K5: 3 | L5: ='REPORTE RECAUDO x BANCO'!G33 -> 0 | N5: 3 | O5: ='REPORTE RECAUDO x BANCO'!H33 -> 1.9018313e+08 | Q5: 3 | R5: ='REPORTE RECAUDO x BANCO'!D33+'REPORTE RECAUDO x BANCO'!E33 -> 0
B6: 4 | C6: ='REPORTE RECAUDO x BANCO'!I42 -> 74190304 | E6: 4 | F6: ='REPORTE RECAUDO x BANCO'!F42 -> 1262390 | H6: 4 | I6: ='REPORTE RECAUDO x BANCO'!C42 -> 48073886 | K6: 4 | L6: ='REPORTE RECAUDO x BANCO'!G42 -> 0 | N6: 4 | O6: ='REPORTE RECAUDO x BANCO'!H42 -> 24854028 | Q6: 4 | R6: ='REPORTE RECAUDO x BANCO'!D42+'REPORTE RECAUDO x BANCO'!E42 -> 0
B7: 5 | C7: ='REPORTE RECAUDO x BANCO'!I52 -> 26956968 | E7: 5 | F7: ='REPORTE RECAUDO x BANCO'!F52 -> 0 | H7: 5 | I7: ='REPORTE RECAUDO x BANCO'!C52 -> 8133932 | K7: 5 | L7: ='REPORTE RECAUDO x BANCO'!G52 -> 4085178 | N7: 5 | O7: ='REPORTE RECAUDO x BANCO'!H52 -> 14737858 | Q7: 5 | R7: ='REPORTE RECAUDO x BANCO'!D52+'REPORTE RECAUDO x BANCO'!E52 -> 0
C8: =SUM(C3:C7) -> 5.2422208e+08 | F8: =SUM(F3:F7) -> 3874341 | I8: =SUM(I3:I7) -> 135065158 | L8: =SUM(L3:L7) -> 4085178 | O8: =SUM(O3:O7) -> 3.811974e+08 | R8: =SUM(R3:R7) -> 0
C9: =C8='REPORTE RECAUDO x BANCO'!I3 -> TRUE | F9: =F8='REPORTE RECAUDO x BANCO'!F3 -> TRUE | I9: =I8='REPORTE RECAUDO x BANCO'!C3 -> TRUE | L9: =L8='REPORTE RECAUDO x BANCO'!G3 -> TRUE | O9: =O8='REPORTE RECAUDO x BANCO'!H3 -> TRUE | R9: =R8='REPORTE RECAUDO x BANCO'!D3+'REPORTE RECAUDO x BANCO'!E3 -> TRUE
B11: ASE | C11: ANTICIPOS GENERADOS POR EXTEMPORANEOS | E11: ASE | F11: ANTICIPOS GENERADOS POR EXTEMPORANEOS | H11: ASE | I11: ANTICIPOS GENERADOS POR EXTEMPORANEOS | K11: ASE | L11: ANTICIPOS GENERADOS POR EXTEMPORANEOS | N11: ASE | O11: ANTICIPOS GENERADOS POR EXTEMPORANEOS | Q11: ASE | R11: ANTICIPOS GENERADOS POR EXTEMPORANEOS | T11: Anticipos generados por pagos aplicados de reversiones
B12: 1 | C12: ='ANT EXT-REV'!C4 -> 691640 | E12: 1 | F12: ='ANT EXT-REV'!C20 -> 0 | H12: 1 | I12: ='ANT EXT-REV'!C36 -> 691640 | K12: 1 | L12: ='ANT EXT-REV'!C44 -> 0 | N12: 1 | O12: ='ANT EXT-REV'!C12 -> 0 | Q12: 1 | R12: ='ANT EXT-REV'!C28 -> 0 | T12: Sale del reporte Recaudo reversado
B13: 2 | C13: ='ANT EXT-REV'!E4 -> 12142859 | E13: 2 | F13: ='ANT EXT-REV'!E20 -> 46130 | H13: 2 | I13: ='ANT EXT-REV'!E36 -> 9423137 | K13: 2 | L13: ='ANT EXT-REV'!E44 -> 0 | N13: 2 | O13: ='ANT EXT-REV'!E12 -> 2673592 | Q13: 2 | R13: ='ANT EXT-REV'!E28 -> 0
B14: 3 | C14: ='ANT EXT-REV'!G4 -> 1272990 | E14: 3 | F14: ='ANT EXT-REV'!G20 -> 0 | H14: 3 | I14: ='ANT EXT-REV'!G36 -> 1272990 | K14: 3 | L14: ='ANT EXT-REV'!G44 -> 0 | N14: 3 | O14: ='ANT EXT-REV'!G12 -> 0 | Q14: 3 | R14: ='ANT EXT-REV'!G28 -> 0
B15: 4 | C15: ='ANT EXT-REV'!I4 -> 91642042 | E15: 4 | F15: ='ANT EXT-REV'!I20 -> 1086850 | H15: 4 | I15: ='ANT EXT-REV'!I36 -> 86158377 | K15: 4 | L15: ='ANT EXT-REV'!I44 -> 0 | N15: 4 | O15: ='ANT EXT-REV'!I12 -> 4396815 | Q15: 4 | R15: ='ANT EXT-REV'!I28 -> 0
B16: 5 | C16: ='ANT EXT-REV'!K4 -> 0 | E16: 5 | F16: ='ANT EXT-REV'!K20 -> 0 | H16: 5 | I16: ='ANT EXT-REV'!K36 -> 0 | K16: 5 | L16: ='ANT EXT-REV'!K44 -> 0 | N16: 5 | O16: ='ANT EXT-REV'!K12 -> 0 | Q16: 5 | R16: ='ANT EXT-REV'!K28 -> 0
C17: =SUM(C12:C16) -> 1.0574953e+08 | F17: =SUM(F12:F16) -> 1132980 | I17: =SUM(I12:I16) -> 97546144 | L17: =SUM(L12:L16) -> 0 | O17: =SUM(O12:O16) -> 7070407 | R17: =SUM(R12:R16) -> 0
C18: =C17='ANT EXT-REV'!M4 -> TRUE | F18: =F17='ANT EXT-REV'!M20 -> TRUE | I18: =I17='ANT EXT-REV'!M36 -> TRUE | L18: =L17='ANT EXT-REV'!M44 -> TRUE | O18: =O17='ANT EXT-REV'!M12 -> TRUE | R18: =R17='ANT EXT-REV'!M28 -> TRUE
B20: ASE | C20: ANTICIPOS QUE CARGAN POR REVERSIONES | E20: ASE | F20: ANTICIPOS QUE CARGAN POR REVERSIONES | H20: ASE | I20: ANTICIPOS QUE CARGAN POR REVERSIONES | K20: ASE | L20: ANTICIPOS QUE CARGAN POR REVERSIONES | N20: ASE | O20: ANTICIPOS QUE CARGAN POR REVERSIONES | Q20: ASE | R20: ANTICIPOS QUE CARGAN POR REVERSIONES | T20: Anticipos que cargan de reversiones
B21: 1 | C21: ='ANT EXT-REV'!D4 -> -137440 | E21: 1 | F21: ='ANT EXT-REV'!D20 -> 0 | H21: 1 | I21: ='ANT EXT-REV'!D36 -> -137440 | K21: 1 | L21: ='ANT EXT-REV'!D44 -> 0 | N21: 1 | O21: ='ANT EXT-REV'!D12 -> 0 | Q21: 1 | R21: ='ANT EXT-REV'!D28 -> 0 | T21: Sale del reporte Recaudo reversado
B22: 2 | C22: ='ANT EXT-REV'!F4 -> -139792 | E22: 2 | F22: ='ANT EXT-REV'!F20 -> 0 | H22: 2 | I22: ='ANT EXT-REV'!F36 -> -105290 | K22: 2 | L22: ='ANT EXT-REV'!F44 -> 0 | N22: 2 | O22: ='ANT EXT-REV'!F12 -> -34502 | Q22: 2 | R22: ='ANT EXT-REV'!F28 -> 0
B23: 3 | C23: ='ANT EXT-REV'!H4 -> -541790 | E23: 3 | F23: ='ANT EXT-REV'!H20 -> 0 | H23: 3 | I23: ='ANT EXT-REV'!H36 -> -541790 | K23: 3 | L23: ='ANT EXT-REV'!H44 -> 0 | N23: 3 | O23: ='ANT EXT-REV'!H12 -> 0 | Q23: 3 | R23: ='ANT EXT-REV'!H28 -> 0
B24: 4 | C24: ='ANT EXT-REV'!J4 -> -780507.47 | E24: 4 | F24: ='ANT EXT-REV'!J20 -> 0 | H24: 4 | I24: ='ANT EXT-REV'!J36 -> -706763.34 | K24: 4 | L24: ='ANT EXT-REV'!J44 -> 0 | N24: 4 | O24: ='ANT EXT-REV'!J12 -> -73744.13 | Q24: 4 | R24: ='ANT EXT-REV'!J28 -> 0
B25: 5 | C25: ='ANT EXT-REV'!L4 -> 0 | E25: 5 | F25: ='ANT EXT-REV'!L20 -> 0 | H25: 5 | I25: ='ANT EXT-REV'!L36 -> 0 | K25: 5 | L25: ='ANT EXT-REV'!L44 -> 0 | N25: 5 | O25: ='ANT EXT-REV'!L12 -> 0 | Q25: 5 | R25: ='ANT EXT-REV'!L28 -> 0
C26: =SUM(C21:C25) -> -1599529.5 | F26: =SUM(F21:F25) -> 0 | I26: =SUM(I21:I25) -> -1491283.3 | L26: =SUM(L21:L25) -> 0 | O26: =SUM(O21:O25) -> -108246.13 | R26: =SUM(R21:R25) -> 0
C27: =C26='ANT EXT-REV'!N4 -> TRUE | F27: =F26='ANT EXT-REV'!N20 -> TRUE | I27: =I26='ANT EXT-REV'!N36 -> TRUE | L27: =L26='ANT EXT-REV'!N44 -> TRUE | O27: =O26='ANT EXT-REV'!N12 -> TRUE | R27: =R26='ANT EXT-REV'!N28 -> TRUE

Sheet BCE SC POR FACT.
C2: ASE | D2: SUBSIDIO | E2: CONTRIBUCION | F2: TOTAL BSC | H2: SISTEMA
C3: 1 | D3: -6.6055391e+09 | E3: 2.1040376e+09 | F3: =D3+E3 -> -4.5015016e+09 | H3: =DetRetri2026092!J9 -> -4501501560 | I3: =F3-H3 -> -0.34999943
C4: 2 | D4: -5.5089379e+09 | E4: 1.95863e+09 | F4: =D4+E4 -> -3.5503079e+09 | H4: =DetRetri2026092!J10 -> -3550307908 | I4: =F4-H4 -> -0.4800005
C5: 3 | D5: -2.0642657e+09 | E5: 1.313676e+09 | F5: =D5+E5 -> -7.5058976e+08 | H5: =DetRetri2026092!J11 -> -750589760 | I5: =F5-H5 -> 0.4000001
C6: 4 | D6: -2.5882756e+09 | E6: 1.8741347e+09 | F6: =D6+E6 -> -7.1414094e+08 | H6: =DetRetri2026092!J12 -> -714140939 | I6: =F6-H6 -> -0.3599999
C7: 5 | D7: -1.2358747e+09 | E7: 1.1376358e+09 | F7: =D7+E7 -> -98238892 | H7: =DetRetri2026092!J13 -> -98238892 | I7: =F7-H7 -> 0.059999943
F9: =SUM(F3:F7) -> -9.6147791e+09 | H9: =SUM(H3:H7) -> -9614779059 | I9: =F9-H9 -> -0.73000145
H10: =H9=DetRetri2026092!J14 -> TRUE
D11: =SUM(D3:D7) -> -1.8002893e+10 | E11: =SUM(E3:E7) -> 8.388114e+09 | F11: =SUM(D3:E7) -> -9.6147791e+09
F12: =ROUND(F11,2)=ROUND(F9,2) -> TRUE
F13: =ROUND(F11,2)-ROUND(F9,2) -> 0
D18: ASE | E18: REMUN TOTAL | F18: VALIDA 1 | G18: VALIDA 2 | H18: DIFERENCIA VALIDA 2
D19: 1 | E19: ='CONSOLIDADO_TOTAL RECAUDO'!J104 -> -4.5015016e+09 | F19: =E19=F3 -> TRUE | G19: =E19=H3 -> FALSE | H19: =E19-H3 -> -0.34999943
D20: 2 | E20: ='CONSOLIDADO_TOTAL RECAUDO'!J105 -> -3.5503079e+09 | F20: =E20=F4 -> TRUE | G20: =E20=H4 -> FALSE | H20: =E20-H4 -> -0.4800005
D21: 3 | E21: ='CONSOLIDADO_TOTAL RECAUDO'!J106 -> -7.5058976e+08 | F21: =E21=F5 -> TRUE | G21: =E21=H5 -> FALSE | H21: =E21-H5 -> 0.4000001
D22: 4 | E22: ='CONSOLIDADO_TOTAL RECAUDO'!J107 -> -7.1414094e+08 | F22: =E22=F6 -> TRUE | G22: =E22=H6 -> FALSE | H22: =E22-H6 -> -0.3599999
D23: 5 | E23: ='CONSOLIDADO_TOTAL RECAUDO'!J108 -> -98238892 | F23: =E23=F7 -> TRUE | G23: =E23=H7 -> FALSE | H23: =E23-H7 -> 0.059999943
E24: =SUM(E19:E23) -> -9.6147791e+09 | F24: =E24=F9 -> TRUE | G24: =E24=H9 -> FALSE | H24: =E24-H9 -> -0.73000145

Sheet Reporte Componentes R1
B4: PROMOAMBIENTAL
F5: Total | G5: Componente TDF | H5: Componente TTL | I5: Componente TVIAT | J5: Aprovechamiento | K5: CCSA Prest.Aprov. | L5: SERVICIO ESPECIALES | M5: Componente TCS | N5: Componente TLU | O5: Componente TBL | P5: Componente TRT | Q5: CCSA Prest. No Aprov. | R5: Ajuste Decena | S5: Ajuste Recargo Aseo | T5: Intereses Cte Financiac. Aseo | U5: Exonera-Recargo Aseo | V5: Exonera-Ajuste Decena Aseo | W5: Exonera-Recargo Aseo | X5: Exonera-Recargo Aseo | Y5: Intereses Cte Financiac. Aseo | Z5: Rec.Intereses
E6: Vlr Servicio | F6: -17225.21 | G6: -1127.52 | H6: -479 | I6: -209.2 | J6: -3072.3 | K6: -198.78 | L6: 0 | M6: -1743.38 | N6: -1458.17 | O6: -5823.96 | P6: -2788.6 | Q6: -324.3 | R6: 0 | S6: 0 | T6: 0 | U6: 0 | V6: 0 | W6: 0 | X6: 0 | Y6: 0 | Z6: 0
D7: O | E7: Total | F7: -17225.21 | G7: -1127.52 | H7: -479 | I7: -209.2 | J7: -3072.3 | K7: -198.78 | L7: 0 | M7: -1743.38 | N7: -1458.17 | O7: -5823.96 | P7: -2788.6 | Q7: -324.3 | R7: 0 | S7: 0 | T7: 0 | U7: 0 | V7: 0 | W7: 0 | X7: 0 | Y7: 0 | Z7: 0
C8: OCCIDENTE | D8: Total | F8: -17225.21 | G8: -1127.52 | H8: -479 | I8: -209.2 | J8: -3072.3 | K8: -198.78 | L8: 0 | M8: -1743.38 | N8: -1458.17 | O8: -5823.96 | P8: -2788.6 | Q8: -324.3 | R8: 0 | S8: 0 | T8: 0 | U8: 0 | V8: 0 | W8: 0 | X8: 0 | Y8: 0 | Z8: 0
B9: Mes | C9: Total | F9: -17225.21 | G9: -1127.52 | H9: -479 | I9: -209.2 | J9: -3072.3 | K9: -198.78 | L9: 0 | M9: -1743.38 | N9: -1458.17 | O9: -5823.96 | P9: -2788.6 | Q9: -324.3 | R9: 0 | S9: 0 | T9: 0 | U9: 0 | V9: 0 | W9: 0 | X9: 0 | Y9: 0 | Z9: 0
A10: AFaseo | B10: Total | F10: -17225.21 | G10: -1127.52 | H10: -479 | I10: -209.2 | J10: -3072.3 | K10: -198.78 | L10: 0 | M10: -1743.38 | N10: -1458.17 | O10: -5823.96 | P10: -2788.6 | Q10: -324.3 | R10: 0 | S10: 0 | T10: 0 | U10: 0 | V10: 0 | W10: 0 | X10: 0 | Y10: 0 | Z10: 0
E11: Vlr Servicio | F11: 40070 | G11: 1956.64 | H11: 1090.23 | I11: 579.83 | J11: 9781.04 | K11: 359.68 | L11: 0 | M11: 3155.11 | N11: 3024.18 | O11: 14196.18 | P11: 5344.07 | Q11: 586.85 | R11: -3.81 | S11: 0 | T11: 0 | U11: 0 | V11: 0 | W11: 0 | X11: 0 | Y11: 0 | Z11: 0
D12: T | E12: Total | F12: 40070 | G12: 1956.64 | H12: 1090.23 | I12: 579.83 | J12: 9781.04 | K12: 359.68 | L12: 0 | M12: 3155.11 | N12: 3024.18 | O12: 14196.18 | P12: 5344.07 | Q12: 586.85 | R12: -3.81 | S12: 0 | T12: 0 | U12: 0 | V12: 0 | W12: 0 | X12: 0 | Y12: 0 | Z12: 0
C13: OCCIDENTE | D13: Total | F13: 40070 | G13: 1956.64 | H13: 1090.23 | I13: 579.83 | J13: 9781.04 | K13: 359.68 | L13: 0 | M13: 3155.11 | N13: 3024.18 | O13: 14196.18 | P13: 5344.07 | Q13: 586.85 | R13: -3.81 | S13: 0 | T13: 0 | U13: 0 | V13: 0 | W13: 0 | X13: 0 | Y13: 0 | Z13: 0
B14: Aplicacion nuevos x reversion | C14: Total | F14: 40070 | G14: 1956.64 | H14: 1090.23 | I14: 579.83 | J14: 9781.04 | K14: 359.68 | L14: 0 | M14: 3155.11 | N14: 3024.18 | O14: 14196.18 | P14: 5344.07 | Q14: 586.85 | R14: -3.81 | S14: 0 | T14: 0 | U14: 0 | V14: 0 | W14: 0 | X14: 0 | Y14: 0 | Z14: 0
E15: Vlr Servicio | F15: 1.3820608e+10 | G15: 7.2609079e+08 | H15: 4.0461759e+08 | I15: 2.1507678e+08 | J15: 3.251669e+09 | K15: 1.2220472e+08 | L15: 8899784.6 | M15: 1.075307e+09 | N15: 1.0244595e+09 | O15: 4.8175803e+09 | P15: 1.9751857e+09 | Q15: 1.9940879e+08 | R15: 108332.55 | S15: 0 | T15: 0 | U15: 0 | V15: 0 | W15: 0 | X15: 0 | Y15: 0 | Z15: 0
E16: Vlr Intereses | F16: 2775510.5 | G16: 173184.52 | H16: 90025.64 | I16: 45834.86 | J16: 593178.71 | K16: 25683.52 | L16: 1137.27 | M16: 223805.96 | N16: 203715.02 | O16: 915969.2 | P16: 460731.85 | Q16: 41886.91 | R16: 287.49 | S16: 0 | T16: 69.57 | U16: 0 | V16: 0 | W16: 0 | X16: 0 | Y16: 0 | Z16: 0
D17: E | E17: Total | F17: 1.3823384e+10 | G17: 7.2626397e+08 | H17: 4.0470762e+08 | I17: 2.1512261e+08 | J17: 3.2522621e+09 | K17: 1.222304e+08 | L17: 8900921.8 | M17: 1.0755308e+09 | N17: 1.0246632e+09 | O17: 4.8184963e+09 | P17: 1.9756465e+09 | Q17: 1.9945067e+08 | R17: 108620.04 | S17: 0 | T17: 69.57 | U17: 0 | V17: 0 | W17: 0 | X17: 0 | Y17: 0 | Z17: 0
C18: ENEL | D18: Total | F18: 1.3823384e+10 | G18: 7.2626397e+08 | H18: 4.0470762e+08 | I18: 2.1512261e+08 | J18: 3.2522621e+09 | K18: 1.222304e+08 | L18: 8900921.8 | M18: 1.0755308e+09 | N18: 1.0246632e+09 | O18: 4.8184963e+09 | P18: 1.9756465e+09 | Q18: 1.9945067e+08 | R18: 108620.04 | S18: 0 | T18: 69.57 | U18: 0 | V18: 0 | W18: 0 | X18: 0 | Y18: 0 | Z18: 0
E19: Vlr Servicio | F19: 32423892 | G19: 2094905.1 | H19: 1163712.2 | I19: 616207.45 | J19: 6735190.8 | K19: 225631.74 | L19: 0 | M19: 1960612.4 | N19: 2382394.7 | O19: 11164316 | P19: 5712544.2 | Q19: 368628.92 | R19: -251.29 | S19: 0 | T19: 0 | U19: 0 | V19: 0 | W19: 0 | X19: 0 | Y19: 0 | Z19: 0
E20: Vlr Intereses | F20: 103289.61 | G20: 6294.04 | H20: 3163.57 | I20: 1714.05 | J20: 22356.07 | K20: 784.39 | L20: 0 | M20: 6905.15 | N20: 7794.49 | O20: 35934.39 | P20: 17009.19 | Q20: 1280.21 | R20: 53.94 | S20: 0 | T20: 0.12 | U20: 0 | V20: 0 | W20: 0 | X20: 0 | Y20: 0 | Z20: 0
D21: H | E21: Total | F21: 32527182 | G21: 2101199.1 | H21: 1166875.8 | I21: 617921.5 | J21: 6757546.8 | K21: 226416.13 | L21: 0 | M21: 1967517.6 | N21: 2390189.2 | O21: 11200250 | P21: 5729553.4 | Q21: 369909.13 | R21: -197.35 | S21: 0 | T21: 0.12 | U21: 0 | V21: 0 | W21: 0 | X21: 0 | Y21: 0 | Z21: 0
E22: Vlr Servicio | F22: 95497576 | G22: 11573781 | H22: 6315699.4 | I22: 3344369 | J22: 11196862 | K22: 506065.73 | L22: 135643.06 | M22: 4492396.4 | N22: 4604644.3 | O22: 20948918 | P22: 31553963 | Q22: 825687.23 | R22: -452.16 | S22: 0 | T22: 0 | U22: 0 | V22: 0 | W22: 0 | X22: 0 | Y22: 0 | Z22: 0
E23: Vlr Intereses | F23: 165198.17 | G23: 9910.54 | H23: 4898.7 | I23: 2681.95 | J23: 31220.87 | K23: 1643.89 | L23: 0 | M23: 14419.27 | N23: 13134.82 | O23: 57844.58 | P23: 26763.02 | Q23: 2681.01 | R23: -0.59 | S23: 0 | T23: 0.11 | U23: 0 | V23: 0 | W23: 0 | X23: 0 | Y23: 0 | Z23: 0
D24: O | E24: Total | F24: 95662775 | G24: 11583691 | H24: 6320598.1 | I24: 3347050.9 | J24: 11228083 | K24: 507709.62 | L24: 135643.06 | M24: 4506815.7 | N24: 4617779.1 | O24: 21006763 | P24: 31580726 | Q24: 828368.24 | R24: -452.75 | S24: 0 | T24: 0.11 | U24: 0 | V24: 0 | W24: 0 | X24: 0 | Y24: 0 | Z24: 0
E25: Vlr Servicio | F25: 4.5899942e+08 | G25: 72781452 | H25: 40662720 | I25: 21480324 | J25: 34870261 | K25: 898680.48 | L25: 19324973 | M25: 7870315.9 | N25: 10737963 | O25: 50379165 | P25: 1.9852882e+08 | Q25: 1466127.9 | R25: -1383.76 | S25: 0 | T25: 0 | U25: 0 | V25: 0 | W25: 0 | X25: 0 | Y25: 0 | Z25: 0
E26: Vlr Intereses | F26: 882023.55 | G26: 103988.24 | H26: 56003.01 | I26: 29383.84 | J26: 116356.97 | K26: 3816.91 | L26: 48754.08 | M26: 33492.66 | N26: 37349.61 | O26: 164534.39 | P26: 282106.88 | Q26: 6236.98 | R26: -0.08 | S26: 0.03 | T26: 0.03 | U26: 0 | V26: 0 | W26: 0 | X26: 0 | Y26: 0 | Z26: 0
D27: T | E27: Total | F27: 4.5988144e+08 | G27: 72885440 | H27: 40718723 | I27: 21509708 | J27: 34986618 | K27: 902497.39 | L27: 19373727 | M27: 7903808.5 | N27: 10775312 | O27: 50543700 | P27: 1.9881092e+08 | Q27: 1472364.9 | R27: -1383.84 | S27: 0.03 | T27: 0.03 | U27: 0 | V27: 0 | W27: 0 | X27: 0 | Y27: 0 | Z27: 0
C28: OCCIDENTE | D28: Total | F28: 5.880714e+08 | G28: 86570330 | H28: 48206196 | I28: 25474680 | J28: 52972247 | K28: 1636623.1 | L28: 19509370 | M28: 14378142 | N28: 17783281 | O28: 82750712 | P28: 2.361212e+08 | Q28: 2670642.2 | R28: -2033.94 | S28: 0.03 | T28: 0.26 | U28: 0 | V28: 0 | W28: 0 | X28: 0 | Y28: 0 | Z28: 0
B29: Mes | C29: Total | F29: 1.4411455e+10 | G29: 8.128343e+08 | H29: 4.5291382e+08 | I29: 2.4059729e+08 | J29: 3.3052344e+09 | K29: 1.2386702e+08 | L29: 28410292 | M29: 1.0899089e+09 | N29: 1.0424465e+09 | O29: 4.901247e+09 | P29: 2.2117677e+09 | Q29: 2.0212131e+08 | R29: 106586.1 | S29: 0.03 | T29: 69.83 | U29: 0 | V29: 0 | W29: 0 | X29: 0 | Y29: 0 | Z29: 0
A30: Componente | B30: Total | F30: 1.4411495e+10 | G30: 8.1283626e+08 | H30: 4.5291491e+08 | I30: 2.4059787e+08 | J30: 3.3052442e+09 | K30: 1.2386738e+08 | L30: 28410292 | M30: 1089912064 | N30: 1.0424495e+09 | O30: 4.9012612e+09 | P30: 2.211773e+09 | Q30: 2.021219e+08 | R30: 106582.29 | S30: 0.03 | T30: 69.83 | U30: 0 | V30: 0 | W30: 0 | X30: 0 | Y30: 0 | Z30: 0
E31: Subsidio(-)/Contribucion(+) | F31: 1.4524686e+09 | G31: 1.4297322e+08 | H31: 79654038 | I31: 42355359 | J31: 2.4241903e+08 | K31: 9336364.5 | L31: 0 | M31: 80865229 | N31: 78214633 | O31: 3.6849954e+08 | P31: 3.9291835e+08 | Q31: 15232879 | R31: 0 | S31: 0 | T31: 0 | U31: 0 | V31: 0 | W31: 0 | X31: 0 | Y31: 0 | Z31: 0
D32: E | E32: Total | F32: 1.4524686e+09 | G32: 1.4297322e+08 | H32: 79654038 | I32: 42355359 | J32: 2.4241903e+08 | K32: 9336364.5 | L32: 0 | M32: 80865229 | N32: 78214633 | O32: 3.6849954e+08 | P32: 3.9291835e+08 | Q32: 15232879 | R32: 0 | S32: 0 | T32: 0 | U32: 0 | V32: 0 | W32: 0 | X32: 0 | Y32: 0 | Z32: 0
C33: ENEL | D33: Total | F33: 1.4524686e+09 | G33: 1.4297322e+08 | H33: 79654038 | I33: 42355359 | J33: 2.4241903e+08 | K33: 9336364.5 | L33: 0 | M33: 80865229 | N33: 78214633 | O33: 3.6849954e+08 | P33: 3.9291835e+08 | Q33: 15232879 | R33: 0 | S33: 0 | T33: 0 | U33: 0 | V33: 0 | W33: 0 | X33: 0 | Y33: 0 | Z33: 0
E34: Subsidio(-)/Contribucion(+) | F34: 5898418.4 | G34: 881999.26 | H34: 489087.28 | I34: 260611.8 | J34: 636049.85 | K34: 10462.68 | L34: 0 | M34: 91956.29 | N34: 193499.75 | O34: 909344.29 | P34: 2408335.8 | Q34: 17071.35 | R34: 0 | S34: 0 | T34: 0 | U34: 0 | V34: 0 | W34: 0 | X34: 0 | Y34: 0 | Z34: 0
D35: H | E35: Total | F35: 5898418.4 | G35: 881999.26 | H35: 489087.28 | I35: 260611.8 | J35: 636049.85 | K35: 10462.68 | L35: 0 | M35: 91956.29 | N35: 193499.75 | O35: 909344.29 | P35: 2408335.8 | Q35: 17071.35 | R35: 0 | S35: 0 | T35: 0 | U35: 0 | V35: 0 | W35: 0 | X35: 0 | Y35: 0 | Z35: 0
E36: Subsidio(-)/Contribucion(+) | F36: 13098226 | G36: 2940924 | H36: 1605818.6 | I36: 857242.56 | J36: -362631.74 | K36: -26684.44 | L36: 0 | M36: -237386.59 | N36: 21203.47 | O36: 315579.15 | P36: 8027696.6 | Q36: -43535.67 | R36: 0 | S36: 0 | T36: 0 | U36: 0 | V36: 0 | W36: 0 | X36: 0 | Y36: 0 | Z36: 0
D37: O | E37: Total | F37: 13098226 | G37: 2940924 | H37: 1605818.6 | I37: 857242.56 | J37: -362631.74 | K37: -26684.44 | L37: 0 | M37: -237386.59 | N37: 21203.47 | O37: 315579.15 | P37: 8027696.6 | Q37: -43535.67 | R37: 0 | S37: 0 | T37: 0 | U37: 0 | V37: 0 | W37: 0 | X37: 0 | Y37: 0 | Z37: 0
E38: Subsidio(-)/Contribucion(+) | F38: 1.3584738e+08 | G38: 23857697 | H38: 13350084 | I38: 7071037.8 | J38: 8488542.9 | K38: 229087.23 | L38: 0 | M38: 2009970.9 | N38: 2694316.7 | O38: 12601163 | P38: 65171708 | Q38: 373777.59 | R38: 0 | S38: 0 | T38: 0 | U38: 0 | V38: 0 | W38: 0 | X38: 0 | Y38: 0 | Z38: 0
D39: T | E39: Total | F39: 1.3584738e+08 | G39: 23857697 | H39: 13350084 | I39: 7071037.8 | J39: 8488542.9 | K39: 229087.23 | L39: 0 | M39: 2009970.9 | N39: 2694316.7 | O39: 12601163 | P39: 65171708 | Q39: 373777.59 | R39: 0 | S39: 0 | T39: 0 | U39: 0 | V39: 0 | W39: 0 | X39: 0 | Y39: 0 | Z39: 0
C40: OCCIDENTE | D40: Total | F40: 1.5484403e+08 | G40: 27680620 | H40: 15444990 | I40: 8188892.2 | J40: 8761961 | K40: 212865.47 | L40: 0 | M40: 1864540.6 | N40: 2909020 | O40: 13826086 | P40: 75607740 | Q40: 347313.27 | R40: 0 | S40: 0 | T40: 0 | U40: 0 | V40: 0 | W40: 0 | X40: 0 | Y40: 0 | Z40: 0
B41: Mes | C41: Total | F41: 1.6073127e+09 | G41: 1.7065384e+08 | H41: 95099028 | I41: 50544251 | J41: 2.5118099e+08 | K41: 9549230 | L41: 0 | M41: 82729770 | N41: 81123653 | O41: 3.8232563e+08 | P41: 4.6852609e+08 | Q41: 15580192 | R41: 0 | S41: 0 | T41: 0 | U41: 0 | V41: 0 | W41: 0 | X41: 0 | Y41: 0 | Z41: 0
A42: Subs/Cont | B42: Total | F42: 1.6073127e+09 | G42: 1.7065384e+08 | H42: 95099028 | I42: 50544251 | J42: 2.5118099e+08 | K42: 9549230 | L42: 0 | M42: 82729770 | N42: 81123653 | O42: 3.8232563e+08 | P42: 4.6852609e+08 | Q42: 15580192 | R42: 0 | S42: 0 | T42: 0 | U42: 0 | V42: 0 | W42: 0 | X42: 0 | Y42: 0 | Z42: 0
A43: Total | F43: 1.6018791e+10 | G43: 9.8348897e+08 | H43: 5.4801346e+08 | I43: 2.9114192e+08 | J43: 3.5564221e+09 | K43: 1.3341642e+08 | L43: 28410292 | M43: 1.1726401e+09 | N43: 1.1235717e+09 | O43: 5.283581e+09 | P43: 2.6802963e+09 | Q43: 2.1770177e+08 | R43: 106582.29 | S43: 0.03 | T43: 69.83 | U43: 0 | V43: 0 | W43: 0 | X43: 0 | Y43: 0 | Z43: 0
...

Sheet Rem. Anticipos R2
B1: PROMOAMBIENTAL
E2: Total | F2: Componente TDF | G2: Componente TTL | H2: Componente TVIAT | I2: Aprovechamiento | J2: CCSA Prest.Aprov. | K2: Especiales | L2: Componente TCS | M2: Componente TLU | N2: Componente TBL | O2: Componente TRT | P2: CCSA Prest. No Aprov. | Q2: Deb/Cred | R2: Deb/Cred-otros
D3: Vlr Servicio | E3: 55834234 | F3: 3094647.4 | G3: 1682765.2 | H3: 530662.91 | I3: 14660029 | J3: 506485.61 | K3: 0 | L3: 5081668.9 | M3: 4157674.5 | N3: 16968786 | O3: 8430869 | P3: 720682.78 | Q3: -37.03 | R3: 0
D4: Vlr Intereses | E4: 3707.99 | F4: 156.46 | G4: 86.98 | H4: 46.44 | I4: 813.79 | J4: 38.21 | K4: 0 | L4: 335.01 | M4: 322.78 | N4: 1416.95 | O4: 429 | P4: 62.35 | Q4: 0.02 | R4: 0
C5: E | D5: Total | E5: 55837942 | F5: 3094803.9 | G5: 1682852.2 | H5: 530709.35 | I5: 14660843 | J5: 506523.82 | K5: 0 | L5: 5082003.9 | M5: 4157997.2 | N5: 16970203 | O5: 8431298 | P5: 720745.13 | Q5: -37.01 | R5: 0
B6: ENEL | C6: Total | E6: 55837942 | F6: 3094803.9 | G6: 1682852.2 | H6: 530709.35 | I6: 14660843 | J6: 506523.82 | K6: 0 | L6: 5082003.9 | M6: 4157997.2 | N6: 16970203 | O6: 8431298 | P6: 720745.13 | Q6: -37.01 | R6: 0
D7: Vlr Servicio | E7: 2493179.1 | F7: 105458.8 | G7: 60546.26 | H7: 25821.53 | I7: 658727.02 | J7: 20098.4 | K7: 0 | L7: 179573.87 | M7: 217698.78 | N7: 900619.58 | O7: 296715.15 | P7: 27929.76 | Q7: -10 | R7: 0
D8: Vlr Intereses | E8: 732.75 | F8: 36.24 | G8: 18.73 | H8: 10.23 | I8: 195.31 | J8: 4.71 | K8: 0 | L8: 41.31 | M8: 56.94 | N8: 262.11 | O8: 99.47 | P8: 7.68 | Q8: 0.02 | R8: 0
C9: H | D9: Total | E9: 2493911.9 | F9: 105495.04 | G9: 60564.99 | H9: 25831.76 | I9: 658922.33 | J9: 20103.11 | K9: 0 | L9: 179615.18 | M9: 217755.72 | N9: 900881.69 | O9: 296814.62 | P9: 27937.44 | Q9: -9.98 | R9: 0
D10: Vlr Servicio | E10: 2223198.6 | F10: 147874.33 | G10: 83270.12 | H10: 44538.96 | I10: 324582.72 | J10: 14764.44 | K10: 0 | L10: 134454.14 | M10: 151788.8 | N10: 653436.37 | O10: 644060.97 | P10: 24424.93 | Q10: 2.78 | R10: 0
D11: Vlr Intereses | E11: 676.52 | F11: 18.42 | G11: 9.52 | H11: 5.19 | I11: 108.14 | J11: 12.59 | K11: 0 | L11: 109.25 | M11: 100.54 | N11: 242.05 | O11: 50.3 | P11: 20.52 | Q11: 0 | R11: 0
C12: O | D12: Total | E12: 2223875.1 | F12: 147892.75 | G12: 83279.64 | H12: 44544.15 | I12: 324690.86 | J12: 14777.03 | K12: 0 | L12: 134563.39 | M12: 151889.34 | N12: 653678.42 | O12: 644111.27 | P12: 24445.45 | Q12: 2.78 | R12: 0
D13: Vlr Servicio | E13: 20285169 | F13: 2616611 | G13: 1450507.4 | H13: 764170.91 | I13: 2505995.4 | J13: 57900.44 | K13: 1030668 | L13: 683264.29 | M13: 755299.62 | N13: 2961183 | O13: 7368849.4 | P13: 90741.67 | Q13: -22.49 | R13: 0
D14: Vlr Intereses | E14: 22217.37 | F14: 1381.19 | G14: 639.86 | H14: 371.8 | I14: 5346.65 | J14: 194.18 | K14: 0 | L14: 1703.91 | M14: 1518.67 | N14: 6962.94 | O14: 3781.33 | P14: 316.83 | Q14: 0.01 | R14: 0
C15: T | D15: Total | E15: 20307386 | F15: 2617992.2 | G15: 1451147.2 | H15: 764542.71 | I15: 2511342.1 | J15: 58094.62 | K15: 1030668 | L15: 684968.2 | M15: 756818.29 | N15: 2968145.9 | O15: 7372630.7 | P15: 91058.5 | Q15: -22.48 | R15: 0
B16: OCCIDENTE | C16: Total | E16: 25025173 | F16: 2871380 | G16: 1594991.9 | H16: 834918.62 | I16: 3494955.2 | J16: 92974.76 | K16: 1030668 | L16: 999146.77 | M16: 1126463.4 | N16: 4522706 | O16: 8313556.6 | P16: 143441.39 | Q16: -29.68 | R16: 0
A17: Componente | B17: Total | E17: 80863115 | F17: 5966183.8 | G17: 3277844.1 | H17: 1365628 | I17: 18155798 | J17: 599498.58 | K17: 1030668 | L17: 6081150.7 | M17: 5284460.6 | N17: 21492909 | O17: 16744855 | P17: 864186.52 | Q17: -66.69 | R17: 0
D18: Subsidio(-)/Contribucion(+) | E18: -19207014 | F18: -617716.24 | G18: -328873.02 | H18: -172186.54 | I18: -5306584.7 | J18: -192729.4 | K18: 0 | L18: -1649344.1 | M18: -1543787.5 | N18: -7413085.7 | O18: -1667377.9 | P18: -315328.54 | Q18: 0 | R18: 0
C19: E | D19: Total | E19: -19207014 | F19: -617716.24 | G19: -328873.02 | H19: -172186.54 | I19: -5306584.7 | J19: -192729.4 | K19: 0 | L19: -1649344.1 | M19: -1543787.5 | N19: -7413085.7 | O19: -1667377.9 | P19: -315328.54 | Q19: 0 | R19: 0
B20: ENEL | C20: Total | E20: -19207014 | F20: -617716.24 | G20: -328873.02 | H20: -172186.54 | I20: -5306584.7 | J20: -192729.4 | K20: 0 | L20: -1649344.1 | M20: -1543787.5 | N20: -7413085.7 | O20: -1667377.9 | P20: -315328.54 | Q20: 0 | R20: 0
D21: Subsidio(-)/Contribucion(+) | E21: -372078.25 | F21: -10720.26 | G21: -5973.28 | H21: -4443.92 | I21: -103772.07 | J21: -4179.18 | K21: 0 | L21: -33851.55 | M21: -33425.82 | N21: -139613.89 | O21: -29279.68 | P21: -6818.6 | Q21: 0 | R21: 0
C22: H | D22: Total | E22: -372078.25 | F22: -10720.26 | G22: -5973.28 | H22: -4443.92 | I22: -103772.07 | J22: -4179.18 | K22: 0 | L22: -33851.55 | M22: -33425.82 | N22: -139613.89 | O22: -29279.68 | P22: -6818.6 | Q22: 0 | R22: 0
D23: Subsidio(-)/Contribucion(+) | E23: 561663.57 | F23: 85215.3 | G23: 47452.88 | H23: 25221.76 | I23: 57091.22 | J23: 1115.44 | K23: 0 | L23: 8666.79 | M23: 16123.86 | N23: 85989.95 | O23: 232941.23 | P23: 1845.14 | Q23: 0 | R23: 0
C24: O | D24: Total | E24: 561663.57 | F24: 85215.3 | G24: 47452.88 | H24: 25221.76 | I24: 57091.22 | J24: 1115.44 | K24: 0 | L24: 8666.79 | M24: 16123.86 | N24: 85989.95 | O24: 232941.23 | P24: 1845.14 | Q24: 0 | R24: 0
D25: Subsidio(-)/Contribucion(+) | E25: 6792970.1 | F25: 1198577.8 | G25: 647576.97 | H25: 267551.01 | I25: 336837.22 | J25: 10835.7 | K25: 0 | L25: 130771.96 | M25: 148376.47 | N25: 751931.64 | O25: 3281949.7 | P25: 18561.61 | Q25: 0 | R25: 0
C26: T | D26: Total | E26: 6792970.1 | F26: 1198577.8 | G26: 647576.97 | H26: 267551.01 | I26: 336837.22 | J26: 10835.7 | K26: 0 | L26: 130771.96 | M26: 148376.47 | N26: 751931.64 | O26: 3281949.7 | P26: 18561.61 | Q26: 0 | R26: 0
B27: OCCIDENTE | C27: Total | E27: 6982555.4 | F27: 1273072.8 | G27: 689056.57 | H27: 288328.85 | I27: 290156.37 | J27: 7771.96 | K27: 0 | L27: 105587.2 | M27: 131074.51 | N27: 698307.7 | O27: 3485611.3 | P27: 13588.15 | Q27: 0 | R27: 0
A28: Subs/Cont | B28: Total | E28: -12224458 | F28: 655356.59 | G28: 360183.55 | H28: 116142.31 | I28: -5016428.3 | J28: -184957.44 | K28: 0 | L28: -1543756.9 | M28: -1412712.9 | N28: -6714778 | O28: 1818233.4 | P28: -301740.39 | Q28: 0 | R28: 0
A29: Total | E29: 68638657 | F29: 6621540.4 | G29: 3638027.6 | H29: 1481770.3 | I29: 13139370 | J29: 414541.14 | K29: 1030668 | L29: 4537393.8 | M29: 3871747.6 | N29: 14778131 | O29: 18563088 | P29: 562446.13 | Q29: -66.69 | R29: 0
B43: TOTAL | C43: OPORTUNO | D43: Total | E43: =E17+E28-K17 -> 67607989 | F43: =F17 -> 5966183.8 | G43: =G17 -> 3277844.1 | H43: =H17 -> 1365628 | I43: =I17 -> 18155798 | J43: =J17 -> 599498.58 | K43: =K17 -> 1030668 | L43: =L17 -> 6081150.7 | M43: =M17 -> 5284460.6 | ... S43: =S17 -> 0
D44: Subsidio(-)/Contribucion(+) | E44: =E28 -> -12224458
B46: RECIPROCIDAD | C46: OPORTUNO | D46: Total | E46: 0 | F46: 0 | G46: 0 | H46: 0 | I46: 0 | J46: 0 | K46: 0 | L46: 0 | M46: 0 | N46: 0 | O46: 0 | P46: 0 | Q46: 0 | R46: 0 | S46: 0
D47: Subsidio(-)/Contribucion(+) | E47: 0
B49: ENEL | C49: OPORTUNO | D49: Total | E49: =E20+E6-K6 -> 36630929 | F49: =F6 -> 3094803.9 | G49: =G6 -> 1682852.2 | H49: =H6 -> 530709.35 | I49: =I6 -> 14660843 | J49: =J6 -> 506523.82 | K49: =K6 -> 0 | L49: =L6 -> 5082003.9 | M49: =M6 -> 4157997.2 | ... S49: =S6 -> 0
D50: Subsidio(-)/Contribucion(+) | E50: =E20 -> -19207014
B52: ENERBIT | C52: OPORTUNO | D52: Total | E52: 0 | F52: 0 | G52: 0 | H52: 0 | I52: 0 | J52: 0 | K52: 0 | L52: 0 | M52: 0 | N52: 0 | O52: 0 | P52: 0 | Q52: 0 | R52: 0
D53: Subsidio(-)/Contribucion(+) | E53: 0
B55: OCCIDENTE | C55: OPORTUNO | D55: Total | E55: =E16+E27-K16 -> 30977060 | F55: =F16 -> 2871380 | G55: =G16 -> 1594991.9 | H55: =H16 -> 834918.62 | I55: =I16 -> 3494955.2 | J55: =J16 -> 92974.76 | K55: =K16 -> 1030668 | L55: =L16 -> 999146.77 | M55: =M16 -> 1126463.4 | ... S55: =S16 -> 0
D56: Subsidio(-)/Contribucion(+) | E56: =E27 -> 6982555.4
B58: CIUDAD LIMPIA-ACUEDUCTO | C58: OPORTUNO | D58: Total | E58: 0 | F58: 0 | G58: 0 | H58: 0 | I58: 0 | J58: 0 | K58: 0 | L58: 0 | M58: 0 | N58: 0 | O58: 0 | P58: 0 | Q58: 0 | R58: 0 | S58: 0
...

Sheet Reversion Pagos R4
B1: PROMOAMBIENTAL
D2: Total | E2: Componente TDF | F2: Componente TTL | G2: Componente TVIAT | H2: Aprovechamiento | I2: CCSA Prest.Aprov. | J2: Componente TCS | K2: Componente TLU | L2: Componente TBL | M2: Componente TRT | N2: CCSA Prest. No Aprov. | O2: Ajuste Decena | P2: SERVICIO ESPECIALES | Q2: Ajuste Recargo Aseo | R2: Otros
C3: Vlr Servicio | D3: -902656.46 | E3: -50786.1 | F3: -28687.84 | G3: -15112.67 | H3: -214829.29 | I3: -7567.12 | J3: -66377.88 | K3: -64591.46 | L3: -303450.84 | M3: -138897.31 | N3: -12346.16 | O3: -9.79 | P3: 0 | Q3: 0 | R3: 0
C4: Vlr Intereses | D4: -84.31 | E4: -4.65 | F4: -2.63 | G4: -1.39 | H4: -20.46 | I4: -0.71 | J4: -6.2 | K4: -6.14 | L4: -28.19 | M4: -12.78 | N4: -1.15 | O4: -0.01 | P4: 0 | Q4: 0 | R4: 0
B5: Componente | C5: Total | D5: -902740.77 | E5: -50790.75 | F5: -28690.47 | G5: -15114.06 | H5: -214849.75 | I5: -7567.83 | J5: -66384.08 | K5: -64597.6 | L5: -303479.03 | M5: -138910.09 | N5: -12347.31 | O5: -9.8 | P5: 0 | Q5: 0 | R5: 0
C6: Subsidio(-)/Contribucion(+) | D6: -342249.23 | E6: -20012.25 | F6: -11305.96 | G6: -5961.84 | H6: -80024.59 | I6: -2832.43 | J6: -24845.71 | K6: -24218.43 | L6: -113481.59 | M6: -54945.16 | N6: -4621.27 | O6: 0 | P6: 0 | Q6: 0 | R6: 0
B7: Subs/Cont | C7: Total | D7: -342249.23 | E7: -20012.25 | F7: -11305.96 | G7: -5961.84 | H7: -80024.59 | I7: -2832.43 | J7: -24845.71 | K7: -24218.43 | L7: -113481.59 | M7: -54945.16 | N7: -4621.27 | O7: 0 | P7: 0 | Q7: 0 | R7: 0
A8: ENEL | B8: Total | D8: -1244990 | E8: -70803 | F8: -39996.43 | G8: -21075.9 | H8: -294874.34 | I8: -10400.26 | J8: -91229.79 | K8: -88816.03 | L8: -416960.62 | M8: -193855.25 | N8: -16968.58 | O8: -9.8 | P8: 0 | Q8: 0 | R8: 0
C9: Vlr Servicio | D9: -40070 | E9: -2042.17 | F9: -1153.02 | G9: -605.19 | H9: -10019.35 | I9: -249.19 | J9: -2185.89 | K9: -3113.99 | L9: -14745.86 | M9: -5553.38 | N9: -406.58 | O9: 4.62 | P9: 0 | Q9: 0 | R9: 0
B10: Componente | C10: Total | D10: -40070 | E10: -2042.17 | F10: -1153.02 | G10: -605.19 | H10: -10019.35 | I10: -249.19 | J10: -2185.89 | K10: -3113.99 | L10: -14745.86 | M10: -5553.38 | N10: -406.58 | O10: 4.62 | P10: 0 | Q10: 0 | R10: 0
A11: OCCIDENTE | B11: Total | D11: -40070 | E11: -2042.17 | F11: -1153.02 | G11: -605.19 | H11: -10019.35 | I11: -249.19 | J11: -2185.89 | K11: -3113.99 | L11: -14745.86 | M11: -5553.38 | N11: -406.58 | O11: 4.62 | P11: 0 | Q11: 0 | R11: 0
A12: Total | D12: -1285060 | E12: -72845.17 | F12: -41149.45 | G12: -21681.09 | H12: -304893.69 | I12: -10649.45 | J12: -93415.68 | K12: -91930.02 | L12: -431706.48 | M12: -199408.63 | N12: -17375.16 | O12: -5.18 | P12: 0 | Q12: 0 | R12: 0
A70: TOTAL | B70: OPORTUNO | C70: Total | D70: =D12-P12 -> -1285060 | E70: =E5+E10 -> -52832.92 | F70: =F5+F10 -> -29843.49 | G70: =G5+G10 -> -15719.25 | H70: =H5+H10 -> -224869.1 | I70: =I5+I10 -> -7817.02 | J70: =J5+J10 -> -68569.97 | K70: =K5+K10 -> -67711.59 | L70: =L5+L10 -> -318224.89 | ... R70: =R5+R10 -> 0
C71: Subsidio(-)/Contribucion(+) | D71: =D7 -> -342249.23
A73: RECIPROCIDAD | B73: OPORTUNO | C73: Total | D73: 0 | E73: 0 | F73: 0 | G73: 0 | H73: 0 | I73: 0 | J73: 0 | K73: 0 | L73: 0 | M73: 0 | N73: 0 | O73: 0 | P73: 0 | Q73: 0 | R73: 0
C74: Subsidio(-)/Contribucion(+) | D74: 0
A76: ENEL | B76: OPORTUNO | C76: Total | D76: =D8-P8 -> -1244990 | E76: =E5 -> -50790.75 | F76: =F5 -> -28690.47 | G76: =G5 -> -15114.06 | H76: =H5 -> -214849.75 | I76: =I5 -> -7567.83 | J76: =J5 -> -66384.08 | K76: =K5 -> -64597.6 | L76: =L5 -> -303479.03 | ... R76: =R5 -> 0
C77: Subsidio(-)/Contribucion(+) | D77: =D7 -> -342249.23
A79: ENERBIT | B79: OPORTUNO | C79: Total | D79: 0 | E79: 0 | F79: 0 | G79: 0 | H79: 0 | I79: 0 | J79: 0 | K79: 0 | L79: 0 | M79: 0 | N79: 0 | O79: 0 | P79: 0 | Q79: 0 | R79: 0
C80: Subsidio(-)/Contribucion(+) | D80: 0
A82: OCCIDENTE | B82: OPORTUNO | C82: Total | D82: =D11-P11 -> -40070 | E82: =E10 -> -2042.17 | F82: =F10 -> -1153.02 | G82: =G10 -> -605.19 | H82: =H10 -> -10019.35 | I82: =I10 -> -249.19 | J82: =J10 -> -2185.89 | K82: =K10 -> -3113.99 | L82: =L10 -> -14745.86 | ... R82: =R10 -> 0
C83: Subsidio(-)/Contribucion(+) | D83: 0
A85: CIUDAD LIMPIA-ACUEDUCTO | B85: OPORTUNO | C85: Total | D85: 0 | E85: 0 | F85: 0 | G85: 0 | H85: 0 | I85: 0 | J85: 0 | K85: 0 | L85: 0 | M85: 0 | N85: 0 | O85: 0 | P85: 0 | Q85: 0 | R85: 0
C86: Subsidio(-)/Contribucion(+) | D86: 0
B88: LIME
D89: Total | E89: Componente TDF | F89: Componente TTL | G89: Componente TVIAT | H89: Aprovechamiento | I89: CCSA Prest.Aprov. | J89: Componente TCS | K89: Componente TLU | L89: Componente TBL | M89: Componente TRT | N89: CCSA Prest. No Aprov. | O89: Ajuste Decena | P89: SERVICIO ESPECIALES | Q89: Ajuste Recargo Aseo | R89: Otros
C90: Vlr Servicio | D90: -50598099 | E90: -3020381.9 | F90: -1629949.6 | G90: -850506.71 | H90: -12343961 | I90: -436345.15 | J90: -3854743.4 | K90: -3881901.3 | L90: -17844917 | M90: -6019284.2 | N90: -716097.95 | O90: -10.88 | P90: 0 | Q90: 0 | R90: 0
C91: Vlr Intereses | D91: -863642.25 | E91: -86868.6 | F91: -40393.28 | G91: -20594.22 | H91: -182194.3 | I91: -5497.81 | J91: -48405.41 | K91: -58042.26 | L91: -238361.58 | M91: -174296.88 | N91: -8984.88 | O91: -3.29 | P91: 0 | Q91: 0.26 | R91: 0
B92: Componente | C92: Total | D92: -51461741 | E92: -3107250.5 | F92: -1670342.9 | G92: -871100.93 | H92: -12526155 | I92: -441842.96 | J92: -3903148.8 | K92: -3939943.5 | L92: -18083278 | M92: -6193581.1 | N92: -725082.83 | O92: -14.17 | P92: 0 | Q92: 0.26 | R92: 0
C93: Subsidio(-)/Contribucion(+) | D93: 9920875 | E93: 303875.69 | F93: 150290.09 | G93: 72257.8 | H93: 2865204.2 | I93: 96655.6 | J93: 848909.8 | K93: 888082.75 | L93: 3956095.5 | M93: 581803.98 | N93: 157699.54 | O93: 0 | P93: 0 | Q93: 0 | R93: 0
B94: Subs/Cont | C94: Total | D94: 9920875 | E94: 303875.69 | F94: 150290.09 | G94: 72257.8 | H94: 2865204.2 | I94: 96655.6 | J94: 848909.8 | K94: 888082.75 | L94: 3956095.5 | M94: 581803.98 | N94: 157699.54 | O94: 0 | P94: 0 | Q94: 0 | R94: 0
A95: ENEL | B95: Total | D95: -41540866 | E95: -2803374.8 | F95: -1520052.8 | G95: -798843.13 | H95: -9660951 | I95: -345187.36 | J95: -3054239 | K95: -3051860.8 | L95: -14127183 | M95: -5611777.1 | N95: -567383.29 | O95: -14.17 | P95: 0 | Q95: 0.26 | R95: 0
C96: Vlr Servicio | D96: -76886.16 | E96: -3878.52 | F96: -2172.78 | G96: -1192.62 | H96: -20529.3 | I96: -491.85 | J96: -4314.5 | K96: -6347.49 | L96: -29323.18 | M96: -7837.65 | N96: -802.5 | O96: 4.23 | P96: 0 | Q96: 0 | R96: 0
