Workbook
Name \0: #REF!
Name _1: #REF!
Name _2: #REF!
Name _A655555: #REF!
Name _CFR1: #REF!
Name _cia1: #REF!
Name _XL250: #REF!
Name A: #REF!
Name ADM: [1]!ADM
Name ADM: [1]!ADM
Name ADM: [1]!ADM
Name ADM: [1]!ADM
Name ADM: [1]!ADM
Name ADM_: [1]!ADM
Name ADM_: [1]!ADM
Name ADM_: [1]!ADM
Name ADM_: [1]!ADM
Name ADM_: [1]!ADM
Name AI: #REF!
Name Air: #REF!
Name AP: '[2]TARIFA no aforos'!$C$12
Name Bancos: [3]Fx!$C$1:$C$23
Name CBL: #REF!
Name CCS: #REF!
Name CDT_p: [4]CDT!$C$3
Name CFR: #REF!
Name cia: #REF!
Name COM: #REF!
Name CRT: #REF!
Name CRT___CTEp___CDTp___CMRv: #REF!
Name CRT_aislados: '[4]COSTOS AJUSTADOS'!$C$13
Name CRT_costas: #REF!
Name CTE_p: [4]CTE!$C$5
Name Denominador: #REF!
Name dg: [1]!ADM
Name dg: [1]!ADM
Name dg: [1]!ADM
Name dg: [1]!ADM
Name dg: [1]!ADM
Name DIAS: [5]CONTRA!#REF!
Name Fmerc: #REF!
Name FPS: #REF!
Name InformacionGeneral: [1]!InformacionGeneral
Name InformacionGeneral: [1]!InformacionGeneral
Name InformacionGeneral: [1]!InformacionGeneral
Name InformacionGeneral: [1]!InformacionGeneral
Name InformacionGeneral: [1]!InformacionGeneral
Name INTFIN: #REF!
Name INV: [1]!INV
Name INV: [1]!INV
Name INV: [1]!INV
Name INV: [1]!INV
Name INV: [1]!INV
Name K: #REF!
Name N: '[4]COSTOS AJUSTADOS'!#REF!
Name Na: '[2]TARIFA no aforos'!$C$39
Name nfc: '[4]COSTOS AJUSTADOS'!#REF!
Name OYM: [1]!OYM
Name OYM: [1]!OYM
Name OYM: [1]!OYM

Sheet Recaudo EAAB Reciprocidad
B2: OPORTUNO | C2: ASE | D2: VALOR 1° Q | E2: NUMERO REG. 1°Q | F2: VALOR 2° Q | G2: NUMERO REG. 2°Q
C3: 1 | D3: 0 | E3: 0 | F3: 0 | G3: 0
C4: 2 | D4: 29345550 | E4: 341 | F4: 24173030 | G4: 330
C5: 3 | D5: 0 | E5: 0 | F5: 0 | G5: 0
C6: 4 | D6: 15240310 | E6: 108 | F6: 15822520 | G6: 133
C7: 5 | D7: 0 | E7: 0 | F7: 0 | G7: 0
C8: X
D9: 44585860 | E9: 449 | F9: 39995550 | G9: 463
C11: ASE | D11: VALOR 1° Q | E11: NUMERO REG. 1°Q | F11: VALOR 2° Q | G11: NUMERO REG. 2°Q
B12: EXTEMP. | C12: 1 | D12: 0 | E12: 0 | F12: 0 | G12: 0
C13: 2 | D13: 0 | E13: 0 | F13: 58730 | G13: 1
C14: 3 | D14: 0 | E14: 0 | F14: 0 | G14: 0
C15: 4 | D15: 0 | E15: 0 | F15: 63120 | G15: 1
C16: 5 | D16: 0 | E16: 0 | F16: 0 | G16: 0
C17: X
D18: 0 | E18: 0 | F18: 121850 | G18: 2
C20: ASE | D20: VALOR 1° Q | E20: NUMERO REG. 1°Q | F20: VALOR 2° Q | G20: NUMERO REG. 2°Q | I20: VALOR TOTAL MES | J20: NUMERO REGISTROS MES
B21: TOTAL | C21: 1 | D21: 0 | E21: 0 | F21: 0 | G21: 0 | I21: 0 | J21: 0
C22: 2 | D22: 29345550 | E22: 341 | F22: 24231760 | G22: 331 | I22: 53577310 | J22: 672
C23: 3 | D23: 0 | E23: 0 | F23: 0 | G23: 0 | I23: 0 | J23: 0
C24: 4 | D24: 15240310 | E24: 108 | F24: 15885640 | G24: 134 | I24: 31125950 | J24: 242
C25: 5 | D25: 0 | E25: 0 | F25: 0 | G25: 0 | I25: 0 | J25: 0
C26: X | I26: 0 | J26: 0
D27: 44585860 | E27: 449 | F27: 40117400 | G27: 465 | I27: 84703260 | J27: 914
B31: OPORTUNO | D31: =D9=SUM(D3:D8) -> TRUE | E31: =E9=SUM(E3:E8) -> TRUE | F31: =F9=SUM(F3:F8) -> TRUE | G31: =G9=SUM(G3:G8) -> TRUE
B33: EXTEMP. | D33: =D18=SUM(D12:D17) -> TRUE | E33: =E18=SUM(E12:E17) -> TRUE | F33: =F18=SUM(F12:F17) -> TRUE | G33: =G18=SUM(G12:G17) -> TRUE
B35: TOTAL | D35: =D27=SUM(D21:D26) -> TRUE | E35: =E27=SUM(E21:E26) -> TRUE | F35: =F27=SUM(F21:F26) -> TRUE | G35: =G27=SUM(G21:G26) -> TRUE | I35: =I27=SUM(I21:I26) -> TRUE | J35: =J27=SUM(J21:J26) -> TRUE
E69: =C69-G17 -> 0

Sheet Recaudo ENEL
B2: OPORTUNO | C2: ASE | D2: VALOR 1° Q | E2: NUMERO REG. 1°Q | F2: VALOR 2° Q | G2: NUMERO REG. 2°Q
C3: 1 | D3: 16020970408 | E3: 330319 | F3: 16467129562 | G3: 273797
C4: 2 | D4: 11733539858 | E4: 232298 | F4: 19037496395 | G4: 406215
C5: 3 | D5: 9618825681 | E5: 222340 | F5: 13952517350 | G5: 269668
C6: 4 | D6: 10290225466 | E6: 177955 | F6: 6579568126 | G6: 120492
C7: 5 | D7: 8111886280 | E7: 159077 | F7: 11684535987 | G7: 242618
C8: X
D9: 55775447693 | E9: 1121989 | F9: 67721247420 | G9: 1312790
C11: ASE | D11: VALOR 1° Q | E11: NUMERO REG. 1°Q | F11: VALOR 2° Q | G11: NUMERO REG. 2°Q
B12: EXTEMP. | C12: 1 | D12: 223833110 | E12: 3064 | F12: 193558629 | G12: 3299
C13: 2 | D13: 99273804 | E13: 1926 | F13: 53213747 | G13: 918
C14: 3 | D14: 66145670 | E14: 1462 | F14: 74684472 | G14: 1206
C15: 4 | D15: 85892126 | E15: 1255 | F15: 60823284 | G15: 1331
C16: 5 | D16: 166326259 | E16: 2744 | F16: 41090640 | G16: 830
C17: X
D18: 641470969 | E18: 10451 | F18: 423370772 | G18: 7584
C20: ASE | D20: VALOR 1° Q | E20: NUMERO REG. 1°Q | F20: VALOR 2° Q | G20: NUMERO REG. 2°Q | I20: VALOR TOTAL MES | J20: NUMERO REGISTROS MES
B21: TOTAL | C21: 1 | D21: 16244803518 | E21: 333383 | F21: 16660688191 | G21: 277096 | I21: 32905491709 | J21: 610479
C22: 2 | D22: 11832813662 | E22: 234224 | F22: 19090710142 | G22: 407133 | I22: 30923523804 | J22: 641357
C23: 3 | D23: 9684971351 | E23: 223802 | F23: 14027201822 | G23: 270874 | I23: 23712173173 | J23: 494676
C24: 4 | D24: 10376117592 | E24: 179210 | F24: 6640391410 | G24: 121823 | I24: 17016509002 | J24: 301033
C25: 5 | D25: 8278212539 | E25: 161821 | F25: 11725626627 | G25: 243448 | I25: 20003839166 | J25: 405269
C26: X | I26: 0 | J26: 0
D27: 56416918662 | E27: 1132440 | F27: 68144618192 | G27: 1320374 | I27: 124561536854 | J27: 2452814
B31: OPORTUNO | D31: =D9=SUM(D3:D8) -> TRUE | E31: =E9=SUM(E3:E8) -> TRUE | F31: =F9=SUM(F3:F8) -> TRUE | G31: =G9=SUM(G3:G8) -> TRUE
B33: EXTEMP. | D33: =D18=SUM(D12:D17) -> TRUE | E33: =E18=SUM(E12:E17) -> TRUE | F33: =F18=SUM(F12:F17) -> TRUE | G33: =G18=SUM(G12:G17) -> TRUE
B35: TOTAL | D35: =D27=SUM(D21:D26) -> TRUE | E35: =E27=SUM(E21:E26) -> TRUE | F35: =F27=SUM(F21:F26) -> TRUE | G35: =G27=SUM(G21:G26) -> TRUE | I35: =I27=SUM(I21:I26) -> TRUE | J35: =J27=SUM(J21:J26) -> TRUE
E69: =C69-G17 -> 0

Sheet Recaudo ENERBIT
B2: OPORTUNO | C2: ASE | D2: VALOR 1° Q | E2: NUMERO REG. 1°Q | F2: VALOR 2° Q | G2: NUMERO REG. 2°Q
C3: 1 | D3: 0 | E3: 0 | F3: 0 | G3: 0
C4: 2 | D4: 0 | E4: 0 | F4: 0 | G4: 0
C5: 3 | D5: 0 | E5: 0 | F5: 0 | G5: 0
C6: 4 | D6: 0 | E6: 0 | F6: 0 | G6: 0
C7: 5 | D7: 129429946 | E7: 2854 | F7: 28645323 | G7: 545
C8: X
D9: 129429946 | E9: 2854 | F9: 28645323 | G9: 545
C11: ASE | D11: VALOR 1° Q | E11: NUMERO REG. 1°Q | F11: VALOR 2° Q | G11: NUMERO REG. 2°Q
B12: EXTEMP. | C12: 1 | D12: 0 | E12: 0 | F12: 0 | G12: 0
C13: 2 | D13: 0 | E13: 0 | F13: 0 | G13: 0
C14: 3 | D14: 0 | E14: 0 | F14: 0 | G14: 0
C15: 4 | D15: 0 | E15: 0 | F15: 0 | G15: 0
C16: 5 | D16: 106710 | E16: 1 | F16: 0 | G16: 0
C17: X
D18: 106710 | E18: 1 | F18: 0 | G18: 0
C20: ASE | D20: VALOR 1° Q | E20: NUMERO REG. 1°Q | F20: VALOR 2° Q | G20: NUMERO REG. 2°Q | I20: VALOR TOTAL MES | J20: NUMERO REGISTROS MES
B21: TOTAL | C21: 1 | D21: 0 | E21: 0 | F21: 0 | G21: 0 | I21: 0 | J21: 0
C22: 2 | D22: 0 | E22: 0 | F22: 0 | G22: 0 | I22: 0 | J22: 0
C23: 3 | D23: 0 | E23: 0 | F23: 0 | G23: 0 | I23: 0 | J23: 0
C24: 4 | D24: 0 | E24: 0 | F24: 0 | G24: 0 | I24: 0 | J24: 0
C25: 5 | D25: 129536656 | E25: 2855 | F25: 28645323 | G25: 545 | I25: 158181979 | J25: 3400
C26: X | I26: 0 | J26: 0
D27: 129536656 | E27: 2855 | F27: 28645323 | G27: 545 | I27: 158181979 | J27: 3400
B31: OPORTUNO | D31: =D9=SUM(D3:D8) -> TRUE | E31: =E9=SUM(E3:E8) -> TRUE | F31: =F9=SUM(F3:F8) -> TRUE | G31: =G9=SUM(G3:G8) -> TRUE
B33: EXTEMP. | D33: =D18=SUM(D12:D17) -> TRUE | E33: =E18=SUM(E12:E17) -> TRUE | F33: =F18=SUM(F12:F17) -> TRUE | G33: =G18=SUM(G12:G17) -> TRUE
B35: TOTAL | D35: =D27=SUM(D21:D26) -> TRUE | E35: =E27=SUM(E21:E26) -> TRUE | F35: =F27=SUM(F21:F26) -> TRUE | G35: =G27=SUM(G21:G26) -> TRUE | I35: =I27=SUM(I21:I26) -> TRUE | J35: =J27=SUM(J21:J26) -> TRUE
E69: =C69-G17 -> 0

Sheet Recaudo EAAB + Ciud Limp
B2: Ciudad Limpia - Prestador | C2: ASE | D2: VALOR 1° Q | E2: NUMERO REG. 1°Q | F2: VALOR 2° Q | G2: NUMERO REG. 2°Q
C3: 1 | D3: 0 | E3: 0 | F3: 0 | G3: 0
C4: 2 | D4: 0 | E4: 0 | F4: 0 | G4: 0
C5: 3 | D5: 0 | E5: 0 | F5: 0 | G5: 0
C6: 4 | D6: 0 | E6: 0 | F6: 0 | G6: 0
C7: 5 | D7: 0 | E7: 0 | F7: 0 | G7: 0
C8: X
D9: 0 | E9: 0 | F9: 0 | G9: 0
C11: ASE | D11: VALOR 1° Q | E11: NUMERO REG. 1°Q | F11: VALOR 2° Q | G11: NUMERO REG. 2°Q
B12: EAAB - Prestador | C12: 1 | D12: 0 | E12: 0 | F12: 0 | G12: 0
C13: 2 | D13: 0 | E13: 0 | F13: 0 | G13: 0
C14: 3 | D14: 0 | E14: 0 | F14: 0 | G14: 0
C15: 4 | D15: 0 | E15: 0 | F15: 0 | G15: 0
C16: 5 | D16: 0 | E16: 0 | F16: 0 | G16: 0
C17: X
D18: 0 | E18: 0 | F18: 0 | G18: 0
C20: ASE | D20: VALOR 1° Q | E20: NUMERO REG. 1°Q | F20: VALOR 2° Q | G20: NUMERO REG. 2°Q | I20: VALOR TOTAL MES | J20: NUMERO REGISTROS MES
B21: TOTAL | C21: 1 | D21: 0 | E21: 0 | F21: 0 | G21: 0 | I21: 0 | J21: 0
C22: 2 | D22: 0 | E22: 0 | F22: 0 | G22: 0 | I22: 0 | J22: 0
C23: 3 | D23: 0 | E23: 0 | F23: 0 | G23: 0 | I23: 0 | J23: 0
C24: 4 | D24: 0 | E24: 0 | F24: 0 | G24: 0 | I24: 0 | J24: 0
C25: 5 | D25: 0 | E25: 0 | F25: 0 | G25: 0 | I25: 0 | J25: 0
C26: X | I26: 0 | J26: 0
D27: 0 | E27: 0 | F27: 0 | G27: 0 | I27: 0 | J27: 0
B31: OPORTUNO | D31: =D9=SUM(D3:D8) -> TRUE | E31: =E9=SUM(E3:E8) -> TRUE | F31: =F9=SUM(F3:F8) -> TRUE | G31: =G9=SUM(G3:G8) -> TRUE
B33: EXTEMP. | D33: =D18=SUM(D12:D17) -> TRUE | E33: =E18=SUM(E12:E17) -> TRUE | F33: =F18=SUM(F12:F17) -> TRUE | G33: =G18=SUM(G12:G17) -> TRUE
B35: TOTAL | D35: =D27=SUM(D21:D26) -> TRUE | E35: =E27=SUM(E21:E26) -> TRUE | F35: =F27=SUM(F21:F26) -> TRUE | G35: =G27=SUM(G21:G26) -> TRUE | I35: =I27=SUM(I21:I26) -> TRUE | J35: =J27=SUM(J21:J26) -> TRUE

Sheet Recaudo Directa Occidente
B2: OPORTUNO | C2: ASE | D2: VALOR 1° Q | E2: NUMERO REG. 1°Q | F2: VALOR 2° Q | G2: NUMERO REG. 2°Q
C3: 1 | D3: 335015748 | E3: 1590 | F3: 644977472 | G3: 2386
C4: 2 | D4: 389025865 | E4: 2713 | F4: 1127716979 | G4: 9079
C5: 3 | D5: 346289622 | E5: 1123 | F5: 858037220 | G5: 2287
C6: 4 | D6: 236541566 | E6: 1643 | F6: 362907055 | G6: 2213
C7: 5 | D7: 155743651 | E7: 776 | F7: 271576031 | G7: 1257
C8: X | D8: 0 | E8: 0 | F8: 0 | G8: 0
D9: 1462616452 | E9: 7845 | F9: 3265214757 | G9: 17222
C11: ASE | D11: VALOR 1° Q | E11: NUMERO REG. 1°Q | F11: VALOR 2° Q | G11: NUMERO REG. 2°Q
B12: EXTEMP. | C12: 1 | D12: 205459944 | E12: 70 | F12: 160336245 | G12: 481
C13: 2 | D13: 33195420 | E13: 58 | F13: 298229199 | G13: 665
C14: 3 | D14: 126229443 | E14: 55 | F14: 387133299 | G14: 251
C15: 4 | D15: 2600820 | E15: 21 | F15: 123732462 | G15: 270
C16: 5 | D16: 25989911 | E16: 18 | F16: 49923090 | G16: 176
C17: X | D17: 0 | E17: 0 | F17: 0 | G17: 0
D18: 393475538 | E18: 222 | F18: 1019354295 | G18: 1843
C20: ASE | D20: VALOR 1° Q | E20: NUMERO REG. 1°Q | F20: VALOR 2° Q | G20: NUMERO REG. 2°Q | I20: VALOR TOTAL MES | J20: NUMERO REGISTROS MES
B21: TOTAL | C21: 1 | D21: 540475692 | E21: 1660 | F21: 805313717 | G21: 2867 | I21: 1345789409 | J21: 4527
C22: 2 | D22: 422221285 | E22: 2771 | F22: 1425946178 | G22: 9744 | I22: 1848167463 | J22: 12515
C23: 3 | D23: 472519065 | E23: 1178 | F23: 1245170519 | G23: 2538 | I23: 1717689584 | J23: 3716
C24: 4 | D24: 239142386 | E24: 1664 | F24: 486639517 | G24: 2483 | I24: 725781903 | J24: 4147
C25: 5 | D25: 181733562 | E25: 794 | F25: 321499121 | G25: 1433 | I25: 503232683 | J25: 2227
C26: X | D26: 0 | E26: 0 | F26: 0 | G26: 0 | I26: 0 | J26: 0
D27: 1856091990 | E27: 8067 | F27: 4284569052 | G27: 19065 | I27: 6140661042 | J27: 27132
B31: OPORTUNO | D31: =D9=SUM(D3:D8) -> TRUE | E31: =E9=SUM(E3:E8) -> TRUE | F31: =F9=SUM(F3:F8) -> TRUE | G31: =G9=SUM(G3:G8) -> TRUE
B33: EXTEMP. | D33: =D18=SUM(D12:D17) -> TRUE | E33: =E18=SUM(E12:E17) -> TRUE | F33: =F18=SUM(F12:F17) -> TRUE | G33: =G18=SUM(G12:G17) -> TRUE
B35: TOTAL | D35: =D27=SUM(D21:D26) -> TRUE | E35: =E27=SUM(E21:E26) -> TRUE | F35: =F27=SUM(F21:F26) -> TRUE | G35: =G27=SUM(G21:G26) -> TRUE | I35: =I27=SUM(I21:I26) -> TRUE | J35: =J27=SUM(J21:J26) -> TRUE
E69: =C69-G17 -> 0

Sheet REPORTE RECAUDO x BANCO
C1: ENEL | D1: CIUDAD LIMPIA | E1: EAB | F1: NUEVO ESQUEMA | G1: ENERBIT | H1: OCCIDENTE | I1: Total
B2: 1-APLICADOS A FACTURACION | C2: =C13+C23+C32+C41+C51 -> 6.7949268e+10 | D2: =D13+D23+D32+D41+D51 -> 0 | E2: =E13+E23+E32+E41+E51 -> 0 | F2: =F13+F23+F32+F41+F51 -> 17028090 | G2: =G13+G23+G32+G41+G51 -> 26864220 | H2: =H13+H23+H32+H41+H51 -> 4.1068552e+09 | I2: =SUM(C2:H2) -> 7.2100015e+10
B3: 2-SALDOS A FAVOR GENERADOS | C3: =C14+C24+C33+C42+C52 -> 2.3671717e+08 | D3: =D14+D24+D33+D42+D52 -> 0 | E3: =E14+E24+E33+E42+E52 -> 0 | F3: =F14+F24+F33+F42+F52 -> 23089310 | G3: =G14+G24+G33+G42+G52 -> 1781103 | H3: =H14+H24+H33+H42+H52 -> 1.3687274e+08 | I3: =SUM(C3:H3) -> 3.9846032e+08
B4: 3-APLICADOS A FINANCIACIONES NUEVAS | C4: =C15+C25+C34+C43+C53 -> 0 | D4: =D15+D25+D34+D43+D53 -> 0 | E4: =E15+E25+E34+E43+E53 -> 0 | F4: =F15+F25+F34+F43+F53 -> 0 | G4: =G15+G25+G34+G43+G53 -> 0 | H4: =H15+H25+H34+H43+H53 -> 40841134 | I4: =SUM(C4:H4) -> 40841134
B5: 7-APLICADOS A RECIBOS SERVICIOS ESPECIALES | C5: =C16+C26+C35+C44+C54 -> 0 | D5: =D16+D26+D35+D44+D54 -> 0 | E5: =E16+E26+E35+E44+E54 -> 0 | F5: =F16+F26+F35+F44+F54 -> 0 | G5: =G16+G26+G35+G44+G54 -> 0 | H5: =H16+H26+H35+H44+H54 -> 0 | I5: =SUM(C5:H5) -> 0
B6: Total | C6: =SUM(C2:C5) -> 68185984867 | D6: =SUM(D2:D5) -> 0 | E6: =SUM(E2:E5) -> 0 | F6: =SUM(F2:F5) -> 40117400 | G6: =SUM(G2:G5) -> 28645323 | H6: =SUM(H2:H5) -> 4.2845691e+09 | I6: =SUM(I2:I5) -> 7.2539317e+10
C7: =C6=(C17+C27+C36+C45+C55) -> TRUE | D7: =D6=(D17+D27+D36+D45+D55) -> TRUE | E7: =E6=(E17+E27+E36+E45+E55) -> TRUE | F7: =F6=(F17+F27+F36+F45+F55) -> TRUE | H7: =H6=(H17+H27+H36+H45+H55) -> TRUE | I7: =I6=(I17+I27+I36+I45+I55) -> TRUE
B10: ASE 1
B11: Resumen Recaudo Aplicado Por Servicio
C12: ENEL | D12: CIUDAD LIMPIA | E12: EAB | F12: NUEVO ESQUEMA | G12: ENERBIT | H12: OCCIDENTE | I12: Total
B13: 1-APLICADOS A FACTURACION | C13: 1.6577116e+10 | D13: 0 | E13: 0 | F13: 0 | G13: 0 | H13: 7.7622223e+08 | I13: =SUM(C13:H13) -> 1.7353338e+10 | J13: =SUM(C13:H13)=I13 -> TRUE
B14: 2-SALDOS A FAVOR GENERADOS | C14: 83572548 | D14: 0 | E14: 0 | F14: 0 | G14: 0 | H14: 17358484 | I14: =SUM(C14:H14) -> 1.0093103e+08 | J14: =SUM(C14:H14)=I14 -> TRUE
B15: 3-APLICADOS A FINANCIACIONES NUEVAS | C15: 0 | D15: 0 | E15: 0 | F15: 0 | G15: 0 | H15: 11733000 | I15: =SUM(C15:H15) -> 11733000 | J15: =SUM(C15:H15)=I15 -> TRUE
B16: 7-APLICADOS A RECIBOS SERVICIOS ESPECIALES | C16: 0 | D16: 0 | E16: 0 | F16: 0 | G16: 0 | H16: 0 | I16: =SUM(C16:H16) -> 0 | J16: =SUM(C16:H16)=I16 -> TRUE
B17: Total | C17: =SUM(C13:C16) -> 16660688191 | D17: =SUM(D13:D16) -> 0 | E17: =SUM(E13:E16) -> 0 | F17: =SUM(F13:F16) -> 0 | G17: =SUM(G13:G16) -> 0 | H17: =SUM(H13:H16) -> 805313717 | I17: =SUM(I13:I16) -> 17466001908 | J17: =SUM(C17:H17)=I17 -> TRUE
B20: ASE 2
B21: Resumen Recaudo Aplicado Por Servicio
C22: ENEL | D22: CIUDAD LIMPIA | E22: EAB | F22: NUEVO ESQUEMA | G22: ENERBIT | H22: OCCIDENTE | I22: Total
B23: 1-APLICADOS A FACTURACION | C23: 19047798453 | D23: 0 | E23: 0 | F23: 11411240 | G23: 0 | H23: 1346513069 | I23: =SUM(C23:H23) -> 20405722762 | J23: =SUM(C23:H23)=I23 -> TRUE
B24: 2-SALDOS A FAVOR GENERADOS | C24: 44281124 | D24: 0 | E24: 0 | F24: 12820520 | G24: 0 | H24: 79433109 | I24: =SUM(C24:H24) -> 136534753 | J24: =SUM(C24:H24)=I24 -> TRUE
B25: 3-APLICADOS A FINANCIACIONES NUEVAS | C25: 0 | D25: 0 | E25: 0 | F25: 0 | G25: 0 | H25: 0 | I25: =SUM(C25:H25) -> 0 | J25: =SUM(C25:H25)=I25 -> TRUE
B26: 7-APLICADOS A RECIBOS SERVICIOS ESPECIALES | C26: 0 | D26: 0 | E26: 0 | F26: 0 | G26: 0 | H26: 0 | I26: =SUM(C26:H26) -> 0 | J26: =SUM(C26:H26)=I26 -> TRUE
B27: Total | C27: =SUM(C23:C26) -> 19092079577 | D27: =SUM(D23:D26) -> 0 | E27: =SUM(E23:E26) -> 0 | F27: =SUM(F23:F26) -> 24231760 | G27: =SUM(G23:G26) -> 0 | H27: =SUM(H23:H26) -> 1425946178 | I27: =SUM(I23:I26) -> 20542257515 | J27: =SUM(C27:H27)=I27 -> TRUE
B29: ASE 3
B30: Resumen Recaudo Aplicado Por Servicio
C31: ENEL | D31: CIUDAD LIMPIA | E31: EAB | F31: NUEVO ESQUEMA | G31: ENERBIT | H31: OCCIDENTE | I31: Total
B32: 1-APLICADOS A FACTURACION | C32: 14010202412 | D32: 0 | E32: 0 | F32: 0 | G32: 0 | H32: 1.2278438e+09 | I32: =SUM(C32:H32) -> 1.5238046e+10 | J32: =SUM(C32:H32)=I32 -> TRUE
B33: 2-SALDOS A FAVOR GENERADOS | C33: 44039530 | D33: 0 | E33: 0 | F33: 0 | G33: 0 | H33: 14844503 | I33: =SUM(C33:H33) -> 58884033 | J33: =SUM(C33:H33)=I33 -> TRUE
B34: 3-APLICADOS A FINANCIACIONES NUEVAS | C34: 0 | D34: 0 | E34: 0 | F34: 0 | G34: 0 | H34: 2482198.7 | I34: =SUM(C34:H34) -> 2482198.7 | J34: =SUM(C34:H34)=I34 -> TRUE
B35: 7-APLICADOS A RECIBOS SERVICIOS ESPECIALES | C35: 0 | D35: 0 | E35: 0 | F35: 0 | G35: 0 | H35: 0 | I35: =SUM(C35:H35) -> 0 | J35: =SUM(C35:H35)=I35 -> TRUE
B36: Total | C36: =SUM(C32:C35) -> 14054241942 | D36: =SUM(D32:D35) -> 0 | E36: =SUM(E32:E35) -> 0 | F36: =SUM(F32:F35) -> 0 | G36: =SUM(G32:G35) -> 0 | H36: =SUM(H32:H35) -> 1245170519 | I36: =SUM(I32:I35) -> 15299412461 | J36: =SUM(C36:H36)=I36 -> TRUE
B38: ASE 4
B39: Resumen Recaudo Aplicado Por Servicio
C40: ENEL | D40: CIUDAD LIMPIA | E40: EAB | F40: NUEVO ESQUEMA | G40: ENERBIT | H40: OCCIDENTE | I40: Total
B41: 1-APLICADOS A FACTURACION | C41: 6603996268 | D41: 0 | E41: 0 | F41: 5616850 | G41: 0 | H41: 4.4604021e+08 | I41: =SUM(C41:H41) -> 7.0556533e+09 | J41: =SUM(C41:H41)=I41 -> TRUE
B42: 2-SALDOS A FAVOR GENERADOS | C42: 48826052 | D42: 0 | E42: 0 | F42: 10268790 | G42: 0 | H42: 14631795 | I42: =SUM(C42:H42) -> 73726637 | J42: =SUM(C42:H42)=I42 -> TRUE
B43: 3-APLICADOS A FINANCIACIONES NUEVAS | C43: 0 | D43: 0 | E43: 0 | F43: 0 | G43: 0 | H43: 25967508 | I43: =SUM(C43:H43) -> 25967508 | J43: =SUM(C43:H43)=I43 -> TRUE
B44: 7-APLICADOS A RECIBOS SERVICIOS ESPECIALES | C44: 0 | D44: 0 | E44: 0 | F44: 0 | G44: 0 | H44: 0 | I44: =SUM(C44:H44) -> 0 | J44: =SUM(C44:H44)=I44 -> TRUE
B45: Total | C45: =SUM(C41:C44) -> 6652822320 | D45: =SUM(D41:D44) -> 0 | E45: =SUM(E41:E44) -> 0 | F45: =SUM(F41:F44) -> 15885640 | G45: =SUM(G41:G44) -> 0 | H45: =SUM(H41:H44) -> 4.8663952e+08 | I45: =SUM(I41:I44) -> 7155347477 | J45: =SUM(C45:H45)=I45 -> TRUE
B48: ASE 5
...

Sheet ANT EXT-REV
C1: ASE 1 | E1: ASE 2 | G1: ASE 3 | I1: ASE 4 | K1: ASE 5 | M1: TOTAL
C2: REPORTE 3 | D2: REPORTE 4 | E2: REPORTE 3 | F2: REPORTE 4 | G2: REPORTE 3 | H2: REPORTE 4 | I2: REPORTE 3 | J2: REPORTE 4 | K2: REPORTE 3 | L2: REPORTE 4 | M2: REPORTE 3 | N2: REPORTE 4
B3: APLICADO | C3: =C11+C19+C27+C35+C43 -> 49580 | D3: =D11+D19+D27+D35+D43 -> -16536713 | E3: =E11+E19+E27+E35+E43 -> 56190070 | F3: =F11+F19+F27+F35+F43 -> -71069759 | G3: =G11+G19+G27+G35+G43 -> 1307680 | H3: =H11+H19+H27+H35+H43 -> -32310980 | I3: =I11+I19+I27+I35+I43 -> 4343101 | J3: =J11+J19+J27+J35+J43 -> -33738104 | ... L3: =L11+L19+L27+L35+L43 -> -3092375.5 | M3: =C3+E3+G3+I3+K3 -> 62332280 | N3: =D3+F3+H3+J3+L3 -> -1.5674793e+08 | P3: =N3=(-VALIDACION_TOTAL!M9) -> TRUE
B4: ANTICIPOS | C4: =C12+C20+C28+C36+C44 -> 82340 | D4: =D12+D20+D28+D36+D44 -> -182537.91 | E4: =E12+E20+E28+E36+E44 -> 5228610 | F4: =F12+F20+F28+F36+F44 -> 0 | G4: =G12+G20+G28+G36+G44 -> 0 | H4: =H12+H20+H28+H36+H44 -> -2423600.2 | I4: =I12+I20+I28+I36+I44 -> 14538094 | J4: =J12+J20+J28+J36+J44 -> -14979760 | ... L4: =L12+L20+L28+L36+L44 -> -215053.47 | M4: =C4+E4+G4+I4+K4 -> 19936594 | N4: =D4+F4+H4+J4+L4 -> -17800951 | P4: =N4=(-'CONSOLIDADO_TOTAL RECAUDO'!L131) -> TRUE
B5: TOTAL | C5: =SUM(C3:C4) -> 131920 | D5: =SUM(D3:D4) -> -16719251 | E5: =SUM(E3:E4) -> 61418680 | F5: =SUM(F3:F4) -> -71069759 | G5: =SUM(G3:G4) -> 1307680 | H5: =SUM(H3:H4) -> -34734580 | I5: =SUM(I3:I4) -> 18881195 | J5: =SUM(J3:J4) -> -48717864 | ... N5: =SUM(N3:N4) -> -174548883
C6: =C5=(C13+C21+C29+C37+C45) -> TRUE | D6: =D5=(D13+D21+D29+D37+D45) -> TRUE | E6: =E5=(E13+E21+E29+E37+E45) -> TRUE | F6: =F5=(F13+F21+F29+F37+F45) -> TRUE | G6: =G5=(G13+G21+G29+G37+G45) -> TRUE | H6: =H5=(H13+H21+H29+H37+H45) -> TRUE | I6: =I5=(I13+I21+I29+I37+I45) -> TRUE | J6: =J5=(J13+J21+J29+J37+J45) -> TRUE | ... N6: =N5=(N13+N21+N29+N37+N45) -> TRUE
B8: BANCO DE OCCIDENTE
C9: ASE 1 | E9: ASE 2 | G9: ASE 3 | I9: ASE 4 | K9: ASE 5 | M9: TOTAL
C10: REPORTE 3 | D10: REPORTE 4 | E10: REPORTE 3 | F10: REPORTE 4 | G10: REPORTE 3 | H10: REPORTE 4 | I10: REPORTE 3 | J10: REPORTE 4 | K10: REPORTE 3 | L10: REPORTE 4 | M10: REPORTE 3 | N10: REPORTE 4
B11: APLICADO | C11: 0 | D11: -1002751.4 | E11: 111210 | F11: -290750 | G11: 0 | H11: -306659.8 | I11: 691194 | J11: -3233428.3 | K11: 441849 | L11: -1026775.5 | M11: =C11+E11+G11+I11+K11 -> 1244253 | N11: =D11+F11+H11+J11+L11 -> -5860365.1
B12: ANTICIPOS | C12: 82340 | D12: -165648.61 | E12: 1370 | F12: 0 | G12: 0 | H12: -2343750.2 | I12: 2209000 | J12: -14593376 | K12: 87550 | L12: -165773.47 | M12: =C12+E12+G12+I12+K12 -> 2380260 | N12: =D12+F12+H12+J12+L12 -> -17268548
B13: TOTAL | C13: =SUM(C11:C12) -> 82340 | D13: =SUM(D11:D12) -> -1168400 | E13: =SUM(E11:E12) -> 112580 | F13: =SUM(F11:F12) -> -290750 | G13: =SUM(G11:G12) -> 0 | H13: =SUM(H11:H12) -> -2650410 | I13: =SUM(I11:I12) -> 2900194 | J13: =SUM(J11:J12) -> -17826804 | ... N13: =SUM(N11:N12) -> -23128913
B16: EAAB RECIPROCIDAD
C17: ASE 1 | E17: ASE 2 | G17: ASE 3 | I17: ASE 4 | K17: ASE 5 | M17: TOTAL
C18: REPORTE 3 | D18: REPORTE 4 | E18: REPORTE 3 | F18: REPORTE 4 | G18: REPORTE 3 | H18: REPORTE 4 | I18: REPORTE 3 | J18: REPORTE 4 | K18: REPORTE 3 | L18: REPORTE 4 | M18: REPORTE 3 | N18: REPORTE 4
B19: APLICADO | C19: 0 | D19: 0 | E19: 0 | F19: 0 | G19: 0 | H19: 0 | I19: 41900 | J19: -736030 | K19: 0 | L19: 0 | M19: =C19+E19+G19+I19+K19 -> 41900 | N19: =D19+F19+H19+J19+L19 -> -736030
B20: ANTICIPOS | C20: 0 | D20: 0 | E20: 0 | F20: 0 | G20: 0 | H20: 0 | I20: 694130 | J20: 0 | K20: 0 | L20: 0 | M20: =C20+E20+G20+I20+K20 -> 694130 | N20: =D20+F20+H20+J20+L20 -> 0
B21: TOTAL | C21: =SUM(C19:C20) -> 0 | D21: =SUM(D19:D20) -> 0 | E21: =SUM(E19:E20) -> 0 | F21: =SUM(F19:F20) -> 0 | G21: =SUM(G19:G20) -> 0 | H21: =SUM(H19:H20) -> 0 | I21: =SUM(I19:I20) -> 736030 | J21: =SUM(J19:J20) -> -736030 | ... L21: =SUM(L19:L20) -> 0 | M21: =C21+E21+G21+I21+K21 -> 736030 | N21: =SUM(N19:N20) -> -736030
B24: EAAB CIUDAD LIMPIA
C25: ASE 1 | E25: ASE 2 | G25: ASE 3 | I25: ASE 4 | K25: ASE 5 | M25: TOTAL
C26: REPORTE 3 | D26: REPORTE 4 | E26: REPORTE 3 | F26: REPORTE 4 | G26: REPORTE 3 | H26: REPORTE 4 | I26: REPORTE 3 | J26: REPORTE 4 | K26: REPORTE 3 | L26: REPORTE 4 | M26: REPORTE 3 | N26: REPORTE 4
B27: APLICADO | C27: 0 | D27: 0 | E27: 0 | F27: 0 | G27: 0 | H27: 0 | I27: 0 | J27: 0 | K27: 0 | L27: 0 | M27: =C27+E27+G27+I27+K27 -> 0 | N27: =D27+F27+H27+J27+L27 -> 0
B28: ANTICIPOS | C28: 0 | D28: 0 | E28: 0 | F28: 0 | G28: 0 | H28: 0 | I28: 0 | J28: 0 | K28: 0 | L28: 0 | M28: =C28+E28+G28+I28+K28 -> 0 | N28: =D28+F28+H28+J28+L28 -> 0
B29: TOTAL | C29: =SUM(C27:C28) -> 0 | D29: =SUM(D27:D28) -> 0 | E29: =SUM(E27:E28) -> 0 | F29: =SUM(F27:F28) -> 0 | G29: =SUM(G27:G28) -> 0 | H29: =SUM(H27:H28) -> 0 | I29: =SUM(I27:I28) -> 0 | J29: =SUM(J27:J28) -> 0 | ... N29: =SUM(N27:N28) -> 0
B32: ENEL
C33: ASE 1 | E33: ASE 2 | G33: ASE 3 | I33: ASE 4 | K33: ASE 5 | M33: TOTAL
C34: REPORTE 3 | D34: REPORTE 4 | E34: REPORTE 3 | F34: REPORTE 4 | G34: REPORTE 3 | H34: REPORTE 4 | I34: REPORTE 3 | J34: REPORTE 4 | K34: REPORTE 3 | L34: REPORTE 4 | M34: REPORTE 3 | N34: REPORTE 4
B35: APLICADO | C35: 49580 | D35: -15533962 | E35: 56078860 | F35: -70779009 | G35: 1307680 | H35: -32004320 | I35: 3610007 | J35: -29768646 | K35: 0 | L35: -2065600 | M35: =C35+E35+G35+I35+K35 -> 61046127 | N35: =D35+F35+H35+J35+L35 -> -1.5015154e+08
B36: ANTICIPOS | C36: 0 | D36: -16889.3 | E36: 5227240 | F36: 0 | G36: 0 | H36: -79850 | I36: 11634964 | J36: -386384.11 | K36: 0 | L36: -49280 | M36: =C36+E36+G36+I36+K36 -> 16862204 | N36: =D36+F36+H36+J36+L36 -> -532403.41
B37: TOTAL | C37: =SUM(C35:C36) -> 49580 | D37: =SUM(D35:D36) -> -15550851 | E37: =SUM(E35:E36) -> 61306100 | F37: =SUM(F35:F36) -> -70779009 | G37: =SUM(G35:G36) -> 1307680 | H37: =SUM(H35:H36) -> -32084170 | I37: =SUM(I35:I36) -> 15244971 | J37: =SUM(J35:J36) -> -30155030 | ... N37: =SUM(N35:N36) -> -150683940
B40: ENERBIT
C41: ASE 1 | E41: ASE 2 | G41: ASE 3 | I41: ASE 4 | K41: ASE 5 | M41: TOTAL
C42: REPORTE 3 | D42: REPORTE 4 | E42: REPORTE 3 | F42: REPORTE 4 | G42: REPORTE 3 | H42: REPORTE 4 | I42: REPORTE 3 | J42: REPORTE 4 | K42: REPORTE 3 | L42: REPORTE 4 | M42: REPORTE 3 | N42: REPORTE 4
B43: APLICADO | C43: 0 | D43: 0 | E43: 0 | F43: 0 | G43: 0 | H43: 0 | I43: 0 | J43: 0 | K43: 0 | L43: 0 | M43: =C43+E43+G43+I43+K43 -> 0 | N43: =D43+F43+H43+J43+L43 -> 0
B44: ANTICIPOS | C44: 0 | D44: 0 | E44: 0 | F44: 0 | G44: 0 | H44: 0 | I44: 0 | J44: 0 | K44: 0 | L44: 0 | M44: =C44+E44+G44+I44+K44 -> 0 | N44: =D44+F44+H44+J44+L44 -> 0
B45: TOTAL | C45: =SUM(C43:C44) -> 0 | D45: =SUM(D43:D44) -> 0 | E45: =SUM(E43:E44) -> 0 | F45: =SUM(F43:F44) -> 0 | G45: =SUM(G43:G44) -> 0 | H45: =SUM(H43:H44) -> 0 | I45: =SUM(I43:I44) -> 0 | J45: =SUM(J43:J44) -> 0 | ... N45: =SUM(N43:N44) -> 0

Sheet ANTICIPOS USUARIOS
B1: TOTAL | E1: RECIPRCIDAD | H1: ENEL | K1: ENERBIT | N1: OCCIDENTE | Q1: EAAB-CIUDADLIMPIA
B2: ASE | C2: ANTICIPOS GENERADOS POR PAGO | E2: ASE | F2: ANTICIPOS GENERADOS POR PAGO | H2: ASE | I2: ANTICIPOS GENERADOS POR PAGO | K2: ASE | L2: ANTICIPOS GENERADOS POR PAGO | N2: ASE | O2: ANTICIPOS GENERADOS POR PAGO | Q2: ASE | R2: ANTICIPOS GENERADOS POR PAGO | T2: Anticipos generados por pago
B3: 1 | C3: ='REPORTE RECAUDO x BANCO'!I14 -> 1.0093103e+08 | E3: 1 | F3: ='REPORTE RECAUDO x BANCO'!F14 -> 0 | H3: 1 | I3: ='REPORTE RECAUDO x BANCO'!C14 -> 83572548 | K3: 1 | L3: ='REPORTE RECAUDO x BANCO'!G14 -> 0 | N3: 1 | O3: ='REPORTE RECAUDO x BANCO'!H14 -> 17358484 | Q3: 1 | R3: ='REPORTE RECAUDO x BANCO'!D14+'REPORTE RECAUDO x BANCO'!E14 -> 0 | T3: Sale del reporte Recaudo por Bancos.
B4: 2 | C4: ='REPORTE RECAUDO x BANCO'!I24 -> 136534753 | E4: 2 | F4: ='REPORTE RECAUDO x BANCO'!F24 -> 12820520 | H4: 2 | I4: ='REPORTE RECAUDO x BANCO'!C24 -> 44281124 | K4: 2 | L4: ='REPORTE RECAUDO x BANCO'!G24 -> 0 | N4: 2 | O4: ='REPORTE RECAUDO x BANCO'!H24 -> 79433109 | Q4: 2 | R4: ='REPORTE RECAUDO x BANCO'!D24+'REPORTE RECAUDO x BANCO'!E24 -> 0
B5: 3 | C5: ='REPORTE RECAUDO x BANCO'!I33 -> 58884033 | E5: 3 | F5: ='REPORTE RECAUDO x BANCO'!F33 -> 0 | H5: 3 | I5: ='REPORTE RECAUDO x BANCO'!C33 -> 44039530 | K5: 3 | L5: ='REPORTE RECAUDO x BANCO'!G33 -> 0 | N5: 3 | O5: ='REPORTE RECAUDO x BANCO'!H33 -> 14844503 | Q5: 3 | R5: ='REPORTE RECAUDO x BANCO'!D33+'REPORTE RECAUDO x BANCO'!E33 -> 0
B6: 4 | C6: ='REPORTE RECAUDO x BANCO'!I42 -> 73726637 | E6: 4 | F6: ='REPORTE RECAUDO x BANCO'!F42 -> 10268790 | H6: 4 | I6: ='REPORTE RECAUDO x BANCO'!C42 -> 48826052 | K6: 4 | L6: ='REPORTE RECAUDO x BANCO'!G42 -> 0 | N6: 4 | O6: ='REPORTE RECAUDO x BANCO'!H42 -> 14631795 | Q6: 4 | R6: ='REPORTE RECAUDO x BANCO'!D42+'REPORTE RECAUDO x BANCO'!E42 -> 0
B7: 5 | C7: ='REPORTE RECAUDO x BANCO'!I52 -> 28383866 | E7: 5 | F7: ='REPORTE RECAUDO x BANCO'!F52 -> 0 | H7: 5 | I7: ='REPORTE RECAUDO x BANCO'!C52 -> 15997915 | K7: 5 | L7: ='REPORTE RECAUDO x BANCO'!G52 -> 1781103 | N7: 5 | O7: ='REPORTE RECAUDO x BANCO'!H52 -> 10604848 | Q7: 5 | R7: ='REPORTE RECAUDO x BANCO'!D52+'REPORTE RECAUDO x BANCO'!E52 -> 0
C8: =SUM(C3:C7) -> 3.9846032e+08 | F8: =SUM(F3:F7) -> 23089310 | I8: =SUM(I3:I7) -> 2.3671717e+08 | L8: =SUM(L3:L7) -> 1781103 | O8: =SUM(O3:O7) -> 1.3687274e+08 | R8: =SUM(R3:R7) -> 0
C9: =C8='REPORTE RECAUDO x BANCO'!I3 -> TRUE | F9: =F8='REPORTE RECAUDO x BANCO'!F3 -> TRUE | I9: =I8='REPORTE RECAUDO x BANCO'!C3 -> TRUE | L9: =L8='REPORTE RECAUDO x BANCO'!G3 -> TRUE | O9: =O8='REPORTE RECAUDO x BANCO'!H3 -> TRUE | R9: =R8='REPORTE RECAUDO x BANCO'!D3+'REPORTE RECAUDO x BANCO'!E3 -> TRUE
B11: ASE | C11: ANTICIPOS GENERADOS POR EXTEMPORANEOS | E11: ASE | F11: ANTICIPOS GENERADOS POR EXTEMPORANEOS | H11: ASE | I11: ANTICIPOS GENERADOS POR EXTEMPORANEOS | K11: ASE | L11: ANTICIPOS GENERADOS POR EXTEMPORANEOS | N11: ASE | O11: ANTICIPOS GENERADOS POR EXTEMPORANEOS | Q11: ASE | R11: ANTICIPOS GENERADOS POR EXTEMPORANEOS | T11: Anticipos generados por pagos aplicados de reversiones
B12: 1 | C12: ='ANT EXT-REV'!C4 -> 82340 | E12: 1 | F12: ='ANT EXT-REV'!C20 -> 0 | H12: 1 | I12: ='ANT EXT-REV'!C36 -> 0 | K12: 1 | L12: ='ANT EXT-REV'!C44 -> 0 | N12: 1 | O12: ='ANT EXT-REV'!C12 -> 82340 | Q12: 1 | R12: ='ANT EXT-REV'!C28 -> 0 | T12: Sale del reporte Recaudo reversado
B13: 2 | C13: ='ANT EXT-REV'!E4 -> 5228610 | E13: 2 | F13: ='ANT EXT-REV'!E20 -> 0 | H13: 2 | I13: ='ANT EXT-REV'!E36 -> 5227240 | K13: 2 | L13: ='ANT EXT-REV'!E44 -> 0 | N13: 2 | O13: ='ANT EXT-REV'!E12 -> 1370 | Q13: 2 | R13: ='ANT EXT-REV'!E28 -> 0
B14: 3 | C14: ='ANT EXT-REV'!G4 -> 0 | E14: 3 | F14: ='ANT EXT-REV'!G20 -> 0 | H14: 3 | I14: ='ANT EXT-REV'!G36 -> 0 | K14: 3 | L14: ='ANT EXT-REV'!G44 -> 0 | N14: 3 | O14: ='ANT EXT-REV'!G12 -> 0 | Q14: 3 | R14: ='ANT EXT-REV'!G28 -> 0
B15: 4 | C15: ='ANT EXT-REV'!I4 -> 14538094 | E15: 4 | F15: ='ANT EXT-REV'!I20 -> 694130 | H15: 4 | I15: ='ANT EXT-REV'!I36 -> 11634964 | K15: 4 | L15: ='ANT EXT-REV'!I44 -> 0 | N15: 4 | O15: ='ANT EXT-REV'!I12 -> 2209000 | Q15: 4 | R15: ='ANT EXT-REV'!I28 -> 0
B16: 5 | C16: ='ANT EXT-REV'!K4 -> 87550 | E16: 5 | F16: ='ANT EXT-REV'!K20 -> 0 | H16: 5 | I16: ='ANT EXT-REV'!K36 -> 0 | K16: 5 | L16: ='ANT EXT-REV'!K44 -> 0 | N16: 5 | O16: ='ANT EXT-REV'!K12 -> 87550 | Q16: 5 | R16: ='ANT EXT-REV'!K28 -> 0
C17: =SUM(C12:C16) -> 19936594 | F17: =SUM(F12:F16) -> 694130 | I17: =SUM(I12:I16) -> 16862204 | L17: =SUM(L12:L16) -> 0 | O17: =SUM(O12:O16) -> 2380260 | R17: =SUM(R12:R16) -> 0
C18: =C17='ANT EXT-REV'!M4 -> TRUE | F18: =F17='ANT EXT-REV'!M20 -> TRUE | I18: =I17='ANT EXT-REV'!M36 -> TRUE | L18: =L17='ANT EXT-REV'!M44 -> TRUE | O18: =O17='ANT EXT-REV'!M12 -> TRUE | R18: =R17='ANT EXT-REV'!M28 -> TRUE
B20: ASE | C20: ANTICIPOS QUE CARGAN POR REVERSIONES | E20: ASE | F20: ANTICIPOS QUE CARGAN POR REVERSIONES | H20: ASE | I20: ANTICIPOS QUE CARGAN POR REVERSIONES | K20: ASE | L20: ANTICIPOS QUE CARGAN POR REVERSIONES | N20: ASE | O20: ANTICIPOS QUE CARGAN POR REVERSIONES | Q20: ASE | R20: ANTICIPOS QUE CARGAN POR REVERSIONES | T20: Anticipos que cargan de reversiones
B21: 1 | C21: ='ANT EXT-REV'!D4 -> -182537.91 | E21: 1 | F21: ='ANT EXT-REV'!D20 -> 0 | H21: 1 | I21: ='ANT EXT-REV'!D36 -> -16889.3 | K21: 1 | L21: ='ANT EXT-REV'!D44 -> 0 | N21: 1 | O21: ='ANT EXT-REV'!D12 -> -165648.61 | Q21: 1 | R21: ='ANT EXT-REV'!D28 -> 0 | T21: Sale del reporte Recaudo reversado
B22: 2 | C22: ='ANT EXT-REV'!F4 -> 0 | E22: 2 | F22: ='ANT EXT-REV'!F20 -> 0 | H22: 2 | I22: ='ANT EXT-REV'!F36 -> 0 | K22: 2 | L22: ='ANT EXT-REV'!F44 -> 0 | N22: 2 | O22: ='ANT EXT-REV'!F12 -> 0 | Q22: 2 | R22: ='ANT EXT-REV'!F28 -> 0
B23: 3 | C23: ='ANT EXT-REV'!H4 -> -2423600.2 | E23: 3 | F23: ='ANT EXT-REV'!H20 -> 0 | H23: 3 | I23: ='ANT EXT-REV'!H36 -> -79850 | K23: 3 | L23: ='ANT EXT-REV'!H44 -> 0 | N23: 3 | O23: ='ANT EXT-REV'!H12 -> -2343750.2 | Q23: 3 | R23: ='ANT EXT-REV'!H28 -> 0
B24: 4 | C24: ='ANT EXT-REV'!J4 -> -14979760 | E24: 4 | F24: ='ANT EXT-REV'!J20 -> 0 | H24: 4 | I24: ='ANT EXT-REV'!J36 -> -386384.11 | K24: 4 | L24: ='ANT EXT-REV'!J44 -> 0 | N24: 4 | O24: ='ANT EXT-REV'!J12 -> -14593376 | Q24: 4 | R24: ='ANT EXT-REV'!J28 -> 0
B25: 5 | C25: ='ANT EXT-REV'!L4 -> -215053.47 | E25: 5 | F25: ='ANT EXT-REV'!L20 -> 0 | H25: 5 | I25: ='ANT EXT-REV'!L36 -> -49280 | K25: 5 | L25: ='ANT EXT-REV'!L44 -> 0 | N25: 5 | O25: ='ANT EXT-REV'!L12 -> -165773.47 | Q25: 5 | R25: ='ANT EXT-REV'!L28 -> 0
C26: =SUM(C21:C25) -> -17800951 | F26: =SUM(F21:F25) -> 0 | I26: =SUM(I21:I25) -> -532403.41 | L26: =SUM(L21:L25) -> 0 | O26: =SUM(O21:O25) -> -17268548 | R26: =SUM(R21:R25) -> 0
C27: =C26='ANT EXT-REV'!N4 -> TRUE | F27: =F26='ANT EXT-REV'!N20 -> TRUE | I27: =I26='ANT EXT-REV'!N36 -> TRUE | L27: =L26='ANT EXT-REV'!N44 -> TRUE | O27: =O26='ANT EXT-REV'!N12 -> TRUE | R27: =R26='ANT EXT-REV'!N28 -> TRUE

Sheet BCE SC POR FACT.
C2: ASE | D2: SUBSIDIO | E2: CONTRIBUCION | F2: TOTAL BSC | H2: SISTEMA
C3: 1 | D3: -6.0415123e+09 | E3: 2.4520577e+09 | F3: =D3+E3 -> -3.5894547e+09 | H3: =DetRetri2026072!J9 -> -3589454666 | I3: =F3-H3 -> 0.45000029
C4: 2 | D4: -5.5026723e+09 | E4: 2.2614785e+09 | F4: =D4+E4 -> -3.2411937e+09 | H4: =DetRetri2026072!J10 -> -3241193714 | I4: =F4-H4 -> -0.11000013
C5: 3 | D5: -2.1159662e+09 | E5: 1.2627217e+09 | F5: =D5+E5 -> -8.5324456e+08 | H5: =DetRetri2026072!J11 -> -853244565 | I5: =F5-H5 -> 0.49000001
C6: 4 | D6: -2.4678057e+09 | E6: 1.767923e+09 | F6: =D6+E6 -> -6.9988271e+08 | H6: =DetRetri2026072!J12 -> -699882713 | I6: =F6-H6 -> -0.37000012
C7: 5 | D7: -1.1386507e+09 | E7: 1.0556917e+09 | F7: =D7+E7 -> -82959024 | H7: =DetRetri2026072!J13 -> -82959024 | I7: =F7-H7 -> 0.33999991
F9: =SUM(F3:F7) -> -8.4667347e+09 | H9: =SUM(H3:H7) -> -8466734682 | I9: =F9-H9 -> 0.80000019
H10: =H9=DetRetri2026072!J14 -> TRUE
D11: =SUM(D3:D7) -> -1.7266607e+10 | E11: =SUM(E3:E7) -> 8.7998726e+09 | F11: =SUM(D3:E7) -> -8.4667347e+09
F12: =ROUND(F11,2)=ROUND(F9,2) -> TRUE
F13: =ROUND(F11,2)-ROUND(F9,2) -> 0
D18: ASE | E18: REMUN TOTAL | F18: VALIDA 1 | G18: VALIDA 2 | H18: DIFERENCIA VALIDA 2
D19: 1 | E19: ='CONSOLIDADO_TOTAL RECAUDO'!J104 -> -3.5894547e+09 | F19: =E19=F3 -> TRUE | G19: =E19=H3 -> FALSE | H19: =E19-H3 -> 0.45000029
D20: 2 | E20: ='CONSOLIDADO_TOTAL RECAUDO'!J105 -> -3.2411937e+09 | F20: =E20=F4 -> TRUE | G20: =E20=H4 -> FALSE | H20: =E20-H4 -> -0.11000013
D21: 3 | E21: ='CONSOLIDADO_TOTAL RECAUDO'!J106 -> -8.5324456e+08 | F21: =E21=F5 -> TRUE | G21: =E21=H5 -> FALSE | H21: =E21-H5 -> 0.49000001
D22: 4 | E22: ='CONSOLIDADO_TOTAL RECAUDO'!J107 -> -6.9988271e+08 | F22: =E22=F6 -> TRUE | G22: =E22=H6 -> FALSE | H22: =E22-H6 -> -0.37000012
D23: 5 | E23: ='CONSOLIDADO_TOTAL RECAUDO'!J108 -> -82959024 | F23: =E23=F7 -> TRUE | G23: =E23=H7 -> FALSE | H23: =E23-H7 -> 0.33999991
E24: =SUM(E19:E23) -> -8.4667347e+09 | F24: =E24=F9 -> TRUE | G24: =E24=H9 -> FALSE | H24: =E24-H9 -> 0.80000019

Sheet Reporte Componentes R1
B4: PROMOAMBIENTAL
F5: Total | G5: Componente TDF | H5: Componente TTL | I5: Componente TVIAT | J5: Aprovechamiento | K5: CCSA Prest.Aprov. | L5: SERVICIO ESPECIALES | M5: Componente TCS | N5: Componente TLU | O5: Componente TBL | P5: Componente TRT | Q5: CCSA Prest. No Aprov. | R5: Ajuste Decena | S5: Ajuste Recargo Aseo | T5: Intereses Cte Financiac. Aseo | U5: Exonera-Recargo Aseo | V5: Exonera-Ajuste Decena Aseo | W5: Exonera-Recargo Aseo | X5: Exonera-Recargo Aseo | Y5: Intereses Cte Financiac. Aseo | Z5: Rec.Intereses
E6: Vlr Servicio | F6: -7108.82 | G6: -502.98 | H6: -213.69 | I6: -93.3 | J6: -1231.48 | K6: -79.57 | L6: 0 | M6: -698.02 | N6: -584.17 | O6: -2331.79 | P6: -1243.99 | Q6: -129.83 | R6: 0 | S6: 0 | T6: 0 | U6: 0 | V6: 0 | W6: 0 | X6: 0 | Y6: 0 | Z6: 0
D7: E | E7: Total | F7: -7108.82 | G7: -502.98 | H7: -213.69 | I7: -93.3 | J7: -1231.48 | K7: -79.57 | L7: 0 | M7: -698.02 | N7: -584.17 | O7: -2331.79 | P7: -1243.99 | Q7: -129.83 | R7: 0 | S7: 0 | T7: 0 | U7: 0 | V7: 0 | W7: 0 | X7: 0 | Y7: 0 | Z7: 0
C8: ENEL | D8: Total | F8: -7108.82 | G8: -502.98 | H8: -213.69 | I8: -93.3 | J8: -1231.48 | K8: -79.57 | L8: 0 | M8: -698.02 | N8: -584.17 | O8: -2331.79 | P8: -1243.99 | Q8: -129.83 | R8: 0 | S8: 0 | T8: 0 | U8: 0 | V8: 0 | W8: 0 | X8: 0 | Y8: 0 | Z8: 0
E9: Vlr Servicio | F9: 0 | G9: 0 | H9: 0 | I9: 0 | J9: 0 | K9: 0 | L9: 0 | M9: 0 | N9: 0 | O9: 0 | P9: 0 | Q9: 0 | R9: 0 | S9: 0 | T9: 0 | U9: 0 | V9: 0 | W9: 0 | X9: 0 | Y9: 0 | Z9: 0
D10: H | E10: Total | F10: 0 | G10: 0 | H10: 0 | I10: 0 | J10: 0 | K10: 0 | L10: 0 | M10: 0 | N10: 0 | O10: 0 | P10: 0 | Q10: 0 | R10: 0 | S10: 0 | T10: 0 | U10: 0 | V10: 0 | W10: 0 | X10: 0 | Y10: 0 | Z10: 0
E11: Vlr Servicio | F11: -4108.55 | G11: -263.4 | H11: -111.9 | I11: -48.87 | J11: -738.89 | K11: -47.75 | L11: 0 | M11: -418.8 | N11: -350.5 | O11: -1399.09 | P11: -651.44 | Q11: -77.91 | R11: 0 | S11: 0 | T11: 0 | U11: 0 | V11: 0 | W11: 0 | X11: 0 | Y11: 0 | Z11: 0
D12: O | E12: Total | F12: -4108.55 | G12: -263.4 | H12: -111.9 | I12: -48.87 | J12: -738.89 | K12: -47.75 | L12: 0 | M12: -418.8 | N12: -350.5 | O12: -1399.09 | P12: -651.44 | Q12: -77.91 | R12: 0 | S12: 0 | T12: 0 | U12: 0 | V12: 0 | W12: 0 | X12: 0 | Y12: 0 | Z12: 0
E13: Vlr Servicio | F13: 0 | G13: 0 | H13: 0 | I13: 0 | J13: 0 | K13: 0 | L13: 0 | M13: 0 | N13: 0 | O13: 0 | P13: 0 | Q13: 0 | R13: 0 | S13: 0 | T13: 0 | U13: 0 | V13: 0 | W13: 0 | X13: 0 | Y13: 0 | Z13: 0
D14: T | E14: Total | F14: 0 | G14: 0 | H14: 0 | I14: 0 | J14: 0 | K14: 0 | L14: 0 | M14: 0 | N14: 0 | O14: 0 | P14: 0 | Q14: 0 | R14: 0 | S14: 0 | T14: 0 | U14: 0 | V14: 0 | W14: 0 | X14: 0 | Y14: 0 | Z14: 0
C15: OCCIDENTE | D15: Total | F15: -4108.55 | G15: -263.4 | H15: -111.9 | I15: -48.87 | J15: -738.89 | K15: -47.75 | L15: 0 | M15: -418.8 | N15: -350.5 | O15: -1399.09 | P15: -651.44 | Q15: -77.91 | R15: 0 | S15: 0 | T15: 0 | U15: 0 | V15: 0 | W15: 0 | X15: 0 | Y15: 0 | Z15: 0
B16: Mes | C16: Total | F16: -11217.37 | G16: -766.38 | H16: -325.59 | I16: -142.17 | J16: -1970.37 | K16: -127.32 | L16: 0 | M16: -1116.82 | N16: -934.67 | O16: -3730.88 | P16: -1895.43 | Q16: -207.74 | R16: 0 | S16: 0 | T16: 0 | U16: 0 | V16: 0 | W16: 0 | X16: 0 | Y16: 0 | Z16: 0
A17: AFaseo | B17: Total | F17: -11217.37 | G17: -766.38 | H17: -325.59 | I17: -142.17 | J17: -1970.37 | K17: -127.32 | L17: 0 | M17: -1116.82 | N17: -934.67 | O17: -3730.88 | P17: -1895.43 | Q17: -207.74 | R17: 0 | S17: 0 | T17: 0 | U17: 0 | V17: 0 | W17: 0 | X17: 0 | Y17: 0 | Z17: 0
E18: Vlr Servicio | F18: 9215.69 | G18: 2007.44 | H18: 1133.38 | I18: 594.88 | J18: 0 | K18: 0 | L18: 0 | M18: 0 | N18: 0 | O18: 0 | P18: 5482.6 | Q18: 0 | R18: -2.61 | S18: 0 | T18: 0 | U18: 0 | V18: 0 | W18: 0 | X18: 0 | Y18: 0 | Z18: 0
E19: Vlr Intereses | F19: 0 | G19: 0 | H19: 0 | I19: 0 | J19: 0 | K19: 0 | L19: 0 | M19: 0 | N19: 0 | O19: 0 | P19: 0 | Q19: 0 | R19: 0 | S19: 0 | T19: 0 | U19: 0 | V19: 0 | W19: 0 | X19: 0 | Y19: 0 | Z19: 0
D20: E | E20: Total | F20: 9215.69 | G20: 2007.44 | H20: 1133.38 | I20: 594.88 | J20: 0 | K20: 0 | L20: 0 | M20: 0 | N20: 0 | O20: 0 | P20: 5482.6 | Q20: 0 | R20: -2.61 | S20: 0 | T20: 0 | U20: 0 | V20: 0 | W20: 0 | X20: 0 | Y20: 0 | Z20: 0
C21: ENEL | D21: Total | F21: 9215.69 | G21: 2007.44 | H21: 1133.38 | I21: 594.88 | J21: 0 | K21: 0 | L21: 0 | M21: 0 | N21: 0 | O21: 0 | P21: 5482.6 | Q21: 0 | R21: -2.61 | S21: 0 | T21: 0 | U21: 0 | V21: 0 | W21: 0 | X21: 0 | Y21: 0 | Z21: 0
E22: Vlr Servicio | F22: 0 | G22: 0 | H22: 0 | I22: 0 | J22: 0 | K22: 0 | L22: 0 | M22: 0 | N22: 0 | O22: 0 | P22: 0 | Q22: 370.08 | R22: -1.95 | S22: 0 | T22: 0 | U22: 0 | V22: 0 | W22: 0 | X22: 0 | Y22: 0 | Z22: 0
E23: Vlr Intereses | F23: 0 | G23: 0 | H23: 0 | I23: 0 | J23: 0 | K23: 0 | L23: 0 | M23: 0 | N23: 0 | O23: 0 | P23: 0 | Q23: 0.07 | R23: 0 | S23: 0 | T23: 0 | U23: 0 | V23: 0 | W23: 0 | X23: 0 | Y23: 0 | Z23: 0
D24: H | E24: Total | F24: 0 | G24: 0 | H24: 0 | I24: 0 | J24: 0 | K24: 0 | L24: 0 | M24: 0 | N24: 0 | O24: 0 | P24: 0 | Q24: 370.15 | R24: -1.95 | S24: 0 | T24: 0 | U24: 0 | V24: 0 | W24: 0 | X24: 0 | Y24: 0 | Z24: 0
E25: Vlr Servicio | F25: 0 | G25: 0 | H25: 0 | I25: 0 | J25: 0 | K25: 0 | L25: 0 | M25: 0 | N25: 0 | O25: 0 | P25: 0 | Q25: 370.08 | R25: -1.95 | S25: 0 | T25: 0 | U25: 0 | V25: 0 | W25: 0 | X25: 0 | Y25: 0 | Z25: 0
E26: Vlr Intereses | F26: 0 | G26: 0 | H26: 0 | I26: 0 | J26: 0 | K26: 0 | L26: 0 | M26: 0 | N26: 0 | O26: 0 | P26: 0 | Q26: 0.07 | R26: 0 | S26: 0 | T26: 0 | U26: 0 | V26: 0 | W26: 0 | X26: 0 | Y26: 0 | Z26: 0
D27: O | E27: Total | F27: 0 | G27: 0 | H27: 0 | I27: 0 | J27: 0 | K27: 0 | L27: 0 | M27: 0 | N27: 0 | O27: 0 | P27: 0 | Q27: 370.15 | R27: -1.95 | S27: 0 | T27: 0 | U27: 0 | V27: 0 | W27: 0 | X27: 0 | Y27: 0 | Z27: 0
E28: Vlr Servicio | F28: 0 | G28: 0 | H28: 0 | I28: 0 | J28: 0 | K28: 0 | L28: 0 | M28: 0 | N28: 0 | O28: 0 | P28: 0 | Q28: 0 | R28: 0 | S28: 0 | T28: 0 | U28: 0 | V28: 0 | W28: 0 | X28: 0 | Y28: 0 | Z28: 0
E29: Vlr Intereses | F29: 0 | G29: 0 | H29: 0 | I29: 0 | J29: 0 | K29: 0 | L29: 0 | M29: 0 | N29: 0 | O29: 0 | P29: 0 | Q29: 0 | R29: 0 | S29: 0 | T29: 0 | U29: 0 | V29: 0 | W29: 0 | X29: 0 | Y29: 0 | Z29: 0
D30: T | E30: Total | F30: 0 | G30: 0 | H30: 0 | I30: 0 | J30: 0 | K30: 0 | L30: 0 | M30: 0 | N30: 0 | O30: 0 | P30: 0 | Q30: 0 | R30: 0 | S30: 0 | T30: 0 | U30: 0 | V30: 0 | W30: 0 | X30: 0 | Y30: 0 | Z30: 0
C31: OCCIDENTE | D31: Total | F31: 0 | G31: 0 | H31: 0 | I31: 0 | J31: 0 | K31: 0 | L31: 0 | M31: 0 | N31: 0 | O31: 0 | P31: 0 | Q31: 0 | R31: 0 | S31: 0 | T31: 0 | U31: 0 | V31: 0 | W31: 0 | X31: 0 | Y31: 0 | Z31: 0
B32: Aplicacion nuevos x reversion | C32: Total | F32: 9215.69 | G32: 2007.44 | H32: 1133.38 | I32: 594.88 | J32: 0 | K32: 0 | L32: 0 | M32: 0 | N32: 0 | O32: 0 | P32: 5482.6 | Q32: 0 | R32: -2.61 | S32: 0 | T32: 0 | U32: 0 | V32: 0 | W32: 0 | X32: 0 | Y32: 0 | Z32: 0
E33: Vlr Servicio | F33: 1.5311909e+10 | G33: 8.013638e+08 | H33: 4.5218165e+08 | I33: 2.375767e+08 | J33: 3.7426033e+09 | K33: 1.3187246e+08 | L33: 16515976 | M33: 1.1602294e+09 | N33: 1.1131782e+09 | O33: 5.2698556e+09 | P33: 2.1713711e+09 | Q33: 2.1517844e+08 | R33: -17072.68 | S33: 0 | T33: 0 | U33: 0 | V33: 0 | W33: 0 | X33: 0 | Y33: 0 | Z33: 0
E34: Vlr Intereses | F34: 4090440.9 | G34: 281733.24 | H34: 147454.73 | I34: 76550.04 | J34: 796420.04 | K34: 36830.11 | L34: 516.31 | M34: 325736.63 | N34: 292484.52 | O34: 1313250.7 | P34: 758517.98 | Q34: 60116.44 | R34: 308.42 | S34: 0 | T34: 521.8 | U34: 0 | V34: 0 | W34: 0 | X34: 0 | Y34: 0 | Z34: -0.03
D35: E | E35: Total | F35: 1.5316e+10 | G35: 8.0164553e+08 | H35: 4.5232911e+08 | I35: 2.3765325e+08 | J35: 3.7433997e+09 | K35: 1.3190929e+08 | L35: 16516492 | M35: 1.1605551e+09 | N35: 1.1134707e+09 | O35: 5.2711688e+09 | P35: 2.1721296e+09 | Q35: 2.1523856e+08 | R35: -16764.26 | S35: 0 | T35: 521.8 | U35: 0 | V35: 0 | W35: 0 | X35: 0 | Y35: 0 | Z35: -0.03
C36: ENEL | D36: Total | F36: 1.5316e+10 | G36: 8.0164553e+08 | H36: 4.5232911e+08 | I36: 2.3765325e+08 | J36: 3.7433997e+09 | K36: 1.3190929e+08 | L36: 16516492 | M36: 1.1605551e+09 | N36: 1.1134707e+09 | O36: 5.2711688e+09 | P36: 2.1721296e+09 | Q36: 2.1523856e+08 | R36: -16764.26 | S36: 0 | T36: 521.8 | U36: 0 | V36: 0 | W36: 0 | X36: 0 | Y36: 0 | Z36: -0.03
E37: Vlr Servicio | F37: 32531853 | G37: 2591273.9 | H37: 1444146.4 | I37: 758108.3 | J37: 6042578.8 | K37: 205824.68 | L37: 0 | M37: 1805861.6 | N37: 2163115.5 | O37: 10120980 | P37: 7063994.1 | Q37: 335853.33 | R37: 116.52 | S37: 0 | T37: 0 | U37: 0 | V37: 0 | W37: 0 | X37: 0 | Y37: 0 | Z37: 0
E38: Vlr Intereses | F38: 70410.78 | G38: 4075.34 | H38: 2009.42 | I38: 1036.19 | J38: 14956.08 | K38: 634.42 | L38: 0 | M38: 5556.36 | N38: 5429.24 | O38: 24704.76 | P38: 10925.02 | Q38: 1033.93 | R38: 49.75 | S38: 0 | T38: 0.27 | U38: 0 | V38: 0 | W38: 0 | X38: 0 | Y38: 0 | Z38: 0
D39: H | E39: Total | F39: 32602264 | G39: 2595349.2 | H39: 1446155.9 | I39: 759144.49 | J39: 6057534.9 | K39: 206459.1 | L39: 0 | M39: 1811418 | N39: 2168544.8 | O39: 10145685 | P39: 7074919.1 | Q39: 336887.26 | R39: 166.27 | S39: 0 | T39: 0.27 | U39: 0 | V39: 0 | W39: 0 | X39: 0 | Y39: 0 | Z39: 0
E40: Vlr Servicio | F40: 1.4271862e+08 | G40: 16226923 | H40: 8978685.1 | I40: 4682686.1 | J40: 17356716 | K40: 717148.94 | L40: 4122672 | M40: 6303944.3 | N40: 6897057 | O40: 32134628 | P40: 44127364 | Q40: 1171009.8 | R40: -218.38 | S40: 0 | T40: 0 | U40: 0 | V40: 0 | W40: 0 | X40: 0 | Y40: 0 | Z40: 0
E41: Vlr Intereses | F41: 700269.72 | G41: 40116.7 | H41: 19139.89 | I41: 10101.16 | J41: 153132.53 | K41: 7303.27 | L41: 0 | M41: 64029.13 | N41: 56965.87 | O41: 230260.01 | P41: 107283.27 | Q41: 11912.73 | R41: 27.3 | S41: -2.32 | T41: 0.18 | U41: 0 | V41: 0 | W41: 0 | X41: 0 | Y41: 0 | Z41: 0
D42: O | E42: Total | F42: 1.4341889e+08 | G42: 16267039 | H42: 8997825 | I42: 4692787.3 | J42: 17509848 | K42: 724452.21 | L42: 4122672 | M42: 6367973.5 | N42: 6954022.9 | O42: 32364888 | P42: 44234647 | Q42: 1182922.5 | R42: -191.08 | S42: -2.32 | T42: 0.18 | U42: 0 | V42: 0 | W42: 0 | X42: 0 | Y42: 0 | Z42: 0
E43: Vlr Servicio | F43: 4.4329992e+08 | G43: 77621929 | H43: 43739697 | I43: 23002911 | J43: 27531678 | K43: 700778.07 | L43: 4638006 | M43: 6178734.5 | N43: 8275304.8 | O43: 38410844 | P43: 2.1205741e+08 | Q43: 1143387.7 | R43: -766.24 | S43: 0 | T43: 0 | U43: 0 | V43: 0 | W43: 0 | X43: 0 | Y43: 0 | Z43: 0
...

Sheet Rem. Anticipos R2
B1: PROMOAMBIENTAL
E2: Total | F2: Componente TDF | G2: Componente TTL | H2: Componente TVIAT | I2: Aprovechamiento | J2: CCSA Prest.Aprov. | K2: Especiales | L2: Componente TCS | M2: Componente TLU | N2: Componente TBL | O2: Componente TRT | P2: CCSA Prest. No Aprov. | Q2: Deb/Cred | R2: Deb/Cred-otros
D3: Vlr Servicio | E3: 0 | F3: 0 | G3: 0 | H3: 0 | I3: 0 | J3: 0 | K3: 0 | L3: 0 | M3: 0 | N3: 0 | O3: 0 | P3: 0 | Q3: 0 | R3: 0
D4: Vlr Intereses | E4: 0 | F4: 0 | G4: 0 | H4: 0 | I4: 0 | J4: 0 | K4: 0 | L4: 0 | M4: 0 | N4: 0 | O4: 0 | P4: 0 | Q4: 0 | R4: 0
C5: A | D5: Total | E5: 0 | F5: 0 | G5: 0 | H5: 0 | I5: 0 | J5: 0 | K5: 0 | L5: 0 | M5: 0 | N5: 0 | O5: 0 | P5: 0 | Q5: 0 | R5: 0
B6: EAB | C6: Total | E6: 0 | F6: 0 | G6: 0 | H6: 0 | I6: 0 | J6: 0 | K6: 0 | L6: 0 | M6: 0 | N6: 0 | O6: 0 | P6: 0 | Q6: 0 | R6: 0
D7: Vlr Servicio | E7: 1.0475463e+08 | F7: 6975298.7 | G7: 3988878.1 | H7: 1891710.5 | I7: 21813833 | J7: 885097.78 | K7: 0 | L7: 8065770.6 | M7: 7536469.1 | N7: 33213004 | O7: 19115514 | P7: 1269059.6 | Q7: -0.63 | R7: 0
D8: Vlr Intereses | E8: 15816.77 | F8: 1163.38 | G8: 642.32 | H8: 341.55 | I8: 3027.69 | J8: 126.06 | K8: 0 | L8: 1110.61 | M8: 1054.19 | N8: 4963.73 | O8: 3181.55 | P8: 205.61 | Q8: 0.08 | R8: 0
C9: E | D9: Total | E9: 1.0477045e+08 | F9: 6976462.1 | G9: 3989520.4 | H9: 1892052 | I9: 21816861 | J9: 885223.84 | K9: 0 | L9: 8066881.2 | M9: 7537523.3 | N9: 33217967 | O9: 19118696 | P9: 1269265.2 | Q9: -0.55 | R9: 0
B10: ENEL | C10: Total | E10: 1.0477045e+08 | F10: 6976462.1 | G10: 3989520.4 | H10: 1892052 | I10: 21816861 | J10: 885223.84 | K10: 0 | L10: 8066881.2 | M10: 7537523.3 | N10: 33217967 | O10: 19118696 | P10: 1269265.2 | Q10: -0.55 | R10: 0
D11: Vlr Servicio | E11: 2066328.1 | F11: 95509.13 | G11: 53786.6 | H11: 25807.38 | I11: 498516.51 | J11: 14869.65 | K11: 0 | L11: 154839.34 | M11: 178346.64 | N11: 760377.7 | O11: 261105.9 | P11: 23181.14 | Q11: -11.84 | R11: 0
D12: Vlr Intereses | E12: 53.09 | F12: 2.2 | G12: 1.21 | H12: 0.66 | I12: 13.81 | J12: 0.47 | K12: 0 | L12: 4.11 | M12: 4.2 | N12: 19.61 | O12: 6.05 | P12: 0.77 | Q12: 0 | R12: 0
C13: H | D13: Total | E13: 2066381.2 | F13: 95511.33 | G13: 53787.81 | H13: 25808.04 | I13: 498530.32 | J13: 14870.12 | K13: 0 | L13: 154843.45 | M13: 178350.84 | N13: 760397.31 | O13: 261111.95 | P13: 23181.91 | Q13: -11.84 | R13: 0
D14: Vlr Servicio | E14: 1667705.3 | F14: 94831.21 | G14: 53653.37 | H14: 23974.41 | I14: 360931.98 | J14: 13656.23 | K14: 0 | L14: 118901.31 | M14: 135021.65 | N14: 589240.87 | O14: 258802.75 | P14: 18683.4 | Q14: 8.11 | R14: 0
D15: Vlr Intereses | E15: 534.46 | F15: 31.52 | G15: 17.83 | H15: 9.34 | I15: 118.64 | J15: 4.45 | K15: 0 | L15: 39.04 | M15: 38.33 | N15: 181.9 | O15: 86.11 | P15: 7.3 | Q15: 0 | R15: 0
C16: O | D16: Total | E16: 1668239.8 | F16: 94862.73 | G16: 53671.2 | H16: 23983.75 | I16: 361050.62 | J16: 13660.68 | K16: 0 | L16: 118940.35 | M16: 135059.98 | N16: 589422.77 | O16: 258888.86 | P16: 18690.7 | Q16: 8.11 | R16: 0
D17: Vlr Servicio | E17: 18251249 | F17: 2466979.3 | G17: 1389961.4 | H17: 841642.79 | I17: 1865966 | J17: 51082.32 | K17: 0 | L17: 482981.31 | M17: 671717.75 | N17: 3043351.3 | O17: 7354815.6 | P17: 82820.66 | Q17: -69.46 | R17: 0
D18: Vlr Intereses | E18: 35670.7 | F18: 6587.48 | G18: 3721.93 | H18: 1963.44 | I18: 1660.15 | J18: 49.7 | K18: 0 | L18: 436.97 | M18: 541.21 | N18: 2526.1 | O18: 18102.54 | P18: 81.19 | Q18: -0.01 | R18: 0
C19: T | D19: Total | E19: 18286920 | F19: 2473566.8 | G19: 1393683.3 | H19: 843606.23 | I19: 1867626.2 | J19: 51132.02 | K19: 0 | L19: 483418.28 | M19: 672258.96 | N19: 3045877.4 | O19: 7372918.2 | P19: 82901.85 | Q19: -69.47 | R19: 0
B20: OCCIDENTE | C20: Total | E20: 22021541 | F20: 2663940.8 | G20: 1501142.3 | H20: 893398.02 | I20: 2727207.1 | J20: 79662.82 | K20: 0 | L20: 757202.08 | M20: 985669.78 | N20: 4395697.5 | O20: 7892919 | P20: 124774.46 | Q20: -73.2 | R20: 0
A21: Componente | B21: Total | E21: 1.2679199e+08 | F21: 9640402.9 | G21: 5490662.7 | H21: 2785450 | I21: 24544068 | J21: 964886.66 | K21: 0 | L21: 8824083.3 | M21: 8523193.1 | N21: 37613665 | O21: 27011615 | P21: 1394039.6 | Q21: -73.75 | R21: 0
D22: Subsidio(-)/Contribucion(+) | E22: -7679309.2 | F22: 637875.65 | G22: 341985.27 | H22: 179997 | I22: -2784147.3 | J22: -136924.32 | K22: 0 | L22: -1201987.1 | M22: -1088414.8 | N22: -5141699 | O22: 1734349.6 | P22: -220344.15 | Q22: 0 | R22: 0
C23: E | D23: Total | E23: -7679309.2 | F23: 637875.65 | G23: 341985.27 | H23: 179997 | I23: -2784147.3 | J23: -136924.32 | K23: 0 | L23: -1201987.1 | M23: -1088414.8 | N23: -5141699 | O23: 1734349.6 | P23: -220344.15 | Q23: 0 | R23: 0
B24: ENEL | C24: Total | E24: -7679309.2 | F24: 637875.65 | G24: 341985.27 | H24: 179997 | I24: -2784147.3 | J24: -136924.32 | K24: 0 | L24: -1201987.1 | M24: -1088414.8 | N24: -5141699 | O24: 1734349.6 | P24: -220344.15 | Q24: 0 | R24: 0
D25: Subsidio(-)/Contribucion(+) | E25: -50554.72 | F25: 4736.11 | G25: 2674.07 | H25: 345.4 | I25: -23429.04 | J25: -1776.06 | K25: 0 | L25: -14634.19 | M25: -5072.07 | N25: -23919.85 | O25: 13249.96 | P25: -2729.05 | Q25: 0 | R25: 0
C26: H | D26: Total | E26: -50554.72 | F26: 4736.11 | G26: 2674.07 | H26: 345.4 | I26: -23429.04 | J26: -1776.06 | K26: 0 | L26: -14634.19 | M26: -5072.07 | N26: -23919.85 | O26: 13249.96 | P26: -2729.05 | Q26: 0 | R26: 0
D27: Subsidio(-)/Contribucion(+) | E27: -41372.31 | F27: 12793.71 | G27: 7223.37 | H27: 821.96 | I27: -13378.5 | J27: -1510.5 | K27: 0 | L27: -12344.21 | M27: -12400.64 | N27: -55249.52 | O27: 35136.41 | P27: -2464.39 | Q27: 0 | R27: 0
C28: O | D28: Total | E28: -41372.31 | F28: 12793.71 | G28: 7223.37 | H28: 821.96 | I28: -13378.5 | J28: -1510.5 | K28: 0 | L28: -12344.21 | M28: -12400.64 | N28: -55249.52 | O28: 35136.41 | P28: -2464.39 | Q28: 0 | R28: 0
D29: Subsidio(-)/Contribucion(+) | E29: 6927796.9 | F29: 1130170.6 | G29: 623361.6 | H29: 304609.91 | I29: 533203.52 | J29: 13692.34 | K29: 0 | L29: 126469.3 | M29: 172463.37 | N29: 810419.93 | O29: 3191349.9 | P29: 22056.36 | Q29: 0 | R29: 0
C30: T | D30: Total | E30: 6927796.9 | F30: 1130170.6 | G30: 623361.6 | H30: 304609.91 | I30: 533203.52 | J30: 13692.34 | K30: 0 | L30: 126469.3 | M30: 172463.37 | N30: 810419.93 | O30: 3191349.9 | P30: 22056.36 | Q30: 0 | R30: 0
B31: OCCIDENTE | C31: Total | E31: 6835869.9 | F31: 1147700.5 | G31: 633259.04 | H31: 305777.27 | I31: 496395.98 | J31: 10405.78 | K31: 0 | L31: 99490.9 | M31: 154990.66 | N31: 731250.56 | O31: 3239736.3 | P31: 16862.92 | Q31: 0 | R31: 0
A32: Subs/Cont | B32: Total | E32: -843439.3 | F32: 1785576.1 | G32: 975244.31 | H32: 485774.27 | I32: -2287751.4 | J32: -126518.54 | K32: 0 | L32: -1102496.2 | M32: -933424.09 | N32: -4410448.5 | O32: 4974085.9 | P32: -203481.23 | Q32: 0 | R32: 0
A33: Total | E33: 1.2594855e+08 | F33: 11425979 | G33: 6465907 | H33: 3271224.3 | I33: 22256317 | J33: 838368.12 | K33: 0 | L33: 7721587.1 | M33: 7589769 | N33: 33203216 | O33: 31985701 | P33: 1190558.4 | Q33: -73.75 | R33: 0
B47: TOTAL | C47: OPORTUNO | D47: Total | E47: =E21+E32-K21 -> 1.2594855e+08 | F47: =F21 -> 9640402.9 | G47: =G21 -> 5490662.7 | H47: =H21 -> 2785450 | I47: =I21 -> 24544068 | J47: =J21 -> 964886.66 | K47: =K21 -> 0 | L47: =L21 -> 8824083.3 | M47: =M21 -> 8523193.1 | ... S47: =S21 -> 0
D48: Subsidio(-)/Contribucion(+) | E48: =E32 -> -843439.3
B50: RECIPROCIDAD | C50: OPORTUNO | D50: Total | E50: 0 | F50: 0 | G50: 0 | H50: 0 | I50: 0 | J50: 0 | K50: 0 | L50: 0 | M50: 0 | N50: 0 | O50: 0 | P50: 0 | Q50: 0 | R50: 0 | S50: 0
D51: Subsidio(-)/Contribucion(+) | E51: 0
B53: ENEL | C53: OPORTUNO | D53: Total | E53: =E24+E10+E6-K6-K10 -> 97091143 | F53: =F10+F6 -> 6976462.1 | G53: =G10+G6 -> 3989520.4 | H53: =H10+H6 -> 1892052 | I53: =I10+I6 -> 21816861 | J53: =J10+J6 -> 885223.84 | K53: =K10+K6 -> 0 | L53: =L10+L6 -> 8066881.2 | M53: =M10+M6 -> 7537523.3 | ... S53: =S10+S6 -> 0
D54: Subsidio(-)/Contribucion(+) | E54: =E24 -> -7679309.2
B56: ENERBIT | C56: OPORTUNO | D56: Total | E56: 0 | F56: 0 | G56: 0 | H56: 0 | I56: 0 | J56: 0 | K56: 0 | L56: 0 | M56: 0 | N56: 0 | O56: 0 | P56: 0 | Q56: 0 | R56: 0
...

Sheet Reversion Pagos R4
B1: PROMOAMBIENTAL
D2: Total | E2: Componente TDF | F2: Componente TTL | G2: Componente TVIAT | H2: Aprovechamiento | I2: CCSA Prest.Aprov. | J2: Componente TCS | K2: Componente TLU | L2: Componente TBL | M2: Componente TRT | N2: CCSA Prest. No Aprov. | O2: Ajuste Decena | P2: SERVICIO ESPECIALES | Q2: Ajuste Recargo Aseo | R2: Otros
C3: Vlr Servicio | D3: -15794348 | E3: -792653.97 | F3: -443520.95 | G3: -235150.45 | H3: -3808729.7 | I3: -139986.99 | J3: -1241530.6 | K3: -1202003.5 | L3: -5520144.8 | M3: -2181286.4 | N3: -229451.13 | O3: 110.22 | P3: 0 | Q3: 0 | R3: 0
C4: Vlr Intereses | D4: -23575 | E4: -1070.04 | F4: -517.3 | G4: -287.09 | H4: -5416.02 | I4: -247.11 | J4: -2165.7 | K4: -1867.54 | L4: -8699.17 | M4: -2902.92 | N4: -402.93 | O4: 0.82 | P4: 0 | Q4: 0 | R4: 0
B5: Componente | C5: Total | D5: -15817923 | E5: -793724.01 | F5: -444038.25 | G5: -235437.54 | H5: -3814145.7 | I5: -140234.1 | J5: -1243696.3 | K5: -1203871 | L5: -5528844 | M5: -2184189.4 | N5: -229854.06 | O5: 111.04 | P5: 0 | Q5: 0 | R5: 0
C6: Subsidio(-)/Contribucion(+) | D6: 283961.51 | E6: -50016.63 | F6: -28439.29 | G6: -8473.6 | H6: 123071.72 | I6: 6856.23 | J6: 57818.27 | K6: 55412.62 | L6: 258242.83 | M6: -141530 | N6: 11019.36 | O6: 0 | P6: 0 | Q6: 0 | R6: 0
B7: Subs/Cont | C7: Total | D7: 283961.51 | E7: -50016.63 | F7: -28439.29 | G7: -8473.6 | H7: 123071.72 | I7: 6856.23 | J7: 57818.27 | K7: 55412.62 | L7: 258242.83 | M7: -141530 | N7: 11019.36 | O7: 0 | P7: 0 | Q7: 0 | R7: 0
A8: ENEL | B8: Total | D8: -15533962 | E8: -843740.64 | F8: -472477.54 | G8: -243911.14 | H8: -3691074 | I8: -133377.87 | J8: -1185878 | K8: -1148458.4 | L8: -5270601.2 | M8: -2325719.4 | N8: -218834.7 | O8: 111.04 | P8: 0 | Q8: 0 | R8: 0
C9: Vlr Servicio | D9: -762167.27 | E9: -48309.04 | F9: -26455.25 | G9: -13891.43 | H9: -192277.47 | I9: -4768.85 | J9: -58119.3 | K9: -51919.38 | L9: -246558.5 | M9: -112077.14 | N9: -7780.61 | O9: -10.3 | P9: 0 | Q9: 0 | R9: 0
C10: Vlr Intereses | D10: -177.06 | E10: -11.22 | F10: -6.34 | G10: -3.35 | H10: -43.6 | I10: -1.05 | J10: -9.24 | K10: -12.57 | L10: -57.05 | M10: -30.93 | N10: -1.71 | O10: 0 | P10: 0 | Q10: 0 | R10: 0
B11: Componente | C11: Total | D11: -762344.33 | E11: -48320.26 | F11: -26461.59 | G11: -13894.78 | H11: -192321.07 | I11: -4769.9 | J11: -58128.54 | K11: -51931.95 | L11: -246615.55 | M11: -112108.07 | N11: -7782.32 | O11: -10.3 | P11: 0 | Q11: 0 | R11: 0
C12: Subsidio(-)/Contribucion(+) | D12: -240407.06 | E12: -14057.56 | F12: -7937.89 | G12: -4170.17 | H12: -58249.85 | I12: -1605.37 | J12: -14082 | K12: -17535.88 | L12: -81716.35 | M12: -38432.73 | N12: -2619.26 | O12: 0 | P12: 0 | Q12: 0 | R12: 0
B13: Subs/Cont | C13: Total | D13: -240407.06 | E13: -14057.56 | F13: -7937.89 | G13: -4170.17 | H13: -58249.85 | I13: -1605.37 | J13: -14082 | K13: -17535.88 | L13: -81716.35 | M13: -38432.73 | N13: -2619.26 | O13: 0 | P13: 0 | Q13: 0 | R13: 0
A14: OCCIDENTE | B14: Total | D14: -1002751.4 | E14: -62377.82 | F14: -34399.48 | G14: -18064.95 | H14: -250570.92 | I14: -6375.27 | J14: -72210.54 | K14: -69467.83 | L14: -328331.9 | M14: -150540.8 | N14: -10401.58 | O14: -10.3 | P14: 0 | Q14: 0 | R14: 0
A15: Total | D15: -16536713 | E15: -906118.46 | F15: -506877.02 | G15: -261976.09 | H15: -3941644.9 | I15: -139753.14 | J15: -1258088.5 | K15: -1217926.2 | L15: -5598933.1 | M15: -2476260.1 | N15: -229236.28 | O15: 100.74 | P15: 0 | Q15: 0 | R15: 0
A73: TOTAL | B73: OPORTUNO | C73: Total | D73: =D15-P15 -> -16536713 | E73: =E5+E11 -> -842044.27 | F73: =F5+F11 -> -470499.84 | G73: =G5+G11 -> -249332.32 | H73: =H5+H11 -> -4006466.8 | I73: =I5+I11 -> -145004 | J73: =J5+J11 -> -1301824.8 | K73: =K5+K11 -> -1255802.9 | L73: =L5+L11 -> -5775459.5 | ... R73: =R5+R11 -> 0
C74: Subsidio(-)/Contribucion(+) | D74: =D7+D13 -> 43554.45
A76: RECIPROCIDAD | B76: OPORTUNO | C76: Total | D76: 0 | E76: 0 | F76: 0 | G76: 0 | H76: 0 | I76: 0 | J76: 0 | K76: 0 | L76: 0 | M76: 0 | N76: 0 | O76: 0 | P76: 0 | Q76: 0 | R76: 0
C77: Subsidio(-)/Contribucion(+) | D77: 0
A79: ENEL | B79: OPORTUNO | C79: Total | D79: =D8-P8 -> -15533962 | E79: =E5 -> -793724.01 | F79: =F5 -> -444038.25 | G79: =G5 -> -235437.54 | H79: =H5 -> -3814145.7 | I79: =I5 -> -140234.1 | J79: =J5 -> -1243696.3 | K79: =K5 -> -1203871 | L79: =L5 -> -5528844 | ... R79: =R5 -> 0
C80: Subsidio(-)/Contribucion(+) | D80: =D7 -> 283961.51
A82: ENERBIT | B82: OPORTUNO | C82: Total | D82: 0 | E82: 0 | F82: 0 | G82: 0 | H82: 0 | I82: 0 | J82: 0 | K82: 0 | L82: 0 | M82: 0 | N82: 0 | O82: 0 | P82: 0 | Q82: 0 | R82: 0
C83: Subsidio(-)/Contribucion(+) | D83: 0
A85: OCCIDENTE | B85: OPORTUNO | C85: Total | D85: =D14-P14 -> -1002751.4 | E85: =E11 -> -48320.26 | F85: =F11 -> -26461.59 | G85: =G11 -> -13894.78 | H85: =H11 -> -192321.07 | I85: =I11 -> -4769.9 | J85: =J11 -> -58128.54 | K85: =K11 -> -51931.95 | L85: =L11 -> -246615.55 | ... R85: =R11 -> 0
C86: Subsidio(-)/Contribucion(+) | D86: =D13 -> -240407.06
A88: CIUDAD LIMPIA-ACUEDUCTO | B88: OPORTUNO | C88: Total | D88: 0 | E88: 0 | F88: 0 | G88: 0 | H88: 0 | I88: 0 | J88: 0 | K88: 0 | L88: 0 | M88: 0 | N88: 0 | O88: 0 | P88: 0 | Q88: 0 | R88: 0
C89: Subsidio(-)/Contribucion(+) | D89: 0
B91: LIME
D92: Total | E92: Componente TDF | F92: Componente TTL | G92: Componente TVIAT | H92: Aprovechamiento | I92: CCSA Prest.Aprov. | J92: Componente TCS | K92: Componente TLU | L92: Componente TBL | M92: Componente TRT | N92: CCSA Prest. No Aprov. | O92: Ajuste Decena | P92: SERVICIO ESPECIALES | Q92: Ajuste Recargo Aseo | R92: Otros
C93: Vlr Servicio | D93: -53998016 | E93: -11667185 | F93: -5414703.5 | G93: -2951482.2 | H93: -3201477.2 | I93: -115838.75 | J93: -1017620.8 | K93: -1016768.4 | L93: -4764304 | M93: -23659661 | N93: -188999.83 | O93: 24.58 | P93: 0 | Q93: 0 | R93: 0
C94: Vlr Intereses | D94: -15789582 | E94: -4170790.8 | F94: -1943304.3 | G94: -1075258 | H94: -52026.8 | I94: -1440.2 | J94: -12737.8 | K94: -15000.59 | L94: -66290.83 | M94: -8450381.3 | N94: -2350.38 | O94: -0.84 | P94: 0 | Q94: 0 | R94: 0
B95: Componente | C95: Total | D95: -69787598 | E95: -15837976 | F95: -7358007.8 | G95: -4026740.1 | H95: -3253504 | I95: -117278.95 | J95: -1030358.6 | K95: -1031769 | L95: -4830594.8 | M95: -32110042 | N95: -191350.21 | O95: 23.74 | P95: 0 | Q95: 0 | R95: 0
C96: Subsidio(-)/Contribucion(+) | D96: -991410.96 | E96: -916794.52 | F96: -399784.58 | G96: -225583.16 | H96: 753139.3 | I96: 27321.94 | J96: 241143.71 | K96: 238753.51 | L96: 1113806.2 | M96: -1867991.1 | N96: 44577.73 | O96: 0 | P96: 0 | Q96: 0 | R96: 0
B97: Subs/Cont | C97: Total | D97: -991410.96 | E97: -916794.52 | F97: -399784.58 | G97: -225583.16 | H97: 753139.3 | I97: 27321.94 | J97: 241143.71 | K97: 238753.51 | L97: 1113806.2 | M97: -1867991.1 | N97: 44577.73 | O97: 0 | P97: 0 | Q97: 0 | R97: 0
A98: ENEL | B98: Total | D98: -70779009 | E98: -16754771 | F98: -7757792.4 | G98: -4252323.3 | H98: -2500364.7 | I98: -89957.01 | J98: -789214.84 | K98: -793015.48 | L98: -3716788.6 | M98: -33978033 | N98: -146772.48 | O98: 23.74 | P98: 0 | Q98: 0 | R98: 0
C99: Vlr Servicio | D99: 0 | E99: 0 | F99: 0 | G99: 0 | H99: 0 | I99: 0 | J99: 0 | K99: 0 | L99: 0 | M99: 0 | N99: 0 | O99: 0 | P99: 0 | Q99: 0 | R99: 0
C100: Vlr Intereses | D100: 0 | E100: 0 | F100: 0 | G100: 0 | H100: 0 | I100: 0 | J100: 0 | K100: 0 | L100: 0 | M100: 0 | N100: 0 | O100: 0 | P100: 0 | Q100: 0 | R100: 0
B101: Componente | C101: Total | D101: 0 | E101: 0 | F101: 0 | G101: 0 | H101: 0 | I101: 0 | J101: 0 | K101: 0 | L101: 0 | M101: 0 | N101: 0 | O101: 0 | P101: 0 | Q101: 0 | R101: 0
C102: Subsidio(-)/Contribucion(+) | D102: 0 | E102: 0 | F102: 0 | G102: 0 | H102: 0 | I102: 0 | J102: 0 | K102: 0 | L102: 0 | M102: 0 | N102: 0 | O102: 0 | P102: 0 | Q102: 0 | R102: 0
B103: Subs/Cont | C103: Total | D103: 0 | E103: 0 | F103: 0 | G103: 0 | H103: 0 | I103: 0 | J103: 0 | K103: 0 | L103: 0 | M103: 0 | N103: 0 | O103: 0 | P103: 0 | Q103: 0 | R103: 0
...

Sheet SALDOS POR NOTA
B1: PROMOAMBIENTAL
