Workbook
Name \0: #REF!
Name _1: #REF!
Name _2: #REF!
Name _A655555: #REF!
Name _CFR1: #REF!
Name _cia1: #REF!
Name _XL250: #REF!
Name A: #REF!
Name ADM: [1]!ADM
Name ADM: [1]!ADM
Name ADM: [1]!ADM
Name ADM: [1]!ADM
Name ADM: [1]!ADM
Name ADM_: [1]!ADM
Name ADM_: [1]!ADM
Name ADM_: [1]!ADM
Name ADM_: [1]!ADM
Name ADM_: [1]!ADM
Name AI: #REF!
Name Air: #REF!
Name AP: '[2]TARIFA no aforos'!$C$12
Name Bancos: [3]Fx!$C$1:$C$23
Name CBL: #REF!
Name CCS: #REF!
Name CDT_p: [4]CDT!$C$3
Name CFR: #REF!
Name cia: #REF!
Name COM: #REF!
Name CRT: #REF!
Name CRT___CTEp___CDTp___CMRv: #REF!
Name CRT_aislados: '[4]COSTOS AJUSTADOS'!$C$13
Name CRT_costas: #REF!
Name CTE_p: [4]CTE!$C$5
Name Denominador: #REF!
Name dg: [1]!ADM
Name dg: [1]!ADM
Name dg: [1]!ADM
Name dg: [1]!ADM
Name dg: [1]!ADM
Name DIAS: [5]CONTRA!#REF!
Name Fmerc: #REF!
Name FPS: #REF!
Name InformacionGeneral: [1]!InformacionGeneral
Name InformacionGeneral: [1]!InformacionGeneral
Name InformacionGeneral: [1]!InformacionGeneral
Name InformacionGeneral: [1]!InformacionGeneral
Name InformacionGeneral: [1]!InformacionGeneral
Name INTFIN: #REF!
Name INV: [1]!INV
Name INV: [1]!INV
Name INV: [1]!INV
Name INV: [1]!INV
Name INV: [1]!INV
Name K: #REF!
Name N: '[4]COSTOS AJUSTADOS'!#REF!
Name Na: '[2]TARIFA no aforos'!$C$39
Name nfc: '[4]COSTOS AJUSTADOS'!#REF!
Name OYM: [1]!OYM
Name OYM: [1]!OYM
Name OYM: [1]!OYM

Sheet Recaudo EAAB Reciprocidad
B2: OPORTUNO | C2: ASE | D2: VALOR 1° Q | E2: NUMERO REG. 1°Q | F2: VALOR 2° Q | G2: NUMERO REG. 2°Q
C3: 1 | D3: 0 | E3: 0 | F3: 0 | G3: 0
C4: 2 | D4: 11627730 | E4: 116 | F4: 0 | G4: 0
C5: 3 | D5: 0 | E5: 0 | F5: 0 | G5: 0
C6: 4 | D6: 7382710 | E6: 66 | F6: 0 | G6: 0
C7: 5 | D7: 0 | E7: 0 | F7: 0 | G7: 0
C8: X
D9: 19010440 | E9: 182 | F9: 0 | G9: 0
C11: ASE | D11: VALOR 1° Q | E11: NUMERO REG. 1°Q | F11: VALOR 2° Q | G11: NUMERO REG. 2°Q
B12: EXTEMP. | C12: 1 | D12: 0 | E12: 0 | F12: 0 | G12: 0
C13: 2 | D13: 0 | E13: 0 | F13: 0 | G13: 0
C14: 3 | D14: 0 | E14: 0 | F14: 0 | G14: 0
C15: 4 | D15: 0 | E15: 0 | F15: 0 | G15: 0
C16: 5 | D16: 0 | E16: 0 | F16: 0 | G16: 0
C17: X
D18: 0 | E18: 0 | F18: 0 | G18: 0
C20: ASE | D20: VALOR 1° Q | E20: NUMERO REG. 1°Q | F20: VALOR 2° Q | G20: NUMERO REG. 2°Q | I20: VALOR TOTAL MES | J20: NUMERO REGISTROS MES
B21: TOTAL | C21: 1 | D21: 0 | E21: 0 | F21: 0 | G21: 0 | I21: 0 | J21: 0
C22: 2 | D22: 11627730 | E22: 116 | F22: 0 | G22: 0 | I22: 0 | J22: 0
C23: 3 | D23: 0 | E23: 0 | F23: 0 | G23: 0 | I23: 0 | J23: 0
C24: 4 | D24: 7382710 | E24: 66 | F24: 0 | G24: 0 | I24: 0 | J24: 0
C25: 5 | D25: 0 | E25: 0 | F25: 0 | G25: 0 | I25: 0 | J25: 0
C26: X | I26: 0 | J26: 0
D27: 19010440 | E27: 182 | F27: 0 | G27: 0 | I27: 0 | J27: 0
B31: OPORTUNO | D31: =D9=SUM(D3:D8) -> TRUE | E31: =E9=SUM(E3:E8) -> TRUE | F31: =F9=SUM(F3:F8) -> TRUE | G31: =G9=SUM(G3:G8) -> TRUE
B33: EXTEMP. | D33: =D18=SUM(D12:D17) -> TRUE | E33: =E18=SUM(E12:E17) -> TRUE | F33: =F18=SUM(F12:F17) -> TRUE | G33: =G18=SUM(G12:G17) -> TRUE
B35: TOTAL | D35: =D27=SUM(D21:D26) -> TRUE | E35: =E27=SUM(E21:E26) -> TRUE | F35: =F27=SUM(F21:F26) -> TRUE | G35: =G27=SUM(G21:G26) -> TRUE | I35: =I27=SUM(I21:I26) -> TRUE | J35: =J27=SUM(J21:J26) -> TRUE
E69: =C69-G17 -> 0

Sheet Recaudo ENEL
B2: OPORTUNO | C2: ASE | D2: VALOR 1° Q | E2: NUMERO REG. 1°Q | F2: VALOR 2° Q | G2: NUMERO REG. 2°Q
C3: 1 | D3: 16745673525 | E3: 356945 | F3: 0 | G3: 0
C4: 2 | D4: 12677941411 | E4: 247628 | F4: 0 | G4: 0
C5: 3 | D5: 10157711962 | E5: 233934 | F5: 0 | G5: 0
C6: 4 | D6: 10972037248 | E6: 193770 | F6: 0 | G6: 0
C7: 5 | D7: 8639656940 | E7: 172542 | F7: 0 | G7: 0
C8: X
D9: 59193021086 | E9: 1204819 | F9: 0 | G9: 0
C11: ASE | D11: VALOR 1° Q | E11: NUMERO REG. 1°Q | F11: VALOR 2° Q | G11: NUMERO REG. 2°Q
B12: EXTEMP. | C12: 1 | D12: 202711553 | E12: 2558 | F12: 0 | G12: 0
C13: 2 | D13: 73096641 | E13: 1473 | F13: 0 | G13: 0
C14: 3 | D14: 51248640 | E14: 963 | F14: 0 | G14: 0
C15: 4 | D15: 62236830 | E15: 857 | F15: 0 | G15: 0
C16: 5 | D16: 158575115 | E16: 2854 | F16: 0 | G16: 0
C17: X
D18: 547868779 | E18: 8705 | F18: 0 | G18: 0
C20: ASE | D20: VALOR 1° Q | E20: NUMERO REG. 1°Q | F20: VALOR 2° Q | G20: NUMERO REG. 2°Q | I20: VALOR TOTAL MES | J20: NUMERO REGISTROS MES
B21: TOTAL | C21: 1 | D21: 16948385078 | E21: 359503 | F21: 0 | G21: 0 | I21: 0 | J21: 0
C22: 2 | D22: 12751038052 | E22: 249101 | F22: 0 | G22: 0 | I22: 0 | J22: 0
C23: 3 | D23: 10208960602 | E23: 234897 | F23: 0 | G23: 0 | I23: 0 | J23: 0
C24: 4 | D24: 11034274078 | E24: 194627 | F24: 0 | G24: 0 | I24: 0 | J24: 0
C25: 5 | D25: 8798232055 | E25: 175396 | F25: 0 | G25: 0 | I25: 0 | J25: 0
C26: X | I26: 0 | J26: 0
D27: 59740889865 | E27: 1213524 | F27: 0 | G27: 0 | I27: 0 | J27: 0
B31: OPORTUNO | D31: =D9=SUM(D3:D8) -> TRUE | E31: =E9=SUM(E3:E8) -> TRUE | F31: =F9=SUM(F3:F8) -> TRUE | G31: =G9=SUM(G3:G8) -> TRUE
B33: EXTEMP. | D33: =D18=SUM(D12:D17) -> TRUE | E33: =E18=SUM(E12:E17) -> TRUE | F33: =F18=SUM(F12:F17) -> TRUE | G33: =G18=SUM(G12:G17) -> TRUE
B35: TOTAL | D35: =D27=SUM(D21:D26) -> TRUE | E35: =E27=SUM(E21:E26) -> TRUE | F35: =F27=SUM(F21:F26) -> TRUE | G35: =G27=SUM(G21:G26) -> TRUE | I35: =I27=SUM(I21:I26) -> TRUE | J35: =J27=SUM(J21:J26) -> TRUE
E69: =C69-G17 -> 0

Sheet Recaudo ENERBIT
B2: OPORTUNO | C2: ASE | D2: VALOR 1° Q | E2: NUMERO REG. 1°Q | F2: VALOR 2° Q | G2: NUMERO REG. 2°Q
C3: 1 | D3: 0 | E3: 0 | F3: 0 | G3: 0
C4: 2 | D4: 0 | E4: 0 | F4: 0 | G4: 0
C5: 3 | D5: 0 | E5: 0 | F5: 0 | G5: 0
C6: 4 | D6: 0 | E6: 0 | F6: 0 | G6: 0
C7: 5 | D7: 137371512 | E7: 3020 | F7: 0 | G7: 0
C8: X
D9: 137371512 | E9: 3020 | F9: 0 | G9: 0
C11: ASE | D11: VALOR 1° Q | E11: NUMERO REG. 1°Q | F11: VALOR 2° Q | G11: NUMERO REG. 2°Q
B12: EXTEMP. | C12: 1 | D12: 0 | E12: 0 | F12: 0 | G12: 0
C13: 2 | D13: 0 | E13: 0 | F13: 0 | G13: 0
C14: 3 | D14: 0 | E14: 0 | F14: 0 | G14: 0
C15: 4 | D15: 0 | E15: 0 | F15: 0 | G15: 0
C16: 5 | D16: 1179300 | E16: 6 | F16: 0 | G16: 0
C17: X
D18: 1179300 | E18: 6 | F18: 0 | G18: 0
C20: ASE | D20: VALOR 1° Q | E20: NUMERO REG. 1°Q | F20: VALOR 2° Q | G20: NUMERO REG. 2°Q | I20: VALOR TOTAL MES | J20: NUMERO REGISTROS MES
B21: TOTAL | C21: 1 | D21: 0 | E21: 0 | F21: 0 | G21: 0 | I21: 0 | J21: 0
C22: 2 | D22: 0 | E22: 0 | F22: 0 | G22: 0 | I22: 0 | J22: 0
C23: 3 | D23: 0 | E23: 0 | F23: 0 | G23: 0 | I23: 0 | J23: 0
C24: 4 | D24: 0 | E24: 0 | F24: 0 | G24: 0 | I24: 0 | J24: 0
C25: 5 | D25: 138550812 | E25: 3026 | F25: 0 | G25: 0 | I25: 0 | J25: 0
C26: X | I26: 0 | J26: 0
D27: 138550812 | E27: 3026 | F27: 0 | G27: 0 | I27: 0 | J27: 0
B31: OPORTUNO | D31: =D9=SUM(D3:D8) -> TRUE | E31: =E9=SUM(E3:E8) -> TRUE | F31: =F9=SUM(F3:F8) -> TRUE | G31: =G9=SUM(G3:G8) -> TRUE
B33: EXTEMP. | D33: =D18=SUM(D12:D17) -> TRUE | E33: =E18=SUM(E12:E17) -> TRUE | F33: =F18=SUM(F12:F17) -> TRUE | G33: =G18=SUM(G12:G17) -> TRUE
B35: TOTAL | D35: =D27=SUM(D21:D26) -> TRUE | E35: =E27=SUM(E21:E26) -> TRUE | F35: =F27=SUM(F21:F26) -> TRUE | G35: =G27=SUM(G21:G26) -> TRUE | I35: =I27=SUM(I21:I26) -> TRUE | J35: =J27=SUM(J21:J26) -> TRUE
E69: =C69-G17 -> 0

Sheet Recaudo EAAB + Ciud Limp
B2: Ciudad Limpia - Prestador | C2: ASE | D2: VALOR 1° Q | E2: NUMERO REG. 1°Q | F2: VALOR 2° Q | G2: NUMERO REG. 2°Q
C3: 1 | D3: 0 | E3: 0 | F3: 0 | G3: 0
C4: 2 | D4: 0 | E4: 0 | F4: 0 | G4: 0
C5: 3 | D5: 0 | E5: 0 | F5: 0 | G5: 0
C6: 4 | D6: 0 | E6: 0 | F6: 0 | G6: 0
C7: 5 | D7: 0 | E7: 0 | F7: 0 | G7: 0
C8: X
D9: 0 | E9: 0 | F9: 0 | G9: 0
C11: ASE | D11: VALOR 1° Q | E11: NUMERO REG. 1°Q | F11: VALOR 2° Q | G11: NUMERO REG. 2°Q
B12: EAAB - Prestador | C12: 1 | D12: 0 | E12: 0 | F12: 0 | G12: 0
C13: 2 | D13: 0 | E13: 0 | F13: 0 | G13: 0
C14: 3 | D14: 0 | E14: 0 | F14: 0 | G14: 0
C15: 4 | D15: 0 | E15: 0 | F15: 0 | G15: 0
C16: 5 | D16: 0 | E16: 0 | F16: 0 | G16: 0
C17: X
D18: 0 | E18: 0 | F18: 0 | G18: 0
C20: ASE | D20: VALOR 1° Q | E20: NUMERO REG. 1°Q | F20: VALOR 2° Q | G20: NUMERO REG. 2°Q | I20: VALOR TOTAL MES | J20: NUMERO REGISTROS MES
B21: TOTAL | C21: 1 | D21: 0 | E21: 0 | F21: 0 | G21: 0 | I21: 0 | J21: 0
C22: 2 | D22: 0 | E22: 0 | F22: 0 | G22: 0 | I22: 0 | J22: 0
C23: 3 | D23: 0 | E23: 0 | F23: 0 | G23: 0 | I23: 0 | J23: 0
C24: 4 | D24: 0 | E24: 0 | F24: 0 | G24: 0 | I24: 0 | J24: 0
C25: 5 | D25: 0 | E25: 0 | F25: 0 | G25: 0 | I25: 0 | J25: 0
C26: X | I26: 0 | J26: 0
D27: 0 | E27: 0 | F27: 0 | G27: 0 | I27: 0 | J27: 0
B31: OPORTUNO | D31: =D9=SUM(D3:D8) -> TRUE | E31: =E9=SUM(E3:E8) -> TRUE | F31: =F9=SUM(F3:F8) -> TRUE | G31: =G9=SUM(G3:G8) -> TRUE
B33: EXTEMP. | D33: =D18=SUM(D12:D17) -> TRUE | E33: =E18=SUM(E12:E17) -> TRUE | F33: =F18=SUM(F12:F17) -> TRUE | G33: =G18=SUM(G12:G17) -> TRUE
B35: TOTAL | D35: =D27=SUM(D21:D26) -> TRUE | E35: =E27=SUM(E21:E26) -> TRUE | F35: =F27=SUM(F21:F26) -> TRUE | G35: =G27=SUM(G21:G26) -> TRUE | I35: =I27=SUM(I21:I26) -> TRUE | J35: =J27=SUM(J21:J26) -> TRUE

Sheet Recaudo Directa Occidente
B2: OPORTUNO | C2: ASE | D2: VALOR 1° Q | E2: NUMERO REG. 1°Q | F2: VALOR 2° Q | G2: NUMERO REG. 2°Q
C3: 1 | D3: 510782327 | E3: 2083 | F3: 0 | G3: 0
C4: 2 | D4: 1360190364 | E4: 4795 | F4: 0 | G4: 0
C5: 3 | D5: 650826874 | E5: 1469 | F5: 0 | G5: 0
C6: 4 | D6: 515587332 | E6: 3012 | F6: 0 | G6: 0
C7: 5 | D7: 224557157 | E7: 1221 | F7: 0 | G7: 0
C8: X | D8: 0 | E8: 0 | F8: 0 | G8: 0
D9: 3261944054 | E9: 12580 | F9: 0 | G9: 0
C11: ASE | D11: VALOR 1° Q | E11: NUMERO REG. 1°Q | F11: VALOR 2° Q | G11: NUMERO REG. 2°Q
B12: EXTEMP. | C12: 1 | D12: 23795111 | E12: 50 | F12: 0 | G12: 0
C13: 2 | D13: 62759499 | E13: 134 | F13: 0 | G13: 0
C14: 3 | D14: 48196023 | E14: 55 | F14: 0 | G14: 0
C15: 4 | D15: 5014320 | E15: 32 | F15: 0 | G15: 0
C16: 5 | D16: 14004529 | E16: 30 | F16: 0 | G16: 0
C17: X | D17: 0 | E17: 0 | F17: 0 | G17: 0
D18: 153769482 | E18: 301 | F18: 0 | G18: 0
C20: ASE | D20: VALOR 1° Q | E20: NUMERO REG. 1°Q | F20: VALOR 2° Q | G20: NUMERO REG. 2°Q | I20: VALOR TOTAL MES | J20: NUMERO REGISTROS MES
B21: TOTAL | C21: 1 | D21: 534577438 | E21: 2133 | F21: 0 | G21: 0 | I21: 0 | J21: 0
C22: 2 | D22: 1422949863 | E22: 4929 | F22: 0 | G22: 0 | I22: 0 | J22: 0
C23: 3 | D23: 699022897 | E23: 1524 | F23: 0 | G23: 0 | I23: 0 | J23: 0
C24: 4 | D24: 520601652 | E24: 3044 | F24: 0 | G24: 0 | I24: 0 | J24: 0
C25: 5 | D25: 238561686 | E25: 1251 | F25: 0 | G25: 0 | I25: 0 | J25: 0
C26: X | D26: 0 | E26: 0 | F26: 0 | G26: 0 | I26: 0 | J26: 0
D27: 3415713536 | E27: 12881 | F27: 0 | G27: 0 | I27: 0 | J27: 0
B31: OPORTUNO | D31: =D9=SUM(D3:D8) -> TRUE | E31: =E9=SUM(E3:E8) -> TRUE | F31: =F9=SUM(F3:F8) -> TRUE | G31: =G9=SUM(G3:G8) -> TRUE
B33: EXTEMP. | D33: =D18=SUM(D12:D17) -> TRUE | E33: =E18=SUM(E12:E17) -> TRUE | F33: =F18=SUM(F12:F17) -> TRUE | G33: =G18=SUM(G12:G17) -> TRUE
B35: TOTAL | D35: =D27=SUM(D21:D26) -> TRUE | E35: =E27=SUM(E21:E26) -> TRUE | F35: =F27=SUM(F21:F26) -> TRUE | G35: =G27=SUM(G21:G26) -> TRUE | I35: =I27=SUM(I21:I26) -> TRUE | J35: =J27=SUM(J21:J26) -> TRUE
E69: =C69-G17 -> 0

Sheet REPORTE RECAUDO x BANCO
C1: ENEL | D1: CIUDAD LIMPIA | E1: EAB | F1: NUEVO ESQUEMA | G1: ENERBIT | H1: OCCIDENTE | I1: Total
B2: 1-APLICADOS A FACTURACION | C2: =C13+C23+C32+C41+C51 -> 59646927181 | D2: =D13+D23+D32+D41+D51 -> 0 | E2: =E13+E23+E32+E41+E51 -> 0 | F2: =F13+F23+F32+F41+F51 -> 5603210 | G2: =G13+G23+G32+G41+G51 -> 137170902 | H2: =H13+H23+H32+H41+H51 -> 3.2507019e+09 | I2: =SUM(C2:H2) -> 6.3040403e+10
B3: 2-SALDOS A FAVOR GENERADOS | C3: =C14+C24+C33+C42+C52 -> 95923744 | D3: =D14+D24+D33+D42+D52 -> 0 | E3: =E14+E24+E33+E42+E52 -> 0 | F3: =F14+F24+F33+F42+F52 -> 13407230 | G3: =G14+G24+G33+G42+G52 -> 1379910 | H3: =H14+H24+H33+H42+H52 -> 75193898 | I3: =SUM(C3:H3) -> 1.8590478e+08
B4: 3-APLICADOS A FINANCIACIONES NUEVAS | C4: =C15+C25+C34+C43+C53 -> 0 | D4: =D15+D25+D34+D43+D53 -> 0 | E4: =E15+E25+E34+E43+E53 -> 0 | F4: =F15+F25+F34+F43+F53 -> 0 | G4: =G15+G25+G34+G43+G53 -> 0 | H4: =H15+H25+H34+H43+H53 -> 89817711 | I4: =SUM(C4:H4) -> 89817711
B5: 7-APLICADOS A RECIBOS SERVICIOS ESPECIALES | C5: =C16+C26+C35+C44+C54 -> 0 | D5: =D16+D26+D35+D44+D54 -> 0 | E5: =E16+E26+E35+E44+E54 -> 0 | F5: =F16+F26+F35+F44+F54 -> 0 | G5: =G16+G26+G35+G44+G54 -> 0 | H5: =H16+H26+H35+H44+H54 -> 0 | I5: =SUM(C5:H5) -> 0
B6: Total | C6: =SUM(C2:C5) -> 59742850925 | D6: =SUM(D2:D5) -> 0 | E6: =SUM(E2:E5) -> 0 | F6: =SUM(F2:F5) -> 19010440 | G6: =SUM(G2:G5) -> 138550812 | H6: =SUM(H2:H5) -> 3.4157135e+09 | I6: =SUM(I2:I5) -> 63316125713
C7: =C6=(C17+C27+C36+C45+C55) -> TRUE | D7: =D6=(D17+D27+D36+D45+D55) -> TRUE | E7: =E6=(E17+E27+E36+E45+E55) -> TRUE | F7: =F6=(F17+F27+F36+F45+F55) -> TRUE | H7: =H6=(H17+H27+H36+H45+H55) -> TRUE | I7: =I6=(I17+I27+I36+I45+I55) -> TRUE
B10: ASE 1
B11: Resumen Recaudo Aplicado Por Servicio
C12: ENEL | D12: CIUDAD LIMPIA | E12: EAB | F12: NUEVO ESQUEMA | G12: ENERBIT | H12: OCCIDENTE | I12: Total
B13: 1-APLICADOS A FACTURACION | C13: 16922955923 | D13: 0 | E13: 0 | F13: 0 | G13: 0 | H13: 5.2128716e+08 | I13: =SUM(C13:H13) -> 1.7444243e+10 | J13: =SUM(C13:H13)=I13 -> TRUE
B14: 2-SALDOS A FAVOR GENERADOS | C14: 25429155 | D14: 0 | E14: 0 | F14: 0 | G14: 0 | H14: 7990275.5 | I14: =SUM(C14:H14) -> 33419430 | J14: =SUM(C14:H14)=I14 -> TRUE
B15: 3-APLICADOS A FINANCIACIONES NUEVAS | C15: 0 | D15: 0 | E15: 0 | F15: 0 | G15: 0 | H15: 5300003 | I15: =SUM(C15:H15) -> 5300003 | J15: =SUM(C15:H15)=I15 -> TRUE
B16: 7-APLICADOS A RECIBOS SERVICIOS ESPECIALES | C16: 0 | D16: 0 | E16: 0 | F16: 0 | G16: 0 | H16: 0 | I16: =SUM(C16:H16) -> 0 | J16: =SUM(C16:H16)=I16 -> TRUE
B17: Total | C17: =SUM(C13:C16) -> 16948385078 | D17: =SUM(D13:D16) -> 0 | E17: =SUM(E13:E16) -> 0 | F17: =SUM(F13:F16) -> 0 | G17: =SUM(G13:G16) -> 0 | H17: =SUM(H13:H16) -> 534577438 | I17: =SUM(I13:I16) -> 17482962516 | J17: =SUM(C17:H17)=I17 -> TRUE
B20: ASE 2
B21: Resumen Recaudo Aplicado Por Servicio
C22: ENEL | D22: CIUDAD LIMPIA | E22: EAB | F22: NUEVO ESQUEMA | G22: ENERBIT | H22: OCCIDENTE | I22: Total
B23: 1-APLICADOS A FACTURACION | C23: 12724393063 | D23: 0 | E23: 0 | F23: 3445900 | G23: 0 | H23: 1.3616741e+09 | I23: =SUM(C23:H23) -> 1.4089513e+10 | J23: =SUM(C23:H23)=I23 -> TRUE
B24: 2-SALDOS A FAVOR GENERADOS | C24: 27050219 | D24: 0 | E24: 0 | F24: 8181830 | G24: 0 | H24: 52788865 | I24: =SUM(C24:H24) -> 88020914 | J24: =SUM(C24:H24)=I24 -> TRUE
B25: 3-APLICADOS A FINANCIACIONES NUEVAS | C25: 0 | D25: 0 | E25: 0 | F25: 0 | G25: 0 | H25: 8486848.6 | I25: =SUM(C25:H25) -> 8486848.6 | J25: =SUM(C25:H25)=I25 -> TRUE
B26: 7-APLICADOS A RECIBOS SERVICIOS ESPECIALES | C26: 0 | D26: 0 | E26: 0 | F26: 0 | G26: 0 | H26: 0 | I26: =SUM(C26:H26) -> 0 | J26: =SUM(C26:H26)=I26 -> TRUE
B27: Total | C27: =SUM(C23:C26) -> 12751443282 | D27: =SUM(D23:D26) -> 0 | E27: =SUM(E23:E26) -> 0 | F27: =SUM(F23:F26) -> 11627730 | G27: =SUM(G23:G26) -> 0 | H27: =SUM(H23:H26) -> 1422949863 | I27: =SUM(I23:I26) -> 1.4186021e+10 | J27: =SUM(C27:H27)=I27 -> TRUE
B29: ASE 3
B30: Resumen Recaudo Aplicado Por Servicio
C31: ENEL | D31: CIUDAD LIMPIA | E31: EAB | F31: NUEVO ESQUEMA | G31: ENERBIT | H31: OCCIDENTE | I31: Total
B32: 1-APLICADOS A FACTURACION | C32: 10203127061 | D32: 0 | E32: 0 | F32: 0 | G32: 0 | H32: 6.9348502e+08 | I32: =SUM(C32:H32) -> 1.0896612e+10 | J32: =SUM(C32:H32)=I32 -> TRUE
B33: 2-SALDOS A FAVOR GENERADOS | C33: 6025131 | D33: 0 | E33: 0 | F33: 0 | G33: 0 | H33: 2921040 | I33: =SUM(C33:H33) -> 8946171 | J33: =SUM(C33:H33)=I33 -> TRUE
B34: 3-APLICADOS A FINANCIACIONES NUEVAS | C34: 0 | D34: 0 | E34: 0 | F34: 0 | G34: 0 | H34: 2616838.9 | I34: =SUM(C34:H34) -> 2616838.9 | J34: =SUM(C34:H34)=I34 -> TRUE
B35: 7-APLICADOS A RECIBOS SERVICIOS ESPECIALES | C35: 0 | D35: 0 | E35: 0 | F35: 0 | G35: 0 | H35: 0 | I35: =SUM(C35:H35) -> 0 | J35: =SUM(C35:H35)=I35 -> TRUE
B36: Total | C36: =SUM(C32:C35) -> 10209152192 | D36: =SUM(D32:D35) -> 0 | E36: =SUM(E32:E35) -> 0 | F36: =SUM(F32:F35) -> 0 | G36: =SUM(G32:G35) -> 0 | H36: =SUM(H32:H35) -> 699022897 | I36: =SUM(I32:I35) -> 10908175089 | J36: =SUM(C36:H36)=I36 -> TRUE
B38: ASE 4
B39: Resumen Recaudo Aplicado Por Servicio
C40: ENEL | D40: CIUDAD LIMPIA | E40: EAB | F40: NUEVO ESQUEMA | G40: ENERBIT | H40: OCCIDENTE | I40: Total
B41: 1-APLICADOS A FACTURACION | C41: 11007626472 | D41: 0 | E41: 0 | F41: 2157310 | G41: 0 | H41: 4.4153236e+08 | I41: =SUM(C41:H41) -> 1.1451316e+10 | J41: =SUM(C41:H41)=I41 -> TRUE
B42: 2-SALDOS A FAVOR GENERADOS | C42: 27660196 | D42: 0 | E42: 0 | F42: 5225400 | G42: 0 | H42: 8186683.7 | I42: =SUM(C42:H42) -> 41072280 | J42: =SUM(C42:H42)=I42 -> TRUE
B43: 3-APLICADOS A FINANCIACIONES NUEVAS | C43: 0 | D43: 0 | E43: 0 | F43: 0 | G43: 0 | H43: 70882609 | I43: =SUM(C43:H43) -> 70882609 | J43: =SUM(C43:H43)=I43 -> TRUE
B44: 7-APLICADOS A RECIBOS SERVICIOS ESPECIALES | C44: 0 | D44: 0 | E44: 0 | F44: 0 | G44: 0 | H44: 0 | I44: =SUM(C44:H44) -> 0 | J44: =SUM(C44:H44)=I44 -> TRUE
B45: Total | C45: =SUM(C41:C44) -> 11035286668 | D45: =SUM(D41:D44) -> 0 | E45: =SUM(E41:E44) -> 0 | F45: =SUM(F41:F44) -> 7382710 | G45: =SUM(G41:G44) -> 0 | H45: =SUM(H41:H44) -> 5.2060165e+08 | I45: =SUM(I41:I44) -> 11563271030 | J45: =SUM(C45:H45)=I45 -> TRUE
B48: ASE 5
...

Sheet ANT EXT-REV
C1: ASE 1 | E1: ASE 2 | G1: ASE 3 | I1: ASE 4 | K1: ASE 5 | M1: TOTAL
C2: REPORTE 3 | D2: REPORTE 4 | E2: REPORTE 3 | F2: REPORTE 4 | G2: REPORTE 3 | H2: REPORTE 4 | I2: REPORTE 3 | J2: REPORTE 4 | K2: REPORTE 3 | L2: REPORTE 4 | M2: REPORTE 3 | N2: REPORTE 4
B3: APLICADO | C3: =C11+C19+C27+C35+C43 -> 0 | D3: =D11+D19+D27+D35+D43 -> 0 | E3: =E11+E19+E27+E35+E43 -> 0 | F3: =F11+F19+F27+F35+F43 -> 0 | G3: =G11+G19+G27+G35+G43 -> 0 | H3: =H11+H19+H27+H35+H43 -> 0 | I3: =I11+I19+I27+I35+I43 -> 0 | J3: =J11+J19+J27+J35+J43 -> 0 | ... L3: =L11+L19+L27+L35+L43 -> 0 | M3: =C3+E3+G3+I3+K3 -> 0 | N3: =D3+F3+H3+J3+L3 -> 0 | P3: =N3=(-VALIDACION_TOTAL!M9) -> FALSE
B4: ANTICIPOS | C4: =C12+C20+C28+C36+C44 -> 0 | D4: =D12+D20+D28+D36+D44 -> 0 | E4: =E12+E20+E28+E36+E44 -> 0 | F4: =F12+F20+F28+F36+F44 -> 0 | G4: =G12+G20+G28+G36+G44 -> 0 | H4: =H12+H20+H28+H36+H44 -> 0 | I4: =I12+I20+I28+I36+I44 -> 0 | J4: =J12+J20+J28+J36+J44 -> 0 | ... L4: =L12+L20+L28+L36+L44 -> 0 | M4: =C4+E4+G4+I4+K4 -> 0 | N4: =D4+F4+H4+J4+L4 -> 0 | P4: =N4=(-'CONSOLIDADO_TOTAL RECAUDO'!L131) -> TRUE
B5: TOTAL | C5: =SUM(C3:C4) -> 0 | D5: =SUM(D3:D4) -> 0 | E5: =SUM(E3:E4) -> 0 | F5: =SUM(F3:F4) -> 0 | G5: =SUM(G3:G4) -> 0 | H5: =SUM(H3:H4) -> 0 | I5: =SUM(I3:I4) -> 0 | J5: =SUM(J3:J4) -> 0 | ... N5: =SUM(N3:N4) -> 0
C6: =C5=(C13+C21+C29+C37+C45) -> TRUE | D6: =D5=(D13+D21+D29+D37+D45) -> TRUE | E6: =E5=(E13+E21+E29+E37+E45) -> TRUE | F6: =F5=(F13+F21+F29+F37+F45) -> TRUE | G6: =G5=(G13+G21+G29+G37+G45) -> TRUE | H6: =H5=(H13+H21+H29+H37+H45) -> TRUE | I6: =I5=(I13+I21+I29+I37+I45) -> TRUE | J6: =J5=(J13+J21+J29+J37+J45) -> TRUE | ... N6: =N5=(N13+N21+N29+N37+N45) -> TRUE
B8: BANCO DE OCCIDENTE
C9: ASE 1 | E9: ASE 2 | G9: ASE 3 | I9: ASE 4 | K9: ASE 5 | M9: TOTAL
C10: REPORTE 3 | D10: REPORTE 4 | E10: REPORTE 3 | F10: REPORTE 4 | G10: REPORTE 3 | H10: REPORTE 4 | I10: REPORTE 3 | J10: REPORTE 4 | K10: REPORTE 3 | L10: REPORTE 4 | M10: REPORTE 3 | N10: REPORTE 4
B11: APLICADO | C11: 0 | D11: 0 | E11: 0 | F11: 0 | G11: 0 | H11: 0 | I11: 0 | J11: 0 | K11: 0 | L11: 0 | M11: =C11+E11+G11+I11+K11 -> 0 | N11: =D11+F11+H11+J11+L11 -> 0
B12: ANTICIPOS | C12: 0 | D12: 0 | E12: 0 | F12: 0 | G12: 0 | H12: 0 | I12: 0 | J12: 0 | K12: 0 | L12: 0 | M12: =C12+E12+G12+I12+K12 -> 0 | N12: =D12+F12+H12+J12+L12 -> 0
B13: TOTAL | C13: =SUM(C11:C12) -> 0 | D13: =SUM(D11:D12) -> 0 | E13: =SUM(E11:E12) -> 0 | F13: =SUM(F11:F12) -> 0 | G13: =SUM(G11:G12) -> 0 | H13: =SUM(H11:H12) -> 0 | I13: =SUM(I11:I12) -> 0 | J13: =SUM(J11:J12) -> 0 | ... N13: =SUM(N11:N12) -> 0
B16: EAAB RECIPROCIDAD
C17: ASE 1 | E17: ASE 2 | G17: ASE 3 | I17: ASE 4 | K17: ASE 5 | M17: TOTAL
C18: REPORTE 3 | D18: REPORTE 4 | E18: REPORTE 3 | F18: REPORTE 4 | G18: REPORTE 3 | H18: REPORTE 4 | I18: REPORTE 3 | J18: REPORTE 4 | K18: REPORTE 3 | L18: REPORTE 4 | M18: REPORTE 3 | N18: REPORTE 4
B19: APLICADO | C19: 0 | D19: 0 | E19: 0 | F19: 0 | G19: 0 | H19: 0 | I19: 0 | J19: 0 | K19: 0 | L19: 0 | M19: =C19+E19+G19+I19+K19 -> 0 | N19: =D19+F19+H19+J19+L19 -> 0
B20: ANTICIPOS | C20: 0 | D20: 0 | E20: 0 | F20: 0 | G20: 0 | H20: 0 | I20: 0 | J20: 0 | K20: 0 | L20: 0 | M20: =C20+E20+G20+I20+K20 -> 0 | N20: =D20+F20+H20+J20+L20 -> 0
B21: TOTAL | C21: =SUM(C19:C20) -> 0 | D21: =SUM(D19:D20) -> 0 | E21: =SUM(E19:E20) -> 0 | F21: =SUM(F19:F20) -> 0 | G21: =SUM(G19:G20) -> 0 | H21: =SUM(H19:H20) -> 0 | I21: =SUM(I19:I20) -> 0 | J21: =SUM(J19:J20) -> 0 | ... L21: =SUM(L19:L20) -> 0 | M21: =C21+E21+G21+I21+K21 -> 0 | N21: =SUM(N19:N20) -> 0
B24: EAAB CIUDAD LIMPIA
C25: ASE 1 | E25: ASE 2 | G25: ASE 3 | I25: ASE 4 | K25: ASE 5 | M25: TOTAL
C26: REPORTE 3 | D26: REPORTE 4 | E26: REPORTE 3 | F26: REPORTE 4 | G26: REPORTE 3 | H26: REPORTE 4 | I26: REPORTE 3 | J26: REPORTE 4 | K26: REPORTE 3 | L26: REPORTE 4 | M26: REPORTE 3 | N26: REPORTE 4
B27: APLICADO | C27: 0 | D27: 0 | E27: 0 | F27: 0 | G27: 0 | H27: 0 | I27: 0 | J27: 0 | K27: 0 | L27: 0 | M27: =C27+E27+G27+I27+K27 -> 0 | N27: =D27+F27+H27+J27+L27 -> 0
B28: ANTICIPOS | C28: 0 | D28: 0 | E28: 0 | F28: 0 | G28: 0 | H28: 0 | I28: 0 | J28: 0 | K28: 0 | L28: 0 | M28: =C28+E28+G28+I28+K28 -> 0 | N28: =D28+F28+H28+J28+L28 -> 0
B29: TOTAL | C29: =SUM(C27:C28) -> 0 | D29: =SUM(D27:D28) -> 0 | E29: =SUM(E27:E28) -> 0 | F29: =SUM(F27:F28) -> 0 | G29: =SUM(G27:G28) -> 0 | H29: =SUM(H27:H28) -> 0 | I29: =SUM(I27:I28) -> 0 | J29: =SUM(J27:J28) -> 0 | ... N29: =SUM(N27:N28) -> 0
B32: ENEL
C33: ASE 1 | E33: ASE 2 | G33: ASE 3 | I33: ASE 4 | K33: ASE 5 | M33: TOTAL
C34: REPORTE 3 | D34: REPORTE 4 | E34: REPORTE 3 | F34: REPORTE 4 | G34: REPORTE 3 | H34: REPORTE 4 | I34: REPORTE 3 | J34: REPORTE 4 | K34: REPORTE 3 | L34: REPORTE 4 | M34: REPORTE 3 | N34: REPORTE 4
B35: APLICADO | C35: 0 | D35: 0 | E35: 0 | F35: 0 | G35: 0 | H35: 0 | I35: 0 | J35: 0 | K35: 0 | L35: 0 | M35: =C35+E35+G35+I35+K35 -> 0 | N35: =D35+F35+H35+J35+L35 -> 0
B36: ANTICIPOS | C36: 0 | D36: 0 | E36: 0 | F36: 0 | G36: 0 | H36: 0 | I36: 0 | J36: 0 | K36: 0 | L36: 0 | M36: =C36+E36+G36+I36+K36 -> 0 | N36: =D36+F36+H36+J36+L36 -> 0
B37: TOTAL | C37: =SUM(C35:C36) -> 0 | D37: =SUM(D35:D36) -> 0 | E37: =SUM(E35:E36) -> 0 | F37: =SUM(F35:F36) -> 0 | G37: =SUM(G35:G36) -> 0 | H37: =SUM(H35:H36) -> 0 | I37: =SUM(I35:I36) -> 0 | J37: =SUM(J35:J36) -> 0 | ... N37: =SUM(N35:N36) -> 0
B40: ENERBIT
C41: ASE 1 | E41: ASE 2 | G41: ASE 3 | I41: ASE 4 | K41: ASE 5 | M41: TOTAL
C42: REPORTE 3 | D42: REPORTE 4 | E42: REPORTE 3 | F42: REPORTE 4 | G42: REPORTE 3 | H42: REPORTE 4 | I42: REPORTE 3 | J42: REPORTE 4 | K42: REPORTE 3 | L42: REPORTE 4 | M42: REPORTE 3 | N42: REPORTE 4
B43: APLICADO | C43: 0 | D43: 0 | E43: 0 | F43: 0 | G43: 0 | H43: 0 | I43: 0 | J43: 0 | K43: 0 | L43: 0 | M43: =C43+E43+G43+I43+K43 -> 0 | N43: =D43+F43+H43+J43+L43 -> 0
B44: ANTICIPOS | C44: 0 | D44: 0 | E44: 0 | F44: 0 | G44: 0 | H44: 0 | I44: 0 | J44: 0 | K44: 0 | L44: 0 | M44: =C44+E44+G44+I44+K44 -> 0 | N44: =D44+F44+H44+J44+L44 -> 0
B45: TOTAL | C45: =SUM(C43:C44) -> 0 | D45: =SUM(D43:D44) -> 0 | E45: =SUM(E43:E44) -> 0 | F45: =SUM(F43:F44) -> 0 | G45: =SUM(G43:G44) -> 0 | H45: =SUM(H43:H44) -> 0 | I45: =SUM(I43:I44) -> 0 | J45: =SUM(J43:J44) -> 0 | ... N45: =SUM(N43:N44) -> 0

Sheet ANTICIPOS USUARIOS
B1: TOTAL | E1: RECIPRCIDAD | H1: ENEL | K1: ENERBIT | N1: OCCIDENTE | Q1: EAAB-CIUDADLIMPIA
B2: ASE | C2: ANTICIPOS GENERADOS POR PAGO | E2: ASE | F2: ANTICIPOS GENERADOS POR PAGO | H2: ASE | I2: ANTICIPOS GENERADOS POR PAGO | K2: ASE | L2: ANTICIPOS GENERADOS POR PAGO | N2: ASE | O2: ANTICIPOS GENERADOS POR PAGO | Q2: ASE | R2: ANTICIPOS GENERADOS POR PAGO | T2: Anticipos generados por pago
B3: 1 | C3: ='REPORTE RECAUDO x BANCO'!I14 -> 33419430 | E3: 1 | F3: ='REPORTE RECAUDO x BANCO'!F14 -> 0 | H3: 1 | I3: ='REPORTE RECAUDO x BANCO'!C14 -> 25429155 | K3: 1 | L3: ='REPORTE RECAUDO x BANCO'!G14 -> 0 | N3: 1 | O3: ='REPORTE RECAUDO x BANCO'!H14 -> 7990275.5 | Q3: 1 | R3: ='REPORTE RECAUDO x BANCO'!D14+'REPORTE RECAUDO x BANCO'!E14 -> 0 | T3: Sale del reporte Recaudo por Bancos.
B4: 2 | C4: ='REPORTE RECAUDO x BANCO'!I24 -> 88020914 | E4: 2 | F4: ='REPORTE RECAUDO x BANCO'!F24 -> 8181830 | H4: 2 | I4: ='REPORTE RECAUDO x BANCO'!C24 -> 27050219 | K4: 2 | L4: ='REPORTE RECAUDO x BANCO'!G24 -> 0 | N4: 2 | O4: ='REPORTE RECAUDO x BANCO'!H24 -> 52788865 | Q4: 2 | R4: ='REPORTE RECAUDO x BANCO'!D24+'REPORTE RECAUDO x BANCO'!E24 -> 0
B5: 3 | C5: ='REPORTE RECAUDO x BANCO'!I33 -> 8946171 | E5: 3 | F5: ='REPORTE RECAUDO x BANCO'!F33 -> 0 | H5: 3 | I5: ='REPORTE RECAUDO x BANCO'!C33 -> 6025131 | K5: 3 | L5: ='REPORTE RECAUDO x BANCO'!G33 -> 0 | N5: 3 | O5: ='REPORTE RECAUDO x BANCO'!H33 -> 2921040 | Q5: 3 | R5: ='REPORTE RECAUDO x BANCO'!D33+'REPORTE RECAUDO x BANCO'!E33 -> 0
B6: 4 | C6: ='REPORTE RECAUDO x BANCO'!I42 -> 41072280 | E6: 4 | F6: ='REPORTE RECAUDO x BANCO'!F42 -> 5225400 | H6: 4 | I6: ='REPORTE RECAUDO x BANCO'!C42 -> 27660196 | K6: 4 | L6: ='REPORTE RECAUDO x BANCO'!G42 -> 0 | N6: 4 | O6: ='REPORTE RECAUDO x BANCO'!H42 -> 8186683.7 | Q6: 4 | R6: ='REPORTE RECAUDO x BANCO'!D42+'REPORTE RECAUDO x BANCO'!E42 -> 0
B7: 5 | C7: ='REPORTE RECAUDO x BANCO'!I52 -> 14445987 | E7: 5 | F7: ='REPORTE RECAUDO x BANCO'!F52 -> 0 | H7: 5 | I7: ='REPORTE RECAUDO x BANCO'!C52 -> 9759043 | K7: 5 | L7: ='REPORTE RECAUDO x BANCO'!G52 -> 1379910 | N7: 5 | O7: ='REPORTE RECAUDO x BANCO'!H52 -> 3307034 | Q7: 5 | R7: ='REPORTE RECAUDO x BANCO'!D52+'REPORTE RECAUDO x BANCO'!E52 -> 0
C8: =SUM(C3:C7) -> 1.8590478e+08 | F8: =SUM(F3:F7) -> 13407230 | I8: =SUM(I3:I7) -> 95923744 | L8: =SUM(L3:L7) -> 1379910 | O8: =SUM(O3:O7) -> 75193898 | R8: =SUM(R3:R7) -> 0
C9: =C8='REPORTE RECAUDO x BANCO'!I3 -> TRUE | F9: =F8='REPORTE RECAUDO x BANCO'!F3 -> TRUE | I9: =I8='REPORTE RECAUDO x BANCO'!C3 -> TRUE | L9: =L8='REPORTE RECAUDO x BANCO'!G3 -> TRUE | O9: =O8='REPORTE RECAUDO x BANCO'!H3 -> TRUE | R9: =R8='REPORTE RECAUDO x BANCO'!D3+'REPORTE RECAUDO x BANCO'!E3 -> TRUE
B11: ASE | C11: ANTICIPOS GENERADOS POR EXTEMPORANEOS | E11: ASE | F11: ANTICIPOS GENERADOS POR EXTEMPORANEOS | H11: ASE | I11: ANTICIPOS GENERADOS POR EXTEMPORANEOS | K11: ASE | L11: ANTICIPOS GENERADOS POR EXTEMPORANEOS | N11: ASE | O11: ANTICIPOS GENERADOS POR EXTEMPORANEOS | Q11: ASE | R11: ANTICIPOS GENERADOS POR EXTEMPORANEOS | T11: Anticipos generados por pagos aplicados de reversiones
B12: 1 | C12: ='ANT EXT-REV'!C4 -> 0 | E12: 1 | F12: ='ANT EXT-REV'!C20 -> 0 | H12: 1 | I12: ='ANT EXT-REV'!C36 -> 0 | K12: 1 | L12: ='ANT EXT-REV'!C44 -> 0 | N12: 1 | O12: ='ANT EXT-REV'!C12 -> 0 | Q12: 1 | R12: ='ANT EXT-REV'!C28 -> 0 | T12: Sale del reporte Recaudo reversado
B13: 2 | C13: ='ANT EXT-REV'!E4 -> 0 | E13: 2 | F13: ='ANT EXT-REV'!E20 -> 0 | H13: 2 | I13: ='ANT EXT-REV'!E36 -> 0 | K13: 2 | L13: ='ANT EXT-REV'!E44 -> 0 | N13: 2 | O13: ='ANT EXT-REV'!E12 -> 0 | Q13: 2 | R13: ='ANT EXT-REV'!E28 -> 0
B14: 3 | C14: ='ANT EXT-REV'!G4 -> 0 | E14: 3 | F14: ='ANT EXT-REV'!G20 -> 0 | H14: 3 | I14: ='ANT EXT-REV'!G36 -> 0 | K14: 3 | L14: ='ANT EXT-REV'!G44 -> 0 | N14: 3 | O14: ='ANT EXT-REV'!G12 -> 0 | Q14: 3 | R14: ='ANT EXT-REV'!G28 -> 0
B15: 4 | C15: ='ANT EXT-REV'!I4 -> 0 | E15: 4 | F15: ='ANT EXT-REV'!I20 -> 0 | H15: 4 | I15: ='ANT EXT-REV'!I36 -> 0 | K15: 4 | L15: ='ANT EXT-REV'!I44 -> 0 | N15: 4 | O15: ='ANT EXT-REV'!I12 -> 0 | Q15: 4 | R15: ='ANT EXT-REV'!I28 -> 0
B16: 5 | C16: ='ANT EXT-REV'!K4 -> 0 | E16: 5 | F16: ='ANT EXT-REV'!K20 -> 0 | H16: 5 | I16: ='ANT EXT-REV'!K36 -> 0 | K16: 5 | L16: ='ANT EXT-REV'!K44 -> 0 | N16: 5 | O16: ='ANT EXT-REV'!K12 -> 0 | Q16: 5 | R16: ='ANT EXT-REV'!K28 -> 0
C17: =SUM(C12:C16) -> 0 | F17: =SUM(F12:F16) -> 0 | I17: =SUM(I12:I16) -> 0 | L17: =SUM(L12:L16) -> 0 | O17: =SUM(O12:O16) -> 0 | R17: =SUM(R12:R16) -> 0
C18: =C17='ANT EXT-REV'!M4 -> TRUE | F18: =F17='ANT EXT-REV'!M20 -> TRUE | I18: =I17='ANT EXT-REV'!M36 -> TRUE | L18: =L17='ANT EXT-REV'!M44 -> TRUE | O18: =O17='ANT EXT-REV'!M12 -> TRUE | R18: =R17='ANT EXT-REV'!M28 -> TRUE
B20: ASE | C20: ANTICIPOS QUE CARGAN POR REVERSIONES | E20: ASE | F20: ANTICIPOS QUE CARGAN POR REVERSIONES | H20: ASE | I20: ANTICIPOS QUE CARGAN POR REVERSIONES | K20: ASE | L20: ANTICIPOS QUE CARGAN POR REVERSIONES | N20: ASE | O20: ANTICIPOS QUE CARGAN POR REVERSIONES | Q20: ASE | R20: ANTICIPOS QUE CARGAN POR REVERSIONES | T20: Anticipos que cargan de reversiones
B21: 1 | C21: ='ANT EXT-REV'!D4 -> 0 | E21: 1 | F21: ='ANT EXT-REV'!D20 -> 0 | H21: 1 | I21: ='ANT EXT-REV'!D36 -> 0 | K21: 1 | L21: ='ANT EXT-REV'!D44 -> 0 | N21: 1 | O21: ='ANT EXT-REV'!D12 -> 0 | Q21: 1 | R21: ='ANT EXT-REV'!D28 -> 0 | T21: Sale del reporte Recaudo reversado
B22: 2 | C22: ='ANT EXT-REV'!F4 -> 0 | E22: 2 | F22: ='ANT EXT-REV'!F20 -> 0 | H22: 2 | I22: ='ANT EXT-REV'!F36 -> 0 | K22: 2 | L22: ='ANT EXT-REV'!F44 -> 0 | N22: 2 | O22: ='ANT EXT-REV'!F12 -> 0 | Q22: 2 | R22: ='ANT EXT-REV'!F28 -> 0
B23: 3 | C23: ='ANT EXT-REV'!H4 -> 0 | E23: 3 | F23: ='ANT EXT-REV'!H20 -> 0 | H23: 3 | I23: ='ANT EXT-REV'!H36 -> 0 | K23: 3 | L23: ='ANT EXT-REV'!H44 -> 0 | N23: 3 | O23: ='ANT EXT-REV'!H12 -> 0 | Q23: 3 | R23: ='ANT EXT-REV'!H28 -> 0
B24: 4 | C24: ='ANT EXT-REV'!J4 -> 0 | E24: 4 | F24: ='ANT EXT-REV'!J20 -> 0 | H24: 4 | I24: ='ANT EXT-REV'!J36 -> 0 | K24: 4 | L24: ='ANT EXT-REV'!J44 -> 0 | N24: 4 | O24: ='ANT EXT-REV'!J12 -> 0 | Q24: 4 | R24: ='ANT EXT-REV'!J28 -> 0
B25: 5 | C25: ='ANT EXT-REV'!L4 -> 0 | E25: 5 | F25: ='ANT EXT-REV'!L20 -> 0 | H25: 5 | I25: ='ANT EXT-REV'!L36 -> 0 | K25: 5 | L25: ='ANT EXT-REV'!L44 -> 0 | N25: 5 | O25: ='ANT EXT-REV'!L12 -> 0 | Q25: 5 | R25: ='ANT EXT-REV'!L28 -> 0
C26: =SUM(C21:C25) -> 0 | F26: =SUM(F21:F25) -> 0 | I26: =SUM(I21:I25) -> 0 | L26: =SUM(L21:L25) -> 0 | O26: =SUM(O21:O25) -> 0 | R26: =SUM(R21:R25) -> 0
C27: =C26='ANT EXT-REV'!N4 -> TRUE | F27: =F26='ANT EXT-REV'!N20 -> TRUE | I27: =I26='ANT EXT-REV'!N36 -> TRUE | L27: =L26='ANT EXT-REV'!N44 -> TRUE | O27: =O26='ANT EXT-REV'!N12 -> TRUE | R27: =R26='ANT EXT-REV'!N28 -> TRUE

Sheet BCE SC POR FACT.
C2: ASE | D2: SUBSIDIO | E2: CONTRIBUCION | F2: TOTAL BSC | H2: SISTEMA
C3: 1 | D3: -1.2144311e+09 | E3: 3.8037668e+09 | F3: =D3+E3 -> 2.5893357e+09 | H3: =DetRetri2026091!J9 -> 2589335717 | I3: =F3-H3 -> -0.46000004
C4: 2 | D4: -7.0202293e+09 | E4: 1.9269695e+09 | F4: =D4+E4 -> -5.0932598e+09 | H4: =DetRetri2026091!J10 -> -5093259797 | I4: =F4-H4 -> -0.21999931
C5: 3 | D5: -3.1336986e+09 | E5: 1.9033016e+09 | F5: =D5+E5 -> -1.230397e+09 | H5: =DetRetri2026091!J11 -> -1230396998 | I5: =F5-H5 -> -0.43999982
C6: 4 | D6: -4.4790574e+08 | E6: 4.8603964e+08 | F6: =D6+E6 -> 38133906 | H6: =DetRetri2026091!J12 -> 38133906 | I6: =F6-H6 -> -0.19999999
C7: 5 | D7: -2.5354614e+09 | E7: 1.3113607e+09 | F7: =D7+E7 -> -1.2241007e+09 | H7: =DetRetri2026091!J13 -> -1224100690 | I7: =F7-H7 -> -0.46000028
F9: =SUM(F3:F7) -> -4.9202879e+09 | H9: =SUM(H3:H7) -> -4920287862 | I9: =F9-H9 -> -1.7799988
H10: =H9=DetRetri2026091!J14 -> TRUE
D11: =SUM(D3:D7) -> -1.4351726e+10 | E11: =SUM(E3:E7) -> 9.4314383e+09 | F11: =SUM(D3:E7) -> -4.9202879e+09
F12: =ROUND(F11,2)=ROUND(F9,2) -> TRUE
F13: =ROUND(F11,2)-ROUND(F9,2) -> 0
D18: ASE | E18: REMUN TOTAL | F18: VALIDA 1 | G18: VALIDA 2 | H18: DIFERENCIA VALIDA 2
D19: 1 | E19: ='CONSOLIDADO_TOTAL RECAUDO'!J104 -> 2.5893357e+09 | F19: =E19=F3 -> TRUE | G19: =E19=H3 -> FALSE | H19: =E19-H3 -> -0.46000004
D20: 2 | E20: ='CONSOLIDADO_TOTAL RECAUDO'!J105 -> -5.0932598e+09 | F20: =E20=F4 -> TRUE | G20: =E20=H4 -> FALSE | H20: =E20-H4 -> -0.21999931
D21: 3 | E21: ='CONSOLIDADO_TOTAL RECAUDO'!J106 -> -1.230397e+09 | F21: =E21=F5 -> TRUE | G21: =E21=H5 -> FALSE | H21: =E21-H5 -> -0.43999982
D22: 4 | E22: ='CONSOLIDADO_TOTAL RECAUDO'!J107 -> 38133906 | F22: =E22=F6 -> TRUE | G22: =E22=H6 -> FALSE | H22: =E22-H6 -> -0.19999999
D23: 5 | E23: ='CONSOLIDADO_TOTAL RECAUDO'!J108 -> -1.2241007e+09 | F23: =E23=F7 -> TRUE | G23: =E23=H7 -> FALSE | H23: =E23-H7 -> -0.46000028
E24: =SUM(E19:E23) -> -4.9202879e+09 | F24: =E24=F9 -> TRUE | G24: =E24=H9 -> FALSE | H24: =E24-H9 -> -1.7799988

Sheet Reporte Componentes R1
B4: PROMOAMBIENTAL
F5: Total | G5: Componente TDF | H5: Componente TTL | I5: Componente TVIAT | J5: Aprovechamiento | K5: CCSA Prest.Aprov. | L5: SERVICIO ESPECIALES | M5: Componente TCS | N5: Componente TLU | O5: Componente TBL | P5: Componente TRT | Q5: CCSA Prest. No Aprov. | R5: Ajuste Decena | S5: Ajuste Recargo Aseo | T5: Intereses Cte Financiac. Aseo | U5: Exonera-Recargo Aseo | V5: Exonera-Ajuste Decena Aseo | W5: Exonera-Recargo Aseo | X5: Exonera-Recargo Aseo | Y5: Intereses Cte Financiac. Aseo | Z5: Rec.Intereses
E6: Vlr Servicio | F6: -7108.83 | G6: -502.98 | H6: -213.69 | I6: -93.3 | J6: -1231.48 | K6: -79.58 | L6: 0 | M6: -698.02 | N6: -584.16 | O6: -2331.79 | P6: -1243.99 | Q6: -129.84 | R6: 0 | S6: 0 | T6: 0 | U6: 0 | V6: 0 | W6: 0 | X6: 0 | Y6: 0 | Z6: 0
D7: E | E7: Total | F7: -7108.83 | G7: -502.98 | H7: -213.69 | I7: -93.3 | J7: -1231.48 | K7: -79.58 | L7: 0 | M7: -698.02 | N7: -584.16 | O7: -2331.79 | P7: -1243.99 | Q7: -129.84 | R7: 0 | S7: 0 | T7: 0 | U7: 0 | V7: 0 | W7: 0 | X7: 0 | Y7: 0 | Z7: 0
C8: ENEL | D8: Total | F8: -7108.83 | G8: -502.98 | H8: -213.69 | I8: -93.3 | J8: -1231.48 | K8: -79.58 | L8: 0 | M8: -698.02 | N8: -584.16 | O8: -2331.79 | P8: -1243.99 | Q8: -129.84 | R8: 0 | S8: 0 | T8: 0 | U8: 0 | V8: 0 | W8: 0 | X8: 0 | Y8: 0 | Z8: 0
E9: Vlr Servicio | F9: 0 | G9: 0 | H9: 0 | I9: 0 | J9: 0 | K9: 0 | L9: 0 | M9: 0 | N9: 0 | O9: 0 | P9: 0 | Q9: 0 | R9: 0 | S9: 0 | T9: 0 | U9: 0 | V9: 0 | W9: 0 | X9: 0 | Y9: 0 | Z9: 0
D10: H | E10: Total | F10: 0 | G10: 0 | H10: 0 | I10: 0 | J10: 0 | K10: 0 | L10: 0 | M10: 0 | N10: 0 | O10: 0 | P10: 0 | Q10: 0 | R10: 0 | S10: 0 | T10: 0 | U10: 0 | V10: 0 | W10: 0 | X10: 0 | Y10: 0 | Z10: 0
E11: Vlr Servicio | F11: 0 | G11: 0 | H11: 0 | I11: 0 | J11: 0 | K11: 0 | L11: 0 | M11: 0 | N11: 0 | O11: 0 | P11: 0 | Q11: 0 | R11: 0 | S11: 0 | T11: 0 | U11: 0 | V11: 0 | W11: 0 | X11: 0 | Y11: 0 | Z11: 0
D12: O | E12: Total | F12: 0 | G12: 0 | H12: 0 | I12: 0 | J12: 0 | K12: 0 | L12: 0 | M12: 0 | N12: 0 | O12: 0 | P12: 0 | Q12: 0 | R12: 0 | S12: 0 | T12: 0 | U12: 0 | V12: 0 | W12: 0 | X12: 0 | Y12: 0 | Z12: 0
E13: Vlr Servicio | F13: 0 | G13: 0 | H13: 0 | I13: 0 | J13: 0 | K13: 0 | L13: 0 | M13: 0 | N13: 0 | O13: 0 | P13: 0 | Q13: 0 | R13: 0 | S13: 0 | T13: 0 | U13: 0 | V13: 0 | W13: 0 | X13: 0 | Y13: 0 | Z13: 0
D14: T | E14: Total | F14: 0 | G14: 0 | H14: 0 | I14: 0 | J14: 0 | K14: 0 | L14: 0 | M14: 0 | N14: 0 | O14: 0 | P14: 0 | Q14: 0 | R14: 0 | S14: 0 | T14: 0 | U14: 0 | V14: 0 | W14: 0 | X14: 0 | Y14: 0 | Z14: 0
C15: OCCIDENTE | D15: Total | F15: 0 | G15: 0 | H15: 0 | I15: 0 | J15: 0 | K15: 0 | L15: 0 | M15: 0 | N15: 0 | O15: 0 | P15: 0 | Q15: 0 | R15: 0 | S15: 0 | T15: 0 | U15: 0 | V15: 0 | W15: 0 | X15: 0 | Y15: 0 | Z15: 0
B16: Mes | C16: Total | F16: -7108.83 | G16: -502.98 | H16: -213.69 | I16: -93.3 | J16: -1231.48 | K16: -79.58 | L16: 0 | M16: -698.02 | N16: -584.16 | O16: -2331.79 | P16: -1243.99 | Q16: -129.84 | R16: 0 | S16: 0 | T16: 0 | U16: 0 | V16: 0 | W16: 0 | X16: 0 | Y16: 0 | Z16: 0
A17: AFaseo | B17: Total | F17: -7108.83 | G17: -502.98 | H17: -213.69 | I17: -93.3 | J17: -1231.48 | K17: -79.58 | L17: 0 | M17: -698.02 | N17: -584.16 | O17: -2331.79 | P17: -1243.99 | Q17: -129.84 | R17: 0 | S17: 0 | T17: 0 | U17: 0 | V17: 0 | W17: 0 | X17: 0 | Y17: 0 | Z17: 0
E18: Vlr Servicio | F18: 0 | G18: 0 | H18: 0 | I18: 0 | J18: 0 | K18: 0 | L18: 0 | M18: 0 | N18: 0 | O18: 0 | P18: 0 | Q18: 0 | R18: 0 | S18: 0 | T18: 0 | U18: 0 | V18: 0 | W18: 0 | X18: 0 | Y18: 0 | Z18: 0
E19: Vlr Intereses | F19: 0 | G19: 0 | H19: 0 | I19: 0 | J19: 0 | K19: 0 | L19: 0 | M19: 0 | N19: 0 | O19: 0 | P19: 0 | Q19: 0 | R19: 0 | S19: 0 | T19: 0 | U19: 0 | V19: 0 | W19: 0 | X19: 0 | Y19: 0 | Z19: 0
D20: E | E20: Total | F20: 0 | G20: 0 | H20: 0 | I20: 0 | J20: 0 | K20: 0 | L20: 0 | M20: 0 | N20: 0 | O20: 0 | P20: 0 | Q20: 0 | R20: 0 | S20: 0 | T20: 0 | U20: 0 | V20: 0 | W20: 0 | X20: 0 | Y20: 0 | Z20: 0
C21: ENEL | D21: Total | F21: 0 | G21: 0 | H21: 0 | I21: 0 | J21: 0 | K21: 0 | L21: 0 | M21: 0 | N21: 0 | O21: 0 | P21: 0 | Q21: 0 | R21: 0 | S21: 0 | T21: 0 | U21: 0 | V21: 0 | W21: 0 | X21: 0 | Y21: 0 | Z21: 0
E22: Vlr Servicio | F22: 0 | G22: 0 | H22: 0 | I22: 0 | J22: 0 | K22: 0 | L22: 0 | M22: 0 | N22: 0 | O22: 0 | P22: 0 | Q22: 0 | R22: 0 | S22: 0 | T22: 0 | U22: 0 | V22: 0 | W22: 0 | X22: 0 | Y22: 0 | Z22: 0
E23: Vlr Intereses | F23: 0 | G23: 0 | H23: 0 | I23: 0 | J23: 0 | K23: 0 | L23: 0 | M23: 0 | N23: 0 | O23: 0 | P23: 0 | Q23: 0 | R23: 0 | S23: 0 | T23: 0 | U23: 0 | V23: 0 | W23: 0 | X23: 0 | Y23: 0 | Z23: 0
D24: E | E24: Total | F24: 0 | G24: 0 | H24: 0 | I24: 0 | J24: 0 | K24: 0 | L24: 0 | M24: 0 | N24: 0 | O24: 0 | P24: 0 | Q24: 0 | R24: 0 | S24: 0 | T24: 0 | U24: 0 | V24: 0 | W24: 0 | X24: 0 | Y24: 0 | Z24: 0
C25: ENERBIT | D25: Total | F25: 0 | G25: 0 | H25: 0 | I25: 0 | J25: 0 | K25: 0 | L25: 0 | M25: 0 | N25: 0 | O25: 0 | P25: 0 | Q25: 0 | R25: 0 | S25: 0 | T25: 0 | U25: 0 | V25: 0 | W25: 0 | X25: 0 | Y25: 0 | Z25: 0
E26: Vlr Servicio | F26: 0 | G26: 0 | H26: 0 | I26: 0 | J26: 0 | K26: 0 | L26: 0 | M26: 0 | N26: 0 | O26: 0 | P26: 0 | Q26: 370.08 | R26: -1.95 | S26: 0 | T26: 0 | U26: 0 | V26: 0 | W26: 0 | X26: 0 | Y26: 0 | Z26: 0
E27: Vlr Intereses | F27: 0 | G27: 0 | H27: 0 | I27: 0 | J27: 0 | K27: 0 | L27: 0 | M27: 0 | N27: 0 | O27: 0 | P27: 0 | Q27: 0.07 | R27: 0 | S27: 0 | T27: 0 | U27: 0 | V27: 0 | W27: 0 | X27: 0 | Y27: 0 | Z27: 0
D28: H | E28: Total | F28: 0 | G28: 0 | H28: 0 | I28: 0 | J28: 0 | K28: 0 | L28: 0 | M28: 0 | N28: 0 | O28: 0 | P28: 0 | Q28: 370.15 | R28: -1.95 | S28: 0 | T28: 0 | U28: 0 | V28: 0 | W28: 0 | X28: 0 | Y28: 0 | Z28: 0
E29: Vlr Servicio | F29: 0 | G29: 0 | H29: 0 | I29: 0 | J29: 0 | K29: 0 | L29: 0 | M29: 0 | N29: 0 | O29: 0 | P29: 0 | Q29: 370.08 | R29: -1.95 | S29: 0 | T29: 0 | U29: 0 | V29: 0 | W29: 0 | X29: 0 | Y29: 0 | Z29: 0
E30: Vlr Intereses | F30: 0 | G30: 0 | H30: 0 | I30: 0 | J30: 0 | K30: 0 | L30: 0 | M30: 0 | N30: 0 | O30: 0 | P30: 0 | Q30: 0.07 | R30: 0 | S30: 0 | T30: 0 | U30: 0 | V30: 0 | W30: 0 | X30: 0 | Y30: 0 | Z30: 0
D31: O | E31: Total | F31: 0 | G31: 0 | H31: 0 | I31: 0 | J31: 0 | K31: 0 | L31: 0 | M31: 0 | N31: 0 | O31: 0 | P31: 0 | Q31: 370.15 | R31: -1.95 | S31: 0 | T31: 0 | U31: 0 | V31: 0 | W31: 0 | X31: 0 | Y31: 0 | Z31: 0
E32: Vlr Servicio | F32: 42672.75 | G32: 2083.59 | H32: 1160.96 | I32: 617.46 | J32: 10415.64 | K32: 383.02 | L32: 0 | M32: 3359.81 | N32: 3220.39 | O32: 15117.23 | P32: 5690.79 | Q32: 624.92 | R32: -1.06 | S32: 0 | T32: 0 | U32: 0 | V32: 0 | W32: 0 | X32: 0 | Y32: 0 | Z32: 0
E33: Vlr Intereses | F33: 7.25 | G33: 0.35 | H33: 0.2 | I33: 0.1 | J33: 1.77 | K33: 0.07 | L33: 0 | M33: 0.57 | N33: 0.54 | O33: 2.57 | P33: 0.97 | Q33: 0.11 | R33: 0 | S33: 0 | T33: 0 | U33: 0 | V33: 0 | W33: 0 | X33: 0 | Y33: 0 | Z33: 0
D34: T | E34: Total | F34: 42680 | G34: 2083.94 | H34: 1161.16 | I34: 617.56 | J34: 10417.41 | K34: 383.09 | L34: 0 | M34: 3360.38 | N34: 3220.93 | O34: 15119.8 | P34: 5691.76 | Q34: 625.03 | R34: -1.06 | S34: 0 | T34: 0 | U34: 0 | V34: 0 | W34: 0 | X34: 0 | Y34: 0 | Z34: 0
C35: OCCIDENTE | D35: Total | F35: 42680 | G35: 2083.94 | H35: 1161.16 | I35: 617.56 | J35: 10417.41 | K35: 383.09 | L35: 0 | M35: 3360.38 | N35: 3220.93 | O35: 15119.8 | P35: 5691.76 | Q35: 625.03 | R35: -1.06 | S35: 0 | T35: 0 | U35: 0 | V35: 0 | W35: 0 | X35: 0 | Y35: 0 | Z35: 0
B36: Aplicacion nuevos x reversion | C36: Total | F36: 42680 | G36: 2083.94 | H36: 1161.16 | I36: 617.56 | J36: 10417.41 | K36: 383.09 | L36: 0 | M36: 3360.38 | N36: 3220.93 | O36: 15119.8 | P36: 5691.76 | Q36: 625.03 | R36: -1.06 | S36: 0 | T36: 0 | U36: 0 | V36: 0 | W36: 0 | X36: 0 | Y36: 0 | Z36: 0
E37: Vlr Servicio | F37: 1.9865858e+10 | G37: 9.4982754e+08 | H37: 5.3058782e+08 | I37: 2.8117925e+08 | J37: 4.8115398e+09 | K37: 1.8047125e+08 | L37: 28843603 | M37: 1.5840574e+09 | N37: 1.5109569e+09 | O37: 7.108873e+09 | P37: 2.585077e+09 | Q37: 2.9449051e+08 | R37: -46186.47 | S37: 0 | T37: 0 | U37: 0 | V37: 0 | W37: 0 | X37: 0 | Y37: 0 | Z37: 0
E38: Vlr Intereses | F38: 3221187.2 | G38: 191257.04 | H38: 96240.8 | I38: 48070.33 | J38: 691627.43 | K38: 30779.35 | L38: 1888.23 | M38: 270442.29 | N38: 245214.4 | O38: 1082415 | P38: 513014.61 | Q38: 50206.13 | R38: -5.69 | S38: 0 | T38: 53.13 | U38: 0 | V38: 0 | W38: 0 | X38: 0 | Y38: 0 | Z38: -15.86
D39: E | E39: Total | F39: 1.9869079e+10 | G39: 9.500188e+08 | H39: 5.3068406e+08 | I39: 2.8122732e+08 | J39: 4.8122314e+09 | K39: 1.8050203e+08 | L39: 28845491 | M39: 1.5843279e+09 | N39: 1.5112021e+09 | O39: 7.1099554e+09 | P39: 2.58559e+09 | Q39: 2.9454072e+08 | R39: -46192.16 | S39: 0 | T39: 53.13 | U39: 0 | V39: 0 | W39: 0 | X39: 0 | Y39: 0 | Z39: -15.86
C40: ENEL | D40: Total | F40: 1.9869079e+10 | G40: 9.500188e+08 | H40: 5.3068406e+08 | I40: 2.8122732e+08 | J40: 4.8122314e+09 | K40: 1.8050203e+08 | L40: 28845491 | M40: 1.5843279e+09 | N40: 1.5112021e+09 | O40: 7.1099554e+09 | P40: 2.58559e+09 | Q40: 2.9454072e+08 | R40: -46192.16 | S40: 0 | T40: 53.13 | U40: 0 | V40: 0 | W40: 0 | X40: 0 | Y40: 0 | Z40: -15.86
E41: Vlr Servicio | F41: 0 | G41: 0 | H41: 0 | I41: 0 | J41: 0 | K41: 0 | L41: 0 | M41: 0 | N41: 0 | O41: 0 | P41: 0 | Q41: 0 | R41: 0 | S41: 0 | T41: 0 | U41: 0 | V41: 0 | W41: 0 | X41: 0 | Y41: 0 | Z41: 0
E42: Vlr Intereses | F42: 0 | G42: 0 | H42: 0 | I42: 0 | J42: 0 | K42: 0 | L42: 0 | M42: 0 | N42: 0 | O42: 0 | P42: 0 | Q42: 0 | R42: 0 | S42: 0 | T42: 0 | U42: 0 | V42: 0 | W42: 0 | X42: 0 | Y42: 0 | Z42: 0
D43: E | E43: Total | F43: 0 | G43: 0 | H43: 0 | I43: 0 | J43: 0 | K43: 0 | L43: 0 | M43: 0 | N43: 0 | O43: 0 | P43: 0 | Q43: 0 | R43: 0 | S43: 0 | T43: 0 | U43: 0 | V43: 0 | W43: 0 | X43: 0 | Y43: 0 | Z43: 0
...

Sheet Rem. Anticipos R2
B1: PROMOAMBIENTAL
E2: Total | F2: Componente TDF | G2: Componente TTL | H2: Componente TVIAT | I2: Aprovechamiento | J2: CCSA Prest.Aprov. | K2: Especiales | L2: Componente TCS | M2: Componente TLU | N2: Componente TBL | O2: Componente TRT | P2: CCSA Prest. No Aprov. | Q2: Deb/Cred | R2: Deb/Cred-otros
D3: Vlr Servicio | E3: 0 | F3: 0 | G3: 0 | H3: 0 | I3: 0 | J3: 0 | K3: 0 | L3: 0 | M3: 0 | N3: 0 | O3: 0 | P3: 0 | Q3: 0 | R3: 0
D4: Vlr Intereses | E4: 0 | F4: 0 | G4: 0 | H4: 0 | I4: 0 | J4: 0 | K4: 0 | L4: 0 | M4: 0 | N4: 0 | O4: 0 | P4: 0 | Q4: 0 | R4: 0
C5: A | D5: Total | E5: 0 | F5: 0 | G5: 0 | H5: 0 | I5: 0 | J5: 0 | K5: 0 | L5: 0 | M5: 0 | N5: 0 | O5: 0 | P5: 0 | Q5: 0 | R5: 0
B6: EAB | C6: Total | E6: 0 | F6: 0 | G6: 0 | H6: 0 | I6: 0 | J6: 0 | K6: 0 | L6: 0 | M6: 0 | N6: 0 | O6: 0 | P6: 0 | Q6: 0 | R6: 0
D7: Vlr Servicio | E7: 29113116 | F7: 1628607.2 | G7: 888839.63 | H7: 520100 | I7: 4494462.8 | J7: 206660.7 | K7: 0 | L7: 2285816.4 | M7: 2318036.2 | N7: 11916210 | O7: 4523138.8 | P7: 331271.2 | Q7: -26.69 | R7: 0
D8: Vlr Intereses | E8: 1903.01 | F8: 73.46 | G8: 40.2 | H8: 21.55 | I8: 326.7 | J8: 21.37 | K8: 0 | L8: 192.26 | M8: 174.97 | N8: 818.31 | O8: 199.3 | P8: 34.85 | Q8: 0.04 | R8: 0
C9: E | D9: Total | E9: 29115019 | F9: 1628680.7 | G9: 888879.83 | H9: 520121.55 | I9: 4494789.5 | J9: 206682.07 | K9: 0 | L9: 2286008.7 | M9: 2318211.1 | N9: 11917028 | O9: 4523338.1 | P9: 331306.05 | Q9: -26.65 | R9: 0
B10: ENEL | C10: Total | E10: 29115019 | F10: 1628680.7 | G10: 888879.83 | H10: 520121.55 | I10: 4494789.5 | J10: 206682.07 | K10: 0 | L10: 2286008.7 | M10: 2318211.1 | N10: 11917028 | O10: 4523338.1 | P10: 331306.05 | Q10: -26.65 | R10: 0
D11: Vlr Servicio | E11: 0 | F11: 0 | G11: 0 | H11: 0 | I11: 0 | J11: 0 | K11: 0 | L11: 0 | M11: 0 | N11: 0 | O11: 0 | P11: 0 | Q11: 0 | R11: 0
D12: Vlr Intereses | E12: 0 | F12: 0 | G12: 0 | H12: 0 | I12: 0 | J12: 0 | K12: 0 | L12: 0 | M12: 0 | N12: 0 | O12: 0 | P12: 0 | Q12: 0 | R12: 0
C13: E | D13: Total | E13: 0 | F13: 0 | G13: 0 | H13: 0 | I13: 0 | J13: 0 | K13: 0 | L13: 0 | M13: 0 | N13: 0 | O13: 0 | P13: 0 | Q13: 0 | R13: 0
B14: ENERBIT | C14: Total | E14: 0 | F14: 0 | G14: 0 | H14: 0 | I14: 0 | J14: 0 | K14: 0 | L14: 0 | M14: 0 | N14: 0 | O14: 0 | P14: 0 | Q14: 0 | R14: 0
D15: Vlr Servicio | E15: 793692.13 | F15: 30716.86 | G15: 16909.04 | H15: 9688.4 | I15: 151298.66 | J15: 7470.71 | K15: 0 | L15: 68892.29 | M15: 68745.87 | N15: 346268.88 | O15: 81506.79 | P15: 12188.93 | Q15: 5.7 | R15: 0
D16: Vlr Intereses | E16: 390.56 | F16: 13.47 | G16: 6.62 | H16: 4.12 | I16: 56.72 | J16: 4.51 | K16: 0 | L16: 39.61 | M16: 38.85 | N16: 182.43 | O16: 36.86 | P16: 7.36 | Q16: 0.01 | R16: 0
C17: H | D17: Total | E17: 794082.69 | F17: 30730.33 | G17: 16915.66 | H17: 9692.52 | I17: 151355.38 | J17: 7475.22 | K17: 0 | L17: 68931.9 | M17: 68784.72 | N17: 346451.31 | O17: 81543.65 | P17: 12196.29 | Q17: 5.71 | R17: 0
D18: Vlr Servicio | E18: 462871.22 | F18: 17750.61 | G18: 9935.12 | H18: 5797.01 | I18: 63590.58 | J18: 4697.55 | K18: 0 | L18: 43276.6 | M18: 42645.09 | N18: 218816.26 | O18: 48699.89 | P18: 7664.33 | Q18: -1.82 | R18: 0
D19: Vlr Intereses | E19: 0 | F19: 0 | G19: 0 | H19: 0 | I19: 0 | J19: 0 | K19: 0 | L19: 0 | M19: 0 | N19: 0 | O19: 0 | P19: 0 | Q19: 0 | R19: 0
C20: O | D20: Total | E20: 462871.22 | F20: 17750.61 | G20: 9935.12 | H20: 5797.01 | I20: 63590.58 | J20: 4697.55 | K20: 0 | L20: 43276.6 | M20: 42645.09 | N20: 218816.26 | O20: 48699.89 | P20: 7664.33 | Q20: -1.82 | R20: 0
D21: Vlr Servicio | E21: 2198318.9 | F21: 188049.69 | G21: 89756.71 | H21: 48201.07 | I21: 310657.06 | J21: 11520.24 | K21: 0 | L21: 108962.88 | M21: 96743.8 | N21: 469156.33 | O21: 856474.39 | P21: 18795.96 | Q21: 0.79 | R21: 0
D22: Vlr Intereses | E22: 0 | F22: 0 | G22: 0 | H22: 0 | I22: 0 | J22: 0 | K22: 0 | L22: 0 | M22: 0 | N22: 0 | O22: 0 | P22: 0 | Q22: 0 | R22: 0
C23: T | D23: Total | E23: 2198318.9 | F23: 188049.69 | G23: 89756.71 | H23: 48201.07 | I23: 310657.06 | J23: 11520.24 | K23: 0 | L23: 108962.88 | M23: 96743.8 | N23: 469156.33 | O23: 856474.39 | P23: 18795.96 | Q23: 0.79 | R23: 0
B24: OCCIDENTE | C24: Total | E24: 3455272.8 | F24: 236530.63 | G24: 116607.49 | H24: 63690.6 | I24: 525603.02 | J24: 23693.01 | K24: 0 | L24: 221171.38 | M24: 208173.61 | N24: 1034423.9 | O24: 986717.93 | P24: 38656.58 | Q24: 4.68 | R24: 0
A25: Componente | B25: Total | E25: 32570292 | F25: 1865211.3 | G25: 1005487.3 | H25: 583812.15 | I25: 5020392.6 | J25: 230375.08 | K25: 0 | L25: 2507180.1 | M25: 2526384.8 | N25: 12951452 | O25: 5510056 | P25: 369962.63 | Q25: -21.97 | R25: 0
D26: Subsidio(-)/Contribucion(+) | E26: 0 | F26: 0 | G26: 0 | H26: 0 | I26: 0 | J26: 0 | K26: 0 | L26: 0 | M26: 0 | N26: 0 | O26: 0 | P26: 0 | Q26: 0 | R26: 0
C27: A | D27: Total | E27: 0 | F27: 0 | G27: 0 | H27: 0 | I27: 0 | J27: 0 | K27: 0 | L27: 0 | M27: 0 | N27: 0 | O27: 0 | P27: 0 | Q27: 0 | R27: 0
B28: EAB | C28: Total | E28: 0 | F28: 0 | G28: 0 | H28: 0 | I28: 0 | J28: 0 | K28: 0 | L28: 0 | M28: 0 | N28: 0 | O28: 0 | P28: 0 | Q28: 0 | R28: 0
D29: Subsidio(-)/Contribucion(+) | E29: 1139503.2 | F29: 264067.13 | G29: 147039.05 | H29: 72868.6 | I29: -136480.3 | J29: 3896.46 | K29: 0 | L29: -61838.04 | M29: -5695.54 | N29: 107985.49 | O29: 741490.48 | P29: 6169.9 | Q29: 0 | R29: 0
C30: E | D30: Total | E30: 1139503.2 | F30: 264067.13 | G30: 147039.05 | H30: 72868.6 | I30: -136480.3 | J30: 3896.46 | K30: 0 | L30: -61838.04 | M30: -5695.54 | N30: 107985.49 | O30: 741490.48 | P30: 6169.9 | Q30: 0 | R30: 0
B31: ENEL | C31: Total | E31: 1139503.2 | F31: 264067.13 | G31: 147039.05 | H31: 72868.6 | I31: -136480.3 | J31: 3896.46 | K31: 0 | L31: -61838.04 | M31: -5695.54 | N31: 107985.49 | O31: 741490.48 | P31: 6169.9 | Q31: 0 | R31: 0
D32: Subsidio(-)/Contribucion(+) | E32: 0 | F32: 0 | G32: 0 | H32: 0 | I32: 0 | J32: 0 | K32: 0 | L32: 0 | M32: 0 | N32: 0 | O32: 0 | P32: 0 | Q32: 0 | R32: 0
C33: E | D33: Total | E33: 0 | F33: 0 | G33: 0 | H33: 0 | I33: 0 | J33: 0 | K33: 0 | L33: 0 | M33: 0 | N33: 0 | O33: 0 | P33: 0 | Q33: 0 | R33: 0
B34: ENERBIT | C34: Total | E34: 0 | F34: 0 | G34: 0 | H34: 0 | I34: 0 | J34: 0 | K34: 0 | L34: 0 | M34: 0 | N34: 0 | O34: 0 | P34: 0 | Q34: 0 | R34: 0
D35: Subsidio(-)/Contribucion(+) | E35: 124917.68 | F35: 5425.49 | G35: 3470.55 | H35: 2025.09 | I35: 30214.16 | J35: 1088.11 | K35: 0 | L35: 9544.97 | M35: 9235.05 | N35: 43751.21 | O35: 18387.71 | P35: 1775.34 | Q35: 0 | R35: 0
C36: H | D36: Total | E36: 124917.68 | F36: 5425.49 | G36: 3470.55 | H36: 2025.09 | I36: 30214.16 | J36: 1088.11 | K36: 0 | L36: 9544.97 | M36: 9235.05 | N36: 43751.21 | O36: 18387.71 | P36: 1775.34 | Q36: 0 | R36: 0
D37: Subsidio(-)/Contribucion(+) | E37: 166291.05 | F37: 8434.38 | G37: 4699.6 | H37: 2499.5 | I37: 29821.33 | J37: 1737.19 | K37: 0 | L37: 13525.99 | M37: 12946.73 | N37: 66755.66 | O37: 23036.36 | P37: 2834.31 | Q37: 0 | R37: 0
C38: O | D38: Total | E38: 166291.05 | F38: 8434.38 | G38: 4699.6 | H38: 2499.5 | I38: 29821.33 | J38: 1737.19 | K38: 0 | L38: 13525.99 | M38: 12946.73 | N38: 66755.66 | O38: 23036.36 | P38: 2834.31 | Q38: 0 | R38: 0
D39: Subsidio(-)/Contribucion(+) | E39: 843950.15 | F39: 106181.23 | G39: 59113.51 | H39: 30954.51 | I39: 107753.85 | J39: 4247.21 | K39: 0 | L39: 35494.18 | M39: 35638.24 | N39: 167630.68 | O39: 290007.18 | P39: 6929.56 | Q39: 0 | R39: 0
C40: T | D40: Total | E40: 843950.15 | F40: 106181.23 | G40: 59113.51 | H40: 30954.51 | I40: 107753.85 | J40: 4247.21 | K40: 0 | L40: 35494.18 | M40: 35638.24 | N40: 167630.68 | O40: 290007.18 | P40: 6929.56 | Q40: 0 | R40: 0
...

Sheet Reversion Pagos R4
B1: PROMOAMBIENTAL
D2: Total | E2: Componente TDF | F2: Componente TTL | G2: Componente TVIAT | H2: Aprovechamiento | I2: CCSA Prest.Aprov. | J2: Componente TCS | K2: Componente TLU | L2: Componente TBL | M2: Componente TRT | N2: CCSA Prest. No Aprov. | O2: Ajuste Decena | P2: SERVICIO ESPECIALES | Q2: Ajuste Recargo Aseo | R2: Otros
C3: Vlr Servicio | D3: -4753329.9 | E3: -214159.07 | F3: -114902.14 | G3: -61576.43 | H3: -1165948.6 | I3: -45063.11 | J3: -395289.43 | K3: -369526.83 | L3: -1753828.5 | M3: -560155.38 | N3: -72898.32 | O3: 17.99 | P3: 0 | Q3: 0 | R3: 0
C4: Vlr Intereses | D4: -12501.61 | E4: -542.19 | F4: -246.5 | G4: -140.42 | H4: -2800.13 | I4: -138.59 | J4: -1215.05 | K4: -1024.58 | L4: -4838.23 | M4: -1328.64 | N4: -227.04 | O4: -0.24 | P4: 0 | Q4: 0 | R4: 0
B5: Componente | C5: Total | D5: -4765831.5 | E5: -214701.26 | F5: -115148.64 | G5: -61716.85 | H5: -1168748.8 | I5: -45201.7 | J5: -396504.48 | K5: -370551.41 | L5: -1758666.8 | M5: -561484.02 | N5: -73125.36 | O5: 17.75 | P5: 0 | Q5: 0 | R5: 0
C6: Subsidio(-)/Contribucion(+) | D6: 1304634.2 | E6: 54873.86 | F6: 28576.76 | G6: 15506.07 | H6: 320570.26 | I6: 12973.15 | J6: 113799.96 | K6: 105110.1 | L6: 491550.49 | M6: 140506.71 | N6: 21166.82 | O6: 0 | P6: 0 | Q6: 0 | R6: 0
B7: Subs/Cont | C7: Total | D7: 1304634.2 | E7: 54873.86 | F7: 28576.76 | G7: 15506.07 | H7: 320570.26 | I7: 12973.15 | J7: 113799.96 | K7: 105110.1 | L7: 491550.49 | M7: 140506.71 | N7: 21166.82 | O7: 0 | P7: 0 | Q7: 0 | R7: 0
A8: ENEL | B8: Total | D8: -3461197.3 | E8: -159827.4 | F8: -86571.88 | G8: -46210.78 | H8: -848178.49 | I8: -32228.55 | J8: -282704.52 | K8: -265441.31 | L8: -1267116.3 | M8: -420977.31 | N8: -51958.54 | O8: 17.75 | P8: 0 | Q8: 0 | R8: 0
C9: Vlr Servicio | D9: 0 | E9: 0 | F9: 0 | G9: 0 | H9: 0 | I9: 0 | J9: 0 | K9: 0 | L9: 0 | M9: 0 | N9: 0 | O9: 0 | P9: 0 | Q9: 0 | R9: 0
C10: Vlr Intereses | D10: 0 | E10: 0 | F10: 0 | G10: 0 | H10: 0 | I10: 0 | J10: 0 | K10: 0 | L10: 0 | M10: 0 | N10: 0 | O10: 0 | P10: 0 | Q10: 0 | R10: 0
B11: Componente | C11: Total | D11: 0 | E11: 0 | F11: 0 | G11: 0 | H11: 0 | I11: 0 | J11: 0 | K11: 0 | L11: 0 | M11: 0 | N11: 0 | O11: 0 | P11: 0 | Q11: 0 | R11: 0
C12: Subsidio(-)/Contribucion(+) | D12: 0 | E12: 0 | F12: 0 | G12: 0 | H12: 0 | I12: 0 | J12: 0 | K12: 0 | L12: 0 | M12: 0 | N12: 0 | O12: 0 | P12: 0 | Q12: 0 | R12: 0
B13: Subs/Cont | C13: Total | D13: 0 | E13: 0 | F13: 0 | G13: 0 | H13: 0 | I13: 0 | J13: 0 | K13: 0 | L13: 0 | M13: 0 | N13: 0 | O13: 0 | P13: 0 | Q13: 0 | R13: 0
A14: ENERBIT | B14: Total | D14: 0 | E14: 0 | F14: 0 | G14: 0 | H14: 0 | I14: 0 | J14: 0 | K14: 0 | L14: 0 | M14: 0 | N14: 0 | O14: 0 | P14: 0 | Q14: 0 | R14: 0
C15: Vlr Servicio | D15: -83090.08 | E15: -4319.28 | F15: -2439.7 | G15: -1284.52 | H15: -21380.91 | I15: -495.68 | J15: -4348.01 | K15: -6438.31 | L15: -29729.3 | M15: -11838.57 | N15: -808.72 | O15: -7.08 | P15: 0 | Q15: 0 | R15: 0
C16: Vlr Intereses | D16: -219.92 | E16: -11.38 | F16: -6.42 | G16: -3.38 | H16: -57.73 | I16: -1.29 | J16: -11.47 | K16: -16.98 | L16: -77.95 | M16: -31.19 | N16: -2.12 | O16: -0.01 | P16: 0 | Q16: 0 | R16: 0
B17: Componente | C17: Total | D17: -83310 | E17: -4330.66 | F17: -2446.12 | G17: -1287.9 | H17: -21438.64 | I17: -496.97 | J17: -4359.48 | K17: -6455.29 | L17: -29807.25 | M17: -11869.76 | N17: -810.84 | O17: -7.09 | P17: 0 | Q17: 0 | R17: 0
C18: Subsidio(-)/Contribucion(+) | D18: 0 | E18: 0 | F18: 0 | G18: 0 | H18: 0 | I18: 0 | J18: 0 | K18: 0 | L18: 0 | M18: 0 | N18: 0 | O18: 0 | P18: 0 | Q18: 0 | R18: 0
B19: Subs/Cont | C19: Total | D19: 0 | E19: 0 | F19: 0 | G19: 0 | H19: 0 | I19: 0 | J19: 0 | K19: 0 | L19: 0 | M19: 0 | N19: 0 | O19: 0 | P19: 0 | Q19: 0 | R19: 0
A20: OCCIDENTE | B20: Total | D20: -83310 | E20: -4330.66 | F20: -2446.12 | G20: -1287.9 | H20: -21438.64 | I20: -496.97 | J20: -4359.48 | K20: -6455.29 | L20: -29807.25 | M20: -11869.76 | N20: -810.84 | O20: -7.09 | P20: 0 | Q20: 0 | R20: 0
A21: Total | D21: -3544507.3 | E21: -164158.06 | F21: -89018 | G21: -47498.68 | H21: -869617.13 | I21: -32725.52 | J21: -287064 | K21: -271896.6 | L21: -1296923.5 | M21: -432847.07 | N21: -52769.38 | O21: 10.66 | P21: 0 | Q21: 0 | R21: 0
A79: TOTAL | B79: OPORTUNO | C79: Total | D79: =D21-P21 -> -3544507.3 | E79: =E5+E17 -> -219031.92 | F79: =F5+F17 -> -117594.76 | G79: =G5+G17 -> -63004.75 | H79: =H5+H17 -> -1190187.4 | I79: =I5+I17 -> -45698.67 | J79: =J5+J17 -> -400863.96 | K79: =K5+K17 -> -377006.7 | L79: =L5+L17 -> -1788474 | ... R79: =R5+R17 -> 0
C80: Subsidio(-)/Contribucion(+) | D80: =D7+D19 -> 1304634.2
A82: RECIPROCIDAD | B82: OPORTUNO | C82: Total | D82: 0 | E82: 0 | F82: 0 | G82: 0 | H82: 0 | I82: 0 | J82: 0 | K82: 0 | L82: 0 | M82: 0 | N82: 0 | O82: 0 | P82: 0 | Q82: 0 | R82: 0
C83: Subsidio(-)/Contribucion(+) | D83: 0
A85: ENEL | B85: OPORTUNO | C85: Total | D85: =D8-P8 -> -3461197.3 | E85: =E5 -> -214701.26 | F85: =F5 -> -115148.64 | G85: =G5 -> -61716.85 | H85: =H5 -> -1168748.8 | I85: =I5 -> -45201.7 | J85: =J5 -> -396504.48 | K85: =K5 -> -370551.41 | L85: =L5 -> -1758666.8 | ... R85: =R5 -> 0
C86: Subsidio(-)/Contribucion(+) | D86: =D7 -> 1304634.2
A88: ENERBIT | B88: OPORTUNO | C88: Total | D88: =D14-P14 -> 0 | E88: =E11 -> 0 | F88: =F11 -> 0 | G88: =G11 -> 0 | H88: =H11 -> 0 | I88: =I11 -> 0 | J88: =J11 -> 0 | K88: =K11 -> 0 | L88: =L11 -> 0 | ... R88: =R11 -> 0
C89: Subsidio(-)/Contribucion(+) | D89: =D13 -> 0
A91: OCCIDENTE | B91: OPORTUNO | C91: Total | D91: =D20-P20 -> -83310 | E91: =E17 -> -4330.66 | F91: =F17 -> -2446.12 | G91: =G17 -> -1287.9 | H91: =H17 -> -21438.64 | I91: =I17 -> -496.97 | J91: =J17 -> -4359.48 | K91: =K17 -> -6455.29 | L91: =L17 -> -29807.25 | ... R91: =R17 -> 0
C92: Subsidio(-)/Contribucion(+) | D92: =D19 -> 0
A94: CIUDAD LIMPIA-ACUEDUCTO | B94: OPORTUNO | C94: Total | D94: 0 | E94: 0 | F94: 0 | G94: 0 | H94: 0 | I94: 0 | J94: 0 | K94: 0 | L94: 0 | M94: 0 | N94: 0 | O94: 0 | P94: 0 | Q94: 0 | R94: 0
C95: Subsidio(-)/Contribucion(+) | D95: 0
B97: LIME
D98: Total | E98: Componente TDF | F98: Componente TTL | G98: Componente TVIAT | H98: Aprovechamiento | I98: CCSA Prest.Aprov. | J98: Componente TCS | K98: Componente TLU | L98: Componente TBL | M98: Componente TRT | N98: CCSA Prest. No Aprov. | O98: Ajuste Decena | P98: SERVICIO ESPECIALES | Q98: Ajuste Recargo Aseo | R98: Otros
C99: Vlr Servicio | D99: -10237443 | E99: -563399.38 | F99: -316917.62 | G99: -166722.74 | H99: -2628414.2 | I99: -89684.05 | J99: -786699.09 | K99: -766969.55 | L99: -3636763.4 | M99: -1109050.8 | N99: -146326.35 | O99: 4.57 | P99: -26500 | Q99: 0 | R99: 0
C100: Vlr Intereses | D100: -49535.64 | E100: -2812.32 | F100: -1322.36 | G100: -716.51 | H100: -13748.88 | I100: -368.55 | J100: -3233.3 | K100: -3852.97 | L100: -17279.39 | M100: -5599.52 | N100: -601.36 | O100: -0.48 | P100: 0 | Q100: 0 | R100: 0
B101: Componente | C101: Total | D101: -10286978 | E101: -566211.7 | F101: -318239.98 | G101: -167439.25 | H101: -2642163 | I101: -90052.6 | J101: -789932.39 | K101: -770822.52 | L101: -3654042.8 | M101: -1114650.3 | N101: -146927.71 | O101: 4.09 | P101: -26500 | Q101: 0 | R101: 0
C102: Subsidio(-)/Contribucion(+) | D102: 1547375.8 | E102: 29312.92 | F102: 16341.6 | G102: 8648.05 | H102: 470464.34 | I102: 15992.12 | J102: 140279.81 | K102: 136965.6 | L102: 646070.43 | M102: 57208.93 | N102: 26092.04 | O102: 0 | P102: 0 | Q102: 0 | R102: 0
B103: Subs/Cont | C103: Total | D103: 1547375.8 | E103: 29312.92 | F103: 16341.6 | G103: 8648.05 | H103: 470464.34 | I103: 15992.12 | J103: 140279.81 | K103: 136965.6 | L103: 646070.43 | M103: 57208.93 | N103: 26092.04 | O103: 0 | P103: 0 | Q103: 0 | R103: 0
...

Sheet SALDOS POR NOTA
B1: PROMOAMBIENTAL
C2: Total | D2: Componente TDF | E2: Componente TTL | F2: Componente TVIAT | G2: Aprovechamiento | H2: CCSA Prest.Aprov. | I2: Especiales | J2: Componente TCS | K2: Componente TLU | L2: Componente TBL | M2: Componente TRT | N2: CCSA Prest. No Aprov. | O2: Deb/Cred
B3: Vlr Servicio | C3: 0 | D3: 0 | E3: 0 | F3: 0 | G3: 0 | H3: 0 | I3: 0 | J3: 0 | K3: 0 | L3: 0 | M3: 0 | N3: 0 | O3: 0
B4: Vlr Intereses | C4: 0 | D4: 0 | E4: 0 | F4: 0 | G4: 0 | H4: 0 | I4: 0 | J4: 0 | K4: 0 | L4: 0 | M4: 0 | N4: 0 | O4: 0
A5: Componente | B5: Total | C5: 0 | D5: 0 | E5: 0 | F5: 0 | G5: 0 | H5: 0 | I5: 0 | J5: 0 | K5: 0 | L5: 0 | M5: 0 | N5: 0 | O5: 0
B6: Subsidio(-)/Contribucion(+) | C6: 0 | D6: 0 | E6: 0 | F6: 0 | G6: 0 | H6: 0 | I6: 0 | J6: 0 | K6: 0 | L6: 0 | M6: 0 | N6: 0 | O6: 0
A7: Subs/Cont | B7: Total | C7: 0 | D7: 0 | E7: 0 | F7: 0 | G7: 0 | H7: 0 | I7: 0 | J7: 0 | K7: 0 | L7: 0 | M7: 0 | N7: 0 | O7: 0
A8: Total | C8: 0 | D8: 0 | E8: 0 | F8: 0 | G8: 0 | H8: 0 | I8: 0 | J8: 0 | K8: 0 | L8: 0 | M8: 0 | N8: 0 | O8: 0
B10: Total | C10: =C8-I8 -> 0 | D10: =D5 -> 0 | E10: =E5 -> 0 | F10: =F5 -> 0 | G10: =G5 -> 0 | H10: =H5 -> 0 | I10: =I5 -> 0 | J10: =J5 -> 0 | K10: =K5 -> 0 | ... P10: =P5 -> 0
B11: Subsidio(-)/Contribucion(+) | C11: =C7 -> 0
B14: LIME
C15: Total | D15: Componente TDF | E15: Componente TTL | F15: Componente TVIAT | G15: Aprovechamiento | H15: CCSA Prest.Aprov. | I15: Especiales | J15: Componente TCS | K15: Componente TLU | L15: Componente TBL | M15: Componente TRT | N15: CCSA Prest. No Aprov. | O15: Deb/Cred
B16: Vlr Servicio | C16: 0 | D16: 0 | E16: 0 | F16: 0 | G16: 0 | H16: 0 | I16: 0 | J16: 0 | K16: 0 | L16: 0 | M16: 0 | N16: 0 | O16: 0
B17: Vlr Intereses | C17: 0 | D17: 0 | E17: 0 | F17: 0 | G17: 0 | H17: 0 | I17: 0 | J17: 0 | K17: 0 | L17: 0 | M17: 0 | N17: 0 | O17: 0
A18: Componente | B18: Total | C18: 0 | D18: 0 | E18: 0 | F18: 0 | G18: 0 | H18: 0 | I18: 0 | J18: 0 | K18: 0 | L18: 0 | M18: 0 | N18: 0 | O18: 0
B19: Subsidio(-)/Contribucion(+) | C19: 0 | D19: 0 | E19: 0 | F19: 0 | G19: 0 | H19: 0 | I19: 0 | J19: 0 | K19: 0 | L19: 0 | M19: 0 | N19: 0 | O19: 0
A20: Subs/Cont | B20: Total | C20: 0 | D20: 0 | E20: 0 | F20: 0 | G20: 0 | H20: 0 | I20: 0 | J20: 0 | K20: 0 | L20: 0 | M20: 0 | N20: 0 | O20: 0
A21: Total | C21: 0 | D21: 0 | E21: 0 | F21: 0 | G21: 0 | H21: 0 | I21: 0 | J21: 0 | K21: 0 | L21: 0 | M21: 0 | N21: 0 | O21: 0
B23: Total | C23: =C21-I21 -> 0 | D23: =D18 -> 0 | E23: =E18 -> 0 | F23: =F18 -> 0 | G23: =G18 -> 0 | H23: =H18 -> 0 | I23: =I18 -> 0 | J23: =J18 -> 0 | K23: =K18 -> 0 | ... P23: =P18 -> 0
B24: Subsidio(-)/Contribucion(+) | C24: =C20 -> 0
B27: CIUDAD LIMPIA
C28: Total | D28: Componente TDF | E28: Componente TTL | F28: Componente TVIAT | G28: Aprovechamiento | H28: CCSA Prest.Aprov. | I28: Especiales | J28: Componente TCS | K28: Componente TLU | L28: Componente TBL | M28: Componente TRT | N28: CCSA Prest. No Aprov. | O28: Deb/Cred
B29: Vlr Servicio | C29: 0 | D29: 0 | E29: 0 | F29: 0 | G29: 0 | H29: 0 | I29: 0 | J29: 0 | K29: 0 | L29: 0 | M29: 0 | N29: 0 | O29: 0
B30: Vlr Intereses | C30: 0 | D30: 0 | E30: 0 | F30: 0 | G30: 0 | H30: 0 | I30: 0 | J30: 0 | K30: 0 | L30: 0 | M30: 0 | N30: 0 | O30: 0
