Workbook
Name Bancos: [1]Fx!$C$1:$C$23
Name Ref.: #REF!
Name Ref.: #REF!
Name Ref.: #REF!
Name Ref.: #REF!

Sheet OPORTUNO
C1: =VALUE(C3&1) -> 2026101 | J1: =J16+J20+J24+J28+J32+J36+J40+J44+J48+J52+J56+J60+J64+J68+J72 -> 1616 | K1: =K16+K20+K24+K28+K32+K36+K40+K44+K48+K52+K56+K60+K64+K68+K72 -> 322739090 | L1: =L16+L20+L24+L28+L32+L36+L40+L44+L48+L52+L56+L60+L64+L68+L72 -> 3964 | M1: =M16+M20+M24+M28+M32+M36+M40+M44+M48+M52+M56+M60+M64+M68+M72 -> 839789795 | N1: =N16+N20+N24+N28+N32+N36+N40+N44+N48+N52+N56+N60+N64+N68+N72 -> 1376 | O1: =O16+O20+O24+O28+O32+O36+O40+O44+O48+O52+O56+O60+O64+O68+O72 -> 417500887 | P1: =P16+P20+P24+P28+P32+P36+P40+P44+P48+P52+P56+P60+P64+P68+P72 -> 2591 | Q1: =Q16+Q20+Q24+Q28+Q32+Q36+Q40+Q44+Q48+Q52+Q56+Q60+Q64+Q68+Q72 -> 481464262 | ... Y1: =Y16+Y20+Y24+Y28+Y32+Y36+Y40+Y44+Y48+Y52+Y56+Y60+Y64+Y68+Y72 -> 0
C2: =VALUE(C3&2) -> 2026102 | J2: =J76+J80+J84+J88+J92+J96+J100+J104+J108+J112+J116+J120+J124+J128+J132+J136 -> 666 | K2: =K76+K80+K84+K88+K92+K96+K100+K104+K108+K112+K116+K120+K124+K128+K132+K136 -> 186382057 | L2: =L76+L80+L84+L88+L92+L96+L100+L104+L108+L112+L116+L120+L124+L128+L132+L136 -> 1755 | M2: =M76+M80+M84+M88+M92+M96+M100+M104+M108+M112+M116+M120+M124+M128+M132+M136 -> 338362203 | N2: =N76+N80+N84+N88+N92+N96+N100+N104+N108+N112+N116+N120+N124+N128+N132+N136 -> 620 | O2: =O76+O80+O84+O88+O92+O96+O100+O104+O108+O112+O116+O120+O124+O128+O132+O136 -> 175516493 | P2: =P76+P80+P84+P88+P92+P96+P100+P104+P108+P112+P116+P120+P124+P128+P132+P136 -> 1098 | Q2: =Q76+Q80+Q84+Q88+Q92+Q96+Q100+Q104+Q108+Q112+Q116+Q120+Q124+Q128+Q132+Q136 -> 193541612 | ... Y2: =Y76+Y80+Y84+Y88+Y92+Y96+Y100+Y104+Y108+Y112+Y116+Y120+Y124+Y128+Y132+Y136 -> 0
C3: 202610 | J3: =SUM(J1:J2) -> 2282 | K3: =SUM(K1:K2) -> 509121147 | L3: =SUM(L1:L2) -> 5719 | M3: =SUM(M1:M2) -> 1178151998 | N3: =SUM(N1:N2) -> 1996 | O3: =SUM(O1:O2) -> 593017380 | P3: =SUM(P1:P2) -> 3689 | Q3: =SUM(Q1:Q2) -> 675005874 | ... Y3: =SUM(Y1:Y2) -> 0
H6: 2.5.3. INFORMES DE RECAUDO
H7: R2 - INFORME DE CONCILIACION DE RECAUDOS
H8: CONCILIACION DIARIA DE RECAUDO OPORTUNO DE DIRECTA
E9: NIT: 901 153 639 - 0
H10: =SUBSTITUTE(UPPER(TEXT(DATE(LEFT(C3,4),RIGHT(C3,2),1),"MMMM YYYY"))," ","_") -> OCTUBRE_2026 | K10: Recaudo Oportuno de DIRECTA en Banco de Occidente
B12: FECHA APLICACIÓN | C12: CODIGO REMUNERACIÓN | D12: FECHA RECAUDO | E12: CÓDIGO BC | F12: NOMBRE BANCO | G12: CÓDIGO CR | H12: CANAL RECAUDO | I12: N° CUENTA | J12: ASE 1 N° REGISTROS ARCHIVO | K12: ASE 1 VALOR ARCHIVO | L12: ASE 2 N° REGISTROS ARCHIVO | M12: ASE 2 VALOR ARCHIVO | N12: ASE 3 N° REGISTROS ARCHIVO | O12: ASE 3 VALOR ARCHIVO | P12: ASE 4 N° REGISTROS ARCHIVO | Q12: ASE 4 VALOR ARCHIVO | R12: ASE 5 N° REGISTROS ARCHIVO | S12: ASE 5 VALOR ARCHIVO | T12: TOTAL N° REGISTROS APLICADOS | U12: TOTAL VALOR APLICADO | V12: N° REGISTROS REPORTADOS POR BANCO | W12: VALOR REPORTADO POR BANCO | X12: DIFERENCIA REGISTROS | Y12: DIFERENCIA VALOR
B13: 46300 | C13: =C1 -> 2026101 | D13: 1 | E13: 23D | F13: Occidente - Directa | G13: 12 | H13: H23 Directa - CNB - Baloto - Éxito | I13: 230887267 | J13: 11 | K13: 3953890 | L13: 75 | M13: 11970170 | N13: 14 | O13: 1288530 | P13: 13 | Q13: 2480650 | R13: 10 | S13: 710910 | T13: =J13+L13+N13+P13+R13 -> 123 | U13: =K13+M13+O13+Q13+S13 -> 20404150 | V13: 123 | W13: 20404150 | X13: =V13-T13 -> 0 | Y13: =W13-U13 -> 0
B14: 46300 | C14: =C13 -> 2026101 | D14: 1 | E14: 23D | F14: Occidente - Directa | G14: 13 | H14: T23 Directa - Transferencias | I14: 230887267 | J14: =31+1+3 -> 35 | K14: =4539050+665450+1188253 -> 6392753 | L14: =71+1+1 -> 73 | M14: =12487600+3091500+4236270 -> 19815370 | N14: =35+1 -> 36 | O14: =5794800+4271590 -> 10066390 | P14: =1+42 -> 43 | Q14: =3325710+8159500 -> 11485210 | R14: =38+1 -> 39 | S14: =6377890+12894704 -> 19272594 | T14: =J14+L14+N14+P14+R14 -> 226 | U14: =K14+M14+O14+Q14+S14 -> 67032317 | V14: =1+217+1+2+2+3 -> 226 | W14: =3325710+37358840+12894704+3756950+8507860+1188253 -> 67032317 | X14: =V14-T14 -> 0 | Y14: =W14-U14 -> 0
B15: 46300 | C15: =C14 -> 2026101 | D15: 1 | E15: 23D | F15: Occidente - Directa | G15: 14 | H15: O23 Directa - Oficinas | I15: 230887267 | J15: 24 | K15: 1502171 | L15: 81 | M15: 15968206 | N15: 8 | O15: 4333838 | P15: 81 | Q15: 19278432 | R15: 20 | S15: 2196485 | T15: =J15+L15+N15+P15+R15 -> 214 | U15: =K15+M15+O15+Q15+S15 -> 43279132 | V15: 214 | W15: 43279132 | X15: =V15-T15 -> 0 | Y15: =W15-U15 -> 0
C16: =C15 -> 2026101 | F16: TOTAL | J16: =SUM(J13:J15) -> 70 | K16: =SUM(K13:K15) -> 11848814 | L16: =SUM(L13:L15) -> 229 | M16: =SUM(M13:M15) -> 47753746 | N16: =SUM(N13:N15) -> 58 | O16: =SUM(O13:O15) -> 15688758 | P16: =SUM(P13:P15) -> 137 | Q16: =SUM(Q13:Q15) -> 33244292 | ... Y16: =SUM(Y13:Y15) -> 0
B17: 46300 | C17: =C16 -> 2026101 | D17: 2 | E17: 23D | F17: Occidente - Directa | G17: 12 | H17: H23 Directa - CNB - Baloto - Éxito | I17: 230887267 | J17: 11 | K17: 1587980 | L17: 70 | M17: 10987880 | N17: 11 | O17: 1187530 | P17: 17 | Q17: 3853870 | R17: 14 | S17: 942900 | T17: =J17+L17+N17+P17+R17 -> 123 | U17: =K17+M17+O17+Q17+S17 -> 18560160 | V17: 123 | W17: 18560160 | X17: =V17-T17 -> 0 | Y17: =W17-U17 -> 0
B18: 46300 | C18: =C17 -> 2026101 | D18: 2 | E18: 23D | F18: Occidente - Directa | G18: 13 | H18: T23 Directa - Transferencias | I18: 230887267 | J18: 32 | K18: 4838300 | L18: =1+43 -> 44 | M18: =97699+58151410 -> 58249109 | N18: 37 | O18: 13439540 | P18: 30 | Q18: 5646770 | R18: 24 | S18: 5007810 | T18: =J18+L18+N18+P18+R18 -> 167 | U18: =K18+M18+O18+Q18+S18 -> 87181529 | V18: =1+166 -> 167 | W18: =97699+87083830 -> 87181529 | X18: =V18-T18 -> 0 | Y18: =W18-U18 -> 0
B19: 46300 | C19: =C18 -> 2026101 | D19: 2 | E19: 23D | F19: Occidente - Directa | G19: 14 | H19: O23 Directa - Oficinas | I19: 230887267 | J19: 13 | K19: 2352244 | L19: 92 | M19: 21980755 | N19: 4 | O19: 514146 | P19: 67 | Q19: 21244114 | R19: 17 | S19: 2057874 | T19: =J19+L19+N19+P19+R19 -> 193 | U19: =K19+M19+O19+Q19+S19 -> 48149133 | V19: 193 | W19: 48149133 | X19: =V19-T19 -> 0 | Y19: =W19-U19 -> 0
C20: =C19 -> 2026101 | F20: TOTAL | J20: =SUM(J17:J19) -> 56 | K20: =SUM(K17:K19) -> 8778524 | L20: =SUM(L17:L19) -> 206 | M20: =SUM(M17:M19) -> 91217744 | N20: =SUM(N17:N19) -> 52 | O20: =SUM(O17:O19) -> 15141216 | P20: =SUM(P17:P19) -> 114 | Q20: =SUM(Q17:Q19) -> 30744754 | ... Y20: =SUM(Y17:Y19) -> 0
B21: 46300 | C21: =C20 -> 2026101 | D21: 3 | E21: 23D | F21: Occidente - Directa | G21: 12 | H21: H23 Directa - CNB - Baloto - Éxito | I21: 230887267 | J21: 2 | K21: 64240 | L21: 28 | M21: 3565580 | N21: 1 | O21: 450 | P21: 4 | Q21: 717380 | R21: 4 | S21: 196690 | T21: =J21+L21+N21+P21+R21 -> 39 | U21: =K21+M21+O21+Q21+S21 -> 4544340 | V21: 39 | W21: 4544340 | X21: =V21-T21 -> 0 | Y21: =W21-U21 -> 0
B22: 46300 | C22: =C21 -> 2026101 | D22: 3 | E22: 23D | F22: Occidente - Directa | G22: 13 | H22: T23 Directa - Transferencias | I22: 230887267 | J22: 0 | K22: 0 | L22: 0 | M22: 0 | N22: 0 | O22: 0 | P22: 0 | Q22: 0 | R22: 0 | S22: 0 | T22: =J22+L22+N22+P22+R22 -> 0 | U22: =K22+M22+O22+Q22+S22 -> 0 | V22: 0 | W22: 0 | X22: =V22-T22 -> 0 | Y22: =W22-U22 -> 0
B23: 46300 | C23: =C22 -> 2026101 | D23: 3 | E23: 23D | F23: Occidente - Directa | G23: 14 | H23: O23 Directa - Oficinas | I23: 230887267 | J23: 0 | K23: 0 | L23: 0 | M23: 0 | N23: 0 | O23: 0 | P23: 0 | Q23: 0 | R23: 0 | S23: 0 | T23: =J23+L23+N23+P23+R23 -> 0 | U23: =K23+M23+O23+Q23+S23 -> 0 | V23: 0 | W23: 0 | X23: =V23-T23 -> 0 | Y23: =W23-U23 -> 0
C24: =C23 -> 2026101 | F24: TOTAL | J24: =SUM(J21:J23) -> 2 | K24: =SUM(K21:K23) -> 64240 | L24: =SUM(L21:L23) -> 28 | M24: =SUM(M21:M23) -> 3565580 | N24: =SUM(N21:N23) -> 1 | O24: =SUM(O21:O23) -> 450 | P24: =SUM(P21:P23) -> 4 | Q24: =SUM(Q21:Q23) -> 717380 | ... Y24: =SUM(Y21:Y23) -> 0
B25: 46300 | C25: =C24 -> 2026101 | D25: 4 | E25: 23D | F25: Occidente - Directa | G25: 12 | H25: H23 Directa - CNB - Baloto - Éxito | I25: 230887267 | J25: 0 | K25: 0 | L25: 10 | M25: 1370460 | N25: 0 | O25: 0 | P25: 1 | Q25: 44440 | R25: 2 | S25: 91520 | T25: =J25+L25+N25+P25+R25 -> 13 | U25: =K25+M25+O25+Q25+S25 -> 1506420 | V25: 13 | W25: 1506420 | X25: =V25-T25 -> 0 | Y25: =W25-U25 -> 0
B26: 46300 | C26: =C25 -> 2026101 | D26: 4 | E26: 23D | F26: Occidente - Directa | G26: 13 | H26: T23 Directa - Transferencias | I26: 230887267 | J26: 0 | K26: 0 | L26: 0 | M26: 0 | N26: 0 | O26: 0 | P26: 0 | Q26: 0 | R26: 0 | S26: 0 | T26: =J26+L26+N26+P26+R26 -> 0 | U26: =K26+M26+O26+Q26+S26 -> 0 | V26: 0 | W26: 0 | X26: =V26-T26 -> 0 | Y26: =W26-U26 -> 0
B27: 46300 | C27: =C26 -> 2026101 | D27: 4 | E27: 23D | F27: Occidente - Directa | G27: 14 | H27: O23 Directa - Oficinas | I27: 230887267 | J27: 0 | K27: 0 | L27: 0 | M27: 0 | N27: 0 | O27: 0 | P27: 0 | Q27: 0 | R27: 0 | S27: 0 | T27: =J27+L27+N27+P27+R27 -> 0 | U27: =K27+M27+O27+Q27+S27 -> 0 | V27: 0 | W27: 0 | X27: =V27-T27 -> 0 | Y27: =W27-U27 -> 0
C28: =C27 -> 2026101 | F28: TOTAL | J28: =SUM(J25:J27) -> 0 | K28: =SUM(K25:K27) -> 0 | L28: =SUM(L25:L27) -> 10 | M28: =SUM(M25:M27) -> 1370460 | N28: =SUM(N25:N27) -> 0 | O28: =SUM(O25:O27) -> 0 | P28: =SUM(P25:P27) -> 1 | Q28: =SUM(Q25:Q27) -> 44440 | ... Y28: =SUM(Y25:Y27) -> 0
B29: 46301 | C29: =C28 -> 2026101 | D29: 5 | E29: 23D | F29: Occidente - Directa | G29: 12 | H29: H23 Directa - CNB - Baloto - Éxito | I29: 230887267 | J29: 17 | K29: 1014150 | L29: 79 | M29: 10791500 | N29: 17 | O29: 1491490 | P29: 35 | Q29: 4096710 | R29: 13 | S29: 1473610 | T29: =J29+L29+N29+P29+R29 -> 161 | U29: =K29+M29+O29+Q29+S29 -> 18867460 | V29: 161 | W29: 18867460 | X29: =V29-T29 -> 0 | Y29: =W29-U29 -> 0
B30: 46301 | C30: =C29 -> 2026101 | D30: 5 | E30: 23D | F30: Occidente - Directa | G30: 13 | H30: T23 Directa - Transferencias | I30: 230887267 | J30: =50+4+34+11+6 -> 105 | K30: =16983680+3889590+2384060+832870+3316220 -> 27406420 | L30: =162+1+56 -> 219 | M30: =23025940+271290+6119300 -> 29416530 | N30: =71+1+11+1 -> 84 | O30: =18376790+52530+2186960+54370 -> 20670650 | P30: =4+63+51 -> 118 | Q30: =1435105+11376740+4692620 -> 17504465 | R30: =44+13 -> 57 | S30: =3736930+1052647 -> 4789577 | T30: =J30+L30+N30+P30+R30 -> 583 | U30: =K30+M30+O30+Q30+S30 -> 99787642 | V30: =4+390+6+165+12+6 -> 583 | W30: =1435105+73500080+4213410+16435587+887240+3316220 -> 99787642 | X30: =V30-T30 -> 0 | Y30: =W30-U30 -> 0
B31: 46301 | C31: =C30 -> 2026101 | D31: 5 | E31: 23D | F31: Occidente - Directa | G31: 14 | H31: O23 Directa - Oficinas | I31: 230887267 | J31: 33 | K31: 1556364 | L31: 86 | M31: 15092480 | N31: 10 | O31: 3121121 | P31: 93 | Q31: 16103935 | R31: 13 | S31: 1933478 | T31: =J31+L31+N31+P31+R31 -> 235 | U31: =K31+M31+O31+Q31+S31 -> 37807378 | V31: 235 | W31: 37807378 | X31: =V31-T31 -> 0 | Y31: =W31-U31 -> 0
C32: =C31 -> 2026101 | F32: TOTAL | J32: =SUM(J29:J31) -> 155 | K32: =SUM(K29:K31) -> 29976934 | L32: =SUM(L29:L31) -> 384 | M32: =SUM(M29:M31) -> 55300510 | N32: =SUM(N29:N31) -> 111 | O32: =SUM(O29:O31) -> 25283261 | P32: =SUM(P29:P31) -> 246 | Q32: =SUM(Q29:Q31) -> 37705110 | ... Y32: =SUM(Y29:Y31) -> 0
B33: 46302 | C33: =C32 -> 2026101 | D33: 6 | E33: 23D | F33: Occidente - Directa | G33: 12 | H33: H23 Directa - CNB - Baloto - Éxito | I33: 230887267 | J33: 13 | K33: 705990 | L33: 93 | M33: 11166610 | N33: 3 | O33: 184060 | P33: 53 | Q33: 5784650 | R33: 21 | S33: 1697180 | T33: =J33+L33+N33+P33+R33 -> 183 | U33: =K33+M33+O33+Q33+S33 -> 19538490 | V33: 183 | W33: 19538490 | X33: =V33-T33 -> 0 | Y33: =W33-U33 -> 0
B34: 46302 | C34: =C33 -> 2026101 | D34: 6 | E34: 23D | F34: Occidente - Directa | G34: 13 | H34: T23 Directa - Transferencias | I34: 230887267 | J34: =28+9+1 -> 38 | K34: =5187960+7606934+1853670 -> 14648564 | L34: =2+99+2+3 -> 106 | M34: =357220+41098350+202696+2012670 -> 43670936 | N34: =1+51 -> 52 | O34: =78110+33518440 -> 33596550 | P34: =1+60+2 -> 63 | Q34: =83780+6503720+259560 -> 6847060 | R34: =24+1 -> 25 | S34: =2851060+1575710 -> 4426770 | T34: =J34+L34+N34+P34+R34 -> 284 | U34: =K34+M34+O34+Q34+S34 -> 103189880 | V34: =262+4+13+2+3 -> 284 | W34: =89159530+519110+8069190+3429380+2012670 -> 103189880 | X34: =V34-T34 -> 0 | Y34: =W34-U34 -> 0
B35: 46302 | C35: =C34 -> 2026101 | D35: 6 | E35: 23D | F35: Occidente - Directa | G35: 14 | H35: O23 Directa - Oficinas | I35: 230887267 | J35: 107 | K35: 13139374 | L35: 92 | M35: 18961450 | N35: 22 | O35: 6080728 | P35: 97 | Q35: 43569768 | R35: 48 | S35: 2644290 | T35: =J35+L35+N35+P35+R35 -> 366 | U35: =K35+M35+O35+Q35+S35 -> 84395610 | V35: 366 | W35: 84395610 | X35: =V35-T35 -> 0 | Y35: =W35-U35 -> 0
C36: =C35 -> 2026101 | F36: TOTAL | J36: =SUM(J33:J35) -> 158 | K36: =SUM(K33:K35) -> 28493928 | L36: =SUM(L33:L35) -> 291 | M36: =SUM(M33:M35) -> 73798996 | N36: =SUM(N33:N35) -> 77 | O36: =SUM(O33:O35) -> 39861338 | P36: =SUM(P33:P35) -> 213 | Q36: =SUM(Q33:Q35) -> 56201478 | ... Y36: =SUM(Y33:Y35) -> 0
B37: 46303 | C37: =C36 -> 2026101 | D37: 7 | E37: 23D | F37: Occidente - Directa | G37: 12 | H37: H23 Directa - CNB - Baloto - Éxito | I37: 230887267 | J37: 53 | K37: 19997810 | L37: 105 | M37: 8998250 | N37: 32 | O37: 2458970 | P37: 64 | Q37: 6759070 | R37: 43 | S37: 3124160 | T37: =J37+L37+N37+P37+R37 -> 297 | U37: =K37+M37+O37+Q37+S37 -> 41338260 | V37: 297 | W37: 41338260 | X37: =V37-T37 -> 0 | Y37: =W37-U37 -> 0
B38: 46303 | C38: =C37 -> 2026101 | D38: 7 | E38: 23D | F38: Occidente - Directa | G38: 13 | H38: T23 Directa - Transferencias | I38: 230887267 | J38: =63+8 -> 71 | K38: =10359800+4621557 -> 14981357 | L38: =2+118+1 -> 121 | M38: =532110+21914850+1258530 -> 23705490 | N38: =46+11 -> 57 | O38: =14646650+3039740 -> 17686390 | P38: =104+1+1 -> 106 | Q38: =13371420+697432+84860 -> 14153712 | R38: =59+1 -> 60 | S38: =6794730+14060690 -> 20855420 | T38: =J38+L38+N38+P38+R38 -> 415 | U38: =K38+M38+O38+Q38+S38 -> 91382369 | V38: =2+390+10+11+2 -> 415 | W38: =532110+67087450+6577519+3039740+14145550 -> 91382369 | X38: =V38-T38 -> 0 | Y38: =W38-U38 -> 0
B39: 46303 | C39: =C38 -> 2026101 | D39: 7 | E39: 23D | F39: Occidente - Directa | G39: 14 | H39: O23 Directa - Oficinas | I39: 230887267 | J39: 42 | K39: 5108016 | L39: 69 | M39: 10988692 | N39: 7 | O39: 506917 | P39: 80 | Q39: 11442563 | R39: 13 | S39: 541672 | T39: =J39+L39+N39+P39+R39 -> 211 | U39: =K39+M39+O39+Q39+S39 -> 28587860 | V39: 211 | W39: 28587860 | X39: =V39-T39 -> 0 | Y39: =W39-U39 -> 0
C40: =C39 -> 2026101 | F40: TOTAL | J40: =SUM(J37:J39) -> 166 | K40: =SUM(K37:K39) -> 40087183 | L40: =SUM(L37:L39) -> 295 | M40: =SUM(M37:M39) -> 43692432 | N40: =SUM(N37:N39) -> 96 | O40: =SUM(O37:O39) -> 20652277 | P40: =SUM(P37:P39) -> 250 | Q40: =SUM(Q37:Q39) -> 32355345 | ... Y40: =SUM(Y37:Y39) -> 0
B41: 46304 | C41: =C40 -> 2026101 | D41: 8 | E41: 23D | F41: Occidente - Directa | G41: 12 | H41: H23 Directa - CNB - Baloto - Éxito | I41: 230887267 | J41: 23 | K41: 3170540 | L41: 129 | M41: 9364430 | N41: 38 | O41: 3076550 | P41: 75 | Q41: 11616710 | R41: 18 | S41: 855810 | T41: =J41+L41+N41+P41+R41 -> 283 | U41: =K41+M41+O41+Q41+S41 -> 28084040 | V41: 283 | W41: 28084040 | X41: =V41-T41 -> 0 | Y41: =W41-U41 -> 0
B42: 46304 | C42: =C41 -> 2026101 | D42: 8 | E42: 23D | F42: Occidente - Directa | G42: 13 | H42: T23 Directa - Transferencias | I42: 230887267 | J42: =3+65+50 -> 118 | K42: =448170+9778630+7956790 -> 18183590 | L42: =4+110+20 -> 134 | M42: =8645190+52803300+20813210 -> 82261700 | N42: =1+75+11 -> 87 | O42: =56050+29536630+2881720 -> 32474400 | P42: =99+4 -> 103 | Q42: =9052200+691220 -> 9743420 | R42: =1+51+4 -> 56 | S42: =287080+3479240+464190 -> 4230510 | T42: =J42+L42+N42+P42+R42 -> 498 | U42: =K42+M42+O42+Q42+S42 -> 146893620 | V42: =9+400+89 -> 498 | W42: =9436490+104650000+32807130 -> 146893620 | X42: =V42-T42 -> 0 | Y42: =W42-U42 -> 0
B43: 46304 | C43: =C42 -> 2026101 | D43: 8 | E43: 23D | F43: Occidente - Directa | G43: 14 | H43: O23 Directa - Oficinas | I43: 230887267 | J43: 21 | K43: 1973651 | L43: 61 | M43: 15763078 | N43: 5 | O43: 517360 | P43: 50 | Q43: 6560147 | R43: =17 -> 17 | S43: =693148 -> 693148 | T43: =J43+L43+N43+P43+R43 -> 154 | U43: =K43+M43+O43+Q43+S43 -> 25507384 | V43: 154 | W43: 25507384 | X43: =V43-T43 -> 0 | Y43: =W43-U43 -> 0
...

Sheet EXTEMPORANEOS
C1: =OPORTUNO!C1 -> 2026101 | J1: =SUM(J13:J77) -> 73 | K1: =SUM(K13:K77) -> 48127653 | L1: =SUM(L13:L77) -> 54 | M1: =SUM(M13:M77) -> 132160935 | N1: =SUM(N13:N77) -> 11 | O1: =SUM(O13:O77) -> 19609348 | P1: =SUM(P13:P77) -> 9 | Q1: =SUM(Q13:Q77) -> 118198907 | ... Y1: =SUM(Y13:Y77) -> 0
C2: =OPORTUNO!C2 -> 2026102 | J2: =SUM(J82:J166) -> 106 | K2: =SUM(K82:K166) -> 21888196 | L2: =SUM(L82:L166) -> 27 | M2: =SUM(M82:M166) -> 49312788 | N2: =SUM(N82:N166) -> 3 | O2: =SUM(O82:O166) -> 1810000 | P2: =SUM(P82:P166) -> 10 | Q2: =SUM(Q82:Q166) -> 560460 | ... Y2: =SUM(Y82:Y166) -> 0
C3: =OPORTUNO!C3 -> 202610 | J3: =SUM(J1:J2) -> 179 | K3: =SUM(K1:K2) -> 70015849 | L3: =SUM(L1:L2) -> 81 | M3: =SUM(M1:M2) -> 181473723 | N3: =SUM(N1:N2) -> 14 | O3: =SUM(O1:O2) -> 21419348 | P3: =SUM(P1:P2) -> 19 | Q3: =SUM(Q1:Q2) -> 118759367 | ... Y3: =SUM(Y1:Y2) -> 0
H6: 2.5.3. INFORMES DE RECAUDO
H7: R2 - INFORME DE CONCILIACION DE RECAUDOS
H8: CONCILIACION DIARIA DE RECAUDO EXTEMPORANEOS DE DIRECTA
E9: NIT: 901 153 639 - 0
H10: =OPORTUNO!H10 -> OCTUBRE_2026 | K10: Recaudo Extemporaneo de DIRECTA en Banco de Occidente
B12: FECHA APLICACIÓN | C12: CODIGO REMUNERACIÓN | D12: FECHA RECAUDO | E12: CÓDIGO BC | F12: NOMBRE BANCO | G12: CÓDIGO CR | H12: CANAL RECAUDO | I12: N° CUENTA | J12: ASE 1 N° REGISTROS ARCHIVO | K12: ASE 1 VALOR ARCHIVO | L12: ASE 2 N° REGISTROS ARCHIVO | M12: ASE 2 VALOR ARCHIVO | N12: ASE 3 N° REGISTROS ARCHIVO | O12: ASE 3 VALOR ARCHIVO | P12: ASE 4 N° REGISTROS ARCHIVO | Q12: ASE 4 VALOR ARCHIVO | R12: ASE 5 N° REGISTROS ARCHIVO | S12: ASE 5 VALOR ARCHIVO | T12: TOTAL N° REGISTROS APLICADOS | U12: TOTAL VALOR APLICADO | V12: N° REGISTROS REPORTADOS POR BANCO | W12: VALOR REPORTADO POR BANCO | X12: DIFERENCIA REGISTROS | Y12: DIFERENCIA VALOR
B13: 46300 | C13: =C1 -> 2026101 | D13: 46132 | E13: 23D | F13: =VLOOKUP(E13,'Códigos Banco'!$B$3:$D$27,2,0) -> Occidente - Directa | G13: 13 | H13: =VLOOKUP(G13,'Códigos Banco'!$F$3:$G$18,2,0) -> T23 Directa - Transferencias | I13: =VLOOKUP(E13,'Códigos Banco'!$B$3:$D$27,3,0) -> 230887267 | J13: 0 | K13: 0 | L13: 1 | M13: 3212690 | N13: 0 | O13: 0 | P13: 0 | Q13: 0 | R13: 0 | S13: 0 | T13: =J13+L13+N13+P13+R13 -> 1 | U13: =K13+M13+O13+Q13+S13 -> 3212690 | V13: 1 | W13: 3212690 | X13: =V13-T13 -> 0 | Y13: =W13-U13 -> 0
B14: 46300 | C14: =C13 -> 2026101 | D14: 46255 | E14: 23D | F14: =VLOOKUP(E14,'Códigos Banco'!$B$3:$D$27,2,0) -> Occidente - Directa | G14: 13 | H14: =VLOOKUP(G14,'Códigos Banco'!$F$3:$G$18,2,0) -> T23 Directa - Transferencias | I14: =VLOOKUP(E14,'Códigos Banco'!$B$3:$D$27,3,0) -> 230887267 | J14: 0 | K14: 0 | L14: 1 | M14: 102310 | N14: 0 | O14: 0 | P14: 0 | Q14: 0 | R14: 0 | S14: 0 | T14: =J14+L14+N14+P14+R14 -> 1 | U14: =K14+M14+O14+Q14+S14 -> 102310 | V14: 1 | W14: 102310 | X14: =V14-T14 -> 0 | Y14: =W14-U14 -> 0
B15: 46300 | C15: =C14 -> 2026101 | D15: 46265 | E15: 23D | F15: =VLOOKUP(E15,'Códigos Banco'!$B$3:$D$27,2,0) -> Occidente - Directa | G15: 13 | H15: =VLOOKUP(G15,'Códigos Banco'!$F$3:$G$18,2,0) -> T23 Directa - Transferencias | I15: =VLOOKUP(E15,'Códigos Banco'!$B$3:$D$27,3,0) -> 230887267 | J15: =8 -> 8 | K15: =7296440 -> 7296440 | L15: 1 | M15: 633420 | N15: 1 | O15: 783040 | P15: 3 | Q15: 15346300 | R15: 0 | S15: 0 | T15: =J15+L15+N15+P15+R15 -> 13 | U15: =K15+M15+O15+Q15+S15 -> 24059200 | V15: =5+8 -> 13 | W15: =16762760+7296440 -> 24059200 | X15: =V15-T15 -> 0 | Y15: =W15-U15 -> 0
B16: 46300 | C16: =C15 -> 2026101 | D16: 46266 | E16: 23D | F16: =VLOOKUP(E16,'Códigos Banco'!$B$3:$D$27,2,0) -> Occidente - Directa | G16: 13 | H16: =VLOOKUP(G16,'Códigos Banco'!$F$3:$G$18,2,0) -> T23 Directa - Transferencias | I16: =VLOOKUP(E16,'Códigos Banco'!$B$3:$D$27,3,0) -> 230887267 | J16: 0 | K16: 0 | L16: 0 | M16: 0 | N16: 0 | O16: 0 | P16: 2 | Q16: 38500960 | R16: 0 | S16: 0 | T16: =J16+L16+N16+P16+R16 -> 2 | U16: =K16+M16+O16+Q16+S16 -> 38500960 | V16: 2 | W16: 38500960 | X16: =V16-T16 -> 0 | Y16: =W16-U16 -> 0
B17: 46300 | C17: =C16 -> 2026101 | D17: 46267 | E17: 23D | F17: =VLOOKUP(E17,'Códigos Banco'!$B$3:$D$27,2,0) -> Occidente - Directa | G17: 13 | H17: =VLOOKUP(G17,'Códigos Banco'!$F$3:$G$18,2,0) -> T23 Directa - Transferencias | I17: =VLOOKUP(E17,'Códigos Banco'!$B$3:$D$27,3,0) -> 230887267 | J17: 0 | K17: 0 | L17: 1 | M17: 182660 | N17: 0 | O17: 0 | P17: 0 | Q17: 0 | R17: 0 | S17: 0 | T17: =J17+L17+N17+P17+R17 -> 1 | U17: =K17+M17+O17+Q17+S17 -> 182660 | V17: 1 | W17: 182660 | X17: =V17-T17 -> 0 | Y17: =W17-U17 -> 0
B18: 46300 | C18: =C17 -> 2026101 | D18: 46274 | E18: 23D | F18: =VLOOKUP(E18,'Códigos Banco'!$B$3:$D$27,2,0) -> Occidente - Directa | G18: 13 | H18: =VLOOKUP(G18,'Códigos Banco'!$F$3:$G$18,2,0) -> T23 Directa - Transferencias | I18: =VLOOKUP(E18,'Códigos Banco'!$B$3:$D$27,3,0) -> 230887267 | J18: 0 | K18: 0 | L18: 0 | M18: 0 | N18: 0 | O18: 0 | P18: 2 | Q18: 39051447 | R18: 0 | S18: 0 | T18: =J18+L18+N18+P18+R18 -> 2 | U18: =K18+M18+O18+Q18+S18 -> 39051447 | V18: 2 | W18: 39051447 | X18: =V18-T18 -> 0 | Y18: =W18-U18 -> 0
B19: 46300 | C19: =C18 -> 2026101 | D19: 46281 | E19: 23D | F19: =VLOOKUP(E19,'Códigos Banco'!$B$3:$D$27,2,0) -> Occidente - Directa | G19: 13 | H19: =VLOOKUP(G19,'Códigos Banco'!$F$3:$G$18,2,0) -> T23 Directa - Transferencias | I19: =VLOOKUP(E19,'Códigos Banco'!$B$3:$D$27,3,0) -> 230887267 | J19: 9 | K19: 12691930 | L19: 0 | M19: 0 | N19: 0 | O19: 0 | P19: 0 | Q19: 0 | R19: 1 | S19: 527440 | T19: =J19+L19+N19+P19+R19 -> 10 | U19: =K19+M19+O19+Q19+S19 -> 13219370 | V19: =9+1 -> 10 | W19: =12691930+527440 -> 13219370 | X19: =V19-T19 -> 0 | Y19: =W19-U19 -> 0
B20: 46300 | C20: =C19 -> 2026101 | D20: 46283 | E20: 23D | F20: =VLOOKUP(E20,'Códigos Banco'!$B$3:$D$27,2,0) -> Occidente - Directa | G20: 13 | H20: =VLOOKUP(G20,'Códigos Banco'!$F$3:$G$18,2,0) -> T23 Directa - Transferencias | I20: =VLOOKUP(E20,'Códigos Banco'!$B$3:$D$27,3,0) -> 230887267 | J20: 9 | K20: 480304 | L20: 17 | M20: 5832230 | N20: 0 | O20: 0 | P20: 0 | Q20: 0 | R20: 0 | S20: 0 | T20: =J20+L20+N20+P20+R20 -> 26 | U20: =K20+M20+O20+Q20+S20 -> 6312534 | V20: =9+17 -> 26 | W20: =480304+5832230 -> 6312534 | X20: =V20-T20 -> 0 | Y20: =W20-U20 -> 0
B21: 46300 | C21: =C20 -> 2026101 | D21: 46286 | E21: 23D | F21: =VLOOKUP(E21,'Códigos Banco'!$B$3:$D$27,2,0) -> Occidente - Directa | G21: 13 | H21: =VLOOKUP(G21,'Códigos Banco'!$F$3:$G$18,2,0) -> T23 Directa - Transferencias | I21: =VLOOKUP(E21,'Códigos Banco'!$B$3:$D$27,3,0) -> 230887267 | J21: =1 -> 1 | K21: =5936660+1419719 -> 7356379 | L21: 2 | M21: 156076 | N21: 0 | O21: 0 | P21: 0 | Q21: 0 | R21: 0 | S21: 0 | T21: =J21+L21+N21+P21+R21 -> 3 | U21: =K21+M21+O21+Q21+S21 -> 7512455 | V21: 3 | W21: =5936660+1575795 -> 7512455 | X21: =V21-T21 -> 0 | Y21: =W21-U21 -> 0
B22: 46300 | C22: =C21 -> 2026101 | D22: 46293 | E22: 23D | F22: =VLOOKUP(E22,'Códigos Banco'!$B$3:$D$27,2,0) -> Occidente - Directa | G22: 13 | H22: =VLOOKUP(G22,'Códigos Banco'!$F$3:$G$18,2,0) -> T23 Directa - Transferencias | I22: =VLOOKUP(E22,'Códigos Banco'!$B$3:$D$27,3,0) -> 230887267 | L22: 5 | M22: 96248690 | N22: 0 | O22: 0 | P22: 0 | Q22: 0 | R22: 0 | S22: 0 | T22: =J22+L22+N22+P22+R22 -> 5 | U22: =K22+M22+O22+Q22+S22 -> 96248690 | V22: =5 -> 5 | W22: =96248690 -> 96248690 | X22: =V22-T22 -> 0 | Y22: =W22-U22 -> 0
B23: 46300 | C23: =C22 -> 2026101 | D23: 46294 | E23: 23D | F23: =VLOOKUP(E23,'Códigos Banco'!$B$3:$D$27,2,0) -> Occidente - Directa | G23: 13 | H23: =VLOOKUP(G23,'Códigos Banco'!$F$3:$G$18,2,0) -> T23 Directa - Transferencias | I23: =VLOOKUP(E23,'Códigos Banco'!$B$3:$D$27,3,0) -> 230887267 | J23: =5 -> 5 | K23: =344356 -> 344356 | L23: 0 | M23: 0 | N23: 0 | O23: 0 | P23: 0 | Q23: 0 | R23: 0 | S23: 0 | T23: =J23+L23+N23+P23+R23 -> 5 | U23: =K23+M23+O23+Q23+S23 -> 344356 | V23: =5 -> 5 | W23: =344356 -> 344356 | X23: =V23-T23 -> 0 | Y23: =W23-U23 -> 0
B24: 46300 | C24: =C23 -> 2026101 | D24: 46295 | E24: 23D | F24: =VLOOKUP(E24,'Códigos Banco'!$B$3:$D$27,2,0) -> Occidente - Directa | G24: 13 | H24: =VLOOKUP(G24,'Códigos Banco'!$F$3:$G$18,2,0) -> T23 Directa - Transferencias | I24: =VLOOKUP(E24,'Códigos Banco'!$B$3:$D$27,3,0) -> 230887267 | J24: =1 -> 1 | K24: =56790 -> 56790 | L24: 1 | M24: 1425707 | N24: 0 | O24: 0 | P24: 0 | Q24: 0 | R24: 0 | S24: 0 | T24: =J24+L24+N24+P24+R24 -> 2 | U24: =K24+M24+O24+Q24+S24 -> 1482497 | V24: =2 -> 2 | W24: =1482497 -> 1482497 | X24: =V24-T24 -> 0 | Y24: =W24-U24 -> 0
B25: 46301 | C25: =C24 -> 2026101 | D25: 46070 | E25: 23D | F25: =VLOOKUP(E25,'Códigos Banco'!$B$3:$D$27,2,0) -> Occidente - Directa | G25: 13 | H25: =VLOOKUP(G25,'Códigos Banco'!$F$3:$G$18,2,0) -> T23 Directa - Transferencias | I25: =VLOOKUP(E25,'Códigos Banco'!$B$3:$D$27,3,0) -> 230887267 | J25: 9 | K25: 4822020 | L25: 0 | M25: 0 | N25: 0 | O25: 0 | P25: 0 | Q25: 0 | R25: 0 | S25: 0 | T25: =J25+L25+N25+P25+R25 -> 9 | U25: =K25+M25+O25+Q25+S25 -> 4822020 | V25: 9 | W25: 4822020 | X25: =V25-T25 -> 0 | Y25: =W25-U25 -> 0
B26: 46301 | C26: =C25 -> 2026101 | D26: 46225 | E26: 23D | F26: =VLOOKUP(E26,'Códigos Banco'!$B$3:$D$27,2,0) -> Occidente - Directa | G26: 13 | H26: =VLOOKUP(G26,'Códigos Banco'!$F$3:$G$18,2,0) -> T23 Directa - Transferencias | I26: =VLOOKUP(E26,'Códigos Banco'!$B$3:$D$27,3,0) -> 230887267 | J26: 0 | K26: 0 | L26: 0 | M26: 0 | N26: 1 | O26: 1212933 | P26: 0 | Q26: 0 | R26: 0 | S26: 0 | T26: =J26+L26+N26+P26+R26 -> 1 | U26: =K26+M26+O26+Q26+S26 -> 1212933 | V26: 1 | W26: 1212933 | X26: =V26-T26 -> 0 | Y26: =W26-U26 -> 0
B27: 46301 | C27: =C26 -> 2026101 | D27: 46280 | E27: 23D | F27: =VLOOKUP(E27,'Códigos Banco'!$B$3:$D$27,2,0) -> Occidente - Directa | G27: 13 | H27: =VLOOKUP(G27,'Códigos Banco'!$F$3:$G$18,2,0) -> T23 Directa - Transferencias | I27: =VLOOKUP(E27,'Códigos Banco'!$B$3:$D$27,3,0) -> 230887267 | J27: 0 | K27: 0 | L27: 0 | M27: 0 | N27: 7 | O27: 12659140 | P27: 0 | Q27: 0 | R27: 0 | S27: 0 | T27: =J27+L27+N27+P27+R27 -> 7 | U27: =K27+M27+O27+Q27+S27 -> 12659140 | V27: 7 | W27: 12659140 | X27: =V27-T27 -> 0 | Y27: =W27-U27 -> 0
B28: 46304 | C28: =C27 -> 2026101 | D28: 46227 | E28: 23D | F28: =VLOOKUP(E28,'Códigos Banco'!$B$3:$D$27,2,0) -> Occidente - Directa | G28: 13 | H28: =VLOOKUP(G28,'Códigos Banco'!$F$3:$G$18,2,0) -> T23 Directa - Transferencias | I28: =VLOOKUP(E28,'Códigos Banco'!$B$3:$D$27,3,0) -> 230887267 | J28: 0 | K28: 0 | L28: =1+1 -> 2 | M28: =158910+402900 -> 561810 | N28: 0 | O28: 0 | P28: 0 | Q28: 0 | R28: 0 | S28: 0 | T28: =J28+L28+N28+P28+R28 -> 2 | U28: =K28+M28+O28+Q28+S28 -> 561810 | V28: =1+1 -> 2 | W28: =158910+402900 -> 561810 | X28: =V28-T28 -> 0 | Y28: =W28-U28 -> 0
B29: 46304 | C29: =C28 -> 2026101 | D29: 46260 | E29: 23D | F29: =VLOOKUP(E29,'Códigos Banco'!$B$3:$D$27,2,0) -> Occidente - Directa | G29: 13 | H29: =VLOOKUP(G29,'Códigos Banco'!$F$3:$G$18,2,0) -> T23 Directa - Transferencias | I29: =VLOOKUP(E29,'Códigos Banco'!$B$3:$D$27,3,0) -> 230887267 | J29: 14 | K29: 3352270 | L29: 0 | M29: 0 | N29: 0 | O29: 0 | P29: 0 | Q29: 0 | R29: 0 | S29: 0 | T29: =J29+L29+N29+P29+R29 -> 14 | U29: =K29+M29+O29+Q29+S29 -> 3352270 | V29: 14 | W29: 3352270 | X29: =V29-T29 -> 0 | Y29: =W29-U29 -> 0
B30: 46304 | C30: =C29 -> 2026101 | D30: 46287 | E30: 23D | F30: =VLOOKUP(E30,'Códigos Banco'!$B$3:$D$27,2,0) -> Occidente - Directa | G30: 13 | H30: =VLOOKUP(G30,'Códigos Banco'!$F$3:$G$18,2,0) -> T23 Directa - Transferencias | I30: =VLOOKUP(E30,'Códigos Banco'!$B$3:$D$27,3,0) -> 230887267 | J30: 10 | K30: 1019125 | L30: 22 | M30: 14190630 | N30: 0 | O30: 0 | P30: 0 | Q30: 0 | R30: 0 | S30: 0 | T30: =J30+L30+N30+P30+R30 -> 32 | U30: =K30+M30+O30+Q30+S30 -> 15209755 | V30: 32 | W30: 15209755 | X30: =V30-T30 -> 0 | Y30: =W30-U30 -> 0
B31: 46308 | C31: =C30 -> 2026101 | D31: 46282 | E31: 23D | F31: =VLOOKUP(E31,'Códigos Banco'!$B$3:$D$27,2,0) -> Occidente - Directa | G31: 13 | H31: =VLOOKUP(G31,'Códigos Banco'!$F$3:$G$18,2,0) -> T23 Directa - Transferencias | I31: =VLOOKUP(E31,'Códigos Banco'!$B$3:$D$27,3,0) -> 230887267 | J31: 0 | K31: 0 | L31: 0 | M31: 0 | N31: 0 | O31: 0 | P31: 0 | Q31: 0 | R31: 10 | S31: 3331120 | T31: =J31+L31+N31+P31+R31 -> 10 | U31: =K31+M31+O31+Q31+S31 -> 3331120 | V31: 10 | W31: 3331120 | X31: =V31-T31 -> 0 | Y31: =W31-U31 -> 0
B32: 46279 | C32: =C31 -> 2026101 | D32: 46288 | E32: 23D | F32: =VLOOKUP(E32,'Códigos Banco'!$B$3:$D$27,2,0) -> Occidente - Directa | G32: 13 | H32: =VLOOKUP(G32,'Códigos Banco'!$F$3:$G$18,2,0) -> T23 Directa - Transferencias | I32: =VLOOKUP(E32,'Códigos Banco'!$B$3:$D$27,3,0) -> 230887267 | J32: 1 | K32: 1982922 | L32: 0 | M32: 0 | N32: 0 | O32: 0 | P32: 0 | Q32: 0 | R32: 0 | S32: 0 | T32: =J32+L32+N32+P32+R32 -> 1 | U32: =K32+M32+O32+Q32+S32 -> 1982922 | V32: 1 | W32: 1982922 | X32: =V32-T32 -> 0 | Y32: =W32-U32 -> 0
B33: 46279 | C33: =C32 -> 2026101 | D33: 46289 | E33: 23D | F33: =VLOOKUP(E33,'Códigos Banco'!$B$3:$D$27,2,0) -> Occidente - Directa | G33: 13 | H33: =VLOOKUP(G33,'Códigos Banco'!$F$3:$G$18,2,0) -> T23 Directa - Transferencias | I33: =VLOOKUP(E33,'Códigos Banco'!$B$3:$D$27,3,0) -> 230887267 | J33: 2 | K33: 5305437 | L33: 1 | M33: 9614712 | N33: 2 | O33: 4954235 | P33: 2 | Q33: 25300200 | R33: 1 | S33: 944904 | T33: =J33+L33+N33+P33+R33 -> 8 | U33: =K33+M33+O33+Q33+S33 -> 46119488 | V33: 8 | W33: 46119488 | X33: =V33-T33 -> 0 | Y33: =W33-U33 -> 0
B34: 46311 | C34: =C33 -> 2026101 | D34: 46076 | E34: 23D | F34: =VLOOKUP(E34,'Códigos Banco'!$B$3:$D$27,2,0) -> Occidente - Directa | G34: 13 | H34: =VLOOKUP(G34,'Códigos Banco'!$F$3:$G$18,2,0) -> T23 Directa - Transferencias | I34: =VLOOKUP(E34,'Códigos Banco'!$B$3:$D$27,3,0) -> 230887267 | J34: 0 | K34: 0 | L34: 0 | M34: 0 | N34: 0 | O34: 0 | P34: 0 | Q34: 0 | R34: 3 | S34: 407691 | T34: =J34+L34+N34+P34+R34 -> 3 | U34: =K34+M34+O34+Q34+S34 -> 407691 | V34: 3 | W34: 407691 | X34: =V34-T34 -> 0 | Y34: =W34-U34 -> 0
B35: 46311 | C35: =C34 -> 2026101 | D35: 46106 | E35: 23D | F35: =VLOOKUP(E35,'Códigos Banco'!$B$3:$D$27,2,0) -> Occidente - Directa | G35: 13 | H35: =VLOOKUP(G35,'Códigos Banco'!$F$3:$G$18,2,0) -> T23 Directa - Transferencias | I35: =VLOOKUP(E35,'Códigos Banco'!$B$3:$D$27,3,0) -> 230887267 | J35: 0 | K35: 0 | L35: 0 | M35: 0 | N35: 0 | O35: 0 | P35: 0 | Q35: 0 | R35: 2 | S35: 324553 | T35: =J35+L35+N35+P35+R35 -> 2 | U35: =K35+M35+O35+Q35+S35 -> 324553 | V35: 2 | W35: 324553 | X35: =V35-T35 -> 0 | Y35: =W35-U35 -> 0
B36: 46311 | C36: =C35 -> 2026101 | D36: 46128 | E36: 23D | F36: =VLOOKUP(E36,'Códigos Banco'!$B$3:$D$27,2,0) -> Occidente - Directa | G36: 13 | H36: =VLOOKUP(G36,'Códigos Banco'!$F$3:$G$18,2,0) -> T23 Directa - Transferencias | I36: =VLOOKUP(E36,'Códigos Banco'!$B$3:$D$27,3,0) -> 230887267 | J36: 0 | K36: 0 | L36: 0 | M36: 0 | N36: 0 | O36: 0 | P36: 0 | Q36: 0 | R36: 2 | S36: 284399 | T36: =J36+L36+N36+P36+R36 -> 2 | U36: =K36+M36+O36+Q36+S36 -> 284399 | V36: 2 | W36: 284399 | X36: =V36-T36 -> 0 | Y36: =W36-U36 -> 0
B37: 46311 | C37: =C36 -> 2026101 | D37: 46157 | E37: 23D | F37: =VLOOKUP(E37,'Códigos Banco'!$B$3:$D$27,2,0) -> Occidente - Directa | G37: 13 | H37: =VLOOKUP(G37,'Códigos Banco'!$F$3:$G$18,2,0) -> T23 Directa - Transferencias | I37: =VLOOKUP(E37,'Códigos Banco'!$B$3:$D$27,3,0) -> 230887267 | J37: 0 | K37: 0 | L37: 0 | M37: 0 | N37: 0 | O37: 0 | P37: 0 | Q37: 0 | R37: 2 | S37: 331585 | T37: =J37+L37+N37+P37+R37 -> 2 | U37: =K37+M37+O37+Q37+S37 -> 331585 | V37: 2 | W37: 331585 | X37: =V37-T37 -> 0 | Y37: =W37-U37 -> 0
B38: 46311 | C38: =C37 -> 2026101 | D38: 46191 | E38: 23D | F38: =VLOOKUP(E38,'Códigos Banco'!$B$3:$D$27,2,0) -> Occidente - Directa | G38: 13 | H38: =VLOOKUP(G38,'Códigos Banco'!$F$3:$G$18,2,0) -> T23 Directa - Transferencias | I38: =VLOOKUP(E38,'Códigos Banco'!$B$3:$D$27,3,0) -> 230887267 | J38: 0 | K38: 0 | L38: 0 | M38: 0 | N38: 0 | O38: 0 | P38: 0 | Q38: 0 | R38: 2 | S38: 312220 | T38: =J38+L38+N38+P38+R38 -> 2 | U38: =K38+M38+O38+Q38+S38 -> 312220 | V38: 2 | W38: 312220 | X38: =V38-T38 -> 0 | Y38: =W38-U38 -> 0
B39: 46311 | C39: =C38 -> 2026101 | D39: 46220 | E39: 23D | F39: =VLOOKUP(E39,'Códigos Banco'!$B$3:$D$27,2,0) -> Occidente - Directa | G39: 13 | H39: =VLOOKUP(G39,'Códigos Banco'!$F$3:$G$18,2,0) -> T23 Directa - Transferencias | I39: =VLOOKUP(E39,'Códigos Banco'!$B$3:$D$27,3,0) -> 230887267 | J39: 0 | K39: 0 | L39: 0 | M39: 0 | N39: 0 | O39: 0 | P39: 0 | Q39: 0 | R39: 2 | S39: 331300 | T39: =J39+L39+N39+P39+R39 -> 2 | U39: =K39+M39+O39+Q39+S39 -> 331300 | V39: 2 | W39: 331300 | X39: =V39-T39 -> 0 | Y39: =W39-U39 -> 0
B40: 46311 | C40: =C39 -> 2026101 | D40: 46254 | E40: 23D | F40: =VLOOKUP(E40,'Códigos Banco'!$B$3:$D$27,2,0) -> Occidente - Directa | G40: 13 | H40: =VLOOKUP(G40,'Códigos Banco'!$F$3:$G$18,2,0) -> T23 Directa - Transferencias | I40: =VLOOKUP(E40,'Códigos Banco'!$B$3:$D$27,3,0) -> 230887267 | J40: 0 | K40: 0 | L40: 0 | M40: 0 | N40: 0 | O40: 0 | P40: 0 | Q40: 0 | R40: 2 | S40: 317120 | T40: =J40+L40+N40+P40+R40 -> 2 | U40: =K40+M40+O40+Q40+S40 -> 317120 | V40: 2 | W40: 317120 | X40: =V40-T40 -> 0 | Y40: =W40-U40 -> 0
B41: 46311 | C41: =C40 -> 2026101 | D41: 46279 | E41: 23D | F41: =VLOOKUP(E41,'Códigos Banco'!$B$3:$D$27,2,0) -> Occidente - Directa | G41: 13 | H41: =VLOOKUP(G41,'Códigos Banco'!$F$3:$G$18,2,0) -> T23 Directa - Transferencias | I41: =VLOOKUP(E41,'Códigos Banco'!$B$3:$D$27,3,0) -> 230887267 | J41: 4 | K41: 3419680 | L41: 0 | M41: 0 | N41: 0 | O41: 0 | P41: 0 | Q41: 0 | R41: 0 | S41: 0 | T41: =J41+L41+N41+P41+R41 -> 4 | U41: =K41+M41+O41+Q41+S41 -> 3419680 | V41: 4 | W41: 3419680 | X41: =V41-T41 -> 0 | Y41: =W41-U41 -> 0
C42: =C41 -> 2026101 | E42: 23D | F42: =VLOOKUP(E42,'Códigos Banco'!$B$3:$D$27,2,0) -> Occidente - Directa | G42: 13 | H42: =VLOOKUP(G42,'Códigos Banco'!$F$3:$G$18,2,0) -> T23 Directa - Transferencias | I42: =VLOOKUP(E42,'Códigos Banco'!$B$3:$D$27,3,0) -> 230887267 | J42: 0 | K42: 0 | L42: 0 | M42: 0 | N42: 0 | O42: 0 | P42: 0 | Q42: 0 | R42: 0 | S42: 0 | T42: =J42+L42+N42+P42+R42 -> 0 | U42: =K42+M42+O42+Q42+S42 -> 0 | X42: =V42-T42 -> 0 | Y42: =W42-U42 -> 0
C43: =C42 -> 2026101 | E43: 23D | F43: =VLOOKUP(E43,'Códigos Banco'!$B$3:$D$27,2,0) -> Occidente - Directa | G43: 13 | H43: =VLOOKUP(G43,'Códigos Banco'!$F$3:$G$18,2,0) -> T23 Directa - Transferencias | I43: =VLOOKUP(E43,'Códigos Banco'!$B$3:$D$27,3,0) -> 230887267 | J43: 0 | K43: 0 | L43: 0 | M43: 0 | N43: 0 | O43: 0 | P43: 0 | Q43: 0 | R43: 0 | S43: 0 | T43: =J43+L43+N43+P43+R43 -> 0 | U43: =K43+M43+O43+Q43+S43 -> 0 | X43: =V43-T43 -> 0 | Y43: =W43-U43 -> 0
...

Sheet RESUMEN MES
B2: OPORTUNO | C2: ASE | D2: VALOR 1° Q | E2: NUMERO REG. 1°Q | F2: VALOR 2° Q | G2: NUMERO REG. 2°Q
C3: 1 | D3: =OPORTUNO!K1 -> 322739090 | E3: =OPORTUNO!J1 -> 1616 | F3: =OPORTUNO!K2 -> 186382057 | G3: =OPORTUNO!J2 -> 666
C4: 2 | D4: =OPORTUNO!M1 -> 839789795 | E4: =OPORTUNO!L1 -> 3964 | F4: =OPORTUNO!M2 -> 338362203 | G4: =OPORTUNO!L2 -> 1755
C5: 3 | D5: =OPORTUNO!O1 -> 417500887 | E5: =OPORTUNO!N1 -> 1376 | F5: =OPORTUNO!O2 -> 175516493 | G5: =OPORTUNO!N2 -> 620
C6: 4 | D6: =OPORTUNO!Q1 -> 481464262 | E6: =OPORTUNO!P1 -> 2591 | F6: =OPORTUNO!Q2 -> 193541612 | G6: =OPORTUNO!P2 -> 1098
C7: 5 | D7: =OPORTUNO!S1 -> 168793421 | E7: =OPORTUNO!R1 -> 1160 | F7: =OPORTUNO!S2 -> 80286396 | G7: =OPORTUNO!R2 -> 511
C8: X | D8: =OPORTUNO!Y1 -> 0 | E8: =OPORTUNO!X1 -> 0 | F8: =OPORTUNO!Y2 -> 0 | G8: =OPORTUNO!X2 -> 0
D9: =SUM(D3:D8) -> 2230287455 | E9: =SUM(E3:E8) -> 10707 | F9: =SUM(F3:F8) -> 974088761 | G9: =SUM(G3:G8) -> 4650
C11: ASE | D11: VALOR 1° Q | E11: NUMERO REG. 1°Q | F11: VALOR 2° Q | G11: NUMERO REG. 2°Q
B12: EXTEMP. | C12: 1 | D12: =EXTEMPORANEOS!K1 -> 48127653 | E12: =EXTEMPORANEOS!J1 -> 73 | F12: =EXTEMPORANEOS!K2 -> 21888196 | G12: =EXTEMPORANEOS!J2 -> 106
C13: 2 | D13: =EXTEMPORANEOS!M1 -> 132160935 | E13: =EXTEMPORANEOS!L1 -> 54 | F13: =EXTEMPORANEOS!M2 -> 49312788 | G13: =EXTEMPORANEOS!L2 -> 27
C14: 3 | D14: =EXTEMPORANEOS!O1 -> 19609348 | E14: =EXTEMPORANEOS!N1 -> 11 | F14: =EXTEMPORANEOS!O2 -> 1810000 | G14: =EXTEMPORANEOS!N2 -> 3
C15: 4 | D15: =EXTEMPORANEOS!Q1 -> 118198907 | E15: =EXTEMPORANEOS!P1 -> 9 | F15: =EXTEMPORANEOS!Q2 -> 560460 | G15: =EXTEMPORANEOS!P2 -> 10
C16: 5 | D16: =EXTEMPORANEOS!S1 -> 7112332 | E16: =EXTEMPORANEOS!R1 -> 27 | F16: =EXTEMPORANEOS!S2 -> 251760 | G16: =EXTEMPORANEOS!R2 -> 3
C17: X | D17: =EXTEMPORANEOS!Y1 -> 0 | E17: =EXTEMPORANEOS!X1 -> 0 | F17: =EXTEMPORANEOS!Y2 -> 0 | G17: =EXTEMPORANEOS!X2 -> 0
D18: =SUM(D12:D17) -> 325209175 | E18: =SUM(E12:E17) -> 174 | F18: =SUM(F12:F17) -> 73823204 | G18: =SUM(G12:G17) -> 149
C20: ASE | D20: VALOR 1° Q | E20: NUMERO REG. 1°Q | F20: VALOR 2° Q | G20: NUMERO REG. 2°Q | I20: VALOR TOTAL MES | J20: NUMERO REGISTROS MES
B21: TOTAL | C21: 1 | D21: =D3+D12 -> 370866743 | E21: =E3+E12 -> 1689 | F21: =F3+F12 -> 208270253 | G21: =G3+G12 -> 772 | I21: =D21+F21 -> 579136996 | J21: =E21+G21 -> 2461
C22: 2 | D22: =D4+D13 -> 971950730 | E22: =E4+E13 -> 4018 | F22: =F4+F13 -> 387674991 | G22: =G4+G13 -> 1782 | I22: =D22+F22 -> 1359625721 | J22: =E22+G22 -> 5800
C23: 3 | D23: =D5+D14 -> 437110235 | E23: =E5+E14 -> 1387 | F23: =F5+F14 -> 177326493 | G23: =G5+G14 -> 623 | I23: =D23+F23 -> 614436728 | J23: =E23+G23 -> 2010
C24: 4 | D24: =D6+D15 -> 599663169 | E24: =E6+E15 -> 2600 | F24: =F6+F15 -> 194102072 | G24: =G6+G15 -> 1108 | I24: =D24+F24 -> 793765241 | J24: =E24+G24 -> 3708
C25: 5 | D25: =D7+D16 -> 175905753 | E25: =E7+E16 -> 1187 | F25: =F7+F16 -> 80538156 | G25: =G7+G16 -> 514 | I25: =D25+F25 -> 256443909 | J25: =E25+G25 -> 1701
C26: X | D26: =D8+D17 -> 0 | E26: =E8+E17 -> 0 | F26: =F8+F17 -> 0 | G26: =G8+G17 -> 0 | I26: =D26+F26 -> 0 | J26: =E26+G26 -> 0
D27: =SUM(D21:D26) -> 2555496630 | E27: =SUM(E21:E26) -> 10881 | F27: =SUM(F21:F26) -> 1047911965 | G27: =SUM(G21:G26) -> 4799 | I27: =SUM(I21:I26) -> 3603408595 | J27: =SUM(J21:J26) -> 15680

Sheet Pendientes por Identificar
D1: TOTAL MES | E1: =E3+M3 -> 0 | F1: =F3+N3 -> 0
C3: QUINCENA | D3: =A5 -> 2026101 | E3: =SUM(E5:E104) -> 0 | F3: =COUNT(E5:E104) -> 0 | K3: QUINCENA | L3: =I5 -> 2026102 | M3: =SUM(M5:M105) -> 0 | N3: =COUNT(M5:M105) -> 0
A4: Código Remuneración | B4: Fecha de Recaudo | C4: CANAL RECAUDO | D4: Cuenta Contrato | E4: Valor | F4: Observación | I4: Código Remuneración | J4: Fecha de Recaudo | K4: CANAL RECAUDO | L4: Cuenta Contrato | M4: Valor | N4: Observación
A5: =OPORTUNO!C1 -> 2026101 | I5: =OPORTUNO!C2 -> 2026102
A6: =A5 -> 2026101 | I6: =I5 -> 2026102
A7: =A6 -> 2026101 | I7: =I6 -> 2026102
A8: =A7 -> 2026101 | I8: =I7 -> 2026102
A9: =A8 -> 2026101 | I9: =I8 -> 2026102
A10: =A9 -> 2026101 | I10: =I9 -> 2026102
A11: =A10 -> 2026101 | I11: =I10 -> 2026102
A12: =A11 -> 2026101 | I12: =I11 -> 2026102
A13: =A12 -> 2026101 | I13: =I12 -> 2026102
A14: =A13 -> 2026101 | I14: =I13 -> 2026102
A15: =A14 -> 2026101 | I15: =I14 -> 2026102
A16: =A15 -> 2026101 | I16: =I15 -> 2026102
A17: =A16 -> 2026101 | I17: =I16 -> 2026102
... A104: =A103 -> 2026101 | I104: =I103 -> 2026102

Sheet Reversiones
E3: 2.5.3. INFORMES DE RECAUDO | R3: 2.5.3. INFORMES DE RECAUDO
E4: R2 - INFORME DE CONCILIACION DE RECAUDOS | R4: R2 - INFORME DE CONCILIACION DE RECAUDOS
E5: CONCILIACION DIARIA DE RECAUDO REVERSIONES | R5: CONCILIACION DIARIA DE RECAUDO REVERSIONES
B8: QUINCENA | C8: ='Pendientes por Identificar'!D3 -> 2026101 | O8: QUINCENA | P8: ='Pendientes por Identificar'!L3 -> 2026102
E9: =SUM(E11:E1048576) -> 0 | F9: =SUM(F11:F1048576) -> 0 | G9: =SUM(G11:G1048576) -> 0 | H9: =SUM(H11:H1048576) -> 0 | I9: =SUM(I11:I1048576) -> 0 | J9: =SUM(J11:J1048576) -> 0 | R9: =SUM(R11:R1048576) -> 0 | S9: =SUM(S11:S1048576) -> 0 | T9: =SUM(T11:T1048576) -> 0 | U9: =SUM(U11:U1048576) -> 0 | V9: =SUM(V11:V1048576) -> 0 | W9: =SUM(W11:W1048576) -> 0
B10: Fecha de Reversion | C10: Fecha de Recaudo | D10: Entidad que reporto. | E10: ASE 1 Valor | F10: ASE 2 Valor | G10: ASE 3 Valor | H10: ASE 4 Valor | I10: ASE 5 Valor | J10: Valor Reversado | K10: Cuenta Contrato Reversada | L10: Cuenta Contrato Destino | O10: Fecha de Reversion | P10: Fecha de Recaudo | Q10: Entidad que reporto. | R10: ASE 1 Valor | S10: ASE 2 Valor | T10: ASE 3 Valor | U10: ASE 4 Valor | V10: ASE 5 Valor | W10: Valor Reversado | X10: Cuenta Contrato Reversada | Y10: Cuenta Contrato Destino
J11: =SUM(E11:I11) -> 0 | W11: =SUM(R11:V11) -> 0
J12: =SUM(E12:I12) -> 0 | W12: =SUM(R12:V12) -> 0
W13: =SUM(R13:V13) -> 0
J14: =SUM(E14:I14) -> 0 | W14: =SUM(R14:V14) -> 0
J15: =SUM(E15:I15) -> 0 | W15: =SUM(R15:V15) -> 0
J16: =SUM(E16:I16) -> 0 | W16: =SUM(R16:V16) -> 0
J17: =SUM(E17:I17) -> 0 | W17: =SUM(R17:V17) -> 0
J18: =SUM(E18:I18) -> 0 | W18: =SUM(R18:V18) -> 0
J19: =SUM(E19:I19) -> 0 | W19: =SUM(R19:V19) -> 0
J20: =SUM(E20:I20) -> 0 | W20: =SUM(R20:V20) -> 0
J21: =SUM(E21:I21) -> 0 | W21: =SUM(R21:V21) -> 0
J22: =SUM(E22:I22) -> 0 | W22: =SUM(R22:V22) -> 0
J23: =SUM(E23:I23) -> 0 | W23: =SUM(R23:V23) -> 0
J24: =SUM(E24:I24) -> 0 | W24: =SUM(R24:V24) -> 0
J25: =SUM(E25:I25) -> 0 | W25: =SUM(R25:V25) -> 0
... J51: =SUM(E51:I51) -> 0 | W51: =SUM(R51:V51) -> 0
J52: =SUM(E52:I52) -> 0
J53: =SUM(E53:I53) -> 0
J54: =SUM(E54:I54) -> 0
J55: =SUM(E55:I55) -> 0
J56: =SUM(E56:I56) -> 0
J57: =SUM(E57:I57) -> 0
J58: =SUM(E58:I58) -> 0
J59: =SUM(E59:I59) -> 0
J60: =SUM(E60:I60) -> 0
J61: =SUM(E61:I61) -> 0
J62: =SUM(E62:I62) -> 0
J63: =SUM(E63:I63) -> 0
... J74: =SUM(E74:I74) -> 0

Sheet Códigos Banco
B3: Código BC | C3: Nombre Banco | D3: Cuenta Bancaria | F3: Código CR | G3: Canal Recaudo
B4: 1 | C4: Bogotá | D4: 000344531 | F4: 1 | G4: Oficinas | I4: Recaudo directamente en las cajas de los bancos
B5: 2 | C5: Popular | D5: 110025169335 | F5: 2 | G5: Medios Electrónicos - ATH | I5: Cajeros electrónicos,
B6: 6 | C6: CorpBanca | F6: 3 | G6: Baloto | I6: Red de Baloto
B7: 9 | C7: Citibank | D7: 20935235 | F7: 4 | G7: Servibanca | I7: Cajeros electrónicos de Servibanca
B8: 12 | C8: Sudameris | D8: 100004720 | F8: 5 | G8: Cades | I8: Recaudo en los CADES
B9: 19 | C9: Colpatria | D9: 0121016133 | F9: 6 | G9: Cencosud | I9: Recaudo en Cencosud - Jumbo
B10: 23 | C10: Occidente | D10: 256957093 | F10: 7 | G10: Domiciliación - MPD | I10: Debitos automáticos de cuenta bientes - mis pagos al día
B11: 32 | C11: Caja Social | D11: 21003672665 | F11: 8 | G11: Multilinea | I11: recaudo por internet
B12: 51 | C12: Davivienda | D12: 481869999260 | F12: 9 | G12: Credivisa | I12: Recaudo con tarjeta de crédito en las cajas de la EAAB
B13: 52 | C13: Av Villas | D13: 059027227 | F13: 10 | G13: Redeban | I13: Medio electrónicos,
B14: 7 | C14: Bancolombia | F14: 11 | G14: Pse | I14: Página Web de la EAAB
B15: 13 | C15: BBVA | F15: 12 | G15: H23 Directa - CNB - Baloto - Éxito
B16: 14 | C16: Helm Bank - ITAÚ | F16: 13 | G16: T23 Directa - Transferencias
B17: 24 | C17: Efectivo | F17: 14 | G17: O23 Directa - Oficinas
B18: 40 | C18: Agrario
B19: 60 | C19: Pichincha
B20: 116 | C20: Ersco
B21: 130 | C21: Caja especial de recaudo
B22: 23D | C22: Occidente - Directa | D22: 230887267
B23: 200 | C23: Ciudad Limpia - Prestador | D23: N/A
B24: 201 | C24: EAAB - Prestador | D24: N/A

Sheet Conciliación
B2: =SUMAR.SI.CONJUNTO('[Directa 112019.xlsx]EXTEMPORANEOS'!$Q:$Q;'[Directa 112019.xlsx]EXTEMPORANEOS'!$C:$C;2019112;
B3: '[Directa 112019.xlsx]EXTEMPORANEOS'!$D:$D;C2;'[Directa 112019.xlsx]EXTEMPORANEOS'!$H:$H;IZQUIERDA(A2;3)&"*")

Sheet 1_Oportuno Directa Bco Occident
C1: =OPORTUNO!C1 -> 2026101 | J1: =J16+J20+J24+J28+J32+J36+J40+J44+J48+J52+J56+J60+J64+J68+J72 -> 1616 | K1: =K16+K20+K24+K28+K32+K36+K40+K44+K48+K52+K56+K60+K64+K68+K72 -> 322739090 | L1: =L16+L20+L24+L28+L32+L36+L40+L44+L48+L52+L56+L60+L64+L68+L72 -> 3964 | M1: =M16+M20+M24+M28+M32+M36+M40+M44+M48+M52+M56+M60+M64+M68+M72 -> 839789795 | N1: =N16+N20+N24+N28+N32+N36+N40+N44+N48+N52+N56+N60+N64+N68+N72 -> 1376 | O1: =O16+O20+O24+O28+O32+O36+O40+O44+O48+O52+O56+O60+O64+O68+O72 -> 417500887 | P1: =P16+P20+P24+P28+P32+P36+P40+P44+P48+P52+P56+P60+P64+P68+P72 -> 2591 | Q1: =Q16+Q20+Q24+Q28+Q32+Q36+Q40+Q44+Q48+Q52+Q56+Q60+Q64+Q68+Q72 -> 481464262 | ... Y1: =Y16+Y20+Y24+Y28+Y32+Y36+Y40+Y44+Y48+Y52+Y56+Y60+Y64+Y68+Y72 -> 0 | AC1: =C1=OPORTUNO!C1 -> TRUE | AD1: =D1=OPORTUNO!D1 -> TRUE | AE1: =E1=OPORTUNO!E1 -> TRUE | AF1: =F1=OPORTUNO!F1 -> TRUE | AG1: =G1=OPORTUNO!G1 -> TRUE | AH1: =H1=OPORTUNO!H1 -> TRUE | AI1: =I1=OPORTUNO!I1 -> TRUE | AJ1: =J1=OPORTUNO!J1 -> TRUE | ... AY1: =Y1=OPORTUNO!Y1 -> TRUE
C2: =OPORTUNO!C2 -> 2026102 | J2: =J76+J80+J84+J88+J92+J96+J100+J104+J108+J112+J116+J120+J124+J128+J132+J136 -> 666 | K2: =K76+K80+K84+K88+K92+K96+K100+K104+K108+K112+K116+K120+K124+K128+K132+K136 -> 186382057 | L2: =L76+L80+L84+L88+L92+L96+L100+L104+L108+L112+L116+L120+L124+L128+L132+L136 -> 1755 | M2: =M76+M80+M84+M88+M92+M96+M100+M104+M108+M112+M116+M120+M124+M128+M132+M136 -> 338362203 | N2: =N76+N80+N84+N88+N92+N96+N100+N104+N108+N112+N116+N120+N124+N128+N132+N136 -> 620 | O2: =O76+O80+O84+O88+O92+O96+O100+O104+O108+O112+O116+O120+O124+O128+O132+O136 -> 175516493 | P2: =P76+P80+P84+P88+P92+P96+P100+P104+P108+P112+P116+P120+P124+P128+P132+P136 -> 1098 | Q2: =Q76+Q80+Q84+Q88+Q92+Q96+Q100+Q104+Q108+Q112+Q116+Q120+Q124+Q128+Q132+Q136 -> 193541612 | ... Y2: =Y76+Y80+Y84+Y88+Y92+Y96+Y100+Y104+Y108+Y112+Y116+Y120+Y124+Y128+Y132+Y136 -> 0 | AC2: =C2=OPORTUNO!C2 -> TRUE | AD2: =D2=OPORTUNO!D2 -> TRUE | AE2: =E2=OPORTUNO!E2 -> TRUE | AF2: =F2=OPORTUNO!F2 -> TRUE | AG2: =G2=OPORTUNO!G2 -> TRUE | AH2: =H2=OPORTUNO!H2 -> TRUE | AI2: =I2=OPORTUNO!I2 -> TRUE | AJ2: =J2=OPORTUNO!J2 -> TRUE | ... AY2: =Y2=OPORTUNO!Y2 -> TRUE
C3: =OPORTUNO!C3 -> 202610 | J3: =SUM(J1:J2) -> 2282 | K3: =SUM(K1:K2) -> 509121147 | L3: =SUM(L1:L2) -> 5719 | M3: =SUM(M1:M2) -> 1178151998 | N3: =SUM(N1:N2) -> 1996 | O3: =SUM(O1:O2) -> 593017380 | P3: =SUM(P1:P2) -> 3689 | Q3: =SUM(Q1:Q2) -> 675005874 | ... Y3: =SUM(Y1:Y2) -> 0 | AC3: =C3=OPORTUNO!C3 -> TRUE | AD3: =D3=OPORTUNO!D3 -> TRUE | AE3: =E3=OPORTUNO!E3 -> TRUE | AF3: =F3=OPORTUNO!F3 -> TRUE | AG3: =G3=OPORTUNO!G3 -> TRUE | AH3: =H3=OPORTUNO!H3 -> TRUE | AI3: =I3=OPORTUNO!I3 -> TRUE | AJ3: =J3=OPORTUNO!J3 -> TRUE | ... AY3: =Y3=OPORTUNO!Y3 -> TRUE
H6: 2.5.3. INFORMES DE RECAUDO
H7: R2 - INFORME DE CONCILIACION DE RECAUDOS
H8: CONCILIACION DIARIA DE RECAUDO OPORTUNO DE DIRECTA
E9: NIT: 901 153 639 - 0
H10: =OPORTUNO!H10 -> OCTUBRE_2026 | K10: Recaudo Oportuno de DIRECTA en Banco de Occidente
B12: FECHA APLICACIÓN | C12: CODIGO REMUNERACIÓN | D12: FECHA RECAUDO | E12: CÓDIGO BC | F12: NOMBRE BANCO | G12: CÓDIGO CR | H12: CANAL RECAUDO | I12: N° CUENTA | J12: ASE 1 N° REGISTROS ARCHIVO | K12: ASE 1 VALOR ARCHIVO | L12: ASE 2 N° REGISTROS ARCHIVO | M12: ASE 2 VALOR ARCHIVO | N12: ASE 3 N° REGISTROS ARCHIVO | O12: ASE 3 VALOR ARCHIVO | P12: ASE 4 N° REGISTROS ARCHIVO | Q12: ASE 4 VALOR ARCHIVO | R12: ASE 5 N° REGISTROS ARCHIVO | S12: ASE 5 VALOR ARCHIVO | T12: TOTAL N° REGISTROS APLICADOS | U12: TOTAL VALOR APLICADO | V12: N° REGISTROS REPORTADOS POR BANCO | W12: VALOR REPORTADO POR BANCO | X12: DIFERENCIA REGISTROS | Y12: DIFERENCIA VALOR
B13: =OPORTUNO!B13 -> 46300 | C13: =OPORTUNO!C13 -> 2026101 | D13: =OPORTUNO!D13 -> 1 | E13: =OPORTUNO!E13 -> 23D | F13: =OPORTUNO!F13 -> Occidente - Directa | G13: =OPORTUNO!G13 -> 12 | H13: =OPORTUNO!H13 -> H23 Directa - CNB - Baloto - Éxito | I13: =OPORTUNO!I13 -> 230887267 | ... Y13: =OPORTUNO!Y13 -> 0
B14: =OPORTUNO!B14 -> 46300 | C14: =OPORTUNO!C14 -> 2026101 | D14: =OPORTUNO!D14 -> 1 | E14: =OPORTUNO!E14 -> 23D | F14: =OPORTUNO!F14 -> Occidente - Directa | G14: =OPORTUNO!G14 -> 13 | H14: =OPORTUNO!H14 -> T23 Directa - Transferencias | I14: =OPORTUNO!I14 -> 230887267 | ... Y14: =OPORTUNO!Y14 -> 0
B15: =OPORTUNO!B15 -> 46300 | C15: =OPORTUNO!C15 -> 2026101 | D15: =OPORTUNO!D15 -> 1 | E15: =OPORTUNO!E15 -> 23D | F15: =OPORTUNO!F15 -> Occidente - Directa | G15: =OPORTUNO!G15 -> 14 | H15: =OPORTUNO!H15 -> O23 Directa - Oficinas | I15: =OPORTUNO!I15 -> 230887267 | ... Y15: =OPORTUNO!Y15 -> 0
C16: =OPORTUNO!C16 -> 2026101 | F16: =OPORTUNO!F16 -> TOTAL | G16: =OPORTUNO!G16 -> 0 | H16: =OPORTUNO!H16 -> 0 | I16: =OPORTUNO!I16 -> 0 | J16: =OPORTUNO!J16 -> 70 | K16: =OPORTUNO!K16 -> 11848814 | L16: =OPORTUNO!L16 -> 229 | M16: =OPORTUNO!M16 -> 47753746 | ... Y16: =OPORTUNO!Y16 -> 0
B17: =OPORTUNO!B17 -> 46300 | C17: =OPORTUNO!C17 -> 2026101 | D17: =OPORTUNO!D17 -> 2 | E17: =OPORTUNO!E17 -> 23D | F17: =OPORTUNO!F17 -> Occidente - Directa | G17: =OPORTUNO!G17 -> 12 | H17: =OPORTUNO!H17 -> H23 Directa - CNB - Baloto - Éxito | I17: =OPORTUNO!I17 -> 230887267 | ... Y17: =OPORTUNO!Y17 -> 0
B18: =OPORTUNO!B18 -> 46300 | C18: =OPORTUNO!C18 -> 2026101 | D18: =OPORTUNO!D18 -> 2 | E18: =OPORTUNO!E18 -> 23D | F18: =OPORTUNO!F18 -> Occidente - Directa | G18: =OPORTUNO!G18 -> 13 | H18: =OPORTUNO!H18 -> T23 Directa - Transferencias | I18: =OPORTUNO!I18 -> 230887267 | ... Y18: =OPORTUNO!Y18 -> 0
B19: =OPORTUNO!B19 -> 46300 | C19: =OPORTUNO!C19 -> 2026101 | D19: =OPORTUNO!D19 -> 2 | E19: =OPORTUNO!E19 -> 23D | F19: =OPORTUNO!F19 -> Occidente - Directa | G19: =OPORTUNO!G19 -> 14 | H19: =OPORTUNO!H19 -> O23 Directa - Oficinas | I19: =OPORTUNO!I19 -> 230887267 | ... Y19: =OPORTUNO!Y19 -> 0
C20: =OPORTUNO!C20 -> 2026101 | F20: =OPORTUNO!F20 -> TOTAL | G20: =OPORTUNO!G20 -> 0 | H20: =OPORTUNO!H20 -> 0 | I20: =OPORTUNO!I20 -> 0 | J20: =OPORTUNO!J20 -> 56 | K20: =OPORTUNO!K20 -> 8778524 | L20: =OPORTUNO!L20 -> 206 | M20: =OPORTUNO!M20 -> 91217744 | ... Y20: =OPORTUNO!Y20 -> 0
B21: =OPORTUNO!B21 -> 46300 | C21: =OPORTUNO!C21 -> 2026101 | D21: =OPORTUNO!D21 -> 3 | E21: =OPORTUNO!E21 -> 23D | F21: =OPORTUNO!F21 -> Occidente - Directa | G21: =OPORTUNO!G21 -> 12 | H21: =OPORTUNO!H21 -> H23 Directa - CNB - Baloto - Éxito | I21: =OPORTUNO!I21 -> 230887267 | ... Y21: =OPORTUNO!Y21 -> 0
B22: =OPORTUNO!B22 -> 46300 | C22: =OPORTUNO!C22 -> 2026101 | D22: =OPORTUNO!D22 -> 3 | E22: =OPORTUNO!E22 -> 23D | F22: =OPORTUNO!F22 -> Occidente - Directa | G22: =OPORTUNO!G22 -> 13 | H22: =OPORTUNO!H22 -> T23 Directa - Transferencias | I22: =OPORTUNO!I22 -> 230887267 | ... Y22: =OPORTUNO!Y22 -> 0
B23: =OPORTUNO!B23 -> 46300 | C23: =OPORTUNO!C23 -> 2026101 | D23: =OPORTUNO!D23 -> 3 | E23: =OPORTUNO!E23 -> 23D | F23: =OPORTUNO!F23 -> Occidente - Directa | G23: =OPORTUNO!G23 -> 14 | H23: =OPORTUNO!H23 -> O23 Directa - Oficinas | I23: =OPORTUNO!I23 -> 230887267 | ... Y23: =OPORTUNO!Y23 -> 0
C24: =OPORTUNO!C24 -> 2026101 | F24: =OPORTUNO!F24 -> TOTAL | G24: =OPORTUNO!G24 -> 0 | H24: =OPORTUNO!H24 -> 0 | I24: =OPORTUNO!I24 -> 0 | J24: =OPORTUNO!J24 -> 2 | K24: =OPORTUNO!K24 -> 64240 | L24: =OPORTUNO!L24 -> 28 | M24: =OPORTUNO!M24 -> 3565580 | ... Y24: =OPORTUNO!Y24 -> 0
B25: =OPORTUNO!B25 -> 46300 | C25: =OPORTUNO!C25 -> 2026101 | D25: =OPORTUNO!D25 -> 4 | E25: =OPORTUNO!E25 -> 23D | F25: =OPORTUNO!F25 -> Occidente - Directa | G25: =OPORTUNO!G25 -> 12 | H25: =OPORTUNO!H25 -> H23 Directa - CNB - Baloto - Éxito | I25: =OPORTUNO!I25 -> 230887267 | ... Y25: =OPORTUNO!Y25 -> 0
B26: =OPORTUNO!B26 -> 46300 | C26: =OPORTUNO!C26 -> 2026101 | D26: =OPORTUNO!D26 -> 4 | E26: =OPORTUNO!E26 -> 23D | F26: =OPORTUNO!F26 -> Occidente - Directa | G26: =OPORTUNO!G26 -> 13 | H26: =OPORTUNO!H26 -> T23 Directa - Transferencias | I26: =OPORTUNO!I26 -> 230887267 | ... Y26: =OPORTUNO!Y26 -> 0
B27: =OPORTUNO!B27 -> 46300 | C27: =OPORTUNO!C27 -> 2026101 | D27: =OPORTUNO!D27 -> 4 | E27: =OPORTUNO!E27 -> 23D | F27: =OPORTUNO!F27 -> Occidente - Directa | G27: =OPORTUNO!G27 -> 14 | H27: =OPORTUNO!H27 -> O23 Directa - Oficinas | I27: =OPORTUNO!I27 -> 230887267 | ... Y27: =OPORTUNO!Y27 -> 0
C28: =OPORTUNO!C28 -> 2026101 | F28: =OPORTUNO!F28 -> TOTAL | G28: =OPORTUNO!G28 -> 0 | H28: =OPORTUNO!H28 -> 0 | I28: =OPORTUNO!I28 -> 0 | J28: =OPORTUNO!J28 -> 0 | K28: =OPORTUNO!K28 -> 0 | L28: =OPORTUNO!L28 -> 10 | M28: =OPORTUNO!M28 -> 1370460 | ... Y28: =OPORTUNO!Y28 -> 0
B29: =OPORTUNO!B29 -> 46301 | C29: =OPORTUNO!C29 -> 2026101 | D29: =OPORTUNO!D29 -> 5 | E29: =OPORTUNO!E29 -> 23D | F29: =OPORTUNO!F29 -> Occidente - Directa | G29: =OPORTUNO!G29 -> 12 | H29: =OPORTUNO!H29 -> H23 Directa - CNB - Baloto - Éxito | I29: =OPORTUNO!I29 -> 230887267 | ... Y29: =OPORTUNO!Y29 -> 0
B30: =OPORTUNO!B30 -> 46301 | C30: =OPORTUNO!C30 -> 2026101 | D30: =OPORTUNO!D30 -> 5 | E30: =OPORTUNO!E30 -> 23D | F30: =OPORTUNO!F30 -> Occidente - Directa | G30: =OPORTUNO!G30 -> 13 | H30: =OPORTUNO!H30 -> T23 Directa - Transferencias | I30: =OPORTUNO!I30 -> 230887267 | ... Y30: =OPORTUNO!Y30 -> 0
B31: =OPORTUNO!B31 -> 46301 | C31: =OPORTUNO!C31 -> 2026101 | D31: =OPORTUNO!D31 -> 5 | E31: =OPORTUNO!E31 -> 23D | F31: =OPORTUNO!F31 -> Occidente - Directa | G31: =OPORTUNO!G31 -> 14 | H31: =OPORTUNO!H31 -> O23 Directa - Oficinas | I31: =OPORTUNO!I31 -> 230887267 | ... Y31: =OPORTUNO!Y31 -> 0
C32: =OPORTUNO!C32 -> 2026101 | F32: =OPORTUNO!F32 -> TOTAL | G32: =OPORTUNO!G32 -> 0 | H32: =OPORTUNO!H32 -> 0 | I32: =OPORTUNO!I32 -> 0 | J32: =OPORTUNO!J32 -> 155 | K32: =OPORTUNO!K32 -> 29976934 | L32: =OPORTUNO!L32 -> 384 | M32: =OPORTUNO!M32 -> 55300510 | ... Y32: =OPORTUNO!Y32 -> 0
B33: =OPORTUNO!B33 -> 46302 | C33: =OPORTUNO!C33 -> 2026101 | D33: =OPORTUNO!D33 -> 6 | E33: =OPORTUNO!E33 -> 23D | F33: =OPORTUNO!F33 -> Occidente - Directa | G33: =OPORTUNO!G33 -> 12 | H33: =OPORTUNO!H33 -> H23 Directa - CNB - Baloto - Éxito | I33: =OPORTUNO!I33 -> 230887267 | ... Y33: =OPORTUNO!Y33 -> 0
B34: =OPORTUNO!B34 -> 46302 | C34: =OPORTUNO!C34 -> 2026101 | D34: =OPORTUNO!D34 -> 6 | E34: =OPORTUNO!E34 -> 23D | F34: =OPORTUNO!F34 -> Occidente - Directa | G34: =OPORTUNO!G34 -> 13 | H34: =OPORTUNO!H34 -> T23 Directa - Transferencias | I34: =OPORTUNO!I34 -> 230887267 | ... Y34: =OPORTUNO!Y34 -> 0
B35: =OPORTUNO!B35 -> 46302 | C35: =OPORTUNO!C35 -> 2026101 | D35: =OPORTUNO!D35 -> 6 | E35: =OPORTUNO!E35 -> 23D | F35: =OPORTUNO!F35 -> Occidente - Directa | G35: =OPORTUNO!G35 -> 14 | H35: =OPORTUNO!H35 -> O23 Directa - Oficinas | I35: =OPORTUNO!I35 -> 230887267 | ... Y35: =OPORTUNO!Y35 -> 0
C36: =OPORTUNO!C36 -> 2026101 | F36: =OPORTUNO!F36 -> TOTAL | G36: =OPORTUNO!G36 -> 0 | H36: =OPORTUNO!H36 -> 0 | I36: =OPORTUNO!I36 -> 0 | J36: =OPORTUNO!J36 -> 158 | K36: =OPORTUNO!K36 -> 28493928 | L36: =OPORTUNO!L36 -> 291 | M36: =OPORTUNO!M36 -> 73798996 | ... Y36: =OPORTUNO!Y36 -> 0
B37: =OPORTUNO!B37 -> 46303 | C37: =OPORTUNO!C37 -> 2026101 | D37: =OPORTUNO!D37 -> 7 | E37: =OPORTUNO!E37 -> 23D | F37: =OPORTUNO!F37 -> Occidente - Directa | G37: =OPORTUNO!G37 -> 12 | H37: =OPORTUNO!H37 -> H23 Directa - CNB - Baloto - Éxito | I37: =OPORTUNO!I37 -> 230887267 | ... Y37: =OPORTUNO!Y37 -> 0
B38: =OPORTUNO!B38 -> 46303 | C38: =OPORTUNO!C38 -> 2026101 | D38: =OPORTUNO!D38 -> 7 | E38: =OPORTUNO!E38 -> 23D | F38: =OPORTUNO!F38 -> Occidente - Directa | G38: =OPORTUNO!G38 -> 13 | H38: =OPORTUNO!H38 -> T23 Directa - Transferencias | I38: =OPORTUNO!I38 -> 230887267 | ... Y38: =OPORTUNO!Y38 -> 0
B39: =OPORTUNO!B39 -> 46303 | C39: =OPORTUNO!C39 -> 2026101 | D39: =OPORTUNO!D39 -> 7 | E39: =OPORTUNO!E39 -> 23D | F39: =OPORTUNO!F39 -> Occidente - Directa | G39: =OPORTUNO!G39 -> 14 | H39: =OPORTUNO!H39 -> O23 Directa - Oficinas | I39: =OPORTUNO!I39 -> 230887267 | ... Y39: =OPORTUNO!Y39 -> 0
C40: =OPORTUNO!C40 -> 2026101 | F40: =OPORTUNO!F40 -> TOTAL | G40: =OPORTUNO!G40 -> 0 | H40: =OPORTUNO!H40 -> 0 | I40: =OPORTUNO!I40 -> 0 | J40: =OPORTUNO!J40 -> 166 | K40: =OPORTUNO!K40 -> 40087183 | L40: =OPORTUNO!L40 -> 295 | M40: =OPORTUNO!M40 -> 43692432 | ... Y40: =OPORTUNO!Y40 -> 0
B41: =OPORTUNO!B41 -> 46304 | C41: =OPORTUNO!C41 -> 2026101 | D41: =OPORTUNO!D41 -> 8 | E41: =OPORTUNO!E41 -> 23D | F41: =OPORTUNO!F41 -> Occidente - Directa | G41: =OPORTUNO!G41 -> 12 | H41: =OPORTUNO!H41 -> H23 Directa - CNB - Baloto - Éxito | I41: =OPORTUNO!I41 -> 230887267 | ... Y41: =OPORTUNO!Y41 -> 0
B42: =OPORTUNO!B42 -> 46304 | C42: =OPORTUNO!C42 -> 2026101 | D42: =OPORTUNO!D42 -> 8 | E42: =OPORTUNO!E42 -> 23D | F42: =OPORTUNO!F42 -> Occidente - Directa | G42: =OPORTUNO!G42 -> 13 | H42: =OPORTUNO!H42 -> T23 Directa - Transferencias | I42: =OPORTUNO!I42 -> 230887267 | ... Y42: =OPORTUNO!Y42 -> 0
B43: =OPORTUNO!B43 -> 46304 | C43: =OPORTUNO!C43 -> 2026101 | D43: =OPORTUNO!D43 -> 8 | E43: =OPORTUNO!E43 -> 23D | F43: =OPORTUNO!F43 -> Occidente - Directa | G43: =OPORTUNO!G43 -> 14 | H43: =OPORTUNO!H43 -> O23 Directa - Oficinas | I43: =OPORTUNO!I43 -> 230887267 | ... Y43: =OPORTUNO!Y43 -> 0
...

Sheet 2_Extemporaneo Directa Bco Occi
C1: =EXTEMPORANEOS!C1 -> 2026101 | J1: =SUM(J13:J78) -> #REF! | K1: =SUM(K13:K78) -> #REF! | L1: =SUM(L13:L78) -> #REF! | M1: =SUM(M13:M78) -> #REF! | N1: =SUM(N13:N78) -> #REF! | O1: =SUM(O13:O78) -> #REF! | P1: =SUM(P13:P78) -> #REF! | Q1: =SUM(Q13:Q78) -> #REF! | ... Y1: =SUM(Y13:Y78) -> #REF! | AD1: =C1=EXTEMPORANEOS!C1 -> TRUE | AE1: =D1=EXTEMPORANEOS!D1 -> TRUE | AF1: =E1=EXTEMPORANEOS!E1 -> TRUE | AG1: =F1=EXTEMPORANEOS!F1 -> TRUE | AH1: =G1=EXTEMPORANEOS!G1 -> TRUE | AI1: =H1=EXTEMPORANEOS!H1 -> TRUE | AJ1: =I1=EXTEMPORANEOS!I1 -> TRUE | AK1: =J1=EXTEMPORANEOS!J1 -> #REF! | ... AZ1: =Y1=EXTEMPORANEOS!Y1 -> #REF!
C2: =EXTEMPORANEOS!C2 -> 2026102 | J2: =SUM(J83:J164) -> 106 | K2: =SUM(K83:K164) -> 21888196 | L2: =SUM(L83:L164) -> 27 | M2: =SUM(M83:M164) -> 49312788 | N2: =SUM(N83:N164) -> 3 | O2: =SUM(O83:O164) -> 1810000 | P2: =SUM(P83:P164) -> 10 | Q2: =SUM(Q83:Q164) -> 560460 | ... Y2: =SUM(Y83:Y164) -> 0 | AD2: =C2=EXTEMPORANEOS!C2 -> TRUE | AE2: =D2=EXTEMPORANEOS!D2 -> TRUE | AF2: =E2=EXTEMPORANEOS!E2 -> TRUE | AG2: =F2=EXTEMPORANEOS!F2 -> TRUE | AH2: =G2=EXTEMPORANEOS!G2 -> TRUE | AI2: =H2=EXTEMPORANEOS!H2 -> TRUE | AJ2: =I2=EXTEMPORANEOS!I2 -> TRUE | AK2: =J2=EXTEMPORANEOS!J2 -> TRUE | ... AZ2: =Y2=EXTEMPORANEOS!Y2 -> TRUE
C3: =EXTEMPORANEOS!C3 -> 202610 | J3: =SUM(J1:J2) -> #REF! | K3: =SUM(K1:K2) -> #REF! | L3: =SUM(L1:L2) -> #REF! | M3: =SUM(M1:M2) -> #REF! | N3: =SUM(N1:N2) -> #REF! | O3: =SUM(O1:O2) -> #REF! | P3: =SUM(P1:P2) -> #REF! | Q3: =SUM(Q1:Q2) -> #REF! | ... Y3: =SUM(Y1:Y2) -> #REF! | AD3: =C3=EXTEMPORANEOS!C3 -> TRUE | AE3: =D3=EXTEMPORANEOS!D3 -> TRUE | AF3: =E3=EXTEMPORANEOS!E3 -> TRUE | AG3: =F3=EXTEMPORANEOS!F3 -> TRUE | AH3: =G3=EXTEMPORANEOS!G3 -> TRUE | AI3: =H3=EXTEMPORANEOS!H3 -> TRUE | AJ3: =I3=EXTEMPORANEOS!I3 -> TRUE | AK3: =J3=EXTEMPORANEOS!J3 -> #REF! | ... AZ3: =Y3=EXTEMPORANEOS!Y3 -> #REF!
H6: 2.5.3. INFORMES DE RECAUDO
H7: R2 - INFORME DE CONCILIACION DE RECAUDOS
H8: CONCILIACION DIARIA DE RECAUDO EXTEMPORANEOS DE DIRECTA
E9: NIT: 901 153 639 - 0
H10: =EXTEMPORANEOS!H10 -> OCTUBRE_2026 | K10: Recaudo Extemporaneo de DIRECTA en Banco de Occidente
B12: FECHA APLICACIÓN | C12: CODIGO REMUNERACIÓN | D12: FECHA RECAUDO | E12: CÓDIGO BC | F12: NOMBRE BANCO | G12: CÓDIGO CR | H12: CANAL RECAUDO | I12: N° CUENTA | J12: ASE 1 N° REGISTROS ARCHIVO | K12: ASE 1 VALOR ARCHIVO | L12: ASE 2 N° REGISTROS ARCHIVO | M12: ASE 2 VALOR ARCHIVO | N12: ASE 3 N° REGISTROS ARCHIVO | O12: ASE 3 VALOR ARCHIVO | P12: ASE 4 N° REGISTROS ARCHIVO | Q12: ASE 4 VALOR ARCHIVO | R12: ASE 5 N° REGISTROS ARCHIVO | S12: ASE 5 VALOR ARCHIVO | T12: TOTAL N° REGISTROS APLICADOS | U12: TOTAL VALOR APLICADO | V12: N° REGISTROS REPORTADOS POR BANCO | W12: VALOR REPORTADO POR BANCO | X12: DIFERENCIA REGISTROS | Y12: DIFERENCIA VALOR
B13: =EXTEMPORANEOS!B13 -> 46300 | C13: =EXTEMPORANEOS!C13 -> 2026101 | D13: =EXTEMPORANEOS!D13 -> 46132 | E13: =EXTEMPORANEOS!E13 -> 23D | F13: =EXTEMPORANEOS!F13 -> Occidente - Directa | G13: =EXTEMPORANEOS!G13 -> 13 | H13: =EXTEMPORANEOS!H13 -> T23 Directa - Transferencias | I13: =EXTEMPORANEOS!I13 -> 230887267 | ... Y13: =EXTEMPORANEOS!Y13 -> 0
B14: =EXTEMPORANEOS!B14 -> 46300 | C14: =EXTEMPORANEOS!C14 -> 2026101 | D14: =EXTEMPORANEOS!D14 -> 46255 | E14: =EXTEMPORANEOS!E14 -> 23D | F14: =EXTEMPORANEOS!F14 -> Occidente - Directa | G14: =EXTEMPORANEOS!G14 -> 13 | H14: =EXTEMPORANEOS!H14 -> T23 Directa - Transferencias | I14: =EXTEMPORANEOS!I14 -> 230887267 | ... Y14: =EXTEMPORANEOS!Y14 -> 0
B15: =EXTEMPORANEOS!B15 -> 46300 | C15: =EXTEMPORANEOS!C15 -> 2026101 | D15: =EXTEMPORANEOS!D15 -> 46265 | E15: =EXTEMPORANEOS!E15 -> 23D | F15: =EXTEMPORANEOS!F15 -> Occidente - Directa | G15: =EXTEMPORANEOS!G15 -> 13 | H15: =EXTEMPORANEOS!H15 -> T23 Directa - Transferencias | I15: =EXTEMPORANEOS!I15 -> 230887267 | ... Y15: =EXTEMPORANEOS!Y15 -> 0
