Workbook
Name \0: #REF!
Name _1: #REF!
Name _2: #REF!
Name _A655555: #REF!
Name _CFR1: #REF!
Name _cia1: #REF!
Name _XL250: #REF!
Name A: #REF!
Name ADM: [1]!ADM
Name ADM: [1]!ADM
Name ADM: [1]!ADM
Name ADM: [1]!ADM
Name ADM: [1]!ADM
Name ADM_: [1]!ADM
Name ADM_: [1]!ADM
Name ADM_: [1]!ADM
Name ADM_: [1]!ADM
Name ADM_: [1]!ADM
Name AI: #REF!
Name Air: #REF!
Name AP: '[2]TARIFA no aforos'!$C$12
Name Bancos: [3]Fx!$C$1:$C$23
Name CBL: #REF!
Name CCS: #REF!
Name CDT_p: [4]CDT!$C$3
Name CFR: #REF!
Name cia: #REF!
Name COM: #REF!
Name CRT: #REF!
Name CRT___CTEp___CDTp___CMRv: #REF!
Name CRT_aislados: '[4]COSTOS AJUSTADOS'!$C$13
Name CRT_costas: #REF!
Name CTE_p: [4]CTE!$C$5
Name Denominador: #REF!
Name dg: [1]!ADM
Name dg: [1]!ADM
Name dg: [1]!ADM
Name dg: [1]!ADM
Name dg: [1]!ADM
Name DIAS: [5]CONTRA!#REF!
Name Fmerc: #REF!
Name FPS: #REF!
Name InformacionGeneral: [1]!InformacionGeneral
Name InformacionGeneral: [1]!InformacionGeneral
Name InformacionGeneral: [1]!InformacionGeneral
Name InformacionGeneral: [1]!InformacionGeneral
Name InformacionGeneral: [1]!InformacionGeneral
Name INTFIN: #REF!
Name INV: [1]!INV
Name INV: [1]!INV
Name INV: [1]!INV
Name INV: [1]!INV
Name INV: [1]!INV
Name K: #REF!
Name N: '[4]COSTOS AJUSTADOS'!#REF!
Name Na: '[2]TARIFA no aforos'!$C$39
Name nfc: '[4]COSTOS AJUSTADOS'!#REF!
Name OYM: [1]!OYM
Name OYM: [1]!OYM
Name OYM: [1]!OYM

Sheet Recaudo EAAB Reciprocidad
B2: OPORTUNO | C2: ASE | D2: VALOR 1° Q | E2: NUMERO REG. 1°Q | F2: VALOR 2° Q | G2: NUMERO REG. 2°Q
C3: 1 | D3: 0 | E3: 0 | F3: 0 | G3: 0
C4: 2 | D4: 29345550 | E4: 341 | F4: 0 | G4: 0
C5: 3 | D5: 0 | E5: 0 | F5: 0 | G5: 0
C6: 4 | D6: 15240310 | E6: 108 | F6: 0 | G6: 0
C7: 5 | D7: 0 | E7: 0 | F7: 0 | G7: 0
C8: X
D9: 44585860 | E9: 449 | F9: 0 | G9: 0
C11: ASE | D11: VALOR 1° Q | E11: NUMERO REG. 1°Q | F11: VALOR 2° Q | G11: NUMERO REG. 2°Q
B12: EXTEMP. | C12: 1 | D12: 0 | E12: 0 | F12: 0 | G12: 0
C13: 2 | D13: 0 | E13: 0 | F13: 0 | G13: 0
C14: 3 | D14: 0 | E14: 0 | F14: 0 | G14: 0
C15: 4 | D15: 0 | E15: 0 | F15: 0 | G15: 0
C16: 5 | D16: 0 | E16: 0 | F16: 0 | G16: 0
C17: X
D18: 0 | E18: 0 | F18: 0 | G18: 0
C20: ASE | D20: VALOR 1° Q | E20: NUMERO REG. 1°Q | F20: VALOR 2° Q | G20: NUMERO REG. 2°Q | I20: VALOR TOTAL MES | J20: NUMERO REGISTROS MES
B21: TOTAL | C21: 1 | D21: 0 | E21: 0 | F21: 0 | G21: 0 | I21: 0 | J21: 0
C22: 2 | D22: 29345550 | E22: 341 | F22: 0 | G22: 0 | I22: 29345550 | J22: 341
C23: 3 | D23: 0 | E23: 0 | F23: 0 | G23: 0 | I23: 0 | J23: 0
C24: 4 | D24: 15240310 | E24: 108 | F24: 0 | G24: 0 | I24: 15240310 | J24: 108
C25: 5 | D25: 0 | E25: 0 | F25: 0 | G25: 0 | I25: 0 | J25: 0
C26: X | I26: 0 | J26: 0
D27: 44585860 | E27: 449 | F27: 0 | G27: 0 | I27: 44585860 | J27: 449
B31: OPORTUNO | D31: =D9=SUM(D3:D8) -> TRUE | E31: =E9=SUM(E3:E8) -> TRUE | F31: =F9=SUM(F3:F8) -> TRUE | G31: =G9=SUM(G3:G8) -> TRUE
B33: EXTEMP. | D33: =D18=SUM(D12:D17) -> TRUE | E33: =E18=SUM(E12:E17) -> TRUE | F33: =F18=SUM(F12:F17) -> TRUE | G33: =G18=SUM(G12:G17) -> TRUE
B35: TOTAL | D35: =D27=SUM(D21:D26) -> TRUE | E35: =E27=SUM(E21:E26) -> TRUE | F35: =F27=SUM(F21:F26) -> TRUE | G35: =G27=SUM(G21:G26) -> TRUE | I35: =I27=SUM(I21:I26) -> TRUE | J35: =J27=SUM(J21:J26) -> TRUE
E69: =C69-G17 -> 0

Sheet Recaudo ENEL
B2: OPORTUNO | C2: ASE | D2: VALOR 1° Q | E2: NUMERO REG. 1°Q | F2: VALOR 2° Q | G2: NUMERO REG. 2°Q
C3: 1 | D3: 16020970408 | E3: 330319 | F3: 0 | G3: 0
C4: 2 | D4: 11733539858 | E4: 232298 | F4: 0 | G4: 0
C5: 3 | D5: 9618825681 | E5: 222340 | F5: 0 | G5: 0
C6: 4 | D6: 10290225466 | E6: 177955 | F6: 0 | G6: 0
C7: 5 | D7: 8111886280 | E7: 159077 | F7: 0 | G7: 0
C8: X
D9: 55775447693 | E9: 1121989 | F9: 0 | G9: 0
C11: ASE | D11: VALOR 1° Q | E11: NUMERO REG. 1°Q | F11: VALOR 2° Q | G11: NUMERO REG. 2°Q
B12: EXTEMP. | C12: 1 | D12: 223833110 | E12: 3064 | F12: 0 | G12: 0
C13: 2 | D13: 99273804 | E13: 1926 | F13: 0 | G13: 0
C14: 3 | D14: 66145670 | E14: 1462 | F14: 0 | G14: 0
C15: 4 | D15: 85892126 | E15: 1255 | F15: 0 | G15: 0
C16: 5 | D16: 166326259 | E16: 2744 | F16: 0 | G16: 0
C17: X
D18: 641470969 | E18: 10451 | F18: 0 | G18: 0
C20: ASE | D20: VALOR 1° Q | E20: NUMERO REG. 1°Q | F20: VALOR 2° Q | G20: NUMERO REG. 2°Q | I20: VALOR TOTAL MES | J20: NUMERO REGISTROS MES
B21: TOTAL | C21: 1 | D21: 16244803518 | E21: 333383 | F21: 0 | G21: 0 | I21: 16244803518 | J21: 333383
C22: 2 | D22: 11832813662 | E22: 234224 | F22: 0 | G22: 0 | I22: 11832813662 | J22: 234224
C23: 3 | D23: 9684971351 | E23: 223802 | F23: 0 | G23: 0 | I23: 9684971351 | J23: 223802
C24: 4 | D24: 10376117592 | E24: 179210 | F24: 0 | G24: 0 | I24: 10376117592 | J24: 179210
C25: 5 | D25: 8278212539 | E25: 161821 | F25: 0 | G25: 0 | I25: 8278212539 | J25: 161821
C26: X | I26: 0 | J26: 0
D27: 56416918662 | E27: 1132440 | F27: 0 | G27: 0 | I27: 56416918662 | J27: 1132440
B31: OPORTUNO | D31: =D9=SUM(D3:D8) -> TRUE | E31: =E9=SUM(E3:E8) -> TRUE | F31: =F9=SUM(F3:F8) -> TRUE | G31: =G9=SUM(G3:G8) -> TRUE
B33: EXTEMP. | D33: =D18=SUM(D12:D17) -> TRUE | E33: =E18=SUM(E12:E17) -> TRUE | F33: =F18=SUM(F12:F17) -> TRUE | G33: =G18=SUM(G12:G17) -> TRUE
B35: TOTAL | D35: =D27=SUM(D21:D26) -> TRUE | E35: =E27=SUM(E21:E26) -> TRUE | F35: =F27=SUM(F21:F26) -> TRUE | G35: =G27=SUM(G21:G26) -> TRUE | I35: =I27=SUM(I21:I26) -> TRUE | J35: =J27=SUM(J21:J26) -> TRUE
E69: =C69-G17 -> 0

Sheet Recaudo ENERBIT
B2: OPORTUNO | C2: ASE | D2: VALOR 1° Q | E2: NUMERO REG. 1°Q | F2: VALOR 2° Q | G2: NUMERO REG. 2°Q
C3: 1 | D3: 0 | E3: 0 | F3: 0 | G3: 0
C4: 2 | D4: 0 | E4: 0 | F4: 0 | G4: 0
C5: 3 | D5: 0 | E5: 0 | F5: 0 | G5: 0
C6: 4 | D6: 0 | E6: 0 | F6: 0 | G6: 0
C7: 5 | D7: 129429946 | E7: 2854 | F7: 0 | G7: 0
C8: X
D9: 129429946 | E9: 2854 | F9: 0 | G9: 0
C11: ASE | D11: VALOR 1° Q | E11: NUMERO REG. 1°Q | F11: VALOR 2° Q | G11: NUMERO REG. 2°Q
B12: EXTEMP. | C12: 1 | D12: 0 | E12: 0 | F12: 0 | G12: 0
C13: 2 | D13: 0 | E13: 0 | F13: 0 | G13: 0
C14: 3 | D14: 0 | E14: 0 | F14: 0 | G14: 0
C15: 4 | D15: 0 | E15: 0 | F15: 0 | G15: 0
C16: 5 | D16: 106710 | E16: 1 | F16: 0 | G16: 0
C17: X
D18: 106710 | E18: 1 | F18: 0 | G18: 0
C20: ASE | D20: VALOR 1° Q | E20: NUMERO REG. 1°Q | F20: VALOR 2° Q | G20: NUMERO REG. 2°Q | I20: VALOR TOTAL MES | J20: NUMERO REGISTROS MES
B21: TOTAL | C21: 1 | D21: 0 | E21: 0 | F21: 0 | G21: 0 | I21: 0 | J21: 0
C22: 2 | D22: 0 | E22: 0 | F22: 0 | G22: 0 | I22: 0 | J22: 0
C23: 3 | D23: 0 | E23: 0 | F23: 0 | G23: 0 | I23: 0 | J23: 0
C24: 4 | D24: 0 | E24: 0 | F24: 0 | G24: 0 | I24: 0 | J24: 0
C25: 5 | D25: 129536656 | E25: 2855 | F25: 0 | G25: 0 | I25: 129536656 | J25: 2855
C26: X | I26: 0 | J26: 0
D27: 129536656 | E27: 2855 | F27: 0 | G27: 0 | I27: 129536656 | J27: 2855
B31: OPORTUNO | D31: =D9=SUM(D3:D8) -> TRUE | E31: =E9=SUM(E3:E8) -> TRUE | F31: =F9=SUM(F3:F8) -> TRUE | G31: =G9=SUM(G3:G8) -> TRUE
B33: EXTEMP. | D33: =D18=SUM(D12:D17) -> TRUE | E33: =E18=SUM(E12:E17) -> TRUE | F33: =F18=SUM(F12:F17) -> TRUE | G33: =G18=SUM(G12:G17) -> TRUE
B35: TOTAL | D35: =D27=SUM(D21:D26) -> TRUE | E35: =E27=SUM(E21:E26) -> TRUE | F35: =F27=SUM(F21:F26) -> TRUE | G35: =G27=SUM(G21:G26) -> TRUE | I35: =I27=SUM(I21:I26) -> TRUE | J35: =J27=SUM(J21:J26) -> TRUE
E69: =C69-G17 -> 0

Sheet Recaudo EAAB + Ciud Limp
B2: Ciudad Limpia - Prestador | C2: ASE | D2: VALOR 1° Q | E2: NUMERO REG. 1°Q | F2: VALOR 2° Q | G2: NUMERO REG. 2°Q
C3: 1 | D3: 0 | E3: 0 | F3: 0 | G3: 0
C4: 2 | D4: 0 | E4: 0 | F4: 0 | G4: 0
C5: 3 | D5: 0 | E5: 0 | F5: 0 | G5: 0
C6: 4 | D6: 0 | E6: 0 | F6: 0 | G6: 0
C7: 5 | D7: 0 | E7: 0 | F7: 0 | G7: 0
C8: X
D9: 0 | E9: 0 | F9: 0 | G9: 0
C11: ASE | D11: VALOR 1° Q | E11: NUMERO REG. 1°Q | F11: VALOR 2° Q | G11: NUMERO REG. 2°Q
B12: EAAB - Prestador | C12: 1 | D12: 0 | E12: 0 | F12: 0 | G12: 0
C13: 2 | D13: 0 | E13: 0 | F13: 0 | G13: 0
C14: 3 | D14: 0 | E14: 0 | F14: 0 | G14: 0
C15: 4 | D15: 0 | E15: 0 | F15: 0 | G15: 0
C16: 5 | D16: 0 | E16: 0 | F16: 0 | G16: 0
C17: X
D18: 0 | E18: 0 | F18: 0 | G18: 0
C20: ASE | D20: VALOR 1° Q | E20: NUMERO REG. 1°Q | F20: VALOR 2° Q | G20: NUMERO REG. 2°Q | I20: VALOR TOTAL MES | J20: NUMERO REGISTROS MES
B21: TOTAL | C21: 1 | D21: 0 | E21: 0 | F21: 0 | G21: 0 | I21: 0 | J21: 0
C22: 2 | D22: 0 | E22: 0 | F22: 0 | G22: 0 | I22: 0 | J22: 0
C23: 3 | D23: 0 | E23: 0 | F23: 0 | G23: 0 | I23: 0 | J23: 0
C24: 4 | D24: 0 | E24: 0 | F24: 0 | G24: 0 | I24: 0 | J24: 0
C25: 5 | D25: 0 | E25: 0 | F25: 0 | G25: 0 | I25: 0 | J25: 0
C26: X | I26: 0 | J26: 0
D27: 0 | E27: 0 | F27: 0 | G27: 0 | I27: 0 | J27: 0
B31: OPORTUNO | D31: =D9=SUM(D3:D8) -> TRUE | E31: =E9=SUM(E3:E8) -> TRUE | F31: =F9=SUM(F3:F8) -> TRUE | G31: =G9=SUM(G3:G8) -> TRUE
B33: EXTEMP. | D33: =D18=SUM(D12:D17) -> TRUE | E33: =E18=SUM(E12:E17) -> TRUE | F33: =F18=SUM(F12:F17) -> TRUE | G33: =G18=SUM(G12:G17) -> TRUE
B35: TOTAL | D35: =D27=SUM(D21:D26) -> TRUE | E35: =E27=SUM(E21:E26) -> TRUE | F35: =F27=SUM(F21:F26) -> TRUE | G35: =G27=SUM(G21:G26) -> TRUE | I35: =I27=SUM(I21:I26) -> TRUE | J35: =J27=SUM(J21:J26) -> TRUE

Sheet Recaudo Directa Occidente
B2: OPORTUNO | C2: ASE | D2: VALOR 1° Q | E2: NUMERO REG. 1°Q | F2: VALOR 2° Q | G2: NUMERO REG. 2°Q
C3: 1 | D3: 335015748 | E3: 1590 | F3: 0 | G3: 0
C4: 2 | D4: 389025865 | E4: 2713 | F4: 0 | G4: 0
C5: 3 | D5: 346289622 | E5: 1123 | F5: 0 | G5: 0
C6: 4 | D6: 236541566 | E6: 1643 | F6: 0 | G6: 0
C7: 5 | D7: 155743651 | E7: 776 | F7: 0 | G7: 0
C8: X | D8: 0 | E8: 0 | F8: 0 | G8: 0
D9: 1462616452 | E9: 7845 | F9: 0 | G9: 0
C11: ASE | D11: VALOR 1° Q | E11: NUMERO REG. 1°Q | F11: VALOR 2° Q | G11: NUMERO REG. 2°Q
B12: EXTEMP. | C12: 1 | D12: 205459944 | E12: 70 | F12: 0 | G12: 0
C13: 2 | D13: 33195420 | E13: 58 | F13: 0 | G13: 0
C14: 3 | D14: 126229443 | E14: 55 | F14: 0 | G14: 0
C15: 4 | D15: 2600820 | E15: 21 | F15: 0 | G15: 0
C16: 5 | D16: 25989911 | E16: 18 | F16: 0 | G16: 0
C17: X | D17: 0 | E17: 0 | F17: 0 | G17: 0
D18: 393475538 | E18: 222 | F18: 0 | G18: 0
C20: ASE | D20: VALOR 1° Q | E20: NUMERO REG. 1°Q | F20: VALOR 2° Q | G20: NUMERO REG. 2°Q | I20: VALOR TOTAL MES | J20: NUMERO REGISTROS MES
B21: TOTAL | C21: 1 | D21: 540475692 | E21: 1660 | F21: 0 | G21: 0 | I21: 540475692 | J21: 1660
C22: 2 | D22: 422221285 | E22: 2771 | F22: 0 | G22: 0 | I22: 422221285 | J22: 2771
C23: 3 | D23: 472519065 | E23: 1178 | F23: 0 | G23: 0 | I23: 472519065 | J23: 1178
C24: 4 | D24: 239142386 | E24: 1664 | F24: 0 | G24: 0 | I24: 239142386 | J24: 1664
C25: 5 | D25: 181733562 | E25: 794 | F25: 0 | G25: 0 | I25: 181733562 | J25: 794
C26: X | D26: 0 | E26: 0 | F26: 0 | G26: 0 | I26: 0 | J26: 0
D27: 1856091990 | E27: 8067 | F27: 0 | G27: 0 | I27: 1856091990 | J27: 8067
B31: OPORTUNO | D31: =D9=SUM(D3:D8) -> TRUE | E31: =E9=SUM(E3:E8) -> TRUE | F31: =F9=SUM(F3:F8) -> TRUE | G31: =G9=SUM(G3:G8) -> TRUE
B33: EXTEMP. | D33: =D18=SUM(D12:D17) -> TRUE | E33: =E18=SUM(E12:E17) -> TRUE | F33: =F18=SUM(F12:F17) -> TRUE | G33: =G18=SUM(G12:G17) -> TRUE
B35: TOTAL | D35: =D27=SUM(D21:D26) -> TRUE | E35: =E27=SUM(E21:E26) -> TRUE | F35: =F27=SUM(F21:F26) -> TRUE | G35: =G27=SUM(G21:G26) -> TRUE | I35: =I27=SUM(I21:I26) -> TRUE | J35: =J27=SUM(J21:J26) -> TRUE
E69: =C69-G17 -> 0

Sheet REPORTE RECAUDO x BANCO
C1: ENEL | D1: CIUDAD LIMPIA | E1: EAB | F1: NUEVO ESQUEMA | G1: ENERBIT | H1: OCCIDENTE | I1: Total
B2: 1-APLICADOS A FACTURACION | C2: =C13+C23+C32+C41+C51 -> 56225936823 | D2: =D13+D23+D32+D41+D51 -> 0 | E2: =E13+E23+E32+E41+E51 -> 0 | F2: =F13+F23+F32+F41+F51 -> 20835040 | G2: =G13+G23+G32+G41+G51 -> 126372915 | H2: =H13+H23+H32+H41+H51 -> 1.7599753e+09 | I2: =SUM(C2:H2) -> 5.813312e+10
B3: 2-SALDOS A FAVOR GENERADOS | C3: =C14+C24+C33+C42+C52 -> 192969109 | D3: =D14+D24+D33+D42+D52 -> 0 | E3: =E14+E24+E33+E42+E52 -> 0 | F3: =F14+F24+F33+F42+F52 -> 23750820 | G3: =G14+G24+G33+G42+G52 -> 3163741 | H3: =H14+H24+H33+H42+H52 -> 61262183 | I3: =SUM(C3:H3) -> 2.8114585e+08
B4: 3-APLICADOS A FINANCIACIONES NUEVAS | C4: =C15+C25+C34+C43+C53 -> 0 | D4: =D15+D25+D34+D43+D53 -> 0 | E4: =E15+E25+E34+E43+E53 -> 0 | F4: =F15+F25+F34+F43+F53 -> 0 | G4: =G15+G25+G34+G43+G53 -> 0 | H4: =H15+H25+H34+H43+H53 -> 34854485 | I4: =SUM(C4:H4) -> 34854485
B5: 7-APLICADOS A RECIBOS SERVICIOS ESPECIALES | C5: =C16+C26+C35+C44+C54 -> 0 | D5: =D16+D26+D35+D44+D54 -> 0 | E5: =E16+E26+E35+E44+E54 -> 0 | F5: =F16+F26+F35+F44+F54 -> 0 | G5: =G16+G26+G35+G44+G54 -> 0 | H5: =H16+H26+H35+H44+H54 -> 0 | I5: =SUM(C5:H5) -> 0
B6: Total | C6: =SUM(C2:C5) -> 56418905932 | D6: =SUM(D2:D5) -> 0 | E6: =SUM(E2:E5) -> 0 | F6: =SUM(F2:F5) -> 44585860 | G6: =SUM(G2:G5) -> 129536656 | H6: =SUM(H2:H5) -> 1856091990 | I6: =SUM(I2:I5) -> 5.844912e+10
C7: =C6=(C17+C27+C36+C45+C55) -> TRUE | D7: =D6=(D17+D27+D36+D45+D55) -> TRUE | E7: =E6=(E17+E27+E36+E45+E55) -> TRUE | F7: =F6=(F17+F27+F36+F45+F55) -> TRUE | H7: =H6=(H17+H27+H36+H45+H55) -> TRUE | I7: =I6=(I17+I27+I36+I45+I55) -> TRUE
B10: ASE 1
B11: Resumen Recaudo Aplicado Por Servicio
C12: ENEL | D12: CIUDAD LIMPIA | E12: EAB | F12: NUEVO ESQUEMA | G12: ENERBIT | H12: OCCIDENTE | I12: Total
B13: 1-APLICADOS A FACTURACION | C13: 16194517449 | H13: 5.2378272e+08 | I13: =SUM(C13:H13) -> 1.67183e+10 | J13: =SUM(C13:H13)=I13 -> TRUE
B14: 2-SALDOS A FAVOR GENERADOS | C14: 50286069 | H14: 12466967 | I14: =SUM(C14:H14) -> 62753036 | J14: =SUM(C14:H14)=I14 -> TRUE
B15: 3-APLICADOS A FINANCIACIONES NUEVAS | C15: 0 | H15: 4226000 | I15: =SUM(C15:H15) -> 4226000 | J15: =SUM(C15:H15)=I15 -> TRUE
B16: 7-APLICADOS A RECIBOS SERVICIOS ESPECIALES | C16: 0 | I16: =SUM(C16:H16) -> 0 | J16: =SUM(C16:H16)=I16 -> TRUE
B17: Total | C17: =SUM(C13:C16) -> 16244803518 | D17: =SUM(D13:D16) -> 0 | E17: =SUM(E13:E16) -> 0 | F17: =SUM(F13:F16) -> 0 | G17: =SUM(G13:G16) -> 0 | H17: =SUM(H13:H16) -> 540475692 | I17: =SUM(I13:I16) -> 16785279210 | J17: =SUM(C17:H17)=I17 -> TRUE
B20: ASE 2
B21: Resumen Recaudo Aplicado Por Servicio
C22: ENEL | D22: CIUDAD LIMPIA | E22: EAB | F22: NUEVO ESQUEMA | G22: ENERBIT | H22: OCCIDENTE | I22: Total
B23: 1-APLICADOS A FACTURACION | C23: 11785775189 | E23: 0 | F23: 13570060 | H23: 390172374 | I23: =SUM(C23:H23) -> 12189517623 | J23: =SUM(C23:H23)=I23 -> TRUE
B24: 2-SALDOS A FAVOR GENERADOS | C24: 47435723 | E24: 0 | F24: 15775490 | H24: 32048911 | I24: =SUM(C24:H24) -> 95260124 | J24: =SUM(C24:H24)=I24 -> TRUE
B25: 3-APLICADOS A FINANCIACIONES NUEVAS | C25: 0 | E25: 0 | F25: 0 | H25: 0 | I25: =SUM(C25:H25) -> 0 | J25: =SUM(C25:H25)=I25 -> TRUE
B26: 7-APLICADOS A RECIBOS SERVICIOS ESPECIALES | F26: 0 | H26: 0 | I26: =SUM(C26:H26) -> 0 | J26: =SUM(C26:H26)=I26 -> TRUE
B27: Total | C27: =SUM(C23:C26) -> 11833210912 | D27: =SUM(D23:D26) -> 0 | E27: =SUM(E23:E26) -> 0 | F27: =SUM(F23:F26) -> 29345550 | G27: =SUM(G23:G26) -> 0 | H27: =SUM(H23:H26) -> 422221285 | I27: =SUM(I23:I26) -> 12284777747 | J27: =SUM(C27:H27)=I27 -> TRUE
B29: ASE 3
B30: Resumen Recaudo Aplicado Por Servicio
C31: ENEL | D31: CIUDAD LIMPIA | E31: EAB | F31: NUEVO ESQUEMA | G31: ENERBIT | H31: OCCIDENTE | I31: Total
B32: 1-APLICADOS A FACTURACION | C32: 9664176949 | F32: 0 | H32: 4.6662827e+08 | I32: =SUM(C32:H32) -> 1.0130805e+10 | J32: =SUM(C32:H32)=I32 -> TRUE
B33: 2-SALDOS A FAVOR GENERADOS | C33: 21042512 | F33: 0 | H33: 2387269 | I33: =SUM(C33:H33) -> 23429781 | J33: =SUM(C33:H33)=I33 -> TRUE
B34: 3-APLICADOS A FINANCIACIONES NUEVAS | C34: 0 | F34: 0 | H34: 3503528.1 | I34: =SUM(C34:H34) -> 3503528.1 | J34: =SUM(C34:H34)=I34 -> TRUE
B35: 7-APLICADOS A RECIBOS SERVICIOS ESPECIALES | C35: 0 | F35: 0 | I35: =SUM(C35:H35) -> 0 | J35: =SUM(C35:H35)=I35 -> TRUE
B36: Total | C36: =SUM(C32:C35) -> 9685219461 | D36: =SUM(D32:D35) -> 0 | E36: =SUM(E32:E35) -> 0 | F36: =SUM(F32:F35) -> 0 | G36: =SUM(G32:G35) -> 0 | H36: =SUM(H32:H35) -> 472519065 | I36: =SUM(I32:I35) -> 10157738526 | J36: =SUM(C36:H36)=I36 -> TRUE
B38: ASE 4
B39: Resumen Recaudo Aplicado Por Servicio
C40: ENEL | D40: CIUDAD LIMPIA | E40: EAB | F40: NUEVO ESQUEMA | G40: ENERBIT | H40: OCCIDENTE | I40: Total
B41: 1-APLICADOS A FACTURACION | C41: 10340898687 | E41: 0 | F41: 7264980 | H41: 2.0075764e+08 | I41: =SUM(C41:H41) -> 1.0548921e+10 | J41: =SUM(C41:H41)=I41 -> TRUE
B42: 2-SALDOS A FAVOR GENERADOS | C42: 35795695 | E42: 0 | F42: 7975330 | H42: 11928036 | I42: =SUM(C42:H42) -> 55699061 | J42: =SUM(C42:H42)=I42 -> TRUE
B43: 3-APLICADOS A FINANCIACIONES NUEVAS | C43: 0 | E43: 0 | F43: 0 | H43: 26456711 | I43: =SUM(C43:H43) -> 26456711 | J43: =SUM(C43:H43)=I43 -> TRUE
B44: 7-APLICADOS A RECIBOS SERVICIOS ESPECIALES | I44: =SUM(C44:H44) -> 0 | J44: =SUM(C44:H44)=I44 -> TRUE
B45: Total | C45: =SUM(C41:C44) -> 10376694382 | D45: =SUM(D41:D44) -> 0 | E45: =SUM(E41:E44) -> 0 | F45: =SUM(F41:F44) -> 15240310 | G45: =SUM(G41:G44) -> 0 | H45: =SUM(H41:H44) -> 239142386 | I45: =SUM(I41:I44) -> 10631077078 | J45: =SUM(C45:H45)=I45 -> TRUE
B48: ASE 5
...

Sheet ANT EXT-REV
C1: ASE 1 | E1: ASE 2 | G1: ASE 3 | I1: ASE 4 | K1: ASE 5 | M1: TOTAL
C2: REPORTE 3 | D2: REPORTE 4 | E2: REPORTE 3 | F2: REPORTE 4 | G2: REPORTE 3 | H2: REPORTE 4 | I2: REPORTE 3 | J2: REPORTE 4 | K2: REPORTE 3 | L2: REPORTE 4 | M2: REPORTE 3 | N2: REPORTE 4
B3: APLICADO | C3: =C11+C19+C27+C35+C43 -> 11673020 | D3: =D11+D19+D27+D35+D43 -> -12054256 | E3: =E11+E19+E27+E35+E43 -> 0 | F3: =F11+F19+F27+F35+F43 -> -9889189.7 | G3: =G11+G19+G27+G35+G43 -> 10198723 | H3: =H11+H19+H27+H35+H43 -> -16103443 | I3: =I11+I19+I27+I35+I43 -> 5419780 | J3: =J11+J19+J27+J35+J43 -> -21288909 | ... L3: =L11+L19+L27+L35+L43 -> -6421274.7 | M3: =C3+E3+G3+I3+K3 -> 27291523 | N3: =D3+F3+H3+J3+L3 -> -65757072 | P3: =N3=(-VALIDACION_TOTAL!M9) -> TRUE
B4: ANTICIPOS | C4: =C12+C20+C28+C36+C44 -> 1944280 | D4: =D12+D20+D28+D36+D44 -> -8965804.3 | E4: =E12+E20+E28+E36+E44 -> 0 | F4: =F12+F20+F28+F36+F44 -> -649106.28 | G4: =G12+G20+G28+G36+G44 -> 426786.93 | H4: =H12+H20+H28+H36+H44 -> -10201649 | I4: =I12+I20+I28+I36+I44 -> 12360680 | J4: =J12+J20+J28+J36+J44 -> -489671.43 | ... L4: =L12+L20+L28+L36+L44 -> -750593.32 | M4: =C4+E4+G4+I4+K4 -> 15046237 | N4: =D4+F4+H4+J4+L4 -> -21056824 | P4: =N4=(-'CONSOLIDADO_TOTAL RECAUDO'!L131) -> TRUE
B5: TOTAL | C5: =SUM(C3:C4) -> 13617300 | D5: =SUM(D3:D4) -> -21020060 | E5: =SUM(E3:E4) -> 0 | F5: =SUM(F3:F4) -> -10538296 | G5: =SUM(G3:G4) -> 10625510 | H5: =SUM(H3:H4) -> -26305092 | I5: =SUM(I3:I4) -> 17780460 | J5: =SUM(J3:J4) -> -21778580 | ... N5: =SUM(N3:N4) -> -86813896
C6: =C5=(C13+C21+C29+C37+C45) -> TRUE | D6: =D5=(D13+D21+D29+D37+D45) -> TRUE | E6: =E5=(E13+E21+E29+E37+E45) -> TRUE | F6: =F5=(F13+F21+F29+F37+F45) -> TRUE | G6: =G5=(G13+G21+G29+G37+G45) -> TRUE | H6: =H5=(H13+H21+H29+H37+H45) -> TRUE | I6: =I5=(I13+I21+I29+I37+I45) -> TRUE | J6: =J5=(J13+J21+J29+J37+J45) -> TRUE | ... N6: =N5=(N13+N21+N29+N37+N45) -> TRUE
B8: BANCO DE OCCIDENTE
C9: ASE 1 | E9: ASE 2 | G9: ASE 3 | I9: ASE 4 | K9: ASE 5 | M9: TOTAL
C10: REPORTE 3 | D10: REPORTE 4 | E10: REPORTE 3 | F10: REPORTE 4 | G10: REPORTE 3 | H10: REPORTE 4 | I10: REPORTE 3 | J10: REPORTE 4 | K10: REPORTE 3 | L10: REPORTE 4 | M10: REPORTE 3 | N10: REPORTE 4
B11: APLICADO | C11: 11673020 | D11: -12054256 | E11: 0 | F11: 0 | G11: 10198723 | H11: -10531482 | I11: 1855630 | J11: -4856352 | K11: 0 | L11: -950286.68 | M11: =C11+E11+G11+I11+K11 -> 23727373 | N11: =D11+F11+H11+J11+L11 -> -28392376
B12: ANTICIPOS | C12: 1944280 | D12: -8965804.3 | E12: 0 | F12: 0 | G12: 426786.93 | H12: -10145808 | I12: 2723150 | J12: -245148.04 | K12: 314490 | L12: -750593.32 | M12: =C12+E12+G12+I12+K12 -> 5408706.9 | N12: =D12+F12+H12+J12+L12 -> -20107354
B13: TOTAL | C13: =SUM(C11:C12) -> 13617300 | D13: =SUM(D11:D12) -> -21020060 | E13: =SUM(E11:E12) -> 0 | F13: =SUM(F11:F12) -> 0 | G13: =SUM(G11:G12) -> 10625510 | H13: =SUM(H11:H12) -> -20677290 | I13: =SUM(I11:I12) -> 4578780 | J13: =SUM(J11:J12) -> -5101500 | ... N13: =SUM(N11:N12) -> -48499730
B16: EAAB RECIPROCIDAD
C17: ASE 1 | E17: ASE 2 | G17: ASE 3 | I17: ASE 4 | K17: ASE 5 | M17: TOTAL
C18: REPORTE 3 | D18: REPORTE 4 | E18: REPORTE 3 | F18: REPORTE 4 | G18: REPORTE 3 | H18: REPORTE 4 | I18: REPORTE 3 | J18: REPORTE 4 | K18: REPORTE 3 | L18: REPORTE 4 | M18: REPORTE 3 | N18: REPORTE 4
B19: APLICADO | C19: 0 | D19: 0 | E19: 0 | F19: -19778.72 | G19: 0 | H19: 0 | I19: 0 | J19: -464370 | K19: 0 | L19: 0 | M19: =C19+E19+G19+I19+K19 -> 0 | N19: =D19+F19+H19+J19+L19 -> -484148.72
B20: ANTICIPOS | C20: 0 | D20: 0 | E20: 0 | F20: -600714.28 | G20: 0 | H20: 0 | I20: 464370 | J20: 0 | K20: 0 | L20: 0 | M20: =C20+E20+G20+I20+K20 -> 464370 | N20: =D20+F20+H20+J20+L20 -> -600714.28
B21: TOTAL | C21: =SUM(C19:C20) -> 0 | D21: =SUM(D19:D20) -> 0 | E21: =SUM(E19:E20) -> 0 | F21: =SUM(F19:F20) -> -620493 | G21: =SUM(G19:G20) -> 0 | H21: =SUM(H19:H20) -> 0 | I21: =SUM(I19:I20) -> 464370 | J21: =SUM(J19:J20) -> -464370 | ... L21: =SUM(L19:L20) -> 0 | M21: =C21+E21+G21+I21+K21 -> 464370 | N21: =SUM(N19:N20) -> -1084863
B24: EAAB CIUDAD LIMPIA
C25: ASE 1 | E25: ASE 2 | G25: ASE 3 | I25: ASE 4 | K25: ASE 5 | M25: TOTAL
C26: REPORTE 3 | D26: REPORTE 4 | E26: REPORTE 3 | F26: REPORTE 4 | G26: REPORTE 3 | H26: REPORTE 4 | I26: REPORTE 3 | J26: REPORTE 4 | K26: REPORTE 3 | L26: REPORTE 4 | M26: REPORTE 3 | N26: REPORTE 4
B27: APLICADO | C27: 0 | D27: 0 | E27: 0 | F27: 0 | G27: 0 | H27: 0 | I27: 0 | J27: 0 | K27: 0 | L27: 0 | M27: =C27+E27+G27+I27+K27 -> 0 | N27: =D27+F27+H27+J27+L27 -> 0
B28: ANTICIPOS | C28: 0 | D28: 0 | E28: 0 | F28: 0 | G28: 0 | H28: 0 | I28: 0 | J28: 0 | K28: 0 | L28: 0 | M28: =C28+E28+G28+I28+K28 -> 0 | N28: =D28+F28+H28+J28+L28 -> 0
B29: TOTAL | C29: =SUM(C27:C28) -> 0 | D29: =SUM(D27:D28) -> 0 | E29: =SUM(E27:E28) -> 0 | F29: =SUM(F27:F28) -> 0 | G29: =SUM(G27:G28) -> 0 | H29: =SUM(H27:H28) -> 0 | I29: =SUM(I27:I28) -> 0 | J29: =SUM(J27:J28) -> 0 | ... N29: =SUM(N27:N28) -> 0
B32: ENEL
C33: ASE 1 | E33: ASE 2 | G33: ASE 3 | I33: ASE 4 | K33: ASE 5 | M33: TOTAL
C34: REPORTE 3 | D34: REPORTE 4 | E34: REPORTE 3 | F34: REPORTE 4 | G34: REPORTE 3 | H34: REPORTE 4 | I34: REPORTE 3 | J34: REPORTE 4 | K34: REPORTE 3 | L34: REPORTE 4 | M34: REPORTE 3 | N34: REPORTE 4
B35: APLICADO | C35: 0 | D35: 0 | E35: 0 | F35: -9869411 | G35: 0 | H35: -5571961 | I35: 3564150 | J35: -15968187 | K35: 0 | L35: -5470988 | M35: =C35+E35+G35+I35+K35 -> 3564150 | N35: =D35+F35+H35+J35+L35 -> -36880547
B36: ANTICIPOS | C36: 0 | D36: 0 | E36: 0 | F36: -48392 | G36: 0 | H36: -55841 | I36: 9173160 | J36: -244523.39 | K36: 0 | L36: 0 | M36: =C36+E36+G36+I36+K36 -> 9173160 | N36: =D36+F36+H36+J36+L36 -> -348756.39
B37: TOTAL | C37: =SUM(C35:C36) -> 0 | D37: =SUM(D35:D36) -> 0 | E37: =SUM(E35:E36) -> 0 | F37: =SUM(F35:F36) -> -9917803 | G37: =SUM(G35:G36) -> 0 | H37: =SUM(H35:H36) -> -5627802 | I37: =SUM(I35:I36) -> 12737310 | J37: =SUM(J35:J36) -> -16212710 | ... N37: =SUM(N35:N36) -> -37229303
B40: ENERBIT
C41: ASE 1 | E41: ASE 2 | G41: ASE 3 | I41: ASE 4 | K41: ASE 5 | M41: TOTAL
C42: REPORTE 3 | D42: REPORTE 4 | E42: REPORTE 3 | F42: REPORTE 4 | G42: REPORTE 3 | H42: REPORTE 4 | I42: REPORTE 3 | J42: REPORTE 4 | K42: REPORTE 3 | L42: REPORTE 4 | M42: REPORTE 3 | N42: REPORTE 4
B43: APLICADO | C43: 0 | D43: 0 | E43: 0 | F43: 0 | G43: 0 | H43: 0 | I43: 0 | J43: 0 | K43: 0 | L43: 0 | M43: =C43+E43+G43+I43+K43 -> 0 | N43: =D43+F43+H43+J43+L43 -> 0
B44: ANTICIPOS | C44: 0 | D44: 0 | E44: 0 | F44: 0 | G44: 0 | H44: 0 | I44: 0 | J44: 0 | K44: 0 | L44: 0 | M44: =C44+E44+G44+I44+K44 -> 0 | N44: =D44+F44+H44+J44+L44 -> 0
B45: TOTAL | C45: =SUM(C43:C44) -> 0 | D45: =SUM(D43:D44) -> 0 | E45: =SUM(E43:E44) -> 0 | F45: =SUM(F43:F44) -> 0 | G45: =SUM(G43:G44) -> 0 | H45: =SUM(H43:H44) -> 0 | I45: =SUM(I43:I44) -> 0 | J45: =SUM(J43:J44) -> 0 | ... N45: =SUM(N43:N44) -> 0

Sheet ANTICIPOS USUARIOS
B1: TOTAL | E1: RECIPROCIDAD | H1: ENEL | K1: ENERBIT | N1: OCCIDENTE | Q1: EAAB-CIUDADLIMPIA
B2: ASE | C2: ANTICIPOS GENERADOS POR PAGO | E2: ASE | F2: ANTICIPOS GENERADOS POR PAGO | H2: ASE | I2: ANTICIPOS GENERADOS POR PAGO | K2: ASE | L2: ANTICIPOS GENERADOS POR PAGO | N2: ASE | O2: ANTICIPOS GENERADOS POR PAGO | Q2: ASE | R2: ANTICIPOS GENERADOS POR PAGO | T2: Anticipos generados por pago
B3: 1 | C3: ='REPORTE RECAUDO x BANCO'!I14 -> 62753036 | E3: 1 | F3: ='REPORTE RECAUDO x BANCO'!F14 -> 0 | H3: 1 | I3: ='REPORTE RECAUDO x BANCO'!C14 -> 50286069 | K3: 1 | L3: ='REPORTE RECAUDO x BANCO'!G14 -> 0 | N3: 1 | O3: ='REPORTE RECAUDO x BANCO'!H14 -> 12466967 | Q3: 1 | R3: ='REPORTE RECAUDO x BANCO'!D14+'REPORTE RECAUDO x BANCO'!E14 -> 0 | T3: Sale del reporte Recaudo por Bancos.
B4: 2 | C4: ='REPORTE RECAUDO x BANCO'!I24 -> 95260124 | E4: 2 | F4: ='REPORTE RECAUDO x BANCO'!F24 -> 15775490 | H4: 2 | I4: ='REPORTE RECAUDO x BANCO'!C24 -> 47435723 | K4: 2 | L4: ='REPORTE RECAUDO x BANCO'!G24 -> 0 | N4: 2 | O4: ='REPORTE RECAUDO x BANCO'!H24 -> 32048911 | Q4: 2 | R4: ='REPORTE RECAUDO x BANCO'!D24+'REPORTE RECAUDO x BANCO'!E24 -> 0
B5: 3 | C5: ='REPORTE RECAUDO x BANCO'!I33 -> 23429781 | E5: 3 | F5: ='REPORTE RECAUDO x BANCO'!F33 -> 0 | H5: 3 | I5: ='REPORTE RECAUDO x BANCO'!C33 -> 21042512 | K5: 3 | L5: ='REPORTE RECAUDO x BANCO'!G33 -> 0 | N5: 3 | O5: ='REPORTE RECAUDO x BANCO'!H33 -> 2387269 | Q5: 3 | R5: ='REPORTE RECAUDO x BANCO'!D33+'REPORTE RECAUDO x BANCO'!E33 -> 0
B6: 4 | C6: ='REPORTE RECAUDO x BANCO'!I42 -> 55699061 | E6: 4 | F6: ='REPORTE RECAUDO x BANCO'!F42 -> 7975330 | H6: 4 | I6: ='REPORTE RECAUDO x BANCO'!C42 -> 35795695 | K6: 4 | L6: ='REPORTE RECAUDO x BANCO'!G42 -> 0 | N6: 4 | O6: ='REPORTE RECAUDO x BANCO'!H42 -> 11928036 | Q6: 4 | R6: ='REPORTE RECAUDO x BANCO'!D42+'REPORTE RECAUDO x BANCO'!E42 -> 0
B7: 5 | C7: ='REPORTE RECAUDO x BANCO'!I52 -> 44003851 | E7: 5 | F7: ='REPORTE RECAUDO x BANCO'!F52 -> 0 | H7: 5 | I7: ='REPORTE RECAUDO x BANCO'!C52 -> 38409110 | K7: 5 | L7: ='REPORTE RECAUDO x BANCO'!G52 -> 3163741 | N7: 5 | O7: ='REPORTE RECAUDO x BANCO'!H52 -> 2431000 | Q7: 5 | R7: ='REPORTE RECAUDO x BANCO'!D52+'REPORTE RECAUDO x BANCO'!E52 -> 0
C8: =SUM(C3:C7) -> 2.8114585e+08 | F8: =SUM(F3:F7) -> 23750820 | I8: =SUM(I3:I7) -> 192969109 | L8: =SUM(L3:L7) -> 3163741 | O8: =SUM(O3:O7) -> 61262183 | R8: =SUM(R3:R7) -> 0
C9: =C8='REPORTE RECAUDO x BANCO'!I3 -> TRUE | F9: =F8='REPORTE RECAUDO x BANCO'!F3 -> TRUE | I9: =I8='REPORTE RECAUDO x BANCO'!C3 -> TRUE | L9: =L8='REPORTE RECAUDO x BANCO'!G3 -> TRUE | O9: =O8='REPORTE RECAUDO x BANCO'!H3 -> TRUE | R9: =R8='REPORTE RECAUDO x BANCO'!D3+'REPORTE RECAUDO x BANCO'!E3 -> TRUE
B11: ASE | C11: ANTICIPOS GENERADOS POR EXTEMPORANEOS | E11: ASE | F11: ANTICIPOS GENERADOS POR EXTEMPORANEOS | H11: ASE | I11: ANTICIPOS GENERADOS POR EXTEMPORANEOS | K11: ASE | L11: ANTICIPOS GENERADOS POR EXTEMPORANEOS | N11: ASE | O11: ANTICIPOS GENERADOS POR EXTEMPORANEOS | Q11: ASE | R11: ANTICIPOS GENERADOS POR EXTEMPORANEOS | T11: Anticipos generados por pagos aplicados de reversiones
B12: 1 | C12: ='ANT EXT-REV'!C4 -> 1944280 | E12: 1 | F12: ='ANT EXT-REV'!C20 -> 0 | H12: 1 | I12: ='ANT EXT-REV'!C36 -> 0 | K12: 1 | L12: ='ANT EXT-REV'!A12 -> 0 | N12: 1 | O12: ='ANT EXT-REV'!C12 -> 1944280 | Q12: 1 | R12: ='ANT EXT-REV'!C28 -> 0 | T12: Sale del reporte Recaudo reversado
B13: 2 | C13: ='ANT EXT-REV'!E4 -> 0 | E13: 2 | F13: ='ANT EXT-REV'!E20 -> 0 | H13: 2 | I13: ='ANT EXT-REV'!E36 -> 0 | K13: 2 | L13: ='ANT EXT-REV'!E44 -> 0 | N13: 2 | O13: ='ANT EXT-REV'!E12 -> 0 | Q13: 2 | R13: ='ANT EXT-REV'!E28 -> 0
B14: 3 | C14: ='ANT EXT-REV'!G4 -> 426786.93 | E14: 3 | F14: ='ANT EXT-REV'!G20 -> 0 | H14: 3 | I14: ='ANT EXT-REV'!G36 -> 0 | K14: 3 | L14: ='ANT EXT-REV'!G44 -> 0 | N14: 3 | O14: ='ANT EXT-REV'!G12 -> 426786.93 | Q14: 3 | R14: ='ANT EXT-REV'!G28 -> 0
B15: 4 | C15: ='ANT EXT-REV'!I4 -> 12360680 | E15: 4 | F15: ='ANT EXT-REV'!I20 -> 464370 | H15: 4 | I15: ='ANT EXT-REV'!I36 -> 9173160 | K15: 4 | L15: ='ANT EXT-REV'!I44 -> 0 | N15: 4 | O15: ='ANT EXT-REV'!I12 -> 2723150 | Q15: 4 | R15: ='ANT EXT-REV'!I28 -> 0
B16: 5 | C16: ='ANT EXT-REV'!K4 -> 314490 | E16: 5 | F16: ='ANT EXT-REV'!K20 -> 0 | H16: 5 | I16: ='ANT EXT-REV'!K36 -> 0 | K16: 5 | L16: ='ANT EXT-REV'!K44 -> 0 | N16: 5 | O16: ='ANT EXT-REV'!K12 -> 314490 | Q16: 5 | R16: ='ANT EXT-REV'!K28 -> 0
C17: =SUM(C12:C16) -> 15046237 | F17: =SUM(F12:F16) -> 464370 | I17: =SUM(I12:I16) -> 9173160 | L17: =SUM(L12:L16) -> 0 | O17: =SUM(O12:O16) -> 5408706.9 | R17: =SUM(R12:R16) -> 0
C18: =C17='ANT EXT-REV'!M4 -> TRUE | F18: =F17='ANT EXT-REV'!M20 -> TRUE | I18: =I17='ANT EXT-REV'!M36 -> TRUE | L18: =L17='ANT EXT-REV'!M44 -> TRUE | O18: =O17='ANT EXT-REV'!M12 -> TRUE | R18: =R17='ANT EXT-REV'!M28 -> TRUE
B20: ASE | C20: ANTICIPOS QUE CARGAN POR REVERSIONES | E20: ASE | F20: ANTICIPOS QUE CARGAN POR REVERSIONES | H20: ASE | I20: ANTICIPOS QUE CARGAN POR REVERSIONES | K20: ASE | L20: ANTICIPOS QUE CARGAN POR REVERSIONES | N20: ASE | O20: ANTICIPOS QUE CARGAN POR REVERSIONES | Q20: ASE | R20: ANTICIPOS QUE CARGAN POR REVERSIONES | T20: Anticipos que cargan de reversiones
B21: 1 | C21: ='ANT EXT-REV'!D4 -> -8965804.3 | E21: 1 | F21: ='ANT EXT-REV'!D20 -> 0 | H21: 1 | I21: ='ANT EXT-REV'!D36 -> 0 | K21: 1 | L21: ='ANT EXT-REV'!D44 -> 0 | N21: 1 | O21: ='ANT EXT-REV'!D12 -> -8965804.3 | Q21: 1 | R21: ='ANT EXT-REV'!D28 -> 0 | T21: Sale del reporte Recaudo reversado
B22: 2 | C22: ='ANT EXT-REV'!F4 -> -649106.28 | E22: 2 | F22: ='ANT EXT-REV'!F20 -> -600714.28 | H22: 2 | I22: ='ANT EXT-REV'!F36 -> -48392 | K22: 2 | L22: ='ANT EXT-REV'!F44 -> 0 | N22: 2 | O22: ='ANT EXT-REV'!F12 -> 0 | Q22: 2 | R22: ='ANT EXT-REV'!F28 -> 0
B23: 3 | C23: ='ANT EXT-REV'!H4 -> -10201649 | E23: 3 | F23: ='ANT EXT-REV'!H20 -> 0 | H23: 3 | I23: ='ANT EXT-REV'!H36 -> -55841 | K23: 3 | L23: ='ANT EXT-REV'!H44 -> 0 | N23: 3 | O23: ='ANT EXT-REV'!H12 -> -10145808 | Q23: 3 | R23: ='ANT EXT-REV'!H28 -> 0
B24: 4 | C24: ='ANT EXT-REV'!J4 -> -489671.43 | E24: 4 | F24: ='ANT EXT-REV'!J20 -> 0 | H24: 4 | I24: ='ANT EXT-REV'!J36 -> -244523.39 | K24: 4 | L24: ='ANT EXT-REV'!J44 -> 0 | N24: 4 | O24: ='ANT EXT-REV'!J12 -> -245148.04 | Q24: 4 | R24: ='ANT EXT-REV'!J28 -> 0
B25: 5 | C25: ='ANT EXT-REV'!L4 -> -750593.32 | E25: 5 | F25: ='ANT EXT-REV'!L20 -> 0 | H25: 5 | I25: ='ANT EXT-REV'!L36 -> 0 | K25: 5 | L25: ='ANT EXT-REV'!L44 -> 0 | N25: 5 | O25: ='ANT EXT-REV'!L12 -> -750593.32 | Q25: 5 | R25: ='ANT EXT-REV'!L28 -> 0
C26: =SUM(C21:C25) -> -21056824 | F26: =SUM(F21:F25) -> -600714.28 | I26: =SUM(I21:I25) -> -348756.39 | L26: =SUM(L21:L25) -> 0 | O26: =SUM(O21:O25) -> -20107354 | R26: =SUM(R21:R25) -> 0
C27: =C26='ANT EXT-REV'!N4 -> TRUE | F27: =F26='ANT EXT-REV'!N20 -> TRUE | I27: =I26='ANT EXT-REV'!N36 -> TRUE | L27: =L26='ANT EXT-REV'!N44 -> TRUE | O27: =O26='ANT EXT-REV'!N12 -> TRUE | R27: =R26='ANT EXT-REV'!N28 -> TRUE

Sheet BCE SC POR FACT.
C2: ASE | D2: CONTRIBUCION | E2: SUBSIDIO | F2: TOTAL BSC | H2: SISTEMA
C3: 1 | D3: 3.2562352e+09 | E3: -1.2238715e+09 | F3: =D3+E3 -> 2.0323637e+09 | H3: =DetRetri2026071!J9 -> 2032363679 | I3: =F3-H3 -> -0.16000032
C4: 2 | D4: 1.9464918e+09 | E4: -6.9580075e+09 | F4: =D4+E4 -> -5.0115157e+09 | H4: =DetRetri2026071!J10 -> -5011515654 | I4: =F4-H4 -> 0.4100008
C5: 3 | D5: 1.9361099e+09 | E5: -3.1329323e+09 | F5: =D5+E5 -> -1.1968224e+09 | H5: =DetRetri2026071!J11 -> -1196822411 | I5: =F5-H5 -> -0.31000018
C6: 4 | D6: 4.741562e+08 | E6: -4.3820038e+08 | F6: =D6+E6 -> 35955816 | H6: =DetRetri2026071!J12 -> 35955816 | I6: =F6-H6 -> 0.039999962
C7: 5 | D7: 1.2667695e+09 | E7: -2.4771952e+09 | F7: =D7+E7 -> -1.2104256e+09 | H7: =DetRetri2026071!J13 -> -1210425628 | I7: =F7-H7 -> -0.31000018
F9: =SUM(F3:F7) -> -5.3504442e+09 | H9: =SUM(H3:H7) -> -5350444198 | I9: =F9-H9 -> -0.32999992
H10: =H9=DetRetri2026071!J14 -> TRUE
D11: =SUM(D3:D7) -> 8.8797626e+09 | E11: =SUM(E3:E7) -> -1.4230207e+10 | F11: =SUM(D3:E7) -> -5.3504442e+09
F12: =ROUND(F11,2)=ROUND(F9,2) -> TRUE
F13: =ROUND(F11,2)-ROUND(F9,2) -> 0
D18: ASE | E18: REMUN TOTAL | F18: VALIDA 1 | G18: VALIDA 2 | H18: DIFERENCIA VALIDA 2
D19: 1 | E19: ='CONSOLIDADO_TOTAL RECAUDO'!J104 -> 2.0323637e+09 | F19: =E19=F3 -> TRUE | G19: =E19=H3 -> FALSE | H19: =E19-H3 -> -0.16000032
D20: 2 | E20: ='CONSOLIDADO_TOTAL RECAUDO'!J105 -> -5.0115157e+09 | F20: =E20=F4 -> TRUE | G20: =E20=H4 -> FALSE | H20: =E20-H4 -> 0.4100008
D21: 3 | E21: ='CONSOLIDADO_TOTAL RECAUDO'!J106 -> -1.1968224e+09 | F21: =E21=F5 -> TRUE | G21: =E21=H5 -> FALSE | H21: =E21-H5 -> -0.31000018
D22: 4 | E22: ='CONSOLIDADO_TOTAL RECAUDO'!J107 -> 35955816 | F22: =E22=F6 -> TRUE | G22: =E22=H6 -> FALSE | H22: =E22-H6 -> 0.039999962
D23: 5 | E23: ='CONSOLIDADO_TOTAL RECAUDO'!J108 -> -1.2104256e+09 | F23: =E23=F7 -> TRUE | G23: =E23=H7 -> FALSE | H23: =E23-H7 -> -0.31000018
E24: =SUM(E19:E23) -> -5.3504442e+09 | F24: =E24=F9 -> TRUE | G24: =E24=H9 -> FALSE | H24: =E24-H9 -> -0.32999992

Sheet Reporte Componentes R1
B4: PROMOAMBIENTAL
F5: Total | G5: Componente TDF | H5: Componente TTL | I5: Componente TVIAT | J5: Aprovechamiento | K5: CCSA Prest.Aprov. | L5: SERVICIO ESPECIALES | M5: Componente TCS | N5: Componente TLU | O5: Componente TBL | P5: Componente TRT | Q5: CCSA Prest. No Aprov. | R5: Ajuste Decena | S5: Ajuste Recargo Aseo | T5: Intereses Cte Financiac. Aseo | U5: Exonera-Ajuste Decena Aseo | V5: Exonera-Ajuste Decena Aseo | W5: Exonera-Recargo Aseo | X5: Rec.Intereses | Y5: Intereses Cte Financiac. Aseo | Z5: Rec.Intereses
E6: Vlr Servicio | F6: 6311519.1 | G6: 1237789 | H6: 698932.72 | I6: 368148.99 | J6: 164076.41 | K6: 5902 | L6: 0 | M6: 51771.85 | N6: 67502.58 | O6: 315251.82 | P6: 3392526.7 | Q6: 9629.46 | R6: -12.4 | S6: 0 | T6: 0 | U6: 0 | V6: 0 | W6: 0 | X6: 0 | Y6: 0 | Z6: 0
E7: Vlr Intereses | F7: 19996.26 | G7: 4031.92 | H7: 2277.16 | I7: 1198.72 | J7: 279.31 | K7: 16.58 | L7: 0 | M7: 145.13 | N7: 172.52 | O7: 800.55 | P7: 11047.38 | Q7: 26.98 | R7: 0.01 | S7: 0 | T7: 0 | U7: 0 | V7: 0 | W7: 0 | X7: 0 | Y7: 0 | Z7: 0
D8: T | E8: Total | F8: 6331515.4 | G8: 1241820.9 | H8: 701209.88 | I8: 369347.71 | J8: 164355.72 | K8: 5918.58 | L8: 0 | M8: 51916.98 | N8: 67675.1 | O8: 316052.37 | P8: 3403574.1 | Q8: 9656.44 | R8: -12.39 | S8: 0 | T8: 0 | U8: 0 | V8: 0 | W8: 0 | X8: 0 | Y8: 0 | Z8: 0
C9: OCCIDENTE | D9: Total | F9: 6331515.4 | G9: 1241820.9 | H9: 701209.88 | I9: 369347.71 | J9: 164355.72 | K9: 5918.58 | L9: 0 | M9: 51916.98 | N9: 67675.1 | O9: 316052.37 | P9: 3403574.1 | Q9: 9656.44 | R9: -12.39 | S9: 0 | T9: 0 | U9: 0 | V9: 0 | W9: 0 | X9: 0 | Y9: 0 | Z9: 0
B10: Aplicacion nuevos x reversion | C10: Total | F10: 6331515.4 | G10: 1241820.9 | H10: 701209.88 | I10: 369347.71 | J10: 164355.72 | K10: 5918.58 | L10: 0 | M10: 51916.98 | N10: 67675.1 | O10: 316052.37 | P10: 3403574.1 | Q10: 9656.44 | R10: -12.39 | S10: 0 | T10: 0 | U10: 0 | V10: 0 | W10: 0 | X10: 0 | Y10: 0 | Z10: 0
E11: Vlr Servicio | F11: 1.9101452e+10 | G11: 9.1336903e+08 | H11: 5.1531429e+08 | I11: 2.705651e+08 | J11: 4.8346181e+09 | K11: 1.6775998e+08 | L11: 14321632 | M11: 1.4724397e+09 | N11: 1.4224992e+09 | O11: 6.7317027e+09 | P11: 2.4851645e+09 | Q11: 2.7373194e+08 | R11: -33913.97 | S11: 0 | T11: 0 | U11: 0 | V11: 0 | W11: 0 | X11: 0 | Y11: 0 | Z11: 0
E12: Vlr Intereses | F12: 2792245.8 | G12: 155660.99 | H12: 79689.82 | I12: 41740.83 | J12: 633473.57 | K12: 26506.79 | L12: 312.58 | M12: 234143.87 | N12: 212449.63 | O12: 946855.03 | P12: 417682.52 | Q12: 43448.47 | R12: 2.45 | S12: -0.01 | T12: 279.23 | U12: 0 | V12: 0 | W12: 0 | X12: 0 | Y12: 0 | Z12: 0
D13: E | E13: Total | F13: 1.9104245e+10 | G13: 9.1352469e+08 | H13: 5.1539398e+08 | I13: 2.7060684e+08 | J13: 4.8352516e+09 | K13: 1.6778649e+08 | L13: 14321945 | M13: 1.4726738e+09 | N13: 1422711691 | O13: 6.7326496e+09 | P13: 2.4855822e+09 | Q13: 2.7377539e+08 | R13: -33911.52 | S13: -0.01 | T13: 279.23 | U13: 0 | V13: 0 | W13: 0 | X13: 0 | Y13: 0 | Z13: 0
C14: ENEL | D14: Total | F14: 1.9104245e+10 | G14: 9.1352469e+08 | H14: 5.1539398e+08 | I14: 2.7060684e+08 | J14: 4.8352516e+09 | K14: 1.6778649e+08 | L14: 14321945 | M14: 1.4726738e+09 | N14: 1422711691 | O14: 6.7326496e+09 | P14: 2.4855822e+09 | Q14: 2.7377539e+08 | R14: -33911.52 | S14: -0.01 | T14: 279.23 | U14: 0 | V14: 0 | W14: 0 | X14: 0 | Y14: 0 | Z14: 0
E15: Vlr Servicio | F15: 28587198 | G15: 2185895.5 | H15: 1219113.6 | I15: 644213.84 | J15: 5793883.4 | K15: 177172.65 | L15: 0 | M15: 1538870.8 | N15: 1889153.4 | O15: 8885237.5 | P15: 5963781.7 | Q15: 289690.76 | R15: 184.57 | S15: 0 | T15: 0 | U15: 0 | V15: 0 | W15: 0 | X15: 0 | Y15: 0 | Z15: 0
E16: Vlr Intereses | F16: 82135.18 | G16: 4908.79 | H16: 2288.07 | I16: 1256.9 | J16: 18570 | K16: 653.25 | L16: 0 | M16: 5731.29 | N16: 6136.85 | O16: 28338.84 | P16: 13182.06 | Q16: 1068.81 | R16: 0.36 | S16: -0.04 | T16: 0 | U16: 0 | V16: 0 | W16: 0 | X16: 0 | Y16: 0 | Z16: 0
D17: H | E17: Total | F17: 28669333 | G17: 2190804.3 | H17: 1221401.6 | I17: 645470.74 | J17: 5812453.4 | K17: 177825.9 | L17: 0 | M17: 1544602.1 | N17: 1895290.3 | O17: 8913576.4 | P17: 5976963.7 | Q17: 290759.57 | R17: 184.93 | S17: -0.04 | T17: 0 | U17: 0 | V17: 0 | W17: 0 | X17: 0 | Y17: 0 | Z17: 0
E18: Vlr Servicio | F18: 47294938 | G18: 3974790.2 | H18: 2180819.5 | I18: 1154125.1 | J18: 8019548.8 | K18: 328408.33 | L18: 0 | M18: 2889896.9 | N18: 3056486.5 | O18: 14327777 | P18: 10827506 | Q18: 535821.41 | R18: -241.11 | S18: 0 | T18: 0 | U18: 0 | V18: 0 | W18: 0 | X18: 0 | Y18: 0 | Z18: 0
E19: Vlr Intereses | F19: 4126283.3 | G19: 86954.59 | H19: 33264.93 | I19: 11195.04 | J19: 965832.37 | K19: 60914.74 | L19: 0 | M19: 534335.02 | N19: 449770.44 | O19: 1653345.4 | P19: 231094.93 | Q19: 99387.59 | R19: 188.15 | S19: 0 | T19: 0.08 | U19: 0 | V19: 0 | W19: 0 | X19: 0 | Y19: 0 | Z19: 0
D20: O | E20: Total | F20: 51421222 | G20: 4061744.8 | H20: 2214084.4 | I20: 1165320.1 | J20: 8985381.2 | K20: 389323.07 | L20: 0 | M20: 3424231.9 | N20: 3506257 | O20: 15981122 | P20: 11058601 | Q20: 635209 | R20: -52.96 | S20: 0 | T20: 0.08 | U20: 0 | V20: 0 | W20: 0 | X20: 0 | Y20: 0 | Z20: 0
E21: Vlr Servicio | F21: 3.6429799e+08 | G21: 65257819 | H21: 34884827 | I21: 18959565 | J21: 20111069 | K21: 558599.01 | L21: 3865005 | M21: 4887941.6 | N21: 6309959 | O21: 29570698 | P21: 1.7898112e+08 | Q21: 911394.98 | R21: -1.52 | S21: 0 | T21: 0 | U21: 0 | V21: 0 | W21: 0 | X21: 0 | Y21: 0 | Z21: 0
E22: Vlr Intereses | F22: 1153870.1 | G22: 222671.28 | H22: 115190.8 | I22: 63892.82 | J22: 40091.93 | K22: 1378.05 | L22: 6789.53 | M22: 12094.95 | N22: 13714.71 | O22: 63652.17 | P22: 612144.4 | Q22: 2249.01 | R22: 0.47 | S22: -0.01 | T22: 0.02 | U22: 0 | V22: 0 | W22: 0 | X22: 0 | Y22: 0 | Z22: 0
D23: T | E23: Total | F23: 3.6545186e+08 | G23: 65480490 | H23: 35000017 | I23: 19023458 | J23: 20151160 | K23: 559977.06 | L23: 3871794.5 | M23: 4900036.5 | N23: 6323673.7 | O23: 29634350 | P23: 1.7959326e+08 | Q23: 913643.99 | R23: -1.05 | S23: -0.01 | T23: 0.02 | U23: 0 | V23: 0 | W23: 0 | X23: 0 | Y23: 0 | Z23: 0
C24: OCCIDENTE | D24: Total | F24: 4.4554242e+08 | G24: 71733039 | H24: 38435503 | I24: 20834248 | J24: 34948995 | K24: 1127126 | L24: 3871794.5 | M24: 9868870.5 | N24: 11725221 | O24: 54529049 | P24: 1.9662883e+08 | Q24: 1839612.6 | R24: 130.92 | S24: -0.05 | T24: 0.1 | U24: 0 | V24: 0 | W24: 0 | X24: 0 | Y24: 0 | Z24: 0
B25: Mes | C25: Total | F25: 1.9549787e+10 | G25: 9.8525773e+08 | H25: 5.5382948e+08 | I25: 2.9144109e+08 | J25: 4.8702006e+09 | K25: 1.6891361e+08 | L25: 18193739 | M25: 1.4825427e+09 | N25: 1.4344369e+09 | O25: 6.7871786e+09 | P25: 2.682211e+09 | Q25: 2.7561501e+08 | R25: -33780.6 | S25: -0.06 | T25: 279.33 | U25: 0 | V25: 0 | W25: 0 | X25: 0 | Y25: 0 | Z25: 0
A26: Componente | B26: Total | F26: 1.9556118e+10 | G26: 9.8649955e+08 | H26: 5.5453069e+08 | I26: 2.9181043e+08 | J26: 4.8703649e+09 | K26: 168919531 | L26: 18193739 | M26: 1.4825946e+09 | N26: 1.4345046e+09 | O26: 6.7874947e+09 | P26: 2.6856146e+09 | Q26: 2.7562466e+08 | R26: -33792.99 | S26: -0.06 | T26: 279.33 | U26: 0 | V26: 0 | W26: 0 | X26: 0 | Y26: 0 | Z26: 0
E27: Subsidio(-)/Contribucion(+) | F27: 5341504.6 | G27: 1097764.1 | H27: 620054.15 | I27: 326455.64 | J27: 77296.09 | K27: 2815.34 | L27: 0 | M27: 24695.93 | N27: 31713.91 | O27: 147438.86 | P27: 3008677.2 | Q27: 4593.42 | R27: 0 | S27: 0 | T27: 0 | U27: 0 | V27: 0 | W27: 0 | X27: 0 | Y27: 0 | Z27: 0
D28: T | E28: Total | F28: 5341504.6 | G28: 1097764.1 | H28: 620054.15 | I28: 326455.64 | J28: 77296.09 | K28: 2815.34 | L28: 0 | M28: 24695.93 | N28: 31713.91 | O28: 147438.86 | P28: 3008677.2 | Q28: 4593.42 | R28: 0 | S28: 0 | T28: 0 | U28: 0 | V28: 0 | W28: 0 | X28: 0 | Y28: 0 | Z28: 0
C29: OCCIDENTE | D29: Total | F29: 5341504.6 | G29: 1097764.1 | H29: 620054.15 | I29: 326455.64 | J29: 77296.09 | K29: 2815.34 | L29: 0 | M29: 24695.93 | N29: 31713.91 | O29: 147438.86 | P29: 3008677.2 | Q29: 4593.42 | R29: 0 | S29: 0 | T29: 0 | U29: 0 | V29: 0 | W29: 0 | X29: 0 | Y29: 0 | Z29: 0
B30: Aplicacion nuevos x reversion | C30: Total | F30: 5341504.6 | G30: 1097764.1 | H30: 620054.15 | I30: 326455.64 | J30: 77296.09 | K30: 2815.34 | L30: 0 | M30: 24695.93 | N30: 31713.91 | O30: 147438.86 | P30: 3008677.2 | Q30: 4593.42 | R30: 0 | S30: 0 | T30: 0 | U30: 0 | V30: 0 | W30: 0 | X30: 0 | Y30: 0 | Z30: 0
E31: Subsidio(-)/Contribucion(+) | F31: -2.9097271e+09 | G31: -71434201 | H31: -40271751 | I31: -21151234 | J31: -8.5108048e+08 | K31: -28933267 | L31: 0 | M31: -2.5394018e+08 | N31: -2.4481763e+08 | O31: -1.1593136e+09 | P31: -1.9158028e+08 | Q31: -47204497 | R31: 0 | S31: 0 | T31: 0 | U31: 0 | V31: 0 | W31: 0 | X31: 0 | Y31: 0 | Z31: 0
D32: E | E32: Total | F32: -2.9097271e+09 | G32: -71434201 | H32: -40271751 | I32: -21151234 | J32: -8.5108048e+08 | K32: -28933267 | L32: 0 | M32: -2.5394018e+08 | N32: -2.4481763e+08 | O32: -1.1593136e+09 | P32: -1.9158028e+08 | Q32: -47204497 | R32: 0 | S32: 0 | T32: 0 | U32: 0 | V32: 0 | W32: 0 | X32: 0 | Y32: 0 | Z32: 0
C33: ENEL | D33: Total | F33: -2.9097271e+09 | G33: -71434201 | H33: -40271751 | I33: -21151234 | J33: -8.5108048e+08 | K33: -28933267 | L33: 0 | M33: -2.5394018e+08 | N33: -2.4481763e+08 | O33: -1.1593136e+09 | P33: -1.9158028e+08 | Q33: -47204497 | R33: 0 | S33: 0 | T33: 0 | U33: 0 | V33: 0 | W33: 0 | X33: 0 | Y33: 0 | Z33: 0
E34: Subsidio(-)/Contribucion(+) | F34: 6544837.2 | G34: 1138624.2 | H34: 635941.02 | I34: 334662.94 | J34: 575474.01 | K34: 3731.32 | L34: 0 | M34: 34025.38 | N34: 125376.87 | O34: 588048.51 | P34: 3102866.2 | Q34: 6086.75 | R34: 0 | S34: 0 | T34: 0 | U34: 0 | V34: 0 | W34: 0 | X34: 0 | Y34: 0 | Z34: 0
D35: H | E35: Total | F35: 6544837.2 | G35: 1138624.2 | H35: 635941.02 | I35: 334662.94 | J35: 575474.01 | K35: 3731.32 | L35: 0 | M35: 34025.38 | N35: 125376.87 | O35: 588048.51 | P35: 3102866.2 | Q35: 6086.75 | R35: 0 | S35: 0 | T35: 0 | U35: 0 | V35: 0 | W35: 0 | X35: 0 | Y35: 0 | Z35: 0
E36: Subsidio(-)/Contribucion(+) | F36: 4991152.4 | G36: 1838282.8 | H36: 703264.52 | I36: 369579.31 | J36: -596884.46 | K36: -26041.38 | L36: 0 | M36: -227782.49 | N36: -105769.99 | O36: -532864.03 | P36: 3611859.3 | Q36: -42491.1 | R36: 0 | S36: 0 | T36: 0 | U36: 0 | V36: 0 | W36: 0 | X36: 0 | Y36: 0 | Z36: 0
D37: O | E37: Total | F37: 4991152.4 | G37: 1838282.8 | H37: 703264.52 | I37: 369579.31 | J37: -596884.46 | K37: -26041.38 | L37: 0 | M37: -227782.49 | N37: -105769.99 | O37: -532864.03 | P37: 3611859.3 | Q37: -42491.1 | R37: 0 | S37: 0 | T37: 0 | U37: 0 | V37: 0 | W37: 0 | X37: 0 | Y37: 0 | Z37: 0
E38: Subsidio(-)/Contribucion(+) | F38: 70930319 | G38: 13105076 | H38: 7318853 | I38: 3844097.6 | J38: 3676388.6 | K38: 77320.12 | L38: 0 | M38: 692817.17 | N38: 1177808.5 | O38: 5457053.5 | P38: 35454664 | Q38: 126240.53 | R38: 0 | S38: 0 | T38: 0 | U38: 0 | V38: 0 | W38: 0 | X38: 0 | Y38: 0 | Z38: 0
D39: T | E39: Total | F39: 70930319 | G39: 13105076 | H39: 7318853 | I39: 3844097.6 | J39: 3676388.6 | K39: 77320.12 | L39: 0 | M39: 692817.17 | N39: 1177808.5 | O39: 5457053.5 | P39: 35454664 | Q39: 126240.53 | R39: 0 | S39: 0 | T39: 0 | U39: 0 | V39: 0 | W39: 0 | X39: 0 | Y39: 0 | Z39: 0
C40: OCCIDENTE | D40: Total | F40: 82466308 | G40: 16081983 | H40: 8658058.5 | I40: 4548339.8 | J40: 3654978.2 | K40: 55010.06 | L40: 0 | M40: 499060.06 | N40: 1197415.4 | O40: 5512238 | P40: 42169389 | Q40: 89836.18 | R40: 0 | S40: 0 | T40: 0 | U40: 0 | V40: 0 | W40: 0 | X40: 0 | Y40: 0 | Z40: 0
B41: Mes | C41: Total | F41: -2.8272608e+09 | G41: -55352218 | H41: -31613692 | I41: -16602894 | J41: -8.474255e+08 | K41: -28878257 | L41: 0 | M41: -2.5344112e+08 | N41: -2.4362022e+08 | O41: -1.1538013e+09 | P41: -1.4941089e+08 | Q41: -47114661 | R41: 0 | S41: 0 | T41: 0 | U41: 0 | V41: 0 | W41: 0 | X41: 0 | Y41: 0 | Z41: 0
A42: Subs/Cont | B42: Total | F42: -2.8219193e+09 | G42: -54254454 | H42: -30993638 | I42: -16276439 | J42: -8.473482e+08 | K42: -28875442 | L42: 0 | M42: -2.5341642e+08 | N42: -2.435885e+08 | O42: -1.1536539e+09 | P42: -1.4640221e+08 | Q42: -47110067 | R42: 0 | S42: 0 | T42: 0 | U42: 0 | V42: 0 | W42: 0 | X42: 0 | Y42: 0 | Z42: 0
A43: Total | F43: 1.6734199e+10 | G43: 9.322451e+08 | H43: 5.2353705e+08 | I43: 2.75534e+08 | J43: 4.0230167e+09 | K43: 1.4004409e+08 | L43: 18193739 | M43: 1.2291782e+09 | N43: 1.1909161e+09 | O43: 5.6338408e+09 | P43: 2.5392124e+09 | Q43: 2.2851459e+08 | R43: -33792.99 | S43: -0.06 | T43: 279.33 | U43: 0 | V43: 0 | W43: 0 | X43: 0 | Y43: 0 | Z43: 0
...

Sheet Rem. Anticipos R2
B1: PROMOAMBIENTAL
E2: Total | F2: Componente TDF | G2: Componente TTL | H2: Componente TVIAT | I2: Aprovechamiento | J2: CCSA Prest.Aprov. | K2: Especiales | L2: Componente TCS | M2: Componente TLU | N2: Componente TBL | O2: Componente TRT | P2: CCSA Prest. No Aprov. | Q2: Deb/Cred | R2: Deb/Cred-otros
D3: Vlr Servicio | E3: 52775108 | F3: 3005934.7 | G3: 1639699.6 | H3: 850296.11 | I3: 9434909.6 | J3: 259660.97 | K3: 57261.7 | L3: 4787838.2 | M3: 4258606.9 | N3: 19821214 | O3: 8235997.8 | P3: 424283.05 | Q3: -594.76 | R3: 0
D4: Vlr Intereses | E4: 78527.4 | F4: 286.62 | G4: 160.63 | H4: 84.75 | I4: 591.75 | J4: 22.99 | K4: 0 | L4: 196.2 | M4: 185.94 | N4: 856.99 | O4: 783.97 | P4: 37.53 | Q4: 75320.03 | R4: 0
C5: E | D5: Total | E5: 52853635 | F5: 3006221.3 | G5: 1639860.2 | H5: 850380.86 | I5: 9435501.3 | J5: 259683.96 | K5: 57261.7 | L5: 4788034.4 | M5: 4258792.9 | N5: 19822071 | O5: 8236781.7 | P5: 424320.58 | Q5: 74725.27 | R5: 0
B6: ENEL | C6: Total | E6: 52853635 | F6: 3006221.3 | G6: 1639860.2 | H6: 850380.86 | I6: 9435501.3 | J6: 259683.96 | K6: 57261.7 | L6: 4788034.4 | M6: 4258792.9 | N6: 19822071 | O6: 8236781.7 | P6: 424320.58 | Q6: 74725.27 | R6: 0
D7: Vlr Servicio | E7: 217567.77 | F7: 8801.93 | G7: 4969.56 | H7: 1578.39 | I7: 55004.69 | J7: 1915.1 | K7: 0 | L7: 16799.05 | M7: 16182.6 | N7: 85190.74 | O7: 23998.79 | P7: 3124.6 | Q7: 2.32 | R7: 0
C8: H | D8: Total | E8: 217567.77 | F8: 8801.93 | G8: 4969.56 | H8: 1578.39 | I8: 55004.69 | J8: 1915.1 | K8: 0 | L8: 16799.05 | M8: 16182.6 | N8: 85190.74 | O8: 23998.79 | P8: 3124.6 | Q8: 2.32 | R8: 0
D9: Vlr Servicio | E9: 2348432.2 | F9: 133715.17 | G9: 76606.43 | H9: 18339.36 | I9: 656909.12 | J9: 22734.38 | K9: 0 | L9: 268184.65 | M9: 134174.67 | N9: 638198.91 | O9: 360128.88 | P9: 39397.09 | Q9: 43.56 | R9: 0
D10: Vlr Intereses | E10: 1273.6 | F10: 35.71 | G10: 17.46 | H10: 9.61 | I10: 202.72 | J10: 16.33 | K10: 0 | L10: 143.17 | M10: 133.71 | N10: 591.26 | O10: 96.97 | P10: 26.63 | Q10: 0.03 | R10: 0
C11: O | D11: Total | E11: 2349705.8 | F11: 133750.88 | G11: 76623.89 | H11: 18348.97 | I11: 657111.84 | J11: 22750.71 | K11: 0 | L11: 268327.82 | M11: 134308.38 | N11: 638790.17 | O11: 360225.85 | P11: 39423.72 | Q11: 43.59 | R11: 0
D12: Vlr Servicio | E12: 932978.37 | F12: 50950.7 | G12: 28766.79 | H12: 13978.58 | I12: 228040.09 | J12: 7660.4 | K12: 0 | L12: 70556.01 | M12: 64730.4 | N12: 319858.46 | O12: 138447.13 | P12: 9998.72 | Q12: -8.91 | R12: 0
C13: T | D13: Total | E13: 932978.37 | F13: 50950.7 | G13: 28766.79 | H13: 13978.58 | I13: 228040.09 | J13: 7660.4 | K13: 0 | L13: 70556.01 | M13: 64730.4 | N13: 319858.46 | O13: 138447.13 | P13: 9998.72 | Q13: -8.91 | R13: 0
B14: OCCIDENTE | C14: Total | E14: 3500252 | F14: 193503.51 | G14: 110360.24 | H14: 33905.94 | I14: 940156.62 | J14: 32326.21 | K14: 0 | L14: 355682.88 | M14: 215221.38 | N14: 1043839.4 | O14: 522671.77 | P14: 52547.04 | Q14: 37 | R14: 0
A15: Componente | B15: Total | E15: 56353887 | F15: 3199724.8 | G15: 1750220.5 | H15: 884286.8 | I15: 10375658 | J15: 292010.17 | K15: 57261.7 | L15: 5143717.2 | M15: 4474014.3 | N15: 20865910 | O15: 8759453.5 | P15: 476867.62 | Q15: 74762.27 | R15: 0
D16: Subsidio(-)/Contribucion(+) | E16: -891046.91 | F16: 346354.38 | G16: 188770.63 | H16: 112441.44 | I16: -875398.47 | J16: -36178.21 | K16: 0 | L16: -243429.06 | M16: -212863.85 | N16: -1106133.6 | O16: 994081.82 | P16: -58691.97 | Q16: 0 | R16: 0
C17: E | D17: Total | E17: -891046.91 | F17: 346354.38 | G17: 188770.63 | H17: 112441.44 | I17: -875398.47 | J17: -36178.21 | K17: 0 | L17: -243429.06 | M17: -212863.85 | N17: -1106133.6 | O17: 994081.82 | P17: -58691.97 | Q17: 0 | R17: 0
B18: ENEL | C18: Total | E18: -891046.91 | F18: 346354.38 | G18: 188770.63 | H18: 112441.44 | I18: -875398.47 | J18: -36178.21 | K18: 0 | L18: -243429.06 | M18: -212863.85 | N18: -1106133.6 | O18: 994081.82 | P18: -58691.97 | Q18: 0 | R18: 0
D19: Subsidio(-)/Contribucion(+) | E19: 13129.64 | F19: 251.85 | G19: 142.19 | H19: 124.92 | I19: 5077.05 | J19: 191.51 | K19: 0 | L19: 646.85 | M19: 0 | N19: 5694.98 | O19: 687.83 | P19: 312.46 | Q19: 0 | R19: 0
C20: H | D20: Total | E20: 13129.64 | F20: 251.85 | G20: 142.19 | H20: 124.92 | I20: 5077.05 | J20: 191.51 | K20: 0 | L20: 646.85 | M20: 0 | N20: 5694.98 | O20: 687.83 | P20: 312.46 | Q20: 0 | R20: 0
D21: Subsidio(-)/Contribucion(+) | E21: -1366753.9 | F21: -48164.56 | G21: -27193.52 | H21: -14273.06 | I21: -298390.72 | J21: -14114.49 | K21: 0 | L21: -123808.53 | M21: -119265.98 | N21: -566524.06 | O21: -131990.43 | P21: -23028.52 | Q21: 0 | R21: 0
C22: O | D22: Total | E22: -1366753.9 | F22: -48164.56 | G22: -27193.52 | H22: -14273.06 | I22: -298390.72 | J22: -14114.49 | K22: 0 | L22: -123808.53 | M22: -119265.98 | N22: -566524.06 | O22: -131990.43 | P22: -23028.52 | Q22: 0 | R22: 0
D23: Subsidio(-)/Contribucion(+) | E23: 164431.29 | F23: 9572.57 | G23: 5404.71 | H23: 3830.1 | I23: 25069.49 | J23: 1091.6 | K23: 0 | L23: 13271.32 | M23: 12784.24 | N23: 62966.18 | O23: 28660.07 | P23: 1781.01 | Q23: 0 | R23: 0
C24: T | D24: Total | E24: 164431.29 | F24: 9572.57 | G24: 5404.71 | H24: 3830.1 | I24: 25069.49 | J24: 1091.6 | K24: 0 | L24: 13271.32 | M24: 12784.24 | N24: 62966.18 | O24: 28660.07 | P24: 1781.01 | Q24: 0 | R24: 0
B25: OCCIDENTE | C25: Total | E25: -1189192.9 | F25: -38340.14 | G25: -21646.62 | H25: -10318.04 | I25: -268244.18 | J25: -12831.38 | K25: 0 | L25: -109890.36 | M25: -106481.74 | N25: -497862.9 | O25: -102642.53 | P25: -20935.05 | Q25: 0 | R25: 0
A26: Subs/Cont | B26: Total | E26: -2080239.9 | F26: 308014.24 | G26: 167124.01 | H26: 102123.4 | I26: -1143642.6 | J26: -49009.59 | K26: 0 | L26: -353319.42 | M26: -319345.59 | N26: -1603996.5 | O26: 891439.29 | P26: -79627.02 | Q26: 0 | R26: 0
A27: Total | E27: 54273647 | F27: 3507739 | G27: 1917344.5 | H27: 986410.2 | I27: 9232015.3 | J27: 243000.58 | K27: 57261.7 | L27: 4790397.8 | M27: 4154668.7 | N27: 19261914 | O27: 9650892.8 | P27: 397240.6 | Q27: 74762.27 | R27: 0
B41: TOTAL | C41: OPORTUNO | D41: Total | E41: =E15+E26-K15 -> 54216386 | F41: =F15 -> 3199724.8 | G41: =G15 -> 1750220.5 | H41: =H15 -> 884286.8 | I41: =I15 -> 10375658 | J41: =J15 -> 292010.17 | K41: =K15 -> 57261.7 | L41: =L15 -> 5143717.2 | M41: =M15 -> 4474014.3 | ... S41: =S15 -> 0
D42: Subsidio(-)/Contribucion(+) | E42: =E26 -> -2080239.9
B44: RECIPROCIDAD | C44: OPORTUNO | D44: Total | E44: 0 | F44: 0 | G44: 0 | H44: 0 | I44: 0 | J44: 0 | K44: 0 | L44: 0 | M44: 0 | N44: 0 | O44: 0 | P44: 0 | Q44: 0 | R44: 0 | S44: 0
D45: Subsidio(-)/Contribucion(+) | E45: 0
B47: ENEL | C47: OPORTUNO | D47: Total | E47: =E18+E6-K6 -> 51905327 | F47: =F6 -> 3006221.3 | G47: =G6 -> 1639860.2 | H47: =H6 -> 850380.86 | I47: =I6 -> 9435501.3 | J47: =J6 -> 259683.96 | K47: =K6 -> 57261.7 | L47: =L6 -> 4788034.4 | M47: =M6 -> 4258792.9 | ... S47: =S6 -> 0
D48: Subsidio(-)/Contribucion(+) | E48: =E18 -> -891046.91
B50: ENERBIT | C50: OPORTUNO | D50: Total | E50: 0 | F50: 0 | G50: 0 | H50: 0 | I50: 0 | J50: 0 | K50: 0 | L50: 0 | M50: 0 | N50: 0 | O50: 0 | P50: 0 | Q50: 0 | R50: 0
D51: Subsidio(-)/Contribucion(+) | E51: 0
B53: OCCIDENTE | C53: OPORTUNO | D53: Total | E53: =E14+E25-K14 -> 2311059 | F53: =F14 -> 193503.51 | G53: =G14 -> 110360.24 | H53: =H14 -> 33905.94 | I53: =I14 -> 940156.62 | J53: =J14 -> 32326.21 | K53: =K14 -> 0 | L53: =L14 -> 355682.88 | M53: =M14 -> 215221.38 | ... S53: =S14 -> 0
D54: Subsidio(-)/Contribucion(+) | E54: =E25 -> -1189192.9
B56: CIUDAD LIMPIA-ACUEDUCTO | C56: OPORTUNO | D56: Total | E56: 0 | F56: 0 | G56: 0 | H56: 0 | I56: 0 | J56: 0 | K56: 0 | L56: 0 | M56: 0 | N56: 0 | O56: 0 | P56: 0 | Q56: 0 | R56: 0 | S56: 0
D57: Subsidio(-)/Contribucion(+) | E57: 0
B59: LIME
...

Sheet Reversion Pagos R4
B1: PROMOAMBIENTAL
D2: Total | E2: Componente TDF | F2: Componente TTL | G2: Componente TVIAT | H2: Aprovechamiento | I2: CCSA Prest.Aprov. | J2: Componente TCS | K2: Componente TLU | L2: Componente TBL | M2: Componente TRT | N2: CCSA Prest. No Aprov. | O2: Ajuste Decena | P2: SERVICIO ESPECIALES | Q2: Ajuste Recargo Aseo | R2: Otros
C3: Vlr Servicio | D3: -8485687.6 | E3: -1533145.5 | F3: -865959.97 | G3: -456267.38 | H3: -382091.3 | I3: -12179.47 | J3: -112932.75 | K3: -152004.56 | L3: -737957.5 | M3: -4213305.4 | N3: -19871.42 | O3: 27.66 | P3: 0 | Q3: 0 | R3: 0
C4: Vlr Intereses | D4: -26833.73 | E4: -5410.19 | F4: -3055.42 | G4: -1614.59 | H4: -512.83 | I4: -18.28 | J4: -160.4 | K4: -207 | L4: -945.64 | M4: -14879.62 | N4: -29.75 | O4: -0.01 | P4: 0 | Q4: 0 | R4: 0
B5: Componente | C5: Total | D5: -8512521.3 | E5: -1538555.7 | F5: -869015.39 | G5: -457881.97 | H5: -382604.13 | I5: -12197.75 | J5: -113093.15 | K5: -152211.56 | L5: -738903.14 | M5: -4228185 | N5: -19901.17 | O5: 27.65 | P5: 0 | Q5: 0 | R5: 0
C6: Subsidio(-)/Contribucion(+) | D6: -3541734.4 | E6: -668084.55 | F6: -378722.34 | G6: -199766.06 | H6: -126968.15 | I6: -4568.7 | J6: -38734.16 | K6: -50056.15 | L6: -232448.97 | M6: -1834931.2 | N6: -7454.1 | O6: 0 | P6: 0 | Q6: 0 | R6: 0
B7: Subs/Cont | C7: Total | D7: -3541734.4 | E7: -668084.55 | F7: -378722.34 | G7: -199766.06 | H7: -126968.15 | I7: -4568.7 | J7: -38734.16 | K7: -50056.15 | L7: -232448.97 | M7: -1834931.2 | N7: -7454.1 | O7: 0 | P7: 0 | Q7: 0 | R7: 0
A8: OCCIDENTE | B8: Total | D8: -12054256 | E8: -2206640.2 | F8: -1247737.7 | G8: -657648.03 | H8: -509572.28 | I8: -16766.45 | J8: -151827.31 | K8: -202267.71 | L8: -971352.11 | M8: -6063116.2 | N8: -27355.27 | O8: 27.65 | P8: 0 | Q8: 0 | R8: 0
A9: Total | D9: -12054256 | E9: -2206640.2 | F9: -1247737.7 | G9: -657648.03 | H9: -509572.28 | I9: -16766.45 | J9: -151827.31 | K9: -202267.71 | L9: -971352.11 | M9: -6063116.2 | N9: -27355.27 | O9: 27.65 | P9: 0 | Q9: 0 | R9: 0
A67: TOTAL | B67: OPORTUNO | C67: Total | D67: =D9-P9 -> -12054256 | E67: =E5 -> -1538555.7 | F67: =F5 -> -869015.39 | G67: =G5 -> -457881.97 | H67: =H5 -> -382604.13 | I67: =I5 -> -12197.75 | J67: =J5 -> -113093.15 | K67: =K5 -> -152211.56 | L67: =L5 -> -738903.14 | ... R67: =R5 -> 0
C68: Subsidio(-)/Contribucion(+) | D68: =D7 -> -3541734.4
A70: RECIPROCIDAD | B70: OPORTUNO | C70: Total | D70: 0 | E70: 0 | F70: 0 | G70: 0 | H70: 0 | I70: 0 | J70: 0 | K70: 0 | L70: 0 | M70: 0 | N70: 0 | O70: 0 | P70: 0 | Q70: 0 | R70: 0
C71: Subsidio(-)/Contribucion(+) | D71: 0
A73: ENEL | B73: OPORTUNO | C73: Total | D73: 0 | E73: 0 | F73: 0 | G73: 0 | H73: 0 | I73: 0 | J73: 0 | K73: 0 | L73: 0 | M73: 0 | N73: 0 | O73: 0 | P73: 0 | Q73: 0 | R73: 0
C74: Subsidio(-)/Contribucion(+) | D74: 0
A76: ENERBIT | B76: OPORTUNO | C76: Total | D76: 0 | E76: 0 | F76: 0 | G76: 0 | H76: 0 | I76: 0 | J76: 0 | K76: 0 | L76: 0 | M76: 0 | N76: 0 | O76: 0 | P76: 0 | Q76: 0 | R76: 0
C77: Subsidio(-)/Contribucion(+) | D77: 0
A79: OCCIDENTE | B79: OPORTUNO | C79: Total | D79: =D8-P8 -> -12054256 | E79: =E5 -> -1538555.7 | F79: =F5 -> -869015.39 | G79: =G5 -> -457881.97 | H79: =H5 -> -382604.13 | I79: =I5 -> -12197.75 | J79: =J5 -> -113093.15 | K79: =K5 -> -152211.56 | L79: =L5 -> -738903.14 | ... R79: =R5 -> 0
C80: Subsidio(-)/Contribucion(+) | D80: =D7 -> -3541734.4
A82: CIUDAD LIMPIA-ACUEDUCTO | B82: OPORTUNO | C82: Total | D82: 0 | E82: 0 | F82: 0 | G82: 0 | H82: 0 | I82: 0 | J82: 0 | K82: 0 | L82: 0 | M82: 0 | N82: 0 | O82: 0 | P82: 0 | Q82: 0 | R82: 0
C83: Subsidio(-)/Contribucion(+) | D83: 0
B85: LIME
D86: Total | E86: Componente TDF | F86: Componente TTL | G86: Componente TVIAT | H86: Aprovechamiento | I86: CCSA Prest.Aprov. | J86: Componente TCS | K86: Componente TLU | L86: Componente TBL | M86: Componente TRT | N86: CCSA Prest. No Aprov. | O86: Ajuste Decena | P86: SERVICIO ESPECIALES | Q86: Ajuste Recargo Aseo | R86: Otros
C87: Vlr Servicio | D87: -12510091 | E87: -685319.88 | F87: -386138.78 | G87: -203450.42 | H87: -3018006.6 | I87: -115581.1 | J87: -1004303.4 | K87: -984101.17 | L87: -4576813.8 | M87: -1348439.4 | N87: -187944.08 | O87: 7.45 | P87: 0 | Q87: 0 | R87: 0
C88: Vlr Intereses | D88: -28375.39 | E88: -1910.39 | F88: -986.27 | G88: -479.41 | H88: -5748.48 | I88: -254.76 | J88: -2231.44 | K88: -2549.78 | L88: -10026.67 | M88: -3773.44 | N88: -414.85 | O88: 0.1 | P88: 0 | Q88: 0 | R88: 0
B89: Componente | C89: Total | D89: -12538467 | E89: -687230.27 | F89: -387125.05 | G89: -203929.83 | H89: -3023755.1 | I89: -115835.86 | J89: -1006534.8 | K89: -986650.95 | L89: -4586840.5 | M89: -1352212.9 | N89: -188358.93 | O89: 7.55 | P89: 0 | Q89: 0 | R89: 0
C90: Subsidio(-)/Contribucion(+) | D90: 2669055.6 | E90: 90356.23 | F90: 51012.76 | G90: 26867.42 | H90: 688638.15 | I90: 27274.93 | J90: 239249.96 | K90: 234515.54 | L90: 1090962.4 | M90: 175677.7 | N90: 44500.53 | O90: 0 | P90: 0 | Q90: 0 | R90: 0
B91: Subs/Cont | C91: Total | D91: 2669055.6 | E91: 90356.23 | F91: 51012.76 | G91: 26867.42 | H91: 688638.15 | I91: 27274.93 | J91: 239249.96 | K91: 234515.54 | L91: 1090962.4 | M91: 175677.7 | N91: 44500.53 | O91: 0 | P91: 0 | Q91: 0 | R91: 0
A92: ENEL | B92: Total | D92: -9869411 | E92: -596874.04 | F92: -336112.29 | G92: -177062.41 | H92: -2335117 | I92: -88560.93 | J92: -767284.84 | K92: -752135.41 | L92: -3495878.1 | M92: -1176535.2 | N92: -143858.4 | O92: 7.55 | P92: 0 | Q92: 0 | R92: 0
C93: Vlr Servicio | D93: -23269.08 | E93: -163.23 | F93: -92.16 | G93: -48.37 | H93: 0 | I93: -374.65 | J93: -3286.39 | K93: -3205.2 | L93: -15163.76 | M93: -324.05 | N93: -611.27 | O93: 0 | P93: 0 | Q93: 0 | R93: 0
B94: Componente | C94: Total | D94: -23269.08 | E94: -163.23 | F94: -92.16 | G94: -48.37 | H94: 0 | I94: -374.65 | J94: -3286.39 | K94: -3205.2 | L94: -15163.76 | M94: -324.05 | N94: -611.27 | O94: 0 | P94: 0 | Q94: 0 | R94: 0
C95: Subsidio(-)/Contribucion(+) | D95: 3490.36 | E95: 24.48 | F95: 13.82 | G95: 7.26 | H95: 0 | I95: 56.2 | J95: 492.96 | K95: 480.78 | L95: 2274.56 | M95: 48.61 | N95: 91.69 | O95: 0 | P95: 0 | Q95: 0 | R95: 0
B96: Subs/Cont | C96: Total | D96: 3490.36 | E96: 24.48 | F96: 13.82 | G96: 7.26 | H96: 0 | I96: 56.2 | J96: 492.96 | K96: 480.78 | L96: 2274.56 | M96: 48.61 | N96: 91.69 | O96: 0 | P96: 0 | Q96: 0 | R96: 0
A97: NUEVO ESQUEMA | B97: Total | D97: -19778.72 | E97: -138.75 | F97: -78.34 | G97: -41.11 | H97: 0 | I97: -318.45 | J97: -2793.43 | K97: -2724.42 | L97: -12889.2 | M97: -275.44 | N97: -519.58 | O97: 0 | P97: 0 | Q97: 0 | R97: 0
A98: Total | D98: -9889189.7 | E98: -597012.79 | F98: -336190.63 | G98: -177103.52 | H98: -2335117 | I98: -88879.38 | J98: -770078.27 | K98: -754859.83 | L98: -3508767.3 | M98: -1176810.6 | N98: -144377.98 | O98: 7.55 | P98: 0 | Q98: 0 | R98: 0
A161: TOTAL | B161: OPORTUNO | C161: Total | D161: =D98-P98 -> -9889189.7 | E161: =E94+E89 -> -687393.5 | F161: =F94+F89 -> -387217.21 | G161: =G94+G89 -> -203978.2 | H161: =H94+H89 -> -3023755.1 | I161: =I94+I89 -> -116210.51 | J161: =J94+J89 -> -1009821.2 | K161: =K94+K89 -> -989856.15 | L161: =L94+L89 -> -4602004.2 | ... R161: =R94+R89 -> 0
C162: Subsidio(-)/Contribucion(+) | D162: =D96+D91 -> 2672546
