Workbook
Name \0: #REF!
Name _1: #REF!
Name _2: #REF!
Name _A655555: #REF!
Name _CFR1: #REF!
Name _cia1: #REF!
Name _XL250: #REF!
Name A: #REF!
Name ADM: [1]!ADM
Name ADM: [1]!ADM
Name ADM: [1]!ADM
Name ADM: [1]!ADM
Name ADM: [1]!ADM
Name ADM_: [1]!ADM
Name ADM_: [1]!ADM
Name ADM_: [1]!ADM
Name ADM_: [1]!ADM
Name ADM_: [1]!ADM
Name AI: #REF!
Name Air: #REF!
Name AP: '[2]TARIFA no aforos'!$C$12
Name Bancos: [3]Fx!$C$1:$C$23
Name CBL: #REF!
Name CCS: #REF!
Name CDT_p: [4]CDT!$C$3
Name CFR: #REF!
Name cia: #REF!
Name COM: #REF!
Name CRT: #REF!
Name CRT___CTEp___CDTp___CMRv: #REF!
Name CRT_aislados: '[4]COSTOS AJUSTADOS'!$C$13
Name CRT_costas: #REF!
Name CTE_p: [4]CTE!$C$5
Name Denominador: #REF!
Name dg: [1]!ADM
Name dg: [1]!ADM
Name dg: [1]!ADM
Name dg: [1]!ADM
Name dg: [1]!ADM
Name DIAS: [5]CONTRA!#REF!
Name Fmerc: #REF!
Name FPS: #REF!
Name InformacionGeneral: [1]!InformacionGeneral
Name InformacionGeneral: [1]!InformacionGeneral
Name InformacionGeneral: [1]!InformacionGeneral
Name InformacionGeneral: [1]!InformacionGeneral
Name InformacionGeneral: [1]!InformacionGeneral
Name INTFIN: #REF!
Name INV: [1]!INV
Name INV: [1]!INV
Name INV: [1]!INV
Name INV: [1]!INV
Name INV: [1]!INV
Name K: #REF!
Name N: '[4]COSTOS AJUSTADOS'!#REF!
Name Na: '[2]TARIFA no aforos'!$C$39
Name nfc: '[4]COSTOS AJUSTADOS'!#REF!
Name OYM: [1]!OYM
Name OYM: [1]!OYM
Name OYM: [1]!OYM

Sheet Recaudo EAAB Reciprocidad
B2: OPORTUNO | C2: ASE | D2: VALOR 1° Q | E2: NUMERO REG. 1°Q | F2: VALOR 2° Q | G2: NUMERO REG. 2°Q
C3: 1 | D3: 0 | E3: 0 | F3: 0 | G3: 0
C4: 2 | D4: 11627730 | E4: 116 | F4: 0 | G4: 0
C5: 3 | D5: 0 | E5: 0 | F5: 0 | G5: 0
C6: 4 | D6: 7382710 | E6: 66 | F6: 0 | G6: 0
C7: 5 | D7: 0 | E7: 0 | F7: 0 | G7: 0
C8: X
D9: 19010440 | E9: 182 | F9: 0 | G9: 0
C11: ASE | D11: VALOR 1° Q | E11: NUMERO REG. 1°Q | F11: VALOR 2° Q | G11: NUMERO REG. 2°Q
B12: EXTEMP. | C12: 1 | D12: 0 | E12: 0 | F12: 0 | G12: 0
C13: 2 | D13: 0 | E13: 0 | F13: 0 | G13: 0
C14: 3 | D14: 0 | E14: 0 | F14: 0 | G14: 0
C15: 4 | D15: 0 | E15: 0 | F15: 0 | G15: 0
C16: 5 | D16: 0 | E16: 0 | F16: 0 | G16: 0
C17: X
D18: 0 | E18: 0 | F18: 0 | G18: 0
C20: ASE | D20: VALOR 1° Q | E20: NUMERO REG. 1°Q | F20: VALOR 2° Q | G20: NUMERO REG. 2°Q | I20: VALOR TOTAL MES | J20: NUMERO REGISTROS MES
B21: TOTAL | C21: 1 | D21: 0 | E21: 0 | F21: 0 | G21: 0 | I21: 0 | J21: 0
C22: 2 | D22: 11627730 | E22: 116 | F22: 0 | G22: 0 | I22: 11627730 | J22: 116
C23: 3 | D23: 0 | E23: 0 | F23: 0 | G23: 0 | I23: 0 | J23: 0
C24: 4 | D24: 7382710 | E24: 66 | F24: 0 | G24: 0 | I24: 7382710 | J24: 66
C25: 5 | D25: 0 | E25: 0 | F25: 0 | G25: 0 | I25: 0 | J25: 0
C26: X | I26: 0 | J26: 0
D27: 19010440 | E27: 182 | F27: 0 | G27: 0 | I27: 19010440 | J27: 182
B31: OPORTUNO | D31: =D9=SUM(D3:D8) -> TRUE | E31: =E9=SUM(E3:E8) -> TRUE | F31: =F9=SUM(F3:F8) -> TRUE | G31: =G9=SUM(G3:G8) -> TRUE
B33: EXTEMP. | D33: =D18=SUM(D12:D17) -> TRUE | E33: =E18=SUM(E12:E17) -> TRUE | F33: =F18=SUM(F12:F17) -> TRUE | G33: =G18=SUM(G12:G17) -> TRUE
B35: TOTAL | D35: =D27=SUM(D21:D26) -> TRUE | E35: =E27=SUM(E21:E26) -> TRUE | F35: =F27=SUM(F21:F26) -> TRUE | G35: =G27=SUM(G21:G26) -> TRUE | I35: =I27=SUM(I21:I26) -> TRUE | J35: =J27=SUM(J21:J26) -> TRUE
E69: =C69-G17 -> 0

Sheet Recaudo ENEL
B2: OPORTUNO | C2: ASE | D2: VALOR 1° Q | E2: NUMERO REG. 1°Q | F2: VALOR 2° Q | G2: NUMERO REG. 2°Q
C3: 1 | D3: 16745673525 | E3: 356945 | F3: 0 | G3: 0
C4: 2 | D4: 12677941411 | E4: 247628 | F4: 0 | G4: 0
C5: 3 | D5: 10157711962 | E5: 233934 | F5: 0 | G5: 0
C6: 4 | D6: 10972037248 | E6: 193770 | F6: 0 | G6: 0
C7: 5 | D7: 8639656940 | E7: 172542 | F7: 0 | G7: 0
C8: X
D9: 59193021086 | E9: 1204819 | F9: 0 | G9: 0
C11: ASE | D11: VALOR 1° Q | E11: NUMERO REG. 1°Q | F11: VALOR 2° Q | G11: NUMERO REG. 2°Q
B12: EXTEMP. | C12: 1 | D12: 202711553 | E12: 2558 | F12: 0 | G12: 0
C13: 2 | D13: 73096641 | E13: 1473 | F13: 0 | G13: 0
C14: 3 | D14: 51248640 | E14: 963 | F14: 0 | G14: 0
C15: 4 | D15: 62236830 | E15: 857 | F15: 0 | G15: 0
C16: 5 | D16: 158575115 | E16: 2854 | F16: 0 | G16: 0
C17: X
D18: 547868779 | E18: 8705 | F18: 0 | G18: 0
C20: ASE | D20: VALOR 1° Q | E20: NUMERO REG. 1°Q | F20: VALOR 2° Q | G20: NUMERO REG. 2°Q | I20: VALOR TOTAL MES | J20: NUMERO REGISTROS MES
B21: TOTAL | C21: 1 | D21: 16948385078 | E21: 359503 | F21: 0 | G21: 0 | I21: 16948385078 | J21: 359503
C22: 2 | D22: 12751038052 | E22: 249101 | F22: 0 | G22: 0 | I22: 12751038052 | J22: 249101
C23: 3 | D23: 10208960602 | E23: 234897 | F23: 0 | G23: 0 | I23: 10208960602 | J23: 234897
C24: 4 | D24: 11034274078 | E24: 194627 | F24: 0 | G24: 0 | I24: 11034274078 | J24: 194627
C25: 5 | D25: 8798232055 | E25: 175396 | F25: 0 | G25: 0 | I25: 8798232055 | J25: 175396
C26: X | I26: 0 | J26: 0
D27: 59740889865 | E27: 1213524 | F27: 0 | G27: 0 | I27: 59740889865 | J27: 1213524
B31: OPORTUNO | D31: =D9=SUM(D3:D8) -> TRUE | E31: =E9=SUM(E3:E8) -> TRUE | F31: =F9=SUM(F3:F8) -> TRUE | G31: =G9=SUM(G3:G8) -> TRUE
B33: EXTEMP. | D33: =D18=SUM(D12:D17) -> TRUE | E33: =E18=SUM(E12:E17) -> TRUE | F33: =F18=SUM(F12:F17) -> TRUE | G33: =G18=SUM(G12:G17) -> TRUE
B35: TOTAL | D35: =D27=SUM(D21:D26) -> TRUE | E35: =E27=SUM(E21:E26) -> TRUE | F35: =F27=SUM(F21:F26) -> TRUE | G35: =G27=SUM(G21:G26) -> TRUE | I35: =I27=SUM(I21:I26) -> TRUE | J35: =J27=SUM(J21:J26) -> TRUE
E69: =C69-G17 -> 0

Sheet Recaudo ENERBIT
B2: OPORTUNO | C2: ASE | D2: VALOR 1° Q | E2: NUMERO REG. 1°Q | F2: VALOR 2° Q | G2: NUMERO REG. 2°Q
C3: 1 | D3: 0 | E3: 0 | F3: 0 | G3: 0
C4: 2 | D4: 0 | E4: 0 | F4: 0 | G4: 0
C5: 3 | D5: 0 | E5: 0 | F5: 0 | G5: 0
C6: 4 | D6: 0 | E6: 0 | F6: 0 | G6: 0
C7: 5 | D7: 137371512 | E7: 3020 | F7: 0 | G7: 0
C8: X
D9: 137371512 | E9: 3020 | F9: 0 | G9: 0
C11: ASE | D11: VALOR 1° Q | E11: NUMERO REG. 1°Q | F11: VALOR 2° Q | G11: NUMERO REG. 2°Q
B12: EXTEMP. | C12: 1 | D12: 0 | E12: 0 | F12: 0 | G12: 0
C13: 2 | D13: 0 | E13: 0 | F13: 0 | G13: 0
C14: 3 | D14: 0 | E14: 0 | F14: 0 | G14: 0
C15: 4 | D15: 0 | E15: 0 | F15: 0 | G15: 0
C16: 5 | D16: 1179300 | E16: 6 | F16: 0 | G16: 0
C17: X
D18: 1179300 | E18: 6 | F18: 0 | G18: 0
C20: ASE | D20: VALOR 1° Q | E20: NUMERO REG. 1°Q | F20: VALOR 2° Q | G20: NUMERO REG. 2°Q | I20: VALOR TOTAL MES | J20: NUMERO REGISTROS MES
B21: TOTAL | C21: 1 | D21: 0 | E21: 0 | F21: 0 | G21: 0 | I21: 0 | J21: 0
C22: 2 | D22: 0 | E22: 0 | F22: 0 | G22: 0 | I22: 0 | J22: 0
C23: 3 | D23: 0 | E23: 0 | F23: 0 | G23: 0 | I23: 0 | J23: 0
C24: 4 | D24: 0 | E24: 0 | F24: 0 | G24: 0 | I24: 0 | J24: 0
C25: 5 | D25: 138550812 | E25: 3026 | F25: 0 | G25: 0 | I25: 138550812 | J25: 3026
C26: X | I26: 0 | J26: 0
D27: 138550812 | E27: 3026 | F27: 0 | G27: 0 | I27: 138550812 | J27: 3026
B31: OPORTUNO | D31: =D9=SUM(D3:D8) -> TRUE | E31: =E9=SUM(E3:E8) -> TRUE | F31: =F9=SUM(F3:F8) -> TRUE | G31: =G9=SUM(G3:G8) -> TRUE
B33: EXTEMP. | D33: =D18=SUM(D12:D17) -> TRUE | E33: =E18=SUM(E12:E17) -> TRUE | F33: =F18=SUM(F12:F17) -> TRUE | G33: =G18=SUM(G12:G17) -> TRUE
B35: TOTAL | D35: =D27=SUM(D21:D26) -> TRUE | E35: =E27=SUM(E21:E26) -> TRUE | F35: =F27=SUM(F21:F26) -> TRUE | G35: =G27=SUM(G21:G26) -> TRUE | I35: =I27=SUM(I21:I26) -> TRUE | J35: =J27=SUM(J21:J26) -> TRUE
E69: =C69-G17 -> 0

Sheet Recaudo EAAB + Ciud Limp
B2: Ciudad Limpia - Prestador | C2: ASE | D2: VALOR 1° Q | E2: NUMERO REG. 1°Q | F2: VALOR 2° Q | G2: NUMERO REG. 2°Q
C3: 1 | D3: 0 | E3: 0 | F3: 0 | G3: 0
C4: 2 | D4: 0 | E4: 0 | F4: 0 | G4: 0
C5: 3 | D5: 0 | E5: 0 | F5: 0 | G5: 0
C6: 4 | D6: 0 | E6: 0 | F6: 0 | G6: 0
C7: 5 | D7: 0 | E7: 0 | F7: 0 | G7: 0
C8: X
D9: 0 | E9: 0 | F9: 0 | G9: 0
C11: ASE | D11: VALOR 1° Q | E11: NUMERO REG. 1°Q | F11: VALOR 2° Q | G11: NUMERO REG. 2°Q
B12: EAAB - Prestador | C12: 1 | D12: 0 | E12: 0 | F12: 0 | G12: 0
C13: 2 | D13: 0 | E13: 0 | F13: 0 | G13: 0
C14: 3 | D14: 0 | E14: 0 | F14: 0 | G14: 0
C15: 4 | D15: 0 | E15: 0 | F15: 0 | G15: 0
C16: 5 | D16: 0 | E16: 0 | F16: 0 | G16: 0
C17: X
D18: 0 | E18: 0 | F18: 0 | G18: 0
C20: ASE | D20: VALOR 1° Q | E20: NUMERO REG. 1°Q | F20: VALOR 2° Q | G20: NUMERO REG. 2°Q | I20: VALOR TOTAL MES | J20: NUMERO REGISTROS MES
B21: TOTAL | C21: 1 | D21: 0 | E21: 0 | F21: 0 | G21: 0 | I21: 0 | J21: 0
C22: 2 | D22: 0 | E22: 0 | F22: 0 | G22: 0 | I22: 0 | J22: 0
C23: 3 | D23: 0 | E23: 0 | F23: 0 | G23: 0 | I23: 0 | J23: 0
C24: 4 | D24: 0 | E24: 0 | F24: 0 | G24: 0 | I24: 0 | J24: 0
C25: 5 | D25: 0 | E25: 0 | F25: 0 | G25: 0 | I25: 0 | J25: 0
C26: X | I26: 0 | J26: 0
D27: 0 | E27: 0 | F27: 0 | G27: 0 | I27: 0 | J27: 0
B31: OPORTUNO | D31: =D9=SUM(D3:D8) -> TRUE | E31: =E9=SUM(E3:E8) -> TRUE | F31: =F9=SUM(F3:F8) -> TRUE | G31: =G9=SUM(G3:G8) -> TRUE
B33: EXTEMP. | D33: =D18=SUM(D12:D17) -> TRUE | E33: =E18=SUM(E12:E17) -> TRUE | F33: =F18=SUM(F12:F17) -> TRUE | G33: =G18=SUM(G12:G17) -> TRUE
B35: TOTAL | D35: =D27=SUM(D21:D26) -> TRUE | E35: =E27=SUM(E21:E26) -> TRUE | F35: =F27=SUM(F21:F26) -> TRUE | G35: =G27=SUM(G21:G26) -> TRUE | I35: =I27=SUM(I21:I26) -> TRUE | J35: =J27=SUM(J21:J26) -> TRUE

Sheet Recaudo Directa Occidente
B2: OPORTUNO | C2: ASE | D2: VALOR 1° Q | E2: NUMERO REG. 1°Q | F2: VALOR 2° Q | G2: NUMERO REG. 2°Q
C3: 1 | D3: 510782327 | E3: 2083 | F3: 0 | G3: 0
C4: 2 | D4: 1360190364 | E4: 4795 | F4: 0 | G4: 0
C5: 3 | D5: 650826874 | E5: 1469 | F5: 0 | G5: 0
C6: 4 | D6: 515587332 | E6: 3012 | F6: 0 | G6: 0
C7: 5 | D7: 224557157 | E7: 1221 | F7: 0 | G7: 0
C8: X | D8: 0 | E8: 0 | F8: 0 | G8: 0
D9: 3261944054 | E9: 12580 | F9: 0 | G9: 0
C11: ASE | D11: VALOR 1° Q | E11: NUMERO REG. 1°Q | F11: VALOR 2° Q | G11: NUMERO REG. 2°Q
B12: EXTEMP. | C12: 1 | D12: 23795111 | E12: 50 | F12: 0 | G12: 0
C13: 2 | D13: 62759499 | E13: 134 | F13: 0 | G13: 0
C14: 3 | D14: 48196023 | E14: 55 | F14: 0 | G14: 0
C15: 4 | D15: 5014320 | E15: 32 | F15: 0 | G15: 0
C16: 5 | D16: 14004529 | E16: 30 | F16: 0 | G16: 0
C17: X | D17: 0 | E17: 0 | F17: 0 | G17: 0
D18: 153769482 | E18: 301 | F18: 0 | G18: 0
C20: ASE | D20: VALOR 1° Q | E20: NUMERO REG. 1°Q | F20: VALOR 2° Q | G20: NUMERO REG. 2°Q | I20: VALOR TOTAL MES | J20: NUMERO REGISTROS MES
B21: TOTAL | C21: 1 | D21: 534577438 | E21: 2133 | F21: 0 | G21: 0 | I21: 534577438 | J21: 2133
C22: 2 | D22: 1422949863 | E22: 4929 | F22: 0 | G22: 0 | I22: 1422949863 | J22: 4929
C23: 3 | D23: 699022897 | E23: 1524 | F23: 0 | G23: 0 | I23: 699022897 | J23: 1524
C24: 4 | D24: 520601652 | E24: 3044 | F24: 0 | G24: 0 | I24: 520601652 | J24: 3044
C25: 5 | D25: 238561686 | E25: 1251 | F25: 0 | G25: 0 | I25: 238561686 | J25: 1251
C26: X | D26: 0 | E26: 0 | F26: 0 | G26: 0 | I26: 0 | J26: 0
D27: 3415713536 | E27: 12881 | F27: 0 | G27: 0 | I27: 3415713536 | J27: 12881
B31: OPORTUNO | D31: =D9=SUM(D3:D8) -> TRUE | E31: =E9=SUM(E3:E8) -> TRUE | F31: =F9=SUM(F3:F8) -> TRUE | G31: =G9=SUM(G3:G8) -> TRUE
B33: EXTEMP. | D33: =D18=SUM(D12:D17) -> TRUE | E33: =E18=SUM(E12:E17) -> TRUE | F33: =F18=SUM(F12:F17) -> TRUE | G33: =G18=SUM(G12:G17) -> TRUE
B35: TOTAL | D35: =D27=SUM(D21:D26) -> TRUE | E35: =E27=SUM(E21:E26) -> TRUE | F35: =F27=SUM(F21:F26) -> TRUE | G35: =G27=SUM(G21:G26) -> TRUE | I35: =I27=SUM(I21:I26) -> TRUE | J35: =J27=SUM(J21:J26) -> TRUE
E69: =C69-G17 -> 0

Sheet REPORTE RECAUDO x BANCO
C1: ENEL | D1: CIUDAD LIMPIA | E1: EAB | F1: NUEVO ESQUEMA | G1: ENERBIT | H1: OCCIDENTE | I1: Total
B2: 1-APLICADOS A FACTURACION | C2: =C13+C23+C32+C41+C51 -> 59646927181 | D2: =D13+D23+D32+D41+D51 -> 0 | E2: =E13+E23+E32+E41+E51 -> 0 | F2: =F13+F23+F32+F41+F51 -> 5603210 | G2: =G13+G23+G32+G41+G51 -> 137170902 | H2: =H13+H23+H32+H41+H51 -> 3.2507019e+09 | I2: =SUM(C2:H2) -> 6.3040403e+10
B3: 2-SALDOS A FAVOR GENERADOS | C3: =C14+C24+C33+C42+C52 -> 95923744 | D3: =D14+D24+D33+D42+D52 -> 0 | E3: =E14+E24+E33+E42+E52 -> 0 | F3: =F14+F24+F33+F42+F52 -> 13407230 | G3: =G14+G24+G33+G42+G52 -> 1379910 | H3: =H14+H24+H33+H42+H52 -> 75193898 | I3: =SUM(C3:H3) -> 1.8590478e+08
B4: 3-APLICADOS A FINANCIACIONES NUEVAS | C4: =C15+C25+C34+C43+C53 -> 0 | D4: =D15+D25+D34+D43+D53 -> 0 | E4: =E15+E25+E34+E43+E53 -> 0 | F4: =F15+F25+F34+F43+F53 -> 0 | G4: =G15+G25+G34+G43+G53 -> 0 | H4: =H15+H25+H34+H43+H53 -> 89817711 | I4: =SUM(C4:H4) -> 89817711
B5: 7-APLICADOS A RECIBOS SERVICIOS ESPECIALES | C5: =C16+C26+C35+C44+C54 -> 0 | D5: =D16+D26+D35+D44+D54 -> 0 | E5: =E16+E26+E35+E44+E54 -> 0 | F5: =F16+F26+F35+F44+F54 -> 0 | G5: =G16+G26+G35+G44+G54 -> 0 | H5: =H16+H26+H35+H44+H54 -> 0 | I5: =SUM(C5:H5) -> 0
B6: Total | C6: =SUM(C2:C5) -> 59742850925 | D6: =SUM(D2:D5) -> 0 | E6: =SUM(E2:E5) -> 0 | F6: =SUM(F2:F5) -> 19010440 | G6: =SUM(G2:G5) -> 138550812 | H6: =SUM(H2:H5) -> 3.4157135e+09 | I6: =SUM(I2:I5) -> 63316125713
C7: =C6=(C17+C27+C36+C45+C55) -> TRUE | D7: =D6=(D17+D27+D36+D45+D55) -> TRUE | E7: =E6=(E17+E27+E36+E45+E55) -> TRUE | F7: =F6=(F17+F27+F36+F45+F55) -> TRUE | H7: =H6=(H17+H27+H36+H45+H55) -> TRUE | I7: =I6=(I17+I27+I36+I45+I55) -> TRUE
B10: ASE 1
B11: Resumen Recaudo Aplicado Por Servicio
C12: ENEL | D12: CIUDAD LIMPIA | E12: EAB | F12: NUEVO ESQUEMA | G12: ENERBIT | H12: OCCIDENTE | I12: Total
B13: 1-APLICADOS A FACTURACION | C13: 16922955923 | H13: 5.2128716e+08 | I13: =SUM(C13:H13) -> 1.7444243e+10 | J13: =SUM(C13:H13)=I13 -> TRUE
B14: 2-SALDOS A FAVOR GENERADOS | C14: 25429155 | H14: 7990275.5 | I14: =SUM(C14:H14) -> 33419430 | J14: =SUM(C14:H14)=I14 -> TRUE
B15: 3-APLICADOS A FINANCIACIONES NUEVAS | C15: 0 | H15: 5300003 | I15: =SUM(C15:H15) -> 5300003 | J15: =SUM(C15:H15)=I15 -> TRUE
B16: 7-APLICADOS A RECIBOS SERVICIOS ESPECIALES | C16: 0 | I16: =SUM(C16:H16) -> 0 | J16: =SUM(C16:H16)=I16 -> TRUE
B17: Total | C17: =SUM(C13:C16) -> 16948385078 | D17: =SUM(D13:D16) -> 0 | E17: =SUM(E13:E16) -> 0 | F17: =SUM(F13:F16) -> 0 | G17: =SUM(G13:G16) -> 0 | H17: =SUM(H13:H16) -> 534577438 | I17: =SUM(I13:I16) -> 17482962516 | J17: =SUM(C17:H17)=I17 -> TRUE
B20: ASE 2
B21: Resumen Recaudo Aplicado Por Servicio
C22: ENEL | D22: CIUDAD LIMPIA | E22: EAB | F22: NUEVO ESQUEMA | G22: ENERBIT | H22: OCCIDENTE | I22: Total
B23: 1-APLICADOS A FACTURACION | C23: 12724393063 | E23: 0 | F23: 3445900 | H23: 1.3616741e+09 | I23: =SUM(C23:H23) -> 1.4089513e+10 | J23: =SUM(C23:H23)=I23 -> TRUE
B24: 2-SALDOS A FAVOR GENERADOS | C24: 27050219 | E24: 0 | F24: 8181830 | H24: 52788865 | I24: =SUM(C24:H24) -> 88020914 | J24: =SUM(C24:H24)=I24 -> TRUE
B25: 3-APLICADOS A FINANCIACIONES NUEVAS | C25: 0 | E25: 0 | F25: 0 | H25: 8486848.6 | I25: =SUM(C25:H25) -> 8486848.6 | J25: =SUM(C25:H25)=I25 -> TRUE
B26: 7-APLICADOS A RECIBOS SERVICIOS ESPECIALES | F26: 0 | H26: 0 | I26: =SUM(C26:H26) -> 0 | J26: =SUM(C26:H26)=I26 -> TRUE
B27: Total | C27: =SUM(C23:C26) -> 12751443282 | D27: =SUM(D23:D26) -> 0 | E27: =SUM(E23:E26) -> 0 | F27: =SUM(F23:F26) -> 11627730 | G27: =SUM(G23:G26) -> 0 | H27: =SUM(H23:H26) -> 1422949863 | I27: =SUM(I23:I26) -> 1.4186021e+10 | J27: =SUM(C27:H27)=I27 -> TRUE
B29: ASE 3
B30: Resumen Recaudo Aplicado Por Servicio
C31: ENEL | D31: CIUDAD LIMPIA | E31: EAB | F31: NUEVO ESQUEMA | G31: ENERBIT | H31: OCCIDENTE | I31: Total
B32: 1-APLICADOS A FACTURACION | C32: 10203127061 | F32: 0 | H32: 6.9348502e+08 | I32: =SUM(C32:H32) -> 1.0896612e+10 | J32: =SUM(C32:H32)=I32 -> TRUE
B33: 2-SALDOS A FAVOR GENERADOS | C33: 6025131 | F33: 0 | H33: 2921040 | I33: =SUM(C33:H33) -> 8946171 | J33: =SUM(C33:H33)=I33 -> TRUE
B34: 3-APLICADOS A FINANCIACIONES NUEVAS | C34: 0 | F34: 0 | H34: 2616838.9 | I34: =SUM(C34:H34) -> 2616838.9 | J34: =SUM(C34:H34)=I34 -> TRUE
B35: 7-APLICADOS A RECIBOS SERVICIOS ESPECIALES | C35: 0 | F35: 0 | I35: =SUM(C35:H35) -> 0 | J35: =SUM(C35:H35)=I35 -> TRUE
B36: Total | C36: =SUM(C32:C35) -> 10209152192 | D36: =SUM(D32:D35) -> 0 | E36: =SUM(E32:E35) -> 0 | F36: =SUM(F32:F35) -> 0 | G36: =SUM(G32:G35) -> 0 | H36: =SUM(H32:H35) -> 699022897 | I36: =SUM(I32:I35) -> 10908175089 | J36: =SUM(C36:H36)=I36 -> TRUE
B38: ASE 4
B39: Resumen Recaudo Aplicado Por Servicio
C40: ENEL | D40: CIUDAD LIMPIA | E40: EAB | F40: NUEVO ESQUEMA | G40: ENERBIT | H40: OCCIDENTE | I40: Total
B41: 1-APLICADOS A FACTURACION | C41: 11007626472 | E41: 0 | F41: 2157310 | H41: 4.4153236e+08 | I41: =SUM(C41:H41) -> 1.1451316e+10 | J41: =SUM(C41:H41)=I41 -> TRUE
B42: 2-SALDOS A FAVOR GENERADOS | C42: 27660196 | E42: 0 | F42: 5225400 | H42: 8186683.7 | I42: =SUM(C42:H42) -> 41072280 | J42: =SUM(C42:H42)=I42 -> TRUE
B43: 3-APLICADOS A FINANCIACIONES NUEVAS | C43: 0 | E43: 0 | F43: 0 | H43: 70882609 | I43: =SUM(C43:H43) -> 70882609 | J43: =SUM(C43:H43)=I43 -> TRUE
B44: 7-APLICADOS A RECIBOS SERVICIOS ESPECIALES | I44: =SUM(C44:H44) -> 0 | J44: =SUM(C44:H44)=I44 -> TRUE
B45: Total | C45: =SUM(C41:C44) -> 11035286668 | D45: =SUM(D41:D44) -> 0 | E45: =SUM(E41:E44) -> 0 | F45: =SUM(F41:F44) -> 7382710 | G45: =SUM(G41:G44) -> 0 | H45: =SUM(H41:H44) -> 5.2060165e+08 | I45: =SUM(I41:I44) -> 11563271030 | J45: =SUM(C45:H45)=I45 -> TRUE
B48: ASE 5
...

Sheet ANT EXT-REV
C1: ASE 1 | E1: ASE 2 | G1: ASE 3 | I1: ASE 4 | K1: ASE 5 | M1: TOTAL
C2: REPORTE 3 | D2: REPORTE 4 | E2: REPORTE 3 | F2: REPORTE 4 | G2: REPORTE 3 | H2: REPORTE 4 | I2: REPORTE 3 | J2: REPORTE 4 | K2: REPORTE 3 | L2: REPORTE 4 | M2: REPORTE 3 | N2: REPORTE 4
B3: APLICADO | C3: =C11+C19+C27+C35+C43 -> 42680 | D3: =D11+D19+D27+D35+D43 -> -3544507.3 | E3: =E11+E19+E27+E35+E43 -> 0 | F3: =F11+F19+F27+F35+F43 -> -8739602.4 | G3: =G11+G19+G27+G35+G43 -> 169120 | H3: =H11+H19+H27+H35+H43 -> -6125983.9 | I3: =I11+I19+I27+I35+I43 -> 8635714 | J3: =J11+J19+J27+J35+J43 -> -22250060 | ... L3: =L11+L19+L27+L35+L43 -> -9076100 | M3: =C3+E3+G3+I3+K3 -> 8908654 | N3: =D3+F3+H3+J3+L3 -> -49736253 | P3: =N3=(-VALIDACION_TOTAL!M9) -> TRUE
B4: ANTICIPOS | C4: =C12+C20+C28+C36+C44 -> 40630 | D4: =D12+D20+D28+D36+D44 -> -1752.71 | E4: =E12+E20+E28+E36+E44 -> 0 | F4: =F12+F20+F28+F36+F44 -> -310.63 | G4: =G12+G20+G28+G36+G44 -> 2320 | H4: =H12+H20+H28+H36+H44 -> -984746.11 | I4: =I12+I20+I28+I36+I44 -> 10812878 | J4: =J12+J20+J28+J36+J44 -> -459462.22 | ... L4: =L12+L20+L28+L36+L44 -> -133820 | M4: =C4+E4+G4+I4+K4 -> 11165808 | N4: =D4+F4+H4+J4+L4 -> -1580091.7 | P4: =N4=(-'CONSOLIDADO_TOTAL RECAUDO'!L131) -> TRUE
B5: TOTAL | C5: =SUM(C3:C4) -> 83310 | D5: =SUM(D3:D4) -> -3546260 | E5: =SUM(E3:E4) -> 0 | F5: =SUM(F3:F4) -> -8739913 | G5: =SUM(G3:G4) -> 171440 | H5: =SUM(H3:H4) -> -7110730 | I5: =SUM(I3:I4) -> 19448592 | J5: =SUM(J3:J4) -> -22709522 | ... N5: =SUM(N3:N4) -> -51316345
C6: =C5=(C13+C21+C29+C37+C45) -> TRUE | D6: =D5=(D13+D21+D29+D37+D45) -> TRUE | E6: =E5=(E13+E21+E29+E37+E45) -> TRUE | F6: =F5=(F13+F21+F29+F37+F45) -> TRUE | G6: =G5=(G13+G21+G29+G37+G45) -> TRUE | H6: =H5=(H13+H21+H29+H37+H45) -> TRUE | I6: =I5=(I13+I21+I29+I37+I45) -> TRUE | J6: =J5=(J13+J21+J29+J37+J45) -> TRUE | ... N6: =N5=(N13+N21+N29+N37+N45) -> TRUE
B8: BANCO DE OCCIDENTE
C9: ASE 1 | E9: ASE 2 | G9: ASE 3 | I9: ASE 4 | K9: ASE 5 | M9: TOTAL
C10: REPORTE 3 | D10: REPORTE 4 | E10: REPORTE 3 | F10: REPORTE 4 | G10: REPORTE 3 | H10: REPORTE 4 | I10: REPORTE 3 | J10: REPORTE 4 | K10: REPORTE 3 | L10: REPORTE 4 | M10: REPORTE 3 | N10: REPORTE 4
B11: APLICADO | C11: 42680 | D11: -83310 | E11: 0 | F11: 0 | G11: 33180 | H11: -34410 | I11: 239834 | J11: -1742535 | K11: 61140 | L11: -304780 | M11: =C11+E11+G11+I11+K11 -> 376834 | N11: =D11+F11+H11+J11+L11 -> -2165035
B12: ANTICIPOS | C12: 40630 | D12: 0 | E12: 0 | F12: 0 | G12: 1230 | H12: 0 | I12: 1438701 | J12: 0 | K12: 309980 | L12: -66340 | M12: =C12+E12+G12+I12+K12 -> 1790541 | N12: =D12+F12+H12+J12+L12 -> -66340
B13: TOTAL | C13: =SUM(C11:C12) -> 83310 | D13: =SUM(D11:D12) -> -83310 | E13: =SUM(E11:E12) -> 0 | F13: =SUM(F11:F12) -> 0 | G13: =SUM(G11:G12) -> 34410 | H13: =SUM(H11:H12) -> -34410 | I13: =SUM(I11:I12) -> 1678535 | J13: =SUM(J11:J12) -> -1742535 | ... N13: =SUM(N11:N12) -> -2231375
B16: EAAB RECIPROCIDAD
C17: ASE 1 | E17: ASE 2 | G17: ASE 3 | I17: ASE 4 | K17: ASE 5 | M17: TOTAL
C18: REPORTE 3 | D18: REPORTE 4 | E18: REPORTE 3 | F18: REPORTE 4 | G18: REPORTE 3 | H18: REPORTE 4 | I18: REPORTE 3 | J18: REPORTE 4 | K18: REPORTE 3 | L18: REPORTE 4 | M18: REPORTE 3 | N18: REPORTE 4
B19: APLICADO | C19: 0 | D19: 0 | E19: 0 | F19: 0 | G19: 0 | H19: 0 | I19: 208970 | J19: -262000 | K19: 0 | L19: 0 | M19: =C19+E19+G19+I19+K19 -> 208970 | N19: =D19+F19+H19+J19+L19 -> -262000
B20: ANTICIPOS | C20: 0 | D20: 0 | E20: 0 | F20: 0 | G20: 0 | H20: 0 | I20: 53030 | J20: 0 | K20: 0 | L20: 0 | M20: =C20+E20+G20+I20+K20 -> 53030 | N20: =D20+F20+H20+J20+L20 -> 0
B21: TOTAL | C21: =SUM(C19:C20) -> 0 | D21: =SUM(D19:D20) -> 0 | E21: =SUM(E19:E20) -> 0 | F21: =SUM(F19:F20) -> 0 | G21: =SUM(G19:G20) -> 0 | H21: =SUM(H19:H20) -> 0 | I21: =SUM(I19:I20) -> 262000 | J21: =SUM(J19:J20) -> -262000 | ... L21: =SUM(L19:L20) -> 0 | M21: =C21+E21+G21+I21+K21 -> 262000 | N21: =SUM(N19:N20) -> -262000
B24: EAAB CIUDAD LIMPIA
C25: ASE 1 | E25: ASE 2 | G25: ASE 3 | I25: ASE 4 | K25: ASE 5 | M25: TOTAL
C26: REPORTE 3 | D26: REPORTE 4 | E26: REPORTE 3 | F26: REPORTE 4 | G26: REPORTE 3 | H26: REPORTE 4 | I26: REPORTE 3 | J26: REPORTE 4 | K26: REPORTE 3 | L26: REPORTE 4 | M26: REPORTE 3 | N26: REPORTE 4
B27: APLICADO | C27: 0 | D27: 0 | E27: 0 | F27: 0 | G27: 0 | H27: 0 | I27: 0 | J27: 0 | K27: 0 | L27: 0 | M27: =C27+E27+G27+I27+K27 -> 0 | N27: =D27+F27+H27+J27+L27 -> 0
B28: ANTICIPOS | C28: 0 | D28: 0 | E28: 0 | F28: 0 | G28: 0 | H28: 0 | I28: 0 | J28: 0 | K28: 0 | L28: 0 | M28: =C28+E28+G28+I28+K28 -> 0 | N28: =D28+F28+H28+J28+L28 -> 0
B29: TOTAL | C29: =SUM(C27:C28) -> 0 | D29: =SUM(D27:D28) -> 0 | E29: =SUM(E27:E28) -> 0 | F29: =SUM(F27:F28) -> 0 | G29: =SUM(G27:G28) -> 0 | H29: =SUM(H27:H28) -> 0 | I29: =SUM(I27:I28) -> 0 | J29: =SUM(J27:J28) -> 0 | ... N29: =SUM(N27:N28) -> 0
B32: ENEL
C33: ASE 1 | E33: ASE 2 | G33: ASE 3 | I33: ASE 4 | K33: ASE 5 | M33: TOTAL
C34: REPORTE 3 | D34: REPORTE 4 | E34: REPORTE 3 | F34: REPORTE 4 | G34: REPORTE 3 | H34: REPORTE 4 | I34: REPORTE 3 | J34: REPORTE 4 | K34: REPORTE 3 | L34: REPORTE 4 | M34: REPORTE 3 | N34: REPORTE 4
B35: APLICADO | C35: 0 | D35: -3461197.3 | E35: 0 | F35: -8739602.4 | G35: 135940 | H35: -6091573.9 | I35: 8186910 | J35: -20245525 | K35: 0 | L35: -8771320 | M35: =C35+E35+G35+I35+K35 -> 8322850 | N35: =D35+F35+H35+J35+L35 -> -47309218
B36: ANTICIPOS | C36: 0 | D36: -1752.71 | E36: 0 | F36: -310.63 | G36: 1090 | H36: -984746.11 | I36: 9321147 | J36: -459462.22 | K36: 0 | L36: -67480 | M36: =C36+E36+G36+I36+K36 -> 9322237 | N36: =D36+F36+H36+J36+L36 -> -1513751.7
B37: TOTAL | C37: =SUM(C35:C36) -> 0 | D37: =SUM(D35:D36) -> -3462950 | E37: =SUM(E35:E36) -> 0 | F37: =SUM(F35:F36) -> -8739913 | G37: =SUM(G35:G36) -> 137030 | H37: =SUM(H35:H36) -> -7076320 | I37: =SUM(I35:I36) -> 17508057 | J37: =SUM(J35:J36) -> -20704987 | ... N37: =SUM(N35:N36) -> -48822970
B40: ENERBIT
C41: ASE 1 | E41: ASE 2 | G41: ASE 3 | I41: ASE 4 | K41: ASE 5 | M41: TOTAL
C42: REPORTE 3 | D42: REPORTE 4 | E42: REPORTE 3 | F42: REPORTE 4 | G42: REPORTE 3 | H42: REPORTE 4 | I42: REPORTE 3 | J42: REPORTE 4 | K42: REPORTE 3 | L42: REPORTE 4 | M42: REPORTE 3 | N42: REPORTE 4
B43: APLICADO | C43: 0 | D43: 0 | E43: 0 | F43: 0 | G43: 0 | H43: 0 | I43: 0 | J43: 0 | K43: 0 | L43: 0 | M43: =C43+E43+G43+I43+K43 -> 0 | N43: =D43+F43+H43+J43+L43 -> 0
B44: ANTICIPOS | C44: 0 | D44: 0 | E44: 0 | F44: 0 | G44: 0 | H44: 0 | I44: 0 | J44: 0 | K44: 0 | L44: 0 | M44: =C44+E44+G44+I44+K44 -> 0 | N44: =D44+F44+H44+J44+L44 -> 0
B45: TOTAL | C45: =SUM(C43:C44) -> 0 | D45: =SUM(D43:D44) -> 0 | E45: =SUM(E43:E44) -> 0 | F45: =SUM(F43:F44) -> 0 | G45: =SUM(G43:G44) -> 0 | H45: =SUM(H43:H44) -> 0 | I45: =SUM(I43:I44) -> 0 | J45: =SUM(J43:J44) -> 0 | ... N45: =SUM(N43:N44) -> 0

Sheet ANTICIPOS USUARIOS
B1: TOTAL | E1: RECIPROCIDAD | H1: ENEL | K1: ENERBIT | N1: OCCIDENTE | Q1: EAAB-CIUDADLIMPIA
B2: ASE | C2: ANTICIPOS GENERADOS POR PAGO | E2: ASE | F2: ANTICIPOS GENERADOS POR PAGO | H2: ASE | I2: ANTICIPOS GENERADOS POR PAGO | K2: ASE | L2: ANTICIPOS GENERADOS POR PAGO | N2: ASE | O2: ANTICIPOS GENERADOS POR PAGO | Q2: ASE | R2: ANTICIPOS GENERADOS POR PAGO | T2: Anticipos generados por pago
B3: 1 | C3: ='REPORTE RECAUDO x BANCO'!I14 -> 33419430 | E3: 1 | F3: ='REPORTE RECAUDO x BANCO'!F14 -> 0 | H3: 1 | I3: ='REPORTE RECAUDO x BANCO'!C14 -> 25429155 | K3: 1 | L3: ='REPORTE RECAUDO x BANCO'!G14 -> 0 | N3: 1 | O3: ='REPORTE RECAUDO x BANCO'!H14 -> 7990275.5 | Q3: 1 | R3: ='REPORTE RECAUDO x BANCO'!D14+'REPORTE RECAUDO x BANCO'!E14 -> 0 | T3: Sale del reporte Recaudo por Bancos.
B4: 2 | C4: ='REPORTE RECAUDO x BANCO'!I24 -> 88020914 | E4: 2 | F4: ='REPORTE RECAUDO x BANCO'!F24 -> 8181830 | H4: 2 | I4: ='REPORTE RECAUDO x BANCO'!C24 -> 27050219 | K4: 2 | L4: ='REPORTE RECAUDO x BANCO'!G24 -> 0 | N4: 2 | O4: ='REPORTE RECAUDO x BANCO'!H24 -> 52788865 | Q4: 2 | R4: ='REPORTE RECAUDO x BANCO'!D24+'REPORTE RECAUDO x BANCO'!E24 -> 0
B5: 3 | C5: ='REPORTE RECAUDO x BANCO'!I33 -> 8946171 | E5: 3 | F5: ='REPORTE RECAUDO x BANCO'!F33 -> 0 | H5: 3 | I5: ='REPORTE RECAUDO x BANCO'!C33 -> 6025131 | K5: 3 | L5: ='REPORTE RECAUDO x BANCO'!G33 -> 0 | N5: 3 | O5: ='REPORTE RECAUDO x BANCO'!H33 -> 2921040 | Q5: 3 | R5: ='REPORTE RECAUDO x BANCO'!D33+'REPORTE RECAUDO x BANCO'!E33 -> 0
B6: 4 | C6: ='REPORTE RECAUDO x BANCO'!I42 -> 41072280 | E6: 4 | F6: ='REPORTE RECAUDO x BANCO'!F42 -> 5225400 | H6: 4 | I6: ='REPORTE RECAUDO x BANCO'!C42 -> 27660196 | K6: 4 | L6: ='REPORTE RECAUDO x BANCO'!G42 -> 0 | N6: 4 | O6: ='REPORTE RECAUDO x BANCO'!H42 -> 8186683.7 | Q6: 4 | R6: ='REPORTE RECAUDO x BANCO'!D42+'REPORTE RECAUDO x BANCO'!E42 -> 0
B7: 5 | C7: ='REPORTE RECAUDO x BANCO'!I52 -> 14445987 | E7: 5 | F7: ='REPORTE RECAUDO x BANCO'!F52 -> 0 | H7: 5 | I7: ='REPORTE RECAUDO x BANCO'!C52 -> 9759043 | K7: 5 | L7: ='REPORTE RECAUDO x BANCO'!G52 -> 1379910 | N7: 5 | O7: ='REPORTE RECAUDO x BANCO'!H52 -> 3307034 | Q7: 5 | R7: ='REPORTE RECAUDO x BANCO'!D52+'REPORTE RECAUDO x BANCO'!E52 -> 0
C8: =SUM(C3:C7) -> 1.8590478e+08 | F8: =SUM(F3:F7) -> 13407230 | I8: =SUM(I3:I7) -> 95923744 | L8: =SUM(L3:L7) -> 1379910 | O8: =SUM(O3:O7) -> 75193898 | R8: =SUM(R3:R7) -> 0
C9: =C8='REPORTE RECAUDO x BANCO'!I3 -> TRUE | F9: =F8='REPORTE RECAUDO x BANCO'!F3 -> TRUE | I9: =I8='REPORTE RECAUDO x BANCO'!C3 -> TRUE | L9: =L8='REPORTE RECAUDO x BANCO'!G3 -> TRUE | O9: =O8='REPORTE RECAUDO x BANCO'!H3 -> TRUE | R9: =R8='REPORTE RECAUDO x BANCO'!D3+'REPORTE RECAUDO x BANCO'!E3 -> TRUE
B11: ASE | C11: ANTICIPOS GENERADOS POR EXTEMPORANEOS | E11: ASE | F11: ANTICIPOS GENERADOS POR EXTEMPORANEOS | H11: ASE | I11: ANTICIPOS GENERADOS POR EXTEMPORANEOS | K11: ASE | L11: ANTICIPOS GENERADOS POR EXTEMPORANEOS | N11: ASE | O11: ANTICIPOS GENERADOS POR EXTEMPORANEOS | Q11: ASE | R11: ANTICIPOS GENERADOS POR EXTEMPORANEOS | T11: Anticipos generados por pagos aplicados de reversiones
B12: 1 | C12: ='ANT EXT-REV'!C4 -> 40630 | E12: 1 | F12: ='ANT EXT-REV'!C20 -> 0 | H12: 1 | I12: ='ANT EXT-REV'!C36 -> 0 | K12: 1 | L12: ='ANT EXT-REV'!A12 -> 0 | N12: 1 | O12: ='ANT EXT-REV'!C12 -> 40630 | Q12: 1 | R12: ='ANT EXT-REV'!C28 -> 0 | T12: Sale del reporte Recaudo reversado
B13: 2 | C13: ='ANT EXT-REV'!E4 -> 0 | E13: 2 | F13: ='ANT EXT-REV'!E20 -> 0 | H13: 2 | I13: ='ANT EXT-REV'!E36 -> 0 | K13: 2 | L13: ='ANT EXT-REV'!E44 -> 0 | N13: 2 | O13: ='ANT EXT-REV'!E12 -> 0 | Q13: 2 | R13: ='ANT EXT-REV'!E28 -> 0
B14: 3 | C14: ='ANT EXT-REV'!G4 -> 2320 | E14: 3 | F14: ='ANT EXT-REV'!G20 -> 0 | H14: 3 | I14: ='ANT EXT-REV'!G36 -> 1090 | K14: 3 | L14: ='ANT EXT-REV'!G44 -> 0 | N14: 3 | O14: ='ANT EXT-REV'!G12 -> 1230 | Q14: 3 | R14: ='ANT EXT-REV'!G28 -> 0
B15: 4 | C15: ='ANT EXT-REV'!I4 -> 10812878 | E15: 4 | F15: ='ANT EXT-REV'!I20 -> 53030 | H15: 4 | I15: ='ANT EXT-REV'!I36 -> 9321147 | K15: 4 | L15: ='ANT EXT-REV'!I44 -> 0 | N15: 4 | O15: ='ANT EXT-REV'!I12 -> 1438701 | Q15: 4 | R15: ='ANT EXT-REV'!I28 -> 0
B16: 5 | C16: ='ANT EXT-REV'!K4 -> 309980 | E16: 5 | F16: ='ANT EXT-REV'!K20 -> 0 | H16: 5 | I16: ='ANT EXT-REV'!K36 -> 0 | K16: 5 | L16: ='ANT EXT-REV'!K44 -> 0 | N16: 5 | O16: ='ANT EXT-REV'!K12 -> 309980 | Q16: 5 | R16: ='ANT EXT-REV'!K28 -> 0
C17: =SUM(C12:C16) -> 11165808 | F17: =SUM(F12:F16) -> 53030 | I17: =SUM(I12:I16) -> 9322237 | L17: =SUM(L12:L16) -> 0 | O17: =SUM(O12:O16) -> 1790541 | R17: =SUM(R12:R16) -> 0
C18: =C17='ANT EXT-REV'!M4 -> TRUE | F18: =F17='ANT EXT-REV'!M20 -> TRUE | I18: =I17='ANT EXT-REV'!M36 -> TRUE | L18: =L17='ANT EXT-REV'!M44 -> TRUE | O18: =O17='ANT EXT-REV'!M12 -> TRUE | R18: =R17='ANT EXT-REV'!M28 -> TRUE
B20: ASE | C20: ANTICIPOS QUE CARGAN POR REVERSIONES | E20: ASE | F20: ANTICIPOS QUE CARGAN POR REVERSIONES | H20: ASE | I20: ANTICIPOS QUE CARGAN POR REVERSIONES | K20: ASE | L20: ANTICIPOS QUE CARGAN POR REVERSIONES | N20: ASE | O20: ANTICIPOS QUE CARGAN POR REVERSIONES | Q20: ASE | R20: ANTICIPOS QUE CARGAN POR REVERSIONES | T20: Anticipos que cargan de reversiones
B21: 1 | C21: ='ANT EXT-REV'!D4 -> -1752.71 | E21: 1 | F21: ='ANT EXT-REV'!D20 -> 0 | H21: 1 | I21: ='ANT EXT-REV'!D36 -> -1752.71 | K21: 1 | L21: ='ANT EXT-REV'!D44 -> 0 | N21: 1 | O21: ='ANT EXT-REV'!D12 -> 0 | Q21: 1 | R21: ='ANT EXT-REV'!D28 -> 0 | T21: Sale del reporte Recaudo reversado
B22: 2 | C22: ='ANT EXT-REV'!F4 -> -310.63 | E22: 2 | F22: ='ANT EXT-REV'!F20 -> 0 | H22: 2 | I22: ='ANT EXT-REV'!F36 -> -310.63 | K22: 2 | L22: ='ANT EXT-REV'!F44 -> 0 | N22: 2 | O22: ='ANT EXT-REV'!F12 -> 0 | Q22: 2 | R22: ='ANT EXT-REV'!F28 -> 0
B23: 3 | C23: ='ANT EXT-REV'!H4 -> -984746.11 | E23: 3 | F23: ='ANT EXT-REV'!H20 -> 0 | H23: 3 | I23: ='ANT EXT-REV'!H36 -> -984746.11 | K23: 3 | L23: ='ANT EXT-REV'!H44 -> 0 | N23: 3 | O23: ='ANT EXT-REV'!H12 -> 0 | Q23: 3 | R23: ='ANT EXT-REV'!H28 -> 0
B24: 4 | C24: ='ANT EXT-REV'!J4 -> -459462.22 | E24: 4 | F24: ='ANT EXT-REV'!J20 -> 0 | H24: 4 | I24: ='ANT EXT-REV'!J36 -> -459462.22 | K24: 4 | L24: ='ANT EXT-REV'!J44 -> 0 | N24: 4 | O24: ='ANT EXT-REV'!J12 -> 0 | Q24: 4 | R24: ='ANT EXT-REV'!J28 -> 0
B25: 5 | C25: ='ANT EXT-REV'!L4 -> -133820 | E25: 5 | F25: ='ANT EXT-REV'!L20 -> 0 | H25: 5 | I25: ='ANT EXT-REV'!L36 -> -67480 | K25: 5 | L25: ='ANT EXT-REV'!L44 -> 0 | N25: 5 | O25: ='ANT EXT-REV'!L12 -> -66340 | Q25: 5 | R25: ='ANT EXT-REV'!L28 -> 0
C26: =SUM(C21:C25) -> -1580091.7 | F26: =SUM(F21:F25) -> 0 | I26: =SUM(I21:I25) -> -1513751.7 | L26: =SUM(L21:L25) -> 0 | O26: =SUM(O21:O25) -> -66340 | R26: =SUM(R21:R25) -> 0
C27: =C26='ANT EXT-REV'!N4 -> TRUE | F27: =F26='ANT EXT-REV'!N20 -> TRUE | I27: =I26='ANT EXT-REV'!N36 -> TRUE | L27: =L26='ANT EXT-REV'!N44 -> TRUE | O27: =O26='ANT EXT-REV'!N12 -> TRUE | R27: =R26='ANT EXT-REV'!N28 -> TRUE

Sheet BCE SC POR FACT.
C2: ASE | D2: SUBSIDIO | E2: CONTRIBUCION | F2: TOTAL BSC | H2: SISTEMA
C3: 1 | D3: -1.2144311e+09 | E3: 3.8037668e+09 | F3: =D3+E3 -> 2.5893357e+09 | H3: =DetRetri2026091!J9 -> 2589335717 | I3: =F3-H3 -> -0.46000004
C4: 2 | D4: -7.0202293e+09 | E4: 1.9269695e+09 | F4: =D4+E4 -> -5.0932598e+09 | H4: =DetRetri2026091!J10 -> -5093259797 | I4: =F4-H4 -> -0.21999931
C5: 3 | D5: -3.1336986e+09 | E5: 1.9033016e+09 | F5: =D5+E5 -> -1.230397e+09 | H5: =DetRetri2026091!J11 -> -1230396998 | I5: =F5-H5 -> -0.43999982
C6: 4 | D6: -4.4790574e+08 | E6: 4.8603964e+08 | F6: =D6+E6 -> 38133906 | H6: =DetRetri2026091!J12 -> 38133906 | I6: =F6-H6 -> -0.19999999
C7: 5 | D7: -2.5354614e+09 | E7: 1.3113607e+09 | F7: =D7+E7 -> -1.2241007e+09 | H7: =DetRetri2026091!J13 -> -1224100690 | I7: =F7-H7 -> -0.46000028
F9: =SUM(F3:F7) -> -4.9202879e+09 | H9: =SUM(H3:H7) -> -4920287862 | I9: =F9-H9 -> -1.7799988
H10: =H9=DetRetri2026091!J14 -> TRUE
D11: =SUM(D3:D7) -> -1.4351726e+10 | E11: =SUM(E3:E7) -> 9.4314383e+09 | F11: =SUM(D3:E7) -> -4.9202879e+09
F12: =ROUND(F11,2)=ROUND(F9,2) -> TRUE
F13: =ROUND(F11,2)-ROUND(F9,2) -> 0
D18: ASE | E18: REMUN TOTAL | F18: VALIDA 1 | G18: VALIDA 2 | H18: DIFERENCIA VALIDA 2
D19: 1 | E19: ='CONSOLIDADO_TOTAL RECAUDO'!J104 -> 2.5893357e+09 | F19: =E19=F3 -> TRUE | G19: =E19=H3 -> FALSE | H19: =E19-H3 -> -0.46000004
D20: 2 | E20: ='CONSOLIDADO_TOTAL RECAUDO'!J105 -> -5.0932598e+09 | F20: =E20=F4 -> TRUE | G20: =E20=H4 -> FALSE | H20: =E20-H4 -> -0.21999931
D21: 3 | E21: ='CONSOLIDADO_TOTAL RECAUDO'!J106 -> -1.230397e+09 | F21: =E21=F5 -> TRUE | G21: =E21=H5 -> FALSE | H21: =E21-H5 -> -0.43999982
D22: 4 | E22: ='CONSOLIDADO_TOTAL RECAUDO'!J107 -> 38133906 | F22: =E22=F6 -> TRUE | G22: =E22=H6 -> FALSE | H22: =E22-H6 -> -0.19999999
D23: 5 | E23: ='CONSOLIDADO_TOTAL RECAUDO'!J108 -> -1.2241007e+09 | F23: =E23=F7 -> TRUE | G23: =E23=H7 -> FALSE | H23: =E23-H7 -> -0.46000028
E24: =SUM(E19:E23) -> -4.9202879e+09 | F24: =E24=F9 -> TRUE | G24: =E24=H9 -> FALSE | H24: =E24-H9 -> -1.7799988

Sheet Reporte Componentes R1
B4: PROMOAMBIENTAL
F5: Total | G5: Componente TDF | H5: Componente TTL | I5: Componente TVIAT | J5: Aprovechamiento | K5: CCSA Prest.Aprov. | L5: SERVICIO ESPECIALES | M5: Componente TCS | N5: Componente TLU | O5: Componente TBL | P5: Componente TRT | Q5: CCSA Prest. No Aprov. | R5: Ajuste Decena | S5: Ajuste Recargo Aseo | T5: Intereses Cte Financiac. Aseo | U5: Exonera-Recargo Aseo | V5: Exonera-Ajuste Decena Aseo | W5: Exonera-Recargo Aseo | X5: Exonera-Recargo Aseo | Y5: Intereses Cte Financiac. Aseo | Z5: Rec.Intereses
E6: Vlr Servicio | F6: -7108.83 | G6: -502.98 | H6: -213.69 | I6: -93.3 | J6: -1231.48 | K6: -79.58 | L6: 0 | M6: -698.02 | N6: -584.16 | O6: -2331.79 | P6: -1243.99 | Q6: -129.84 | R6: 0 | S6: 0 | T6: 0 | U6: 0 | V6: 0 | W6: 0 | X6: 0 | Y6: 0 | Z6: 0
D7: E | E7: Total | F7: -7108.83 | G7: -502.98 | H7: -213.69 | I7: -93.3 | J7: -1231.48 | K7: -79.58 | L7: 0 | M7: -698.02 | N7: -584.16 | O7: -2331.79 | P7: -1243.99 | Q7: -129.84 | R7: 0 | S7: 0 | T7: 0 | U7: 0 | V7: 0 | W7: 0 | X7: 0 | Y7: 0 | Z7: 0
C8: ENEL | D8: Total | F8: -7108.83 | G8: -502.98 | H8: -213.69 | I8: -93.3 | J8: -1231.48 | K8: -79.58 | L8: 0 | M8: -698.02 | N8: -584.16 | O8: -2331.79 | P8: -1243.99 | Q8: -129.84 | R8: 0 | S8: 0 | T8: 0 | U8: 0 | V8: 0 | W8: 0 | X8: 0 | Y8: 0 | Z8: 0
B9: Mes | C9: Total | F9: -7108.83 | G9: -502.98 | H9: -213.69 | I9: -93.3 | J9: -1231.48 | K9: -79.58 | L9: 0 | M9: -698.02 | N9: -584.16 | O9: -2331.79 | P9: -1243.99 | Q9: -129.84 | R9: 0 | S9: 0 | T9: 0 | U9: 0 | V9: 0 | W9: 0 | X9: 0 | Y9: 0 | Z9: 0
A10: AFaseo | B10: Total | F10: -7108.83 | G10: -502.98 | H10: -213.69 | I10: -93.3 | J10: -1231.48 | K10: -79.58 | L10: 0 | M10: -698.02 | N10: -584.16 | O10: -2331.79 | P10: -1243.99 | Q10: -129.84 | R10: 0 | S10: 0 | T10: 0 | U10: 0 | V10: 0 | W10: 0 | X10: 0 | Y10: 0 | Z10: 0
E11: Vlr Servicio | F11: 42672.75 | G11: 2083.59 | H11: 1160.96 | I11: 617.46 | J11: 10415.64 | K11: 383.02 | L11: 0 | M11: 3359.81 | N11: 3220.39 | O11: 15117.23 | P11: 5690.79 | Q11: 624.92 | R11: -1.06 | S11: 0 | T11: 0 | U11: 0 | V11: 0 | W11: 0 | X11: 0 | Y11: 0 | Z11: 0
E12: Vlr Intereses | F12: 7.25 | G12: 0.35 | H12: 0.2 | I12: 0.1 | J12: 1.77 | K12: 0.07 | L12: 0 | M12: 0.57 | N12: 0.54 | O12: 2.57 | P12: 0.97 | Q12: 0.11 | R12: 0 | S12: 0 | T12: 0 | U12: 0 | V12: 0 | W12: 0 | X12: 0 | Y12: 0 | Z12: 0
D13: T | E13: Total | F13: 42680 | G13: 2083.94 | H13: 1161.16 | I13: 617.56 | J13: 10417.41 | K13: 383.09 | L13: 0 | M13: 3360.38 | N13: 3220.93 | O13: 15119.8 | P13: 5691.76 | Q13: 625.03 | R13: -1.06 | S13: 0 | T13: 0 | U13: 0 | V13: 0 | W13: 0 | X13: 0 | Y13: 0 | Z13: 0
C14: OCCIDENTE | D14: Total | F14: 42680 | G14: 2083.94 | H14: 1161.16 | I14: 617.56 | J14: 10417.41 | K14: 383.09 | L14: 0 | M14: 3360.38 | N14: 3220.93 | O14: 15119.8 | P14: 5691.76 | Q14: 625.03 | R14: -1.06 | S14: 0 | T14: 0 | U14: 0 | V14: 0 | W14: 0 | X14: 0 | Y14: 0 | Z14: 0
B15: Aplicacion nuevos x reversion | C15: Total | F15: 42680 | G15: 2083.94 | H15: 1161.16 | I15: 617.56 | J15: 10417.41 | K15: 383.09 | L15: 0 | M15: 3360.38 | N15: 3220.93 | O15: 15119.8 | P15: 5691.76 | Q15: 625.03 | R15: -1.06 | S15: 0 | T15: 0 | U15: 0 | V15: 0 | W15: 0 | X15: 0 | Y15: 0 | Z15: 0
E16: Vlr Servicio | F16: 1.9865858e+10 | G16: 9.4982754e+08 | H16: 5.3058782e+08 | I16: 2.8117925e+08 | J16: 4.8115398e+09 | K16: 1.8047125e+08 | L16: 28843603 | M16: 1.5840574e+09 | N16: 1.5109569e+09 | O16: 7.108873e+09 | P16: 2.585077e+09 | Q16: 2.9449051e+08 | R16: -46186.47 | S16: 0 | T16: 0 | U16: 0 | V16: 0 | W16: 0 | X16: 0 | Y16: 0 | Z16: 0
E17: Vlr Intereses | F17: 3221187.2 | G17: 191257.04 | H17: 96240.8 | I17: 48070.33 | J17: 691627.43 | K17: 30779.35 | L17: 1888.23 | M17: 270442.29 | N17: 245214.4 | O17: 1082415 | P17: 513014.61 | Q17: 50206.13 | R17: -5.69 | S17: 0 | T17: 53.13 | U17: 0 | V17: 0 | W17: 0 | X17: 0 | Y17: 0 | Z17: -15.86
D18: E | E18: Total | F18: 1.9869079e+10 | G18: 9.500188e+08 | H18: 5.3068406e+08 | I18: 2.8122732e+08 | J18: 4.8122314e+09 | K18: 1.8050203e+08 | L18: 28845491 | M18: 1.5843279e+09 | N18: 1.5112021e+09 | O18: 7.1099554e+09 | P18: 2.58559e+09 | Q18: 2.9454072e+08 | R18: -46192.16 | S18: 0 | T18: 53.13 | U18: 0 | V18: 0 | W18: 0 | X18: 0 | Y18: 0 | Z18: -15.86
C19: ENEL | D19: Total | F19: 1.9869079e+10 | G19: 9.500188e+08 | H19: 5.3068406e+08 | I19: 2.8122732e+08 | J19: 4.8122314e+09 | K19: 1.8050203e+08 | L19: 28845491 | M19: 1.5843279e+09 | N19: 1.5112021e+09 | O19: 7.1099554e+09 | P19: 2.58559e+09 | Q19: 2.9454072e+08 | R19: -46192.16 | S19: 0 | T19: 53.13 | U19: 0 | V19: 0 | W19: 0 | X19: 0 | Y19: 0 | Z19: -15.86
E20: Vlr Servicio | F20: 34834776 | G20: 3050420.4 | H20: 1694569.4 | I20: 901684.59 | J20: 6258963.8 | K20: 206736.51 | L20: 0 | M20: 1810170.8 | N20: 2156347.4 | O20: 10098959 | P20: 8319284.7 | Q20: 337911.22 | R20: -271.21 | S20: 0 | T20: 0 | U20: 0 | V20: 0 | W20: 0 | X20: 0 | Y20: 0 | Z20: 0
E21: Vlr Intereses | F21: 73612.43 | G21: 3963.92 | H21: 2089.52 | I21: 1132.4 | J21: 18172.87 | K21: 548.71 | L21: 0 | M21: 4821.44 | N21: 5503.49 | O21: 25681.1 | P21: 10802.17 | Q21: 897.07 | R21: -0.3 | S21: 0 | T21: 0.04 | U21: 0 | V21: 0 | W21: 0 | X21: 0 | Y21: 0 | Z21: 0
D22: H | E22: Total | F22: 34908389 | G22: 3054384.4 | H22: 1696658.9 | I22: 902816.99 | J22: 6277136.7 | K22: 207285.22 | L22: 0 | M22: 1814992.3 | N22: 2161850.9 | O22: 10124640 | P22: 8330086.8 | Q22: 338808.29 | R22: -271.51 | S22: 0 | T22: 0.04 | U22: 0 | V22: 0 | W22: 0 | X22: 0 | Y22: 0 | Z22: 0
E23: Vlr Servicio | F23: 99460670 | G23: 8743467.5 | H23: 4501924.5 | I23: 2257268.8 | J23: 15226576 | K23: 720340.83 | L23: 71191.32 | M23: 6347720.1 | N23: 6458242.7 | O23: 29949150 | P23: 24008686 | Q23: 1175914.7 | R23: 186.99 | S23: 0 | T23: 0 | U23: 0 | V23: 0 | W23: 0 | X23: 0 | Y23: 0 | Z23: 0
E24: Vlr Intereses | F24: 8554576 | G24: 822696.95 | H24: 248641.09 | I24: 50902.54 | J24: 1306165.8 | K24: 80047.98 | L24: 0 | M24: 702034.32 | N24: 586868.46 | O24: 2182750.4 | P24: 2443333.5 | Q24: 130594.62 | R24: 184.84 | S24: 0 | T24: 355.38 | U24: 0 | V24: 0 | W24: 0 | X24: 0 | Y24: 0 | Z24: 0
D25: O | E25: Total | F25: 1.0801525e+08 | G25: 9566164.5 | H25: 4750565.5 | I25: 2308171.3 | J25: 16532742 | K25: 800388.81 | L25: 71191.32 | M25: 7049754.4 | N25: 7045111.2 | O25: 32131901 | P25: 26452020 | Q25: 1306509.3 | R25: 371.83 | S25: 0 | T25: 355.38 | U25: 0 | V25: 0 | W25: 0 | X25: 0 | Y25: 0 | Z25: 0
E26: Vlr Servicio | F26: 2.3738431e+08 | G26: 38284622 | H26: 21414097 | I26: 11342632 | J26: 19779058 | K26: 508140.34 | L26: 1717780 | M26: 4440916.8 | N26: 6082873.5 | O26: 28426345 | P26: 1.0455968e+08 | Q26: 828965.34 | R26: -796.43 | S26: 0 | T26: 0 | U26: 0 | V26: 0 | W26: 0 | X26: 0 | Y26: 0 | Z26: 0
E27: Vlr Intereses | F27: 1223054.1 | G27: 158799.91 | H27: 78943.63 | I27: 38013.15 | J27: 162199.93 | K27: 5653.98 | L27: 1207.03 | M27: 49618.45 | N27: 61442.74 | O27: 241587.84 | P27: 416341.81 | Q27: 9230.55 | R27: 15.01 | S27: -0.06 | T27: 0.11 | U27: 0 | V27: 0 | W27: 0 | X27: 0 | Y27: 0 | Z27: 0
D28: T | E28: Total | F28: 2.3860737e+08 | G28: 38443422 | H28: 21493041 | I28: 11380645 | J28: 19941258 | K28: 513794.32 | L28: 1718987 | M28: 4490535.3 | N28: 6144316.2 | O28: 28667933 | P28: 1.0497602e+08 | Q28: 838195.89 | R28: -781.42 | S28: -0.06 | T28: 0.11 | U28: 0 | V28: 0 | W28: 0 | X28: 0 | Y28: 0 | Z28: 0
C29: OCCIDENTE | D29: Total | F29: 3.81531e+08 | G29: 51063971 | H29: 27940265 | I29: 14591634 | J29: 42751137 | K29: 1521468.4 | L29: 1790178.4 | M29: 13355282 | N29: 15351278 | O29: 70924473 | P29: 1.3975813e+08 | Q29: 2483513.5 | R29: -681.1 | S29: -0.06 | T29: 355.53 | U29: 0 | V29: 0 | W29: 0 | X29: 0 | Y29: 0 | Z29: 0
B30: Mes | C30: Total | F30: 2.025061e+10 | G30: 1.0010828e+09 | H30: 5.5862433e+08 | I30: 2.9581895e+08 | J30: 4.8549825e+09 | K30: 1.820235e+08 | L30: 30635670 | M30: 1.5976832e+09 | N30: 1.5265534e+09 | O30: 7.1808799e+09 | P30: 2.7253481e+09 | Q30: 2.9702423e+08 | R30: -46873.26 | S30: -0.06 | T30: 408.66 | U30: 0 | V30: 0 | W30: 0 | X30: 0 | Y30: 0 | Z30: -15.86
A31: Componente | B31: Total | F31: 2.0250653e+10 | G31: 1.0010849e+09 | H31: 5.5862549e+08 | I31: 2.9581957e+08 | J31: 4.8549929e+09 | K31: 1.8202388e+08 | L31: 30635670 | M31: 1.5976865e+09 | N31: 1.5265566e+09 | O31: 7.180895e+09 | P31: 2.7253538e+09 | Q31: 2.9702486e+08 | R31: -46874.32 | S31: -0.06 | T31: 408.66 | U31: 0 | V31: 0 | W31: 0 | X31: 0 | Y31: 0 | Z31: -15.86
E32: Subsidio(-)/Contribucion(+) | F32: -2.946116e+09 | G32: -66231005 | H32: -36832734 | I32: -19652614 | J32: -8.2718576e+08 | K32: -30673428 | L32: 0 | M32: -2.6937726e+08 | N32: -2.5777835e+08 | O32: -1.2109156e+09 | P32: -1.7742294e+08 | Q32: -50046274 | R32: 0 | S32: 0 | T32: 0 | U32: 0 | V32: 0 | W32: 0 | X32: 0 | Y32: 0 | Z32: 0
D33: E | E33: Total | F33: -2.946116e+09 | G33: -66231005 | H33: -36832734 | I33: -19652614 | J33: -8.2718576e+08 | K33: -30673428 | L33: 0 | M33: -2.6937726e+08 | N33: -2.5777835e+08 | O33: -1.2109156e+09 | P33: -1.7742294e+08 | Q33: -50046274 | R33: 0 | S33: 0 | T33: 0 | U33: 0 | V33: 0 | W33: 0 | X33: 0 | Y33: 0 | Z33: 0
C34: ENEL | D34: Total | F34: -2.946116e+09 | G34: -66231005 | H34: -36832734 | I34: -19652614 | J34: -8.2718576e+08 | K34: -30673428 | L34: 0 | M34: -2.6937726e+08 | N34: -2.5777835e+08 | O34: -1.2109156e+09 | P34: -1.7742294e+08 | Q34: -50046274 | R34: 0 | S34: 0 | T34: 0 | U34: 0 | V34: 0 | W34: 0 | X34: 0 | Y34: 0 | Z34: 0
E35: Subsidio(-)/Contribucion(+) | F35: 6948561.3 | G35: 1410581.2 | H35: 792768.83 | I35: 419896.52 | J35: 180596.23 | K35: -3882.3 | L35: 0 | M35: -34057.21 | N35: 57414.32 | O35: 271593.35 | P35: 3859983.6 | Q35: -6333.32 | R35: 0 | S35: 0 | T35: 0 | U35: 0 | V35: 0 | W35: 0 | X35: 0 | Y35: 0 | Z35: 0
D36: H | E36: Total | F36: 6948561.3 | G36: 1410581.2 | H36: 792768.83 | I36: 419896.52 | J36: 180596.23 | K36: -3882.3 | L36: 0 | M36: -34057.21 | N36: 57414.32 | O36: 271593.35 | P36: 3859983.6 | Q36: -6333.32 | R36: 0 | S36: 0 | T36: 0 | U36: 0 | V36: 0 | W36: 0 | X36: 0 | Y36: 0 | Z36: 0
E37: Subsidio(-)/Contribucion(+) | F37: 18379766 | G37: 3896523 | H37: 1932685.5 | I37: 904936.27 | J37: 174866.47 | K37: -4332.57 | L37: 0 | M37: -47024.58 | N37: 133689.19 | O37: 548414.37 | P37: 10847077 | Q37: -7068.65 | R37: 0 | S37: 0 | T37: 0 | U37: 0 | V37: 0 | W37: 0 | X37: 0 | Y37: 0 | Z37: 0
D38: O | E38: Total | F38: 18379766 | G38: 3896523 | H38: 1932685.5 | I38: 904936.27 | J38: 174866.47 | K38: -4332.57 | L38: 0 | M38: -47024.58 | N38: 133689.19 | O38: 548414.37 | P38: 10847077 | Q38: -7068.65 | R38: 0 | S38: 0 | T38: 0 | U38: 0 | V38: 0 | W38: 0 | X38: 0 | Y38: 0 | Z38: 0
E39: Subsidio(-)/Contribucion(+) | F39: 1.1972783e+08 | G39: 21174918 | H39: 11896575 | I39: 6266740.5 | J39: 7356037.8 | K39: 191531.36 | L39: 0 | M39: 1677524.2 | N39: 2303267 | O39: 10782216 | P39: 57766394 | Q39: 312627.59 | R39: 0 | S39: 0 | T39: 0 | U39: 0 | V39: 0 | W39: 0 | X39: 0 | Y39: 0 | Z39: 0
D40: T | E40: Total | F40: 1.1972783e+08 | G40: 21174918 | H40: 11896575 | I40: 6266740.5 | J40: 7356037.8 | K40: 191531.36 | L40: 0 | M40: 1677524.2 | N40: 2303267 | O40: 10782216 | P40: 57766394 | Q40: 312627.59 | R40: 0 | S40: 0 | T40: 0 | U40: 0 | V40: 0 | W40: 0 | X40: 0 | Y40: 0 | Z40: 0
C41: OCCIDENTE | D41: Total | F41: 1.4505616e+08 | G41: 26482022 | H41: 14622030 | I41: 7591573.3 | J41: 7711500.5 | K41: 183316.49 | L41: 0 | M41: 1596442.5 | N41: 2494370.5 | O41: 11602224 | P41: 72473455 | Q41: 299225.62 | R41: 0 | S41: 0 | T41: 0 | U41: 0 | V41: 0 | W41: 0 | X41: 0 | Y41: 0 | Z41: 0
B42: Mes | C42: Total | F42: -2.8010598e+09 | G42: -39748983 | H42: -22210705 | I42: -12061041 | J42: -8.1947426e+08 | K42: -30490112 | L42: 0 | M42: -2.6778081e+08 | N42: -2.5528398e+08 | O42: -1.1993134e+09 | P42: -1.0494949e+08 | Q42: -49747048 | R42: 0 | S42: 0 | T42: 0 | U42: 0 | V42: 0 | W42: 0 | X42: 0 | Y42: 0 | Z42: 0
A43: Subs/Cont | B43: Total | F43: -2.8010598e+09 | G43: -39748983 | H43: -22210705 | I43: -12061041 | J43: -8.1947426e+08 | K43: -30490112 | L43: 0 | M43: -2.6778081e+08 | N43: -2.5528398e+08 | O43: -1.1993134e+09 | P43: -1.0494949e+08 | Q43: -49747048 | R43: 0 | S43: 0 | T43: 0 | U43: 0 | V43: 0 | W43: 0 | X43: 0 | Y43: 0 | Z43: 0
...

Sheet Rem. Anticipos R2
B1: PROMOAMBIENTAL
E2: Total | F2: Componente TDF | G2: Componente TTL | H2: Componente TVIAT | I2: Aprovechamiento | J2: CCSA Prest.Aprov. | K2: Especiales | L2: Componente TCS | M2: Componente TLU | N2: Componente TBL | O2: Componente TRT | P2: CCSA Prest. No Aprov. | Q2: Deb/Cred | R2: Deb/Cred-otros
D3: Vlr Servicio | E3: 29113116 | F3: 1628607.2 | G3: 888839.63 | H3: 520100 | I3: 4494462.8 | J3: 206660.7 | K3: 0 | L3: 2285816.4 | M3: 2318036.2 | N3: 11916210 | O3: 4523138.8 | P3: 331271.2 | Q3: -26.69 | R3: 0
D4: Vlr Intereses | E4: 1903.01 | F4: 73.46 | G4: 40.2 | H4: 21.55 | I4: 326.7 | J4: 21.37 | K4: 0 | L4: 192.26 | M4: 174.97 | N4: 818.31 | O4: 199.3 | P4: 34.85 | Q4: 0.04 | R4: 0
C5: E | D5: Total | E5: 29115019 | F5: 1628680.7 | G5: 888879.83 | H5: 520121.55 | I5: 4494789.5 | J5: 206682.07 | K5: 0 | L5: 2286008.7 | M5: 2318211.1 | N5: 11917028 | O5: 4523338.1 | P5: 331306.05 | Q5: -26.65 | R5: 0
B6: ENEL | C6: Total | E6: 29115019 | F6: 1628680.7 | G6: 888879.83 | H6: 520121.55 | I6: 4494789.5 | J6: 206682.07 | K6: 0 | L6: 2286008.7 | M6: 2318211.1 | N6: 11917028 | O6: 4523338.1 | P6: 331306.05 | Q6: -26.65 | R6: 0
D7: Vlr Servicio | E7: 793692.13 | F7: 30716.86 | G7: 16909.04 | H7: 9688.4 | I7: 151298.66 | J7: 7470.71 | K7: 0 | L7: 68892.29 | M7: 68745.87 | N7: 346268.88 | O7: 81506.79 | P7: 12188.93 | Q7: 5.7 | R7: 0
D8: Vlr Intereses | E8: 390.56 | F8: 13.47 | G8: 6.62 | H8: 4.12 | I8: 56.72 | J8: 4.51 | K8: 0 | L8: 39.61 | M8: 38.85 | N8: 182.43 | O8: 36.86 | P8: 7.36 | Q8: 0.01 | R8: 0
C9: H | D9: Total | E9: 794082.69 | F9: 30730.33 | G9: 16915.66 | H9: 9692.52 | I9: 151355.38 | J9: 7475.22 | K9: 0 | L9: 68931.9 | M9: 68784.72 | N9: 346451.31 | O9: 81543.65 | P9: 12196.29 | Q9: 5.71 | R9: 0
D10: Vlr Servicio | E10: 462871.22 | F10: 17750.61 | G10: 9935.12 | H10: 5797.01 | I10: 63590.58 | J10: 4697.55 | K10: 0 | L10: 43276.6 | M10: 42645.09 | N10: 218816.26 | O10: 48699.89 | P10: 7664.33 | Q10: -1.82 | R10: 0
C11: O | D11: Total | E11: 462871.22 | F11: 17750.61 | G11: 9935.12 | H11: 5797.01 | I11: 63590.58 | J11: 4697.55 | K11: 0 | L11: 43276.6 | M11: 42645.09 | N11: 218816.26 | O11: 48699.89 | P11: 7664.33 | Q11: -1.82 | R11: 0
D12: Vlr Servicio | E12: 2198318.9 | F12: 188049.69 | G12: 89756.71 | H12: 48201.07 | I12: 310657.06 | J12: 11520.24 | K12: 0 | L12: 108962.88 | M12: 96743.8 | N12: 469156.33 | O12: 856474.39 | P12: 18795.96 | Q12: 0.79 | R12: 0
D13: Vlr Intereses | E13: 0 | F13: 0 | G13: 0 | H13: 0 | I13: 0 | J13: 0 | K13: 0 | L13: 0 | M13: 0 | N13: 0 | O13: 0 | P13: 0 | Q13: 0 | R13: 0
C14: T | D14: Total | E14: 2198318.9 | F14: 188049.69 | G14: 89756.71 | H14: 48201.07 | I14: 310657.06 | J14: 11520.24 | K14: 0 | L14: 108962.88 | M14: 96743.8 | N14: 469156.33 | O14: 856474.39 | P14: 18795.96 | Q14: 0.79 | R14: 0
B15: OCCIDENTE | C15: Total | E15: 3455272.8 | F15: 236530.63 | G15: 116607.49 | H15: 63690.6 | I15: 525603.02 | J15: 23693.01 | K15: 0 | L15: 221171.38 | M15: 208173.61 | N15: 1034423.9 | O15: 986717.93 | P15: 38656.58 | Q15: 4.68 | R15: 0
A16: Componente | B16: Total | E16: 32570292 | F16: 1865211.3 | G16: 1005487.3 | H16: 583812.15 | I16: 5020392.6 | J16: 230375.08 | K16: 0 | L16: 2507180.1 | M16: 2526384.8 | N16: 12951452 | O16: 5510056 | P16: 369962.63 | Q16: -21.97 | R16: 0
D17: Subsidio(-)/Contribucion(+) | E17: 1139503.2 | F17: 264067.13 | G17: 147039.05 | H17: 72868.6 | I17: -136480.3 | J17: 3896.46 | K17: 0 | L17: -61838.04 | M17: -5695.54 | N17: 107985.49 | O17: 741490.48 | P17: 6169.9 | Q17: 0 | R17: 0
C18: E | D18: Total | E18: 1139503.2 | F18: 264067.13 | G18: 147039.05 | H18: 72868.6 | I18: -136480.3 | J18: 3896.46 | K18: 0 | L18: -61838.04 | M18: -5695.54 | N18: 107985.49 | O18: 741490.48 | P18: 6169.9 | Q18: 0 | R18: 0
B19: ENEL | C19: Total | E19: 1139503.2 | F19: 264067.13 | G19: 147039.05 | H19: 72868.6 | I19: -136480.3 | J19: 3896.46 | K19: 0 | L19: -61838.04 | M19: -5695.54 | N19: 107985.49 | O19: 741490.48 | P19: 6169.9 | Q19: 0 | R19: 0
D20: Subsidio(-)/Contribucion(+) | E20: 124917.68 | F20: 5425.49 | G20: 3470.55 | H20: 2025.09 | I20: 30214.16 | J20: 1088.11 | K20: 0 | L20: 9544.97 | M20: 9235.05 | N20: 43751.21 | O20: 18387.71 | P20: 1775.34 | Q20: 0 | R20: 0
C21: H | D21: Total | E21: 124917.68 | F21: 5425.49 | G21: 3470.55 | H21: 2025.09 | I21: 30214.16 | J21: 1088.11 | K21: 0 | L21: 9544.97 | M21: 9235.05 | N21: 43751.21 | O21: 18387.71 | P21: 1775.34 | Q21: 0 | R21: 0
D22: Subsidio(-)/Contribucion(+) | E22: 166291.05 | F22: 8434.38 | G22: 4699.6 | H22: 2499.5 | I22: 29821.33 | J22: 1737.19 | K22: 0 | L22: 13525.99 | M22: 12946.73 | N22: 66755.66 | O22: 23036.36 | P22: 2834.31 | Q22: 0 | R22: 0
C23: O | D23: Total | E23: 166291.05 | F23: 8434.38 | G23: 4699.6 | H23: 2499.5 | I23: 29821.33 | J23: 1737.19 | K23: 0 | L23: 13525.99 | M23: 12946.73 | N23: 66755.66 | O23: 23036.36 | P23: 2834.31 | Q23: 0 | R23: 0
D24: Subsidio(-)/Contribucion(+) | E24: 843950.15 | F24: 106181.23 | G24: 59113.51 | H24: 30954.51 | I24: 107753.85 | J24: 4247.21 | K24: 0 | L24: 35494.18 | M24: 35638.24 | N24: 167630.68 | O24: 290007.18 | P24: 6929.56 | Q24: 0 | R24: 0
C25: T | D25: Total | E25: 843950.15 | F25: 106181.23 | G25: 59113.51 | H25: 30954.51 | I25: 107753.85 | J25: 4247.21 | K25: 0 | L25: 35494.18 | M25: 35638.24 | N25: 167630.68 | O25: 290007.18 | P25: 6929.56 | Q25: 0 | R25: 0
B26: OCCIDENTE | C26: Total | E26: 1135158.9 | F26: 120041.1 | G26: 67283.66 | H26: 35479.1 | I26: 167789.34 | J26: 7072.51 | K26: 0 | L26: 58565.14 | M26: 57820.02 | N26: 278137.55 | O26: 331431.25 | P26: 11539.21 | Q26: 0 | R26: 0
A27: Subs/Cont | B27: Total | E27: 2274662.1 | F27: 384108.23 | G27: 214322.71 | H27: 108347.7 | I27: 31309.04 | J27: 10968.97 | K27: 0 | L27: -3272.9 | M27: 52124.48 | N27: 386123.04 | O27: 1072921.7 | P27: 17709.11 | Q27: 0 | R27: 0
A28: Total | E28: 34844954 | F28: 2249319.5 | G28: 1219810 | H28: 692159.85 | I28: 5051701.6 | J28: 241344.05 | K28: 0 | L28: 2503907.2 | M28: 2578509.2 | N28: 13337575 | O28: 6582977.7 | P28: 387671.74 | Q28: -21.97 | R28: 0
B42: TOTAL | C42: OPORTUNO | D42: Total | E42: =E16+E27-K16 -> 34844954 | F42: =F16 -> 1865211.3 | G42: =G16 -> 1005487.3 | H42: =H16 -> 583812.15 | I42: =I16 -> 5020392.6 | J42: =J16 -> 230375.08 | K42: =K16 -> 0 | L42: =L16 -> 2507180.1 | M42: =M16 -> 2526384.8 | ... S42: =S16 -> 0
D43: Subsidio(-)/Contribucion(+) | E43: =E27 -> 2274662.1
B45: RECIPROCIDAD | C45: OPORTUNO | D45: Total | E45: 0 | F45: 0 | G45: 0 | H45: 0 | I45: 0 | J45: 0 | K45: 0 | L45: 0 | M45: 0 | N45: 0 | O45: 0 | P45: 0 | Q45: 0 | R45: 0 | S45: 0
D46: Subsidio(-)/Contribucion(+) | E46: 0
B48: ENEL | C48: OPORTUNO | D48: Total | E48: =E19+E6-K6 -> 30254522 | F48: =F6 -> 1628680.7 | G48: =G6 -> 888879.83 | H48: =H6 -> 520121.55 | I48: =I6 -> 4494789.5 | J48: =J6 -> 206682.07 | K48: =K6 -> 0 | L48: =L6 -> 2286008.7 | M48: =M6 -> 2318211.1 | ... S48: =S6 -> 0
D49: Subsidio(-)/Contribucion(+) | E49: =E19 -> 1139503.2
B51: ENERBIT | C51: OPORTUNO | D51: Total | E51: 0 | F51: 0 | G51: 0 | H51: 0 | I51: 0 | J51: 0 | K51: 0 | L51: 0 | M51: 0 | N51: 0 | O51: 0 | P51: 0 | Q51: 0 | R51: 0
D52: Subsidio(-)/Contribucion(+) | E52: 0
B54: OCCIDENTE | C54: OPORTUNO | D54: Total | E54: =E15+E26-K15 -> 4590431.7 | F54: =F15 -> 236530.63 | G54: =G15 -> 116607.49 | H54: =H15 -> 63690.6 | I54: =I15 -> 525603.02 | J54: =J15 -> 23693.01 | K54: =K15 -> 0 | L54: =L15 -> 221171.38 | M54: =M15 -> 208173.61 | ... S54: =S15 -> 0
D55: Subsidio(-)/Contribucion(+) | E55: =E26 -> 1135158.9
B57: CIUDAD LIMPIA-ACUEDUCTO | C57: OPORTUNO | D57: Total | E57: 0 | F57: 0 | G57: 0 | H57: 0 | I57: 0 | J57: 0 | K57: 0 | L57: 0 | M57: 0 | N57: 0 | O57: 0 | P57: 0 | Q57: 0 | R57: 0 | S57: 0
D58: Subsidio(-)/Contribucion(+) | E58: 0
...

Sheet Reversion Pagos R4
B1: PROMOAMBIENTAL
D2: Total | E2: Componente TDF | F2: Componente TTL | G2: Componente TVIAT | H2: Aprovechamiento | I2: CCSA Prest.Aprov. | J2: Componente TCS | K2: Componente TLU | L2: Componente TBL | M2: Componente TRT | N2: CCSA Prest. No Aprov. | O2: Ajuste Decena | P2: SERVICIO ESPECIALES | Q2: Ajuste Recargo Aseo | R2: Otros
C3: Vlr Servicio | D3: -4753329.9 | E3: -214159.07 | F3: -114902.14 | G3: -61576.43 | H3: -1165948.6 | I3: -45063.11 | J3: -395289.43 | K3: -369526.83 | L3: -1753828.5 | M3: -560155.38 | N3: -72898.32 | O3: 17.99 | P3: 0 | Q3: 0 | R3: 0
C4: Vlr Intereses | D4: -12501.61 | E4: -542.19 | F4: -246.5 | G4: -140.42 | H4: -2800.13 | I4: -138.59 | J4: -1215.05 | K4: -1024.58 | L4: -4838.23 | M4: -1328.64 | N4: -227.04 | O4: -0.24 | P4: 0 | Q4: 0 | R4: 0
B5: Componente | C5: Total | D5: -4765831.5 | E5: -214701.26 | F5: -115148.64 | G5: -61716.85 | H5: -1168748.8 | I5: -45201.7 | J5: -396504.48 | K5: -370551.41 | L5: -1758666.8 | M5: -561484.02 | N5: -73125.36 | O5: 17.75 | P5: 0 | Q5: 0 | R5: 0
C6: Subsidio(-)/Contribucion(+) | D6: 1304634.2 | E6: 54873.86 | F6: 28576.76 | G6: 15506.07 | H6: 320570.26 | I6: 12973.15 | J6: 113799.96 | K6: 105110.1 | L6: 491550.49 | M6: 140506.71 | N6: 21166.82 | O6: 0 | P6: 0 | Q6: 0 | R6: 0
B7: Subs/Cont | C7: Total | D7: 1304634.2 | E7: 54873.86 | F7: 28576.76 | G7: 15506.07 | H7: 320570.26 | I7: 12973.15 | J7: 113799.96 | K7: 105110.1 | L7: 491550.49 | M7: 140506.71 | N7: 21166.82 | O7: 0 | P7: 0 | Q7: 0 | R7: 0
A8: ENEL | B8: Total | D8: -3461197.3 | E8: -159827.4 | F8: -86571.88 | G8: -46210.78 | H8: -848178.49 | I8: -32228.55 | J8: -282704.52 | K8: -265441.31 | L8: -1267116.3 | M8: -420977.31 | N8: -51958.54 | O8: 17.75 | P8: 0 | Q8: 0 | R8: 0
C9: Vlr Servicio | D9: -83090.08 | E9: -4319.28 | F9: -2439.7 | G9: -1284.52 | H9: -21380.91 | I9: -495.68 | J9: -4348.01 | K9: -6438.31 | L9: -29729.3 | M9: -11838.57 | N9: -808.72 | O9: -7.08 | P9: 0 | Q9: 0 | R9: 0
C10: Vlr Intereses | D10: -219.92 | E10: -11.38 | F10: -6.42 | G10: -3.38 | H10: -57.73 | I10: -1.29 | J10: -11.47 | K10: -16.98 | L10: -77.95 | M10: -31.19 | N10: -2.12 | O10: -0.01 | P10: 0 | Q10: 0 | R10: 0
B11: Componente | C11: Total | D11: -83310 | E11: -4330.66 | F11: -2446.12 | G11: -1287.9 | H11: -21438.64 | I11: -496.97 | J11: -4359.48 | K11: -6455.29 | L11: -29807.25 | M11: -11869.76 | N11: -810.84 | O11: -7.09 | P11: 0 | Q11: 0 | R11: 0
A12: OCCIDENTE | B12: Total | D12: -83310 | E12: -4330.66 | F12: -2446.12 | G12: -1287.9 | H12: -21438.64 | I12: -496.97 | J12: -4359.48 | K12: -6455.29 | L12: -29807.25 | M12: -11869.76 | N12: -810.84 | O12: -7.09 | P12: 0 | Q12: 0 | R12: 0
A13: Total | D13: -3544507.3 | E13: -164158.06 | F13: -89018 | G13: -47498.68 | H13: -869617.13 | I13: -32725.52 | J13: -287064 | K13: -271896.6 | L13: -1296923.5 | M13: -432847.07 | N13: -52769.38 | O13: 10.66 | P13: 0 | Q13: 0 | R13: 0
A71: TOTAL | B71: OPORTUNO | C71: Total | D71: =D13-P13 -> -3544507.3 | E71: =E11+E5 -> -219031.92 | F71: =F11+F5 -> -117594.76 | G71: =G11+G5 -> -63004.75 | H71: =H11+H5 -> -1190187.4 | I71: =I11+I5 -> -45698.67 | J71: =J11+J5 -> -400863.96 | K71: =K11+K5 -> -377006.7 | L71: =L11+L5 -> -1788474 | ... R71: =R11+R5 -> 0
C72: Subsidio(-)/Contribucion(+) | D72: =D7 -> 1304634.2
A74: RECIPROCIDAD | B74: OPORTUNO | C74: Total | D74: 0 | E74: 0 | F74: 0 | G74: 0 | H74: 0 | I74: 0 | J74: 0 | K74: 0 | L74: 0 | M74: 0 | N74: 0 | O74: 0 | P74: 0 | Q74: 0 | R74: 0
C75: Subsidio(-)/Contribucion(+) | D75: 0
A77: ENEL | B77: OPORTUNO | C77: Total | D77: =D8-P8 -> -3461197.3 | E77: =E5 -> -214701.26 | F77: =F5 -> -115148.64 | G77: =G5 -> -61716.85 | H77: =H5 -> -1168748.8 | I77: =I5 -> -45201.7 | J77: =J5 -> -396504.48 | K77: =K5 -> -370551.41 | L77: =L5 -> -1758666.8 | ... R77: =R5 -> 0
C78: Subsidio(-)/Contribucion(+) | D78: =D7 -> 1304634.2
A80: ENERBIT | B80: OPORTUNO | C80: Total | D80: 0 | E80: 0 | F80: 0 | G80: 0 | H80: 0 | I80: 0 | J80: 0 | K80: 0 | L80: 0 | M80: 0 | N80: 0 | O80: 0 | P80: 0 | Q80: 0 | R80: 0
C81: Subsidio(-)/Contribucion(+) | D81: 0
A83: OCCIDENTE | B83: OPORTUNO | C83: Total | D83: =D12-P12 -> -83310 | E83: =E11 -> -4330.66 | F83: =F11 -> -2446.12 | G83: =G11 -> -1287.9 | H83: =H11 -> -21438.64 | I83: =I11 -> -496.97 | J83: =J11 -> -4359.48 | K83: =K11 -> -6455.29 | L83: =L11 -> -29807.25 | ... R83: =R11 -> 0
C84: Subsidio(-)/Contribucion(+) | D84: 0
A86: CIUDAD LIMPIA-ACUEDUCTO | B86: OPORTUNO | C86: Total | D86: 0 | E86: 0 | F86: 0 | G86: 0 | H86: 0 | I86: 0 | J86: 0 | K86: 0 | L86: 0 | M86: 0 | N86: 0 | O86: 0 | P86: 0 | Q86: 0 | R86: 0
C87: Subsidio(-)/Contribucion(+) | D87: 0
B89: LIME
D90: Total | E90: Componente TDF | F90: Componente TTL | G90: Componente TVIAT | H90: Aprovechamiento | I90: CCSA Prest.Aprov. | J90: Componente TCS | K90: Componente TLU | L90: Componente TBL | M90: Componente TRT | N90: CCSA Prest. No Aprov. | O90: Ajuste Decena | P90: SERVICIO ESPECIALES | Q90: Ajuste Recargo Aseo | R90: Otros
C91: Vlr Servicio | D91: -10237443 | E91: -563399.38 | F91: -316917.62 | G91: -166722.74 | H91: -2628414.2 | I91: -89684.05 | J91: -786699.09 | K91: -766969.55 | L91: -3636763.4 | M91: -1109050.8 | N91: -146326.35 | O91: 4.57 | P91: -26500 | Q91: 0 | R91: 0
C92: Vlr Intereses | D92: -49535.64 | E92: -2812.32 | F92: -1322.36 | G92: -716.51 | H92: -13748.88 | I92: -368.55 | J92: -3233.3 | K92: -3852.97 | L92: -17279.39 | M92: -5599.52 | N92: -601.36 | O92: -0.48 | P92: 0 | Q92: 0 | R92: 0
B93: Componente | C93: Total | D93: -10286978 | E93: -566211.7 | F93: -318239.98 | G93: -167439.25 | H93: -2642163 | I93: -90052.6 | J93: -789932.39 | K93: -770822.52 | L93: -3654042.8 | M93: -1114650.3 | N93: -146927.71 | O93: 4.09 | P93: -26500 | Q93: 0 | R93: 0
C94: Subsidio(-)/Contribucion(+) | D94: 1547375.8 | E94: 29312.92 | F94: 16341.6 | G94: 8648.05 | H94: 470464.34 | I94: 15992.12 | J94: 140279.81 | K94: 136965.6 | L94: 646070.43 | M94: 57208.93 | N94: 26092.04 | O94: 0 | P94: 0 | Q94: 0 | R94: 0
B95: Subs/Cont | C95: Total | D95: 1547375.8 | E95: 29312.92 | F95: 16341.6 | G95: 8648.05 | H95: 470464.34 | I95: 15992.12 | J95: 140279.81 | K95: 136965.6 | L95: 646070.43 | M95: 57208.93 | N95: 26092.04 | O95: 0 | P95: 0 | Q95: 0 | R95: 0
A96: ENEL | B96: Total | D96: -8739602.4 | E96: -536898.78 | F96: -301898.38 | G96: -158791.2 | H96: -2171698.7 | I96: -74060.48 | J96: -649652.58 | K96: -633856.92 | L96: -3007972.4 | M96: -1057441.4 | N96: -120835.67 | O96: 4.09 | P96: -26500 | Q96: 0 | R96: 0
A97: Total | D97: -8739602.4 | E97: -536898.78 | F97: -301898.38 | G97: -158791.2 | H97: -2171698.7 | I97: -74060.48 | J97: -649652.58 | K97: -633856.92 | L97: -3007972.4 | M97: -1057441.4 | N97: -120835.67 | O97: 4.09 | P97: -26500 | Q97: 0 | R97: 0
A160: TOTAL | B160: OPORTUNO | C160: Total | D160: =D97-P97 -> -8713102.4 | E160: =E93 -> -566211.7 | F160: =F93 -> -318239.98 | G160: =G93 -> -167439.25 | H160: =H93 -> -2642163 | I160: =I93 -> -90052.6 | J160: =J93 -> -789932.39 | K160: =K93 -> -770822.52 | L160: =L93 -> -3654042.8 | ... R160: =R93 -> 0
C161: Subsidio(-)/Contribucion(+) | D161: =D95 -> 1547375.8
A163: RECIPROCIDAD | B163: OPORTUNO | C163: Total | D163: 0 | E163: 0 | F163: 0 | G163: 0 | H163: 0 | I163: 0 | J163: 0 | K163: 0 | L163: 0 | M163: 0 | N163: 0 | O163: 0 | P163: 0 | Q163: 0 | R163: 0
C164: Subsidio(-)/Contribucion(+) | D164: 0
A166: ENEL | B166: OPORTUNO | C166: Total | D166: =D96-P96 -> -8713102.4 | E166: =E93 -> -566211.7 | F166: =F93 -> -318239.98 | G166: =G93 -> -167439.25 | H166: =H93 -> -2642163 | I166: =I93 -> -90052.6 | J166: =J93 -> -789932.39 | K166: =K93 -> -770822.52 | L166: =L93 -> -3654042.8 | ... R166: =R93 -> 0
C167: Subsidio(-)/Contribucion(+) | D167: =D95 -> 1547375.8
...

Sheet SALDOS POR NOTA
B1: PROMOAMBIENTAL
