Workbook
Name Bancos: [1]Fx!$C$1:$C$23
Name NNN: #REF!
Name Ref.: #REF!
Name Ref.: #REF!
Name Ref.: #REF!
Name Ref.: #REF!
Name XXX: #REF!

Sheet Oportuno
C1: =VALUE(C3&1) -> 2026091 | J1: =J38+J66+J94+J122+J150+J178+J206+J234+J262+J290+J318+J346+J374+J402+J430 -> 0 | K1: =K38+K66+K94+K122+K150+K178+K206+K234+K262+K290+K318+K346+K374+K402+K430 -> 0 | L1: =L38+L66+L94+L122+L150+L178+L206+L234+L262+L290+L318+L346+L374+L402+L430 -> 0 | M1: =M38+M66+M94+M122+M150+M178+M206+M234+M262+M290+M318+M346+M374+M402+M430 -> 0 | N1: =N38+N66+N94+N122+N150+N178+N206+N234+N262+N290+N318+N346+N374+N402+N430 -> 0 | O1: =O38+O66+O94+O122+O150+O178+O206+O234+O262+O290+O318+O346+O374+O402+O430 -> 0 | P1: =P38+P66+P94+P122+P150+P178+P206+P234+P262+P290+P318+P346+P374+P402+P430 -> 0 | Q1: =Q38+Q66+Q94+Q122+Q150+Q178+Q206+Q234+Q262+Q290+Q318+Q346+Q374+Q402+Q430 -> 0 | ... Y1: =Y38+Y66+Y94+Y122+Y150+Y178+Y206+Y234+Y262+Y290+Y318+Y346+Y374+Y402+Y430 -> 0 | AD1: =AD38+AD66+AD94+AD122+AD150+AD178+AD206+AD234+AD262+AD290+AD318+AD346+AD374+AD402+AD430 -> 0 | AE1: =AE38+AE66+AE94+AE122+AE150+AE178+AE206+AE234+AE262+AE290+AE318+AE346+AE374+AE402+AE430 -> 0 | AF1: =AF38+AF66+AF94+AF122+AF150+AF178+AF206+AF234+AF262+AF290+AF318+AF346+AF374+AF402+AF430 -> 0 | AG1: =AG38+AG66+AG94+AG122+AG150+AG178+AG206+AG234+AG262+AG290+AG318+AG346+AG374+AG402+AG430 -> 0 | AI1: =AI38+AI66+AI94+AI122+AI150+AI178+AI206+AI234+AI262+AI290+AI318+AI346+AI374+AI402+AI430 -> 0 | AJ1: =AJ38+AJ66+AJ94+AJ122+AJ150+AJ178+AJ206+AJ234+AJ262+AJ290+AJ318+AJ346+AJ374+AJ402+AJ430 -> 0 | AK1: =AK38+AK66+AK94+AK122+AK150+AK178+AK206+AK234+AK262+AK290+AK318+AK346+AK374+AK402+AK430 -> 0 | AL1: =AL38+AL66+AL94+AL122+AL150+AL178+AL206+AL234+AL262+AL290+AL318+AL346+AL374+AL402+AL430 -> 0
C2: =VALUE(C3&2) -> 2026092 | J2: =J458+J486+J514+J542+J570+J598+J626+J654+J682+J710+J738+J766+J794+J822+J850+J878 -> 0 | K2: =K458+K486+K514+K542+K570+K598+K626+K654+K682+K710+K738+K766+K794+K822+K850+K878 -> 0 | L2: =L458+L486+L514+L542+L570+L598+L626+L654+L682+L710+L738+L766+L794+L822+L850+L878 -> 0 | M2: =M458+M486+M514+M542+M570+M598+M626+M654+M682+M710+M738+M766+M794+M822+M850+M878 -> 0 | N2: =N458+N486+N514+N542+N570+N598+N626+N654+N682+N710+N738+N766+N794+N822+N850+N878 -> 0 | O2: =O458+O486+O514+O542+O570+O598+O626+O654+O682+O710+O738+O766+O794+O822+O850+O878 -> 0 | P2: =P458+P486+P514+P542+P570+P598+P626+P654+P682+P710+P738+P766+P794+P822+P850+P878 -> 0 | Q2: =Q458+Q486+Q514+Q542+Q570+Q598+Q626+Q654+Q682+Q710+Q738+Q766+Q794+Q822+Q850+Q878 -> 0 | ... Y2: =Y458+Y486+Y514+Y542+Y570+Y598+Y626+Y654+Y682+Y710+Y738+Y766+Y794+Y822+Y850+Y878 -> 0 | AD2: =AD458+AD486+AD514+AD542+AD570+AD598+AD626+AD654+AD682+AD710+AD738+AD766+AD794+AD822+AD850+AD878 -> 0 | AE2: =AE458+AE486+AE514+AE542+AE570+AE598+AE626+AE654+AE682+AE710+AE738+AE766+AE794+AE822+AE850+AE878 -> 0 | AF2: =AF458+AF486+AF514+AF542+AF570+AF598+AF626+AF654+AF682+AF710+AF738+AF766+AF794+AF822+AF850+AF878 -> 0 | AG2: =AG458+AG486+AG514+AG542+AG570+AG598+AG626+AG654+AG682+AG710+AG738+AG766+AG794+AG822+AG850+AG878 -> 0 | AI2: =AI458+AI486+AI514+AI542+AI570+AI598+AI626+AI654+AI682+AI710+AI738+AI766+AI794+AI822+AI850+AI878 -> 0 | AJ2: =AJ458+AJ486+AJ514+AJ542+AJ570+AJ598+AJ626+AJ654+AJ682+AJ710+AJ738+AJ766+AJ794+AJ822+AJ850+AJ878 -> 0 | AK2: =AK458+AK486+AK514+AK542+AK570+AK598+AK626+AK654+AK682+AK710+AK738+AK766+AK794+AK822+AK850+AK878 -> 0 | AL2: =AL458+AL486+AL514+AL542+AL570+AL598+AL626+AL654+AL682+AL710+AL738+AL766+AL794+AL822+AL850+AL878 -> 0
C3: 202609 | J3: =SUM(J1:J2) -> 0 | K3: =SUM(K1:K2) -> 0 | L3: =SUM(L1:L2) -> 0 | M3: =SUM(M1:M2) -> 0 | N3: =SUM(N1:N2) -> 0 | O3: =SUM(O1:O2) -> 0 | P3: =SUM(P1:P2) -> 0 | Q3: =SUM(Q1:Q2) -> 0 | ... Y3: =SUM(Y1:Y2) -> 0 | AD3: =SUM(AD1:AD2) -> 0 | AE3: =SUM(AE1:AE2) -> 0 | AF3: =SUM(AF1:AF2) -> 0 | AG3: =SUM(AG1:AG2) -> 0 | AI3: =SUM(AI1:AI2) -> 0 | AJ3: =SUM(AJ1:AJ2) -> 0 | AK3: =SUM(AK1:AK2) -> 0 | AL3: =SUM(AL1:AL2) -> 0
H6: 2.5.3. INFORMES DE RECAUDO
H7: R2 - INFORME DE CONCILIACION DE RECAUDOS
H8: CONCILIACION DIARIA DE RECAUDO OPORTUNO
E9: NIT: 901 153 639 - 0
H10: =SUBSTITUTE(UPPER(TEXT(DATE(LEFT(C3,4),RIGHT(C3,2),1),"MMMM YYYY"))," ","_") -> SEPTIEMBRE_2026 | J10: Recaudo Oportuno de las cuentas bancarias de ENEL
B12: FECHA APLICACIÓN | C12: CODIGO REMUNERACIÓN | D12: FECHA RECAUDO | E12: CÓDIGO BC | F12: NOMBRE BANCO | G12: CÓDIGO CR | H12: CANAL RECAUDO | I12: N° CUENTA | J12: ASE 1 N° REGISTROS ARCHIVO | K12: ASE 1 VALOR ARCHIVO | L12: ASE 2 N° REGISTROS ARCHIVO | M12: ASE 2 VALOR ARCHIVO | N12: ASE 3 N° REGISTROS ARCHIVO | O12: ASE 3 VALOR ARCHIVO | P12: ASE 4 N° REGISTROS ARCHIVO | Q12: ASE 4 VALOR ARCHIVO | R12: ASE 5 N° REGISTROS ARCHIVO | S12: ASE 5 VALOR ARCHIVO | T12: TOTAL N° REGISTROS APLICADOS | U12: TOTAL VALOR APLICADO | V12: N° REGISTROS REPORTADOS POR BANCO | W12: VALOR REPORTADO POR BANCO | X12: DIFERENCIA REGISTROS | Y12: DIFERENCIA VALOR | AC12: DIFERENCIA REGISTROS | AD12: REGISTROS ENVIADOS EAAB // SON CARTERA | AE12: REGISTROS NO IDENTIFICADO - NI. | AF12: REGISTROS CON VALOR EN $0 | AG12: VALIDACION | AI12: DIFERENCIA VALOR | AJ12: VALOR ENVIADOS EAAB // SON CARTERA | AK12: VALOR NO IDENTIFICADO - NI. | AL12: VALIDACION
B13: 3/09/2026 | C13: =IF(D13<=15,$C$1,$C$2) -> 2026091 | D13: 1 | E13: 20 | F13: =VLOOKUP(E13,'Códigos bancos'!$B$4:$C$29,2,0) -> Bancolombia ENERBIT | G13: 1 | H13: =VLOOKUP(G13,'Códigos bancos'!$F$4:$G$14,2,0) -> Oficinas | J13: 0 | K13: 0 | L13: 0 | M13: 0 | N13: 0 | O13: 0 | P13: 0 | Q13: 0 | R13: 144 | S13: 6520660 | T13: =J13+L13+N13+P13+R13 -> 144 | U13: =K13+M13+O13+Q13+S13 -> 6520660 | V13: 144 | W13: 6520660 | X13: =V13-T13 -> 0 | Y13: =W13-U13 -> 0 | AC13: =X13 -> 0 | AG13: =AC13=(AD13+AE13+AF13) -> TRUE | AI13: =Y13 -> 0 | AL13: =AI13=(AJ13+AK13) -> TRUE
C14: =IF(D14<=15,$C$1,$C$2) -> 2026091 | D14: 1 | E14: 0 | F14: =VLOOKUP(E14,'Códigos bancos'!$B$4:$C$29,2,0) -> #N/A | G14: 1 | H14: =VLOOKUP(G14,'Códigos bancos'!$F$4:$G$14,2,0) -> Oficinas | J14: 0 | K14: 0 | L14: 0 | M14: 0 | N14: 0 | O14: 0 | P14: 0 | Q14: 0 | R14: 0 | T14: =J14+L14+N14+P14+R14 -> 0 | U14: =K14+M14+O14+Q14+S14 -> 0 | V14: 0 | X14: =V14-T14 -> 0 | Y14: =W14-U14 -> 0 | AC14: =X14 -> 0 | AG14: =AC14=(AD14+AE14+AF14) -> TRUE | AI14: =Y14 -> 0 | AL14: =AI14=(AJ14+AK14) -> TRUE
C15: =IF(D15<=15,$C$1,$C$2) -> 2026091 | D15: 1 | E15: 0 | F15: =VLOOKUP(E15,'Códigos bancos'!$B$4:$C$29,2,0) -> #N/A | G15: 1 | H15: =VLOOKUP(G15,'Códigos bancos'!$F$4:$G$14,2,0) -> Oficinas | J15: 0 | K15: 0 | L15: 0 | M15: 0 | N15: 0 | O15: 0 | P15: 0 | Q15: 0 | R15: 0 | S15: 0 | T15: =J15+L15+N15+P15+R15 -> 0 | U15: =K15+M15+O15+Q15+S15 -> 0 | V15: 0 | W15: 0 | X15: =V15-T15 -> 0 | Y15: =W15-U15 -> 0 | AC15: =X15 -> 0 | AG15: =AC15=(AD15+AE15+AF15) -> TRUE | AI15: =Y15 -> 0 | AL15: =AI15=(AJ15+AK15) -> TRUE
C16: =IF(D16<=15,$C$1,$C$2) -> 2026091 | D16: 1 | E16: 0 | F16: =VLOOKUP(E16,'Códigos bancos'!$B$4:$C$29,2,0) -> #N/A | G16: 1 | H16: =VLOOKUP(G16,'Códigos bancos'!$F$4:$G$14,2,0) -> Oficinas | J16: 0 | K16: 0 | L16: 0 | M16: 0 | N16: 0 | O16: 0 | P16: 0 | Q16: 0 | R16: 0 | S16: 0 | T16: =J16+L16+N16+P16+R16 -> 0 | U16: =K16+M16+O16+Q16+S16 -> 0 | V16: 0 | W16: 0 | X16: =V16-T16 -> 0 | Y16: =W16-U16 -> 0 | AC16: =X16 -> 0 | AG16: =AC16=(AD16+AE16+AF16) -> TRUE | AI16: =Y16 -> 0 | AL16: =AI16=(AJ16+AK16) -> TRUE
C17: =IF(D17<=15,$C$1,$C$2) -> 2026091 | D17: 1 | E17: 0 | F17: =VLOOKUP(E17,'Códigos bancos'!$B$4:$C$29,2,0) -> #N/A | G17: 1 | H17: =VLOOKUP(G17,'Códigos bancos'!$F$4:$G$14,2,0) -> Oficinas | J17: 0 | K17: 0 | L17: 0 | M17: 0 | N17: 0 | O17: 0 | P17: 0 | Q17: 0 | R17: 0 | S17: 0 | T17: =J17+L17+N17+P17+R17 -> 0 | U17: =K17+M17+O17+Q17+S17 -> 0 | V17: 0 | W17: 0 | X17: =V17-T17 -> 0 | Y17: =W17-U17 -> 0 | AC17: =X17 -> 0 | AG17: =AC17=(AD17+AE17+AF17) -> TRUE | AI17: =Y17 -> 0 | AL17: =AI17=(AJ17+AK17) -> TRUE
C18: =IF(D18<=15,$C$1,$C$2) -> 2026091 | D18: 1 | E18: 0 | F18: =VLOOKUP(E18,'Códigos bancos'!$B$4:$C$29,2,0) -> #N/A | G18: 1 | H18: =VLOOKUP(G18,'Códigos bancos'!$F$4:$G$14,2,0) -> Oficinas | J18: 0 | K18: 0 | L18: 0 | M18: 0 | N18: 0 | O18: 0 | P18: 0 | Q18: 0 | R18: 0 | S18: 0 | T18: =J18+L18+N18+P18+R18 -> 0 | U18: =K18+M18+O18+Q18+S18 -> 0 | V18: 0 | W18: 0 | X18: =V18-T18 -> 0 | Y18: =W18-U18 -> 0 | AC18: =X18 -> 0 | AG18: =AC18=(AD18+AE18+AF18) -> TRUE | AI18: =Y18 -> 0 | AL18: =AI18=(AJ18+AK18) -> TRUE
C19: =IF(D19<=15,$C$1,$C$2) -> 2026091 | D19: 1 | E19: 0 | F19: =VLOOKUP(E19,'Códigos bancos'!$B$4:$C$29,2,0) -> #N/A | G19: 1 | H19: =VLOOKUP(G19,'Códigos bancos'!$F$4:$G$14,2,0) -> Oficinas | J19: 0 | K19: 0 | L19: 0 | M19: 0 | N19: 0 | O19: 0 | P19: 0 | Q19: 0 | R19: 0 | S19: 0 | T19: =J19+L19+N19+P19+R19 -> 0 | U19: =K19+M19+O19+Q19+S19 -> 0 | V19: 0 | W19: 0 | X19: =V19-T19 -> 0 | Y19: =W19-U19 -> 0 | AC19: =X19 -> 0 | AG19: =AC19=(AD19+AE19+AF19) -> TRUE | AI19: =Y19 -> 0 | AL19: =AI19=(AJ19+AK19) -> TRUE
C20: =IF(D20<=15,$C$1,$C$2) -> 2026091 | D20: 1 | E20: 0 | F20: =VLOOKUP(E20,'Códigos bancos'!$B$4:$C$29,2,0) -> #N/A | G20: 1 | H20: =VLOOKUP(G20,'Códigos bancos'!$F$4:$G$14,2,0) -> Oficinas | J20: 0 | K20: 0 | L20: 0 | M20: 0 | N20: 0 | O20: 0 | P20: 0 | Q20: 0 | R20: 0 | S20: 0 | T20: =J20+L20+N20+P20+R20 -> 0 | U20: =K20+M20+O20+Q20+S20 -> 0 | V20: 0 | W20: 0 | X20: =V20-T20 -> 0 | Y20: =W20-U20 -> 0 | AC20: =X20 -> 0 | AG20: =AC20=(AD20+AE20+AF20) -> TRUE | AI20: =Y20 -> 0 | AL20: =AI20=(AJ20+AK20) -> TRUE
C21: =IF(D21<=15,$C$1,$C$2) -> 2026091 | D21: 1 | E21: 0 | F21: =VLOOKUP(E21,'Códigos bancos'!$B$4:$C$29,2,0) -> #N/A | G21: 1 | H21: =VLOOKUP(G21,'Códigos bancos'!$F$4:$G$14,2,0) -> Oficinas | J21: 0 | K21: 0 | L21: 0 | M21: 0 | N21: 0 | O21: 0 | P21: 0 | Q21: 0 | R21: 0 | S21: 0 | T21: =J21+L21+N21+P21+R21 -> 0 | U21: =K21+M21+O21+Q21+S21 -> 0 | V21: 0 | W21: 0 | X21: =V21-T21 -> 0 | Y21: =W21-U21 -> 0 | AC21: =X21 -> 0 | AG21: =AC21=(AD21+AE21+AF21) -> TRUE | AI21: =Y21 -> 0 | AL21: =AI21=(AJ21+AK21) -> TRUE
C22: =IF(D22<=15,$C$1,$C$2) -> 2026091 | D22: 1 | E22: 0 | F22: =VLOOKUP(E22,'Códigos bancos'!$B$4:$C$29,2,0) -> #N/A | G22: 1 | H22: =VLOOKUP(G22,'Códigos bancos'!$F$4:$G$14,2,0) -> Oficinas | J22: 0 | K22: 0 | L22: 0 | M22: 0 | N22: 0 | O22: 0 | P22: 0 | Q22: 0 | R22: 0 | S22: 0 | T22: =J22+L22+N22+P22+R22 -> 0 | U22: =K22+M22+O22+Q22+S22 -> 0 | V22: 0 | W22: 0 | X22: =V22-T22 -> 0 | Y22: =W22-U22 -> 0 | AC22: =X22 -> 0 | AG22: =AC22=(AD22+AE22+AF22) -> TRUE | AI22: =Y22 -> 0 | AL22: =AI22=(AJ22+AK22) -> TRUE
C23: =IF(D23<=15,$C$1,$C$2) -> 2026091 | D23: 1 | E23: 0 | F23: =VLOOKUP(E23,'Códigos bancos'!$B$4:$C$29,2,0) -> #N/A | G23: 1 | H23: =VLOOKUP(G23,'Códigos bancos'!$F$4:$G$14,2,0) -> Oficinas | J23: 0 | K23: 0 | L23: 0 | M23: 0 | N23: 0 | O23: 0 | P23: 0 | Q23: 0 | R23: 0 | S23: 0 | T23: =J23+L23+N23+P23+R23 -> 0 | U23: =K23+M23+O23+Q23+S23 -> 0 | V23: 0 | W23: 0 | X23: =V23-T23 -> 0 | Y23: =W23-U23 -> 0 | AC23: =X23 -> 0 | AG23: =AC23=(AD23+AE23+AF23) -> TRUE | AI23: =Y23 -> 0 | AL23: =AI23=(AJ23+AK23) -> TRUE
C24: =IF(D24<=15,$C$1,$C$2) -> 2026091 | D24: 1 | E24: 0 | F24: =VLOOKUP(E24,'Códigos bancos'!$B$4:$C$29,2,0) -> #N/A | G24: 1 | H24: =VLOOKUP(G24,'Códigos bancos'!$F$4:$G$14,2,0) -> Oficinas | J24: 0 | K24: 0 | L24: 0 | M24: 0 | N24: 0 | O24: 0 | P24: 0 | Q24: 0 | R24: 0 | S24: 0 | T24: =J24+L24+N24+P24+R24 -> 0 | U24: =K24+M24+O24+Q24+S24 -> 0 | V24: 0 | W24: 0 | X24: =V24-T24 -> 0 | Y24: =W24-U24 -> 0 | AC24: =X24 -> 0 | AG24: =AC24=(AD24+AE24+AF24) -> TRUE | AI24: =Y24 -> 0 | AL24: =AI24=(AJ24+AK24) -> TRUE
C25: =IF(D25<=15,$C$1,$C$2) -> 2026091 | D25: 1 | E25: 0 | F25: =VLOOKUP(E25,'Códigos bancos'!$B$4:$C$29,2,0) -> #N/A | G25: 1 | H25: =VLOOKUP(G25,'Códigos bancos'!$F$4:$G$14,2,0) -> Oficinas | J25: 0 | K25: 0 | L25: 0 | M25: 0 | N25: 0 | O25: 0 | P25: 0 | Q25: 0 | R25: 0 | S25: 0 | T25: =J25+L25+N25+P25+R25 -> 0 | U25: =K25+M25+O25+Q25+S25 -> 0 | V25: 0 | W25: 0 | X25: =V25-T25 -> 0 | Y25: =W25-U25 -> 0 | AC25: =X25 -> 0 | AG25: =AC25=(AD25+AE25+AF25) -> TRUE | AI25: =Y25 -> 0 | AL25: =AI25=(AJ25+AK25) -> TRUE
C26: =IF(D26<=15,$C$1,$C$2) -> 2026091 | D26: 1 | E26: 0 | F26: =VLOOKUP(E26,'Códigos bancos'!$B$4:$C$29,2,0) -> #N/A | G26: 1 | H26: =VLOOKUP(G26,'Códigos bancos'!$F$4:$G$14,2,0) -> Oficinas | J26: 0 | K26: 0 | L26: 0 | M26: 0 | N26: 0 | O26: 0 | P26: 0 | Q26: 0 | R26: 0 | S26: 0 | T26: =J26+L26+N26+P26+R26 -> 0 | U26: =K26+M26+O26+Q26+S26 -> 0 | V26: 0 | W26: 0 | X26: =V26-T26 -> 0 | Y26: =W26-U26 -> 0 | AC26: =X26 -> 0 | AG26: =AC26=(AD26+AE26+AF26) -> TRUE | AI26: =Y26 -> 0 | AL26: =AI26=(AJ26+AK26) -> TRUE
... C28: =IF(D28<=15,$C$1,$C$2) -> 2026091 | D28: 1 | E28: 0 | F28: =VLOOKUP(E28,'Códigos bancos'!$B$4:$C$29,2,0) -> #N/A | G28: 1 | H28: =VLOOKUP(G28,'Códigos bancos'!$F$4:$G$14,2,0) -> Oficinas | J28: 0 | K28: 0 | L28: 0 | M28: 0 | N28: 0 | O28: 0 | P28: 0 | Q28: 0 | R28: 0 | S28: 0 | T28: =J28+L28+N28+P28+R28 -> 0 | U28: =K28+M28+O28+Q28+S28 -> 0 | V28: 0 | W28: 0 | X28: =V28-T28 -> 0 | Y28: =W28-U28 -> 0 | AC28: =X28 -> 0 | AG28: =AC28=(AD28+AE28+AF28) -> TRUE | AI28: =Y28 -> 0 | AL28: =AI28=(AJ28+AK28) -> TRUE
C29: =IF(D29<=15,$C$1,$C$2) -> 2026091 | D29: 1 | E29: 0 | F29: =VLOOKUP(E29,'Códigos bancos'!$B$4:$C$29,2,0) -> #N/A | G29: 1 | H29: =VLOOKUP(G29,'Códigos bancos'!$F$4:$G$14,2,0) -> Oficinas | J29: 0 | K29: 0 | L29: 0 | M29: 0 | N29: 0 | O29: 0 | P29: 0 | Q29: 0 | R29: 0 | S29: 0 | T29: =J29+L29+N29+P29+R29 -> 0 | U29: =K29+M29+O29+Q29+S29 -> 0 | V29: 0 | W29: 0 | X29: =V29-T29 -> 0 | Y29: =W29-U29 -> 0 | AC29: =X29 -> 0 | AG29: =AC29=(AD29+AE29+AF29) -> TRUE | AI29: =Y29 -> 0 | AK29: 0 | AL29: =AI29=(AJ29+AK29) -> TRUE
C30: =IF(D30<=15,$C$1,$C$2) -> 2026091 | D30: 1 | E30: 0 | F30: =VLOOKUP(E30,'Códigos bancos'!$B$4:$C$29,2,0) -> #N/A | G30: 1 | H30: =VLOOKUP(G30,'Códigos bancos'!$F$4:$G$14,2,0) -> Oficinas | J30: 0 | K30: 0 | L30: 0 | M30: 0 | N30: 0 | O30: 0 | P30: 0 | Q30: 0 | R30: 0 | S30: 0 | T30: =J30+L30+N30+P30+R30 -> 0 | U30: =K30+M30+O30+Q30+S30 -> 0 | V30: 0 | W30: 0 | X30: =V30-T30 -> 0 | Y30: =W30-U30 -> 0 | AC30: =X30 -> 0 | AG30: =AC30=(AD30+AE30+AF30) -> TRUE | AI30: =Y30 -> 0 | AK30: 0 | AL30: =AI30=(AJ30+AK30) -> TRUE
C31: =IF(D31<=15,$C$1,$C$2) -> 2026091 | D31: 1 | E31: 0 | F31: =VLOOKUP(E31,'Códigos bancos'!$B$4:$C$29,2,0) -> #N/A | G31: 1 | H31: =VLOOKUP(G31,'Códigos bancos'!$F$4:$G$14,2,0) -> Oficinas | J31: 0 | K31: 0 | L31: 0 | M31: 0 | N31: 0 | O31: 0 | P31: 0 | Q31: 0 | R31: 0 | S31: 0 | T31: =J31+L31+N31+P31+R31 -> 0 | U31: =K31+M31+O31+Q31+S31 -> 0 | V31: 0 | W31: 0 | X31: =V31-T31 -> 0 | Y31: =W31-U31 -> 0 | AC31: =X31 -> 0 | AG31: =AC31=(AD31+AE31+AF31) -> TRUE | AI31: =Y31 -> 0 | AL31: =AI31=(AJ31+AK31) -> TRUE
C32: =IF(D32<=15,$C$1,$C$2) -> 2026091 | D32: 1 | E32: 0 | F32: =VLOOKUP(E32,'Códigos bancos'!$B$4:$C$29,2,0) -> #N/A | G32: 1 | H32: =VLOOKUP(G32,'Códigos bancos'!$F$4:$G$14,2,0) -> Oficinas | J32: 0 | K32: 0 | L32: 0 | M32: 0 | N32: 0 | O32: 0 | P32: 0 | Q32: 0 | R32: 0 | S32: 0 | T32: =J32+L32+N32+P32+R32 -> 0 | U32: =K32+M32+O32+Q32+S32 -> 0 | V32: 0 | W32: 0 | X32: =V32-T32 -> 0 | Y32: =W32-U32 -> 0 | AC32: =X32 -> 0 | AG32: =AC32=(AD32+AE32+AF32) -> TRUE | AI32: =Y32 -> 0 | AL32: =AI32=(AJ32+AK32) -> TRUE
C33: =IF(D33<=15,$C$1,$C$2) -> 2026091 | D33: 1 | E33: 0 | F33: =VLOOKUP(E33,'Códigos bancos'!$B$4:$C$29,2,0) -> #N/A | G33: 1 | H33: =VLOOKUP(G33,'Códigos bancos'!$F$4:$G$14,2,0) -> Oficinas | J33: 0 | K33: 0 | L33: 0 | M33: 0 | N33: 0 | O33: 0 | P33: 0 | Q33: 0 | R33: 0 | S33: 0 | T33: =J33+L33+N33+P33+R33 -> 0 | U33: =K33+M33+O33+Q33+S33 -> 0 | V33: 0 | W33: 0 | X33: =V33-T33 -> 0 | Y33: =W33-U33 -> 0 | AC33: =X33 -> 0 | AG33: =AC33=(AD33+AE33+AF33) -> TRUE | AI33: =Y33 -> 0 | AL33: =AI33=(AJ33+AK33) -> TRUE
C34: =IF(D34<=15,$C$1,$C$2) -> 2026091 | D34: 1 | E34: 0 | F34: =VLOOKUP(E34,'Códigos bancos'!$B$4:$C$29,2,0) -> #N/A | G34: 1 | H34: =VLOOKUP(G34,'Códigos bancos'!$F$4:$G$14,2,0) -> Oficinas | J34: 0 | K34: 0 | L34: 0 | M34: 0 | N34: 0 | O34: 0 | P34: 0 | Q34: 0 | R34: 0 | S34: 0 | T34: =J34+L34+N34+P34+R34 -> 0 | U34: =K34+M34+O34+Q34+S34 -> 0 | V34: 0 | W34: 0 | X34: =V34-T34 -> 0 | Y34: =W34-U34 -> 0 | AC34: =X34 -> 0 | AG34: =AC34=(AD34+AE34+AF34) -> TRUE | AI34: =Y34 -> 0 | AL34: =AI34=(AJ34+AK34) -> TRUE
C35: =IF(D35<=15,$C$1,$C$2) -> 2026091 | D35: 1 | E35: 0 | F35: =VLOOKUP(E35,'Códigos bancos'!$B$4:$C$29,2,0) -> #N/A | G35: 1 | H35: =VLOOKUP(G35,'Códigos bancos'!$F$4:$G$14,2,0) -> Oficinas | J35: 0 | K35: 0 | L35: 0 | M35: 0 | N35: 0 | O35: 0 | P35: 0 | Q35: 0 | R35: 0 | S35: 0 | T35: =J35+L35+N35+P35+R35 -> 0 | U35: =K35+M35+O35+Q35+S35 -> 0 | V35: 0 | W35: 0 | X35: =V35-T35 -> 0 | Y35: =W35-U35 -> 0 | AC35: =X35 -> 0 | AG35: =AC35=(AD35+AE35+AF35) -> TRUE | AL35: =AI35=(AJ35+AK35) -> TRUE
C36: =IF(D36<=15,$C$1,$C$2) -> 2026091 | D36: 1 | E36: 0 | F36: =VLOOKUP(E36,'Códigos bancos'!$B$4:$C$29,2,0) -> #N/A | G36: 1 | H36: =VLOOKUP(G36,'Códigos bancos'!$F$4:$G$14,2,0) -> Oficinas | J36: 0 | K36: 0 | L36: 0 | M36: 0 | N36: 0 | O36: 0 | P36: 0 | Q36: 0 | R36: 0 | S36: 0 | T36: =J36+L36+N36+P36+R36 -> 0 | U36: =K36+M36+O36+Q36+S36 -> 0 | V36: 0 | W36: 0 | X36: =V36-T36 -> 0 | Y36: =W36-U36 -> 0 | AC36: =X36 -> 0 | AG36: =AC36=(AD36+AE36+AF36) -> TRUE | AI36: =Y36 -> 0 | AL36: =AI36=(AJ36+AK36) -> TRUE
C37: =IF(D37<=15,$C$1,$C$2) -> 2026091 | D37: 1 | E37: 0 | F37: =VLOOKUP(E37,'Códigos bancos'!$B$4:$C$29,2,0) -> #N/A | G37: 1 | H37: =VLOOKUP(G37,'Códigos bancos'!$F$4:$G$14,2,0) -> Oficinas | J37: 0 | K37: 0 | L37: 0 | M37: 0 | N37: 0 | O37: 0 | P37: 0 | Q37: 0 | R37: 0 | S37: 0 | T37: =J37+L37+N37+P37+R37 -> 0 | U37: =K37+M37+O37+Q37+S37 -> 0 | V37: 0 | W37: 0 | X37: =V37-T37 -> 0 | Y37: =W37-U37 -> 0 | AC37: =X37 -> 0 | AG37: =AC37=(AD37+AE37+AF37) -> TRUE | AI37: =Y37 -> 0 | AL37: =AI37=(AJ37+AK37) -> TRUE
F38: TOTAL RECAUDO | J38: =SUM(J13:J37) -> 0 | K38: =SUM(K13:K37) -> 0 | L38: =SUM(L13:L37) -> 0 | M38: =SUM(M13:M37) -> 0 | N38: =SUM(N13:N37) -> 0 | O38: =SUM(O13:O37) -> 0 | P38: =SUM(P13:P37) -> 0 | Q38: =SUM(Q13:Q37) -> 0 | ... Y38: =SUM(Y13:Y37) -> 0 | AC38: =SUM(AC13:AC37) -> 0 | AD38: =SUM(AD13:AD37) -> 0 | AE38: =SUM(AE13:AE37) -> 0 | AF38: =SUM(AF13:AF37) -> 0 | AI38: =SUM(AI13:AI37) -> 0 | AJ38: =SUM(AJ13:AJ37) -> 0 | AK38: =SUM(AK13:AK37) -> 0
B40: FECHA APLICACIÓN | C40: CODIGO REMUNERACIÓN | D40: FECHA RECAUDO | E40: CÓDIGO BC | F40: NOMBRE BANCO | G40: CÓDIGO CR | H40: CANAL RECAUDO | I40: N° CUENTA | J40: ASE 1 N° REGISTROS ARCHIVO | K40: ASE 1 VALOR ARCHIVO | L40: ASE 2 N° REGISTROS ARCHIVO | M40: ASE 2 VALOR ARCHIVO | N40: ASE 3 N° REGISTROS ARCHIVO | O40: ASE 3 VALOR ARCHIVO | P40: ASE 4 N° REGISTROS ARCHIVO | Q40: ASE 4 VALOR ARCHIVO | R40: ASE 5 N° REGISTROS ARCHIVO | S40: ASE 5 VALOR ARCHIVO | T40: TOTAL N° REGISTROS APLICADOS | U40: TOTAL VALOR APLICADO | V40: N° REGISTROS REPORTADOS POR BANCO | W40: VALOR REPORTADO POR BANCO | X40: DIFERENCIA REGISTROS | Y40: DIFERENCIA VALOR | AC40: DIFERENCIA REGISTROS | AD40: REGISTROS ENVIADOS EAAB // SON CARTERA | AE40: REGISTROS NO IDENTIFICADO - NI. | AF40: REGISTROS CON VALOR EN $0 | AG40: VALIDACION | AI40: DIFERENCIA VALOR | AJ40: VALOR ENVIADOS EAAB // SON CARTERA | AK40: VALOR NO IDENTIFICADO - NI. | AL40: VALIDACION
B41: 3/09/2026 | C41: =IF(D41<=15,$C$1,$C$2) -> 2026091 | D41: 2 | E41: 20 | F41: =VLOOKUP(E41,'Códigos bancos'!$B$4:$C$29,2,0) -> Bancolombia ENERBIT | G41: 1 | H41: =VLOOKUP(G41,'Códigos bancos'!$F$4:$G$14,2,0) -> Oficinas | J41: 0 | K41: 0 | L41: 0 | M41: 0 | N41: 0 | O41: 0 | P41: 0 | Q41: 0 | R41: 515 | S41: 22706710 | T41: =J41+L41+N41+P41+R41 -> 515 | U41: =K41+M41+O41+Q41+S41 -> 22706710 | V41: 515 | W41: 22706710 | X41: =V41-T41 -> 0 | Y41: =W41-U41 -> 0 | AC41: =X41 -> 0 | AG41: =AC41=(AD41+AE41+AF41) -> TRUE | AI41: =Y41 -> 0 | AL41: =AI41=(AJ41+AK41) -> TRUE
C42: =IF(D42<=15,$C$1,$C$2) -> 2026091 | D42: 2 | E42: 0 | F42: =VLOOKUP(E42,'Códigos bancos'!$B$4:$C$29,2,0) -> #N/A | G42: 1 | H42: =VLOOKUP(G42,'Códigos bancos'!$F$4:$G$14,2,0) -> Oficinas | J42: 0 | K42: 0 | L42: 0 | M42: 0 | N42: 0 | O42: 0 | P42: 0 | Q42: 0 | R42: 0 | S42: 0 | T42: =J42+L42+N42+P42+R42 -> 0 | U42: =K42+M42+O42+Q42+S42 -> 0 | V42: 0 | W42: 0 | X42: =V42-T42 -> 0 | Y42: =W42-U42 -> 0 | AC42: =X42 -> 0 | AG42: =AC42=(AD42+AE42+AF42) -> TRUE | AI42: =Y42 -> 0 | AL42: =AI42=(AJ42+AK42) -> TRUE
C43: =IF(D43<=15,$C$1,$C$2) -> 2026091 | D43: 2 | E43: 0 | F43: =VLOOKUP(E43,'Códigos bancos'!$B$4:$C$29,2,0) -> #N/A | G43: 1 | H43: =VLOOKUP(G43,'Códigos bancos'!$F$4:$G$14,2,0) -> Oficinas | J43: 0 | K43: 0 | L43: 0 | M43: 0 | N43: 0 | O43: 0 | P43: 0 | Q43: 0 | R43: 0 | S43: 0 | T43: =J43+L43+N43+P43+R43 -> 0 | U43: =K43+M43+O43+Q43+S43 -> 0 | V43: 0 | W43: 0 | X43: =V43-T43 -> 0 | Y43: =W43-U43 -> 0 | AC43: =X43 -> 0 | AG43: =AC43=(AD43+AE43+AF43) -> TRUE | AI43: =Y43 -> 0 | AL43: =AI43=(AJ43+AK43) -> TRUE
C44: =IF(D44<=15,$C$1,$C$2) -> 2026091 | D44: 2 | E44: 0 | F44: =VLOOKUP(E44,'Códigos bancos'!$B$4:$C$29,2,0) -> #N/A | G44: 1 | H44: =VLOOKUP(G44,'Códigos bancos'!$F$4:$G$14,2,0) -> Oficinas | J44: 0 | K44: 0 | L44: 0 | M44: 0 | N44: 0 | O44: 0 | P44: 0 | Q44: 0 | R44: 0 | S44: 0 | T44: =J44+L44+N44+P44+R44 -> 0 | U44: =K44+M44+O44+Q44+S44 -> 0 | V44: 0 | W44: 0 | X44: =V44-T44 -> 0 | Y44: =W44-U44 -> 0 | AC44: =X44 -> 0 | AG44: =AC44=(AD44+AE44+AF44) -> TRUE | AI44: =Y44 -> 0 | AL44: =AI44=(AJ44+AK44) -> TRUE
C45: =IF(D45<=15,$C$1,$C$2) -> 2026091 | D45: 2 | E45: 0 | F45: =VLOOKUP(E45,'Códigos bancos'!$B$4:$C$29,2,0) -> #N/A | G45: 1 | H45: =VLOOKUP(G45,'Códigos bancos'!$F$4:$G$14,2,0) -> Oficinas | J45: 0 | K45: 0 | L45: 0 | M45: 0 | N45: 0 | O45: 0 | P45: 0 | Q45: 0 | R45: 0 | S45: 0 | T45: =J45+L45+N45+P45+R45 -> 0 | U45: =K45+M45+O45+Q45+S45 -> 0 | V45: 0 | W45: 0 | X45: =V45-T45 -> 0 | Y45: =W45-U45 -> 0 | AC45: =X45 -> 0 | AG45: =AC45=(AD45+AE45+AF45) -> TRUE | AI45: =Y45 -> 0 | AL45: =AI45=(AJ45+AK45) -> TRUE
...

Sheet EXTEMPORANEO
C1: =Oportuno!C1 -> 2026091 | J1: =SUM(J13:J110) -> 0 | K1: =SUM(K13:K110) -> 0 | L1: =SUM(L13:L110) -> 0 | M1: =SUM(M13:M110) -> 0 | N1: =SUM(N13:N110) -> 0 | O1: =SUM(O13:O110) -> 0 | P1: =SUM(P13:P110) -> 0 | Q1: =SUM(Q13:Q110) -> 0 | ... Y1: =SUM(Y13:Y110) -> 0 | AD1: =SUM(AD13:AD110) -> 0 | AE1: =SUM(AE13:AE110) -> 0 | AF1: =SUM(AF13:AF110) -> 0 | AG1: =SUM(AG13:AG110) -> 0 | AI1: =SUM(AI13:AI110) -> 0 | AJ1: =SUM(AJ13:AJ110) -> 0 | AK1: =SUM(AK13:AK110) -> 0 | AL1: =SUM(AL13:AL110) -> 0
C2: =Oportuno!C2 -> 2026092 | J2: =SUM(J115:J217) -> 0 | K2: =SUM(K115:K217) -> 0 | L2: =SUM(L115:L217) -> 0 | M2: =SUM(M115:M217) -> 0 | N2: =SUM(N115:N217) -> 0 | O2: =SUM(O115:O217) -> 0 | P2: =SUM(P115:P217) -> 0 | Q2: =SUM(Q115:Q217) -> 0 | ... Y2: =SUM(Y115:Y217) -> 0 | AD2: =SUM(AD115:AD217) -> 0 | AE2: =SUM(AE115:AE217) -> 0 | AF2: =SUM(AF115:AF217) -> 0 | AG2: =SUM(AG115:AG217) -> 0 | AI2: =SUM(AI115:AI217) -> 0 | AJ2: =SUM(AJ115:AJ217) -> 0 | AK2: =SUM(AK115:AK217) -> 0 | AL2: =SUM(AL115:AL217) -> 0
C3: =Oportuno!C3 -> 202609 | J3: =SUM(J1:J2) -> 0 | K3: =SUM(K1:K2) -> 0 | L3: =SUM(L1:L2) -> 0 | M3: =SUM(M1:M2) -> 0 | N3: =SUM(N1:N2) -> 0 | O3: =SUM(O1:O2) -> 0 | P3: =SUM(P1:P2) -> 0 | Q3: =SUM(Q1:Q2) -> 0 | ... Y3: =SUM(Y1:Y2) -> 0 | AD3: =SUM(AD1:AD2) -> 0 | AE3: =SUM(AE1:AE2) -> 0 | AF3: =SUM(AF1:AF2) -> 0 | AG3: =SUM(AG1:AG2) -> 0 | AI3: =SUM(AI1:AI2) -> 0 | AJ3: =SUM(AJ1:AJ2) -> 0 | AK3: =SUM(AK1:AK2) -> 0 | AL3: =SUM(AL1:AL2) -> 0
H6: 2.5.3. INFORMES DE RECAUDO
H7: R2 - INFORME DE CONCILIACION DE RECAUDOS
H8: CONCILIACION DIARIA DE RECAUDO EXTEMPORANEO
E9: NIT: 901 153 639 - 0
H10: =Oportuno!H10 -> SEPTIEMBRE_2026
B12: FECHA APLICACIÓN | C12: CODIGO REMUNERACIÓN | D12: FECHA RECAUDO | E12: CÓDIGO BC | F12: NOMBRE BANCO | G12: CÓDIGO CR | H12: CANAL RECAUDO | I12: N° CUENTA | J12: ASE 1 N° REGISTROS ARCHIVO | K12: ASE 1 VALOR ARCHIVO | L12: ASE 2 N° REGISTROS ARCHIVO | M12: ASE 2 VALOR ARCHIVO | N12: ASE 3 N° REGISTROS ARCHIVO | O12: ASE 3 VALOR ARCHIVO | P12: ASE 4 N° REGISTROS ARCHIVO | Q12: ASE 4 VALOR ARCHIVO | R12: ASE 5 N° REGISTROS ARCHIVO | S12: ASE 5 VALOR ARCHIVO | T12: TOTAL N° REGISTROS APLICADOS | U12: TOTAL VALOR APLICADO | V12: N° REGISTROS REPORTADOS POR BANCO | W12: VALOR REPORTADO POR BANCO | X12: DIFERENCIA REGISTROS | Y12: DIFERENCIA VALOR | AC12: DIFERENCIA REGISTROS | AD12: REGISTROS ENVIADOS EAAB // SON CARTERA | AE12: REGISTROS NO IDENTIFICADO - NI. | AF12: REGISTROS CON VALOR EN $0 | AG12: VALIDACION | AI12: DIFERENCIA VALOR | AJ12: VALOR ENVIADOS EAAB // SON CARTERA | AK12: VALOR NO IDENTIFICADO - NI. | AL12: VALIDACION
B13: 3/09/2026 | C13: =$C$1 -> 2026091 | D13: 46260 | E13: 20 | F13: =VLOOKUP(E13,'Códigos bancos'!$B$3:$D$29,2,0) -> Bancolombia ENERBIT | G13: 1 | H13: =VLOOKUP(G13,'Códigos bancos'!$F$3:$G$14,2,0) -> Oficinas | I13: =VLOOKUP(E13,'Códigos bancos'!$B$3:$D$29,3,0) -> 0 | J13: 0 | K13: 0 | L13: 0 | M13: 0 | N13: 0 | O13: 0 | P13: 0 | Q13: 0 | R13: 6 | S13: 1179300 | T13: =J13+L13+N13+P13+R13 -> 6 | U13: =K13+M13+O13+Q13+S13 -> 1179300 | V13: 6 | W13: 1179300 | X13: =V13-T13 -> 0 | Y13: =W13-U13 -> 0 | AC13: =X13 -> 0 | AD13: 0 | AE13: 0 | AF13: 0 | AG13: =AC13=(AD13+AE13+AF13) -> TRUE | AI13: =Y13 -> 0 | AJ13: 0 | AK13: 0 | AL13: =AI13=(AJ13+AK13) -> TRUE
C14: =$C$1 -> 2026091 | F14: =VLOOKUP(E14,'Códigos bancos'!$B$3:$D$29,2,0) -> #N/A | G14: =IFERROR(IF(T14>0,1,""),"") | H14: =VLOOKUP(G14,'Códigos bancos'!$F$3:$G$14,2,0) -> #N/A | I14: =VLOOKUP(E14,'Códigos bancos'!$B$3:$D$29,3,0) -> #N/A | T14: =J14+L14+N14+P14+R14 -> 0 | U14: =K14+M14+O14+Q14+S14 -> 0 | V14: 0 | X14: =V14-T14 -> 0 | Y14: =W14-U14 -> 0 | AC14: =X14 -> 0 | AD14: 0 | AE14: 0 | AF14: 0 | AG14: =AC14=(AD14+AE14+AF14) -> TRUE | AI14: =Y14 -> 0 | AJ14: 0 | AK14: 0 | AL14: =AI14=(AJ14+AK14) -> TRUE
C15: =$C$1 -> 2026091 | F15: =VLOOKUP(E15,'Códigos bancos'!$B$3:$D$29,2,0) -> #N/A | G15: =IFERROR(IF(T15>0,1,""),"") | H15: =VLOOKUP(G15,'Códigos bancos'!$F$3:$G$14,2,0) -> #N/A | I15: =VLOOKUP(E15,'Códigos bancos'!$B$3:$D$29,3,0) -> #N/A | T15: =J15+L15+N15+P15+R15 -> 0 | U15: =K15+M15+O15+Q15+S15 -> 0 | V15: 0 | W15: 0 | X15: =V15-T15 -> 0 | Y15: =W15-U15 -> 0 | AC15: =X15 -> 0 | AD15: 0 | AE15: 0 | AF15: 0 | AG15: =AC15=(AD15+AE15+AF15) -> TRUE | AI15: =Y15 -> 0 | AJ15: 0 | AK15: 0 | AL15: =AI15=(AJ15+AK15) -> TRUE
C16: =$C$1 -> 2026091 | F16: =VLOOKUP(E16,'Códigos bancos'!$B$3:$D$29,2,0) -> #N/A | G16: =IFERROR(IF(T16>0,1,""),"") | H16: =VLOOKUP(G16,'Códigos bancos'!$F$3:$G$14,2,0) -> #N/A | I16: =VLOOKUP(E16,'Códigos bancos'!$B$3:$D$29,3,0) -> #N/A | T16: =J16+L16+N16+P16+R16 -> 0 | U16: =K16+M16+O16+Q16+S16 -> 0 | V16: 0 | W16: 0 | X16: =V16-T16 -> 0 | Y16: =W16-U16 -> 0 | AC16: =X16 -> 0 | AD16: 0 | AE16: 0 | AF16: 0 | AG16: =AC16=(AD16+AE16+AF16) -> TRUE | AI16: =Y16 -> 0 | AJ16: 0 | AK16: 0 | AL16: =AI16=(AJ16+AK16) -> TRUE
C17: =$C$1 -> 2026091 | F17: =VLOOKUP(E17,'Códigos bancos'!$B$3:$D$29,2,0) -> #N/A | G17: =IFERROR(IF(T17>0,1,""),"") | H17: =VLOOKUP(G17,'Códigos bancos'!$F$3:$G$14,2,0) -> #N/A | I17: =VLOOKUP(E17,'Códigos bancos'!$B$3:$D$29,3,0) -> #N/A | T17: =J17+L17+N17+P17+R17 -> 0 | U17: =K17+M17+O17+Q17+S17 -> 0 | V17: 0 | W17: 0 | X17: =V17-T17 -> 0 | Y17: =W17-U17 -> 0 | AC17: =X17 -> 0 | AD17: 0 | AE17: 0 | AF17: 0 | AG17: =AC17=(AD17+AE17+AF17) -> TRUE | AI17: =Y17 -> 0 | AJ17: 0 | AK17: 0 | AL17: =AI17=(AJ17+AK17) -> TRUE
C18: =$C$1 -> 2026091 | F18: =VLOOKUP(E18,'Códigos bancos'!$B$3:$D$29,2,0) -> #N/A | G18: =IFERROR(IF(T18>0,1,""),"") | H18: =VLOOKUP(G18,'Códigos bancos'!$F$3:$G$14,2,0) -> #N/A | I18: =VLOOKUP(E18,'Códigos bancos'!$B$3:$D$29,3,0) -> #N/A | T18: =J18+L18+N18+P18+R18 -> 0 | U18: =K18+M18+O18+Q18+S18 -> 0 | V18: 0 | W18: 0 | X18: =V18-T18 -> 0 | Y18: =W18-U18 -> 0 | AC18: =X18 -> 0 | AD18: 0 | AE18: 0 | AF18: 0 | AG18: =AC18=(AD18+AE18+AF18) -> TRUE | AI18: =Y18 -> 0 | AJ18: 0 | AK18: 0 | AL18: =AI18=(AJ18+AK18) -> TRUE
C19: =$C$1 -> 2026091 | F19: =VLOOKUP(E19,'Códigos bancos'!$B$3:$D$29,2,0) -> #N/A | G19: =IFERROR(IF(T19>0,1,""),"") | H19: =VLOOKUP(G19,'Códigos bancos'!$F$3:$G$14,2,0) -> #N/A | I19: =VLOOKUP(E19,'Códigos bancos'!$B$3:$D$29,3,0) -> #N/A | T19: =J19+L19+N19+P19+R19 -> 0 | U19: =K19+M19+O19+Q19+S19 -> 0 | V19: 0 | W19: 0 | X19: =V19-T19 -> 0 | Y19: =W19-U19 -> 0 | AC19: =X19 -> 0 | AD19: 0 | AE19: 0 | AF19: 0 | AG19: =AC19=(AD19+AE19+AF19) -> TRUE | AI19: =Y19 -> 0 | AJ19: 0 | AK19: 0 | AL19: =AI19=(AJ19+AK19) -> TRUE
C20: =$C$1 -> 2026091 | F20: =VLOOKUP(E20,'Códigos bancos'!$B$3:$D$29,2,0) -> #N/A | G20: =IFERROR(IF(T20>0,1,""),"") | H20: =VLOOKUP(G20,'Códigos bancos'!$F$3:$G$14,2,0) -> #N/A | I20: =VLOOKUP(E20,'Códigos bancos'!$B$3:$D$29,3,0) -> #N/A | T20: =J20+L20+N20+P20+R20 -> 0 | U20: =K20+M20+O20+Q20+S20 -> 0 | V20: 0 | W20: 0 | X20: =V20-T20 -> 0 | Y20: =W20-U20 -> 0 | AC20: =X20 -> 0 | AD20: 0 | AE20: 0 | AF20: 0 | AG20: =AC20=(AD20+AE20+AF20) -> TRUE | AI20: =Y20 -> 0 | AJ20: 0 | AK20: 0 | AL20: =AI20=(AJ20+AK20) -> TRUE
C21: =$C$1 -> 2026091 | F21: =VLOOKUP(E21,'Códigos bancos'!$B$3:$D$29,2,0) -> #N/A | G21: =IFERROR(IF(T21>0,1,""),"") | H21: =VLOOKUP(G21,'Códigos bancos'!$F$3:$G$14,2,0) -> #N/A | I21: =VLOOKUP(E21,'Códigos bancos'!$B$3:$D$29,3,0) -> #N/A | T21: =J21+L21+N21+P21+R21 -> 0 | U21: =K21+M21+O21+Q21+S21 -> 0 | V21: 0 | W21: 0 | X21: =V21-T21 -> 0 | Y21: =W21-U21 -> 0 | AC21: =X21 -> 0 | AD21: 0 | AE21: 0 | AF21: 0 | AG21: =AC21=(AD21+AE21+AF21) -> TRUE | AI21: =Y21 -> 0 | AJ21: 0 | AK21: 0 | AL21: =AI21=(AJ21+AK21) -> TRUE
C22: =$C$1 -> 2026091 | F22: =VLOOKUP(E22,'Códigos bancos'!$B$3:$D$29,2,0) -> #N/A | G22: =IFERROR(IF(T22>0,1,""),"") | H22: =VLOOKUP(G22,'Códigos bancos'!$F$3:$G$14,2,0) -> #N/A | I22: =VLOOKUP(E22,'Códigos bancos'!$B$3:$D$29,3,0) -> #N/A | T22: =J22+L22+N22+P22+R22 -> 0 | U22: =K22+M22+O22+Q22+S22 -> 0 | V22: 0 | W22: 0 | X22: =V22-T22 -> 0 | Y22: =W22-U22 -> 0 | AC22: =X22 -> 0 | AD22: 0 | AE22: 0 | AF22: 0 | AG22: =AC22=(AD22+AE22+AF22) -> TRUE | AI22: =Y22 -> 0 | AJ22: 0 | AK22: 0 | AL22: =AI22=(AJ22+AK22) -> TRUE
C23: =$C$1 -> 2026091 | F23: =VLOOKUP(E23,'Códigos bancos'!$B$3:$D$29,2,0) -> #N/A | G23: =IFERROR(IF(T23>0,1,""),"") | H23: =VLOOKUP(G23,'Códigos bancos'!$F$3:$G$14,2,0) -> #N/A | I23: =VLOOKUP(E23,'Códigos bancos'!$B$3:$D$29,3,0) -> #N/A | T23: =J23+L23+N23+P23+R23 -> 0 | U23: =K23+M23+O23+Q23+S23 -> 0 | V23: 0 | W23: 0 | X23: =V23-T23 -> 0 | Y23: =W23-U23 -> 0 | AC23: =X23 -> 0 | AD23: 0 | AE23: 0 | AF23: 0 | AG23: =AC23=(AD23+AE23+AF23) -> TRUE | AI23: =Y23 -> 0 | AJ23: 0 | AK23: 0 | AL23: =AI23=(AJ23+AK23) -> TRUE
C24: =$C$1 -> 2026091 | F24: =VLOOKUP(E24,'Códigos bancos'!$B$3:$D$29,2,0) -> #N/A | G24: =IFERROR(IF(T24>0,1,""),"") | H24: =VLOOKUP(G24,'Códigos bancos'!$F$3:$G$14,2,0) -> #N/A | I24: =VLOOKUP(E24,'Códigos bancos'!$B$3:$D$29,3,0) -> #N/A | T24: =J24+L24+N24+P24+R24 -> 0 | U24: =K24+M24+O24+Q24+S24 -> 0 | V24: 0 | W24: 0 | X24: =V24-T24 -> 0 | Y24: =W24-U24 -> 0 | AC24: =X24 -> 0 | AD24: 0 | AE24: 0 | AF24: 0 | AG24: =AC24=(AD24+AE24+AF24) -> TRUE | AI24: =Y24 -> 0 | AJ24: 0 | AK24: 0 | AL24: =AI24=(AJ24+AK24) -> TRUE
C25: =$C$1 -> 2026091 | F25: =VLOOKUP(E25,'Códigos bancos'!$B$3:$D$29,2,0) -> #N/A | G25: =IFERROR(IF(T25>0,1,""),"") | H25: =VLOOKUP(G25,'Códigos bancos'!$F$3:$G$14,2,0) -> #N/A | I25: =VLOOKUP(E25,'Códigos bancos'!$B$3:$D$29,3,0) -> #N/A | T25: =J25+L25+N25+P25+R25 -> 0 | U25: =K25+M25+O25+Q25+S25 -> 0 | V25: 0 | W25: 0 | X25: =V25-T25 -> 0 | Y25: =W25-U25 -> 0 | AC25: =X25 -> 0 | AD25: 0 | AE25: 0 | AF25: 0 | AG25: =AC25=(AD25+AE25+AF25) -> TRUE | AI25: =Y25 -> 0 | AJ25: 0 | AK25: 0 | AL25: =AI25=(AJ25+AK25) -> TRUE
C26: =$C$1 -> 2026091 | F26: =VLOOKUP(E26,'Códigos bancos'!$B$3:$D$29,2,0) -> #N/A | G26: =IFERROR(IF(T26>0,1,""),"") | H26: =VLOOKUP(G26,'Códigos bancos'!$F$3:$G$14,2,0) -> #N/A | I26: =VLOOKUP(E26,'Códigos bancos'!$B$3:$D$29,3,0) -> #N/A | T26: =J26+L26+N26+P26+R26 -> 0 | U26: =K26+M26+O26+Q26+S26 -> 0 | V26: 0 | W26: 0 | X26: =V26-T26 -> 0 | Y26: =W26-U26 -> 0 | AC26: =X26 -> 0 | AD26: 0 | AE26: 0 | AF26: 0 | AG26: =AC26=(AD26+AE26+AF26) -> TRUE | AI26: =Y26 -> 0 | AJ26: 0 | AK26: 0 | AL26: =AI26=(AJ26+AK26) -> TRUE
... C110: =$C$1 -> 2026091 | F110: =VLOOKUP(E110,'Códigos bancos'!$B$3:$D$29,2,0) -> #N/A | G110: =IFERROR(IF(T110>0,1,""),"") | H110: =VLOOKUP(G110,'Códigos bancos'!$F$3:$G$14,2,0) -> #N/A | I110: =VLOOKUP(E110,'Códigos bancos'!$B$3:$D$29,3,0) -> #N/A | T110: =J110+L110+N110+P110+R110 -> 0 | U110: =K110+M110+O110+Q110+S110 -> 0 | V110: 0 | W110: 0 | X110: =V110-T110 -> 0 | Y110: =W110-U110 -> 0 | AC110: =X110 -> 0 | AD110: 0 | AE110: 0 | AF110: 0 | AG110: =AC110=(AD110+AE110+AF110) -> TRUE | AI110: =Y110 -> 0 | AJ110: 0 | AK110: 0 | AL110: =AI110=(AJ110+AK110) -> TRUE
B114: FECHA APLICACIÓN | C114: CODIGO REMUNERACIÓN | D114: FECHA RECAUDO | E114: CÓDIGO BC | F114: NOMBRE BANCO | G114: CÓDIGO CR | H114: CANAL RECAUDO | I114: N° CUENTA | J114: ASE 1 N° REGISTROS ARCHIVO | K114: ASE 1 VALOR ARCHIVO | L114: ASE 2 N° REGISTROS ARCHIVO | M114: ASE 2 VALOR ARCHIVO | N114: ASE 3 N° REGISTROS ARCHIVO | O114: ASE 3 VALOR ARCHIVO | P114: ASE 4 N° REGISTROS ARCHIVO | Q114: ASE 4 VALOR ARCHIVO | R114: ASE 5 N° REGISTROS ARCHIVO | S114: ASE 5 VALOR ARCHIVO | T114: TOTAL N° REGISTROS APLICADOS | U114: TOTAL VALOR APLICADO | V114: N° REGISTROS REPORTADOS POR BANCO | W114: VALOR REPORTADO POR BANCO | X114: DIFERENCIA REGISTROS | Y114: DIFERENCIA VALOR | AC114: DIFERENCIA REGISTROS | AD114: REGISTROS ENVIADOS EAAB // SON CARTERA | AE114: REGISTROS NO IDENTIFICADO - NI. | AF114: REGISTROS CON VALOR EN $0 | AG114: VALIDACION | AI114: DIFERENCIA VALOR | AJ114: VALOR ENVIADOS EAAB // SON CARTERA | AK114: VALOR NO IDENTIFICADO - NI. | AL114: VALIDACION
B115: 18/09/2026 | C115: =$C$2 -> 2026092 | D115: 46266 | E115: 20 | F115: =VLOOKUP(E115,'Códigos bancos'!$B$3:$D$29,2,0) -> Bancolombia ENERBIT | G115: =IFERROR(IF(T115>0,1,""),"") -> 1 | H115: =VLOOKUP(G115,'Códigos bancos'!$F$3:$G$14,2,0) -> Oficinas | I115: =VLOOKUP(E115,'Códigos bancos'!$B$3:$D$29,3,0) -> 0 | R115: 17 | S115: 671920 | T115: =J115+L115+N115+P115+R115 -> 17 | U115: =K115+M115+O115+Q115+S115 -> 671920 | V115: 17 | W115: 671920 | X115: =V115-T115 -> 0 | Y115: =W115-U115 -> 0 | AC115: =X115 -> 0 | AD115: 0 | AE115: 0 | AF115: 0 | AG115: =AC115=(AD115+AE115+AF115) -> TRUE | AI115: =Y115 -> 0 | AJ115: 0 | AK115: 0 | AL115: =AI115=(AJ115+AK115) -> TRUE
B116: 18/09/2026 | C116: =$C$2 -> 2026092 | D116: 46267 | E116: 20 | F116: =VLOOKUP(E116,'Códigos bancos'!$B$3:$D$29,2,0) -> Bancolombia ENERBIT | G116: =IFERROR(IF(T116>0,1,""),"") -> 1 | H116: =VLOOKUP(G116,'Códigos bancos'!$F$3:$G$14,2,0) -> Oficinas | I116: =VLOOKUP(E116,'Códigos bancos'!$B$3:$D$29,3,0) -> 0 | R116: 17 | S116: 683150 | T116: =J116+L116+N116+P116+R116 -> 17 | U116: =K116+M116+O116+Q116+S116 -> 683150 | V116: 17 | W116: 683150 | X116: =V116-T116 -> 0 | Y116: =W116-U116 -> 0 | AC116: =X116 -> 0 | AD116: 0 | AE116: 0 | AF116: 0 | AG116: =AC116=(AD116+AE116+AF116) -> TRUE | AI116: =Y116 -> 0 | AJ116: 0 | AK116: 0 | AL116: =AI116=(AJ116+AK116) -> TRUE
B117: 18/09/2026 | C117: =$C$2 -> 2026092 | D117: 46268 | E117: 20 | F117: =VLOOKUP(E117,'Códigos bancos'!$B$3:$D$29,2,0) -> Bancolombia ENERBIT | G117: =IFERROR(IF(T117>0,1,""),"") -> 1 | H117: =VLOOKUP(G117,'Códigos bancos'!$F$3:$G$14,2,0) -> Oficinas | I117: =VLOOKUP(E117,'Códigos bancos'!$B$3:$D$29,3,0) -> 0 | R117: 6 | S117: 289600 | T117: =J117+L117+N117+P117+R117 -> 6 | U117: =K117+M117+O117+Q117+S117 -> 289600 | V117: 6 | W117: 289600 | X117: =V117-T117 -> 0 | Y117: =W117-U117 -> 0 | AC117: =X117 -> 0 | AD117: 0 | AE117: 0 | AF117: 0 | AG117: =AC117=(AD117+AE117+AF117) -> TRUE | AI117: =Y117 -> 0 | AJ117: 0 | AK117: 0 | AL117: =AI117=(AJ117+AK117) -> TRUE
B118: 18/09/2026 | C118: =$C$2 -> 2026092 | D118: 46271 | E118: 20 | F118: =VLOOKUP(E118,'Códigos bancos'!$B$3:$D$29,2,0) -> Bancolombia ENERBIT | G118: =IFERROR(IF(T118>0,1,""),"") -> 1 | H118: =VLOOKUP(G118,'Códigos bancos'!$F$3:$G$14,2,0) -> Oficinas | I118: =VLOOKUP(E118,'Códigos bancos'!$B$3:$D$29,3,0) -> 0 | R118: 3 | S118: 130990 | T118: =J118+L118+N118+P118+R118 -> 3 | U118: =K118+M118+O118+Q118+S118 -> 130990 | V118: 3 | W118: 130990 | X118: =V118-T118 -> 0 | Y118: =W118-U118 -> 0 | AC118: =X118 -> 0 | AD118: 0 | AE118: 0 | AF118: 0 | AG118: =AC118=(AD118+AE118+AF118) -> TRUE | AI118: =Y118 -> 0 | AJ118: 0 | AK118: 0 | AL118: =AI118=(AJ118+AK118) -> TRUE
B119: 18/09/2026 | C119: =$C$2 -> 2026092 | D119: 46272 | E119: 20 | F119: =VLOOKUP(E119,'Códigos bancos'!$B$3:$D$29,2,0) -> Bancolombia ENERBIT | G119: =IFERROR(IF(T119>0,1,""),"") -> 1 | H119: =VLOOKUP(G119,'Códigos bancos'!$F$3:$G$14,2,0) -> Oficinas | I119: =VLOOKUP(E119,'Códigos bancos'!$B$3:$D$29,3,0) -> 0 | R119: 18 | S119: 2462190 | T119: =J119+L119+N119+P119+R119 -> 18 | U119: =K119+M119+O119+Q119+S119 -> 2462190 | V119: 18 | W119: 2462190 | X119: =V119-T119 -> 0 | Y119: =W119-U119 -> 0 | AC119: =X119 -> 0 | AD119: 0 | AE119: 0 | AF119: 0 | AG119: =AC119=(AD119+AE119+AF119) -> TRUE | AI119: =Y119 -> 0 | AJ119: 0 | AK119: 0 | AL119: =AI119=(AJ119+AK119) -> TRUE
B120: 18/09/2026 | C120: =$C$2 -> 2026092 | D120: 46274 | E120: 20 | F120: =VLOOKUP(E120,'Códigos bancos'!$B$3:$D$29,2,0) -> Bancolombia ENERBIT | G120: =IFERROR(IF(T120>0,1,""),"") -> 1 | H120: =VLOOKUP(G120,'Códigos bancos'!$F$3:$G$14,2,0) -> Oficinas | I120: =VLOOKUP(E120,'Códigos bancos'!$B$3:$D$29,3,0) -> 0 | R120: 5 | S120: 272630 | T120: =J120+L120+N120+P120+R120 -> 5 | U120: =K120+M120+O120+Q120+S120 -> 272630 | V120: 5 | W120: 272630 | X120: =V120-T120 -> 0 | Y120: =W120-U120 -> 0 | AC120: =X120 -> 0 | AD120: 0 | AE120: 0 | AF120: 0 | AG120: =AC120=(AD120+AE120+AF120) -> TRUE | AI120: =Y120 -> 0 | AJ120: 0 | AK120: 0 | AL120: =AI120=(AJ120+AK120) -> TRUE
B121: 18/09/2026 | C121: =$C$2 -> 2026092 | D121: 46275 | E121: 20 | F121: =VLOOKUP(E121,'Códigos bancos'!$B$3:$D$29,2,0) -> Bancolombia ENERBIT | G121: =IFERROR(IF(T121>0,1,""),"") -> 1 | H121: =VLOOKUP(G121,'Códigos bancos'!$F$3:$G$14,2,0) -> Oficinas | I121: =VLOOKUP(E121,'Códigos bancos'!$B$3:$D$29,3,0) -> 0 | R121: 8 | S121: 670100 | T121: =J121+L121+N121+P121+R121 -> 8 | U121: =K121+M121+O121+Q121+S121 -> 670100 | V121: 8 | W121: 670100 | X121: =V121-T121 -> 0 | Y121: =W121-U121 -> 0 | AC121: =X121 -> 0 | AD121: 0 | AE121: 0 | AF121: 0 | AG121: =AC121=(AD121+AE121+AF121) -> TRUE | AI121: =Y121 -> 0 | AJ121: 0 | AK121: 0 | AL121: =AI121=(AJ121+AK121) -> TRUE
B122: 18/09/2026 | C122: =$C$2 -> 2026092 | D122: 46279 | E122: 20 | F122: =VLOOKUP(E122,'Códigos bancos'!$B$3:$D$29,2,0) -> Bancolombia ENERBIT | G122: =IFERROR(IF(T122>0,1,""),"") -> 1 | H122: =VLOOKUP(G122,'Códigos bancos'!$F$3:$G$14,2,0) -> Oficinas | I122: =VLOOKUP(E122,'Códigos bancos'!$B$3:$D$29,3,0) -> 0 | R122: 2 | S122: 62102 | T122: =J122+L122+N122+P122+R122 -> 2 | U122: =K122+M122+O122+Q122+S122 -> 62102 | V122: 2 | W122: 62102 | X122: =V122-T122 -> 0 | Y122: =W122-U122 -> 0 | AC122: =X122 -> 0 | AD122: 0 | AE122: 0 | AF122: 0 | AG122: =AC122=(AD122+AE122+AF122) -> TRUE | AI122: =Y122 -> 0 | AJ122: 0 | AK122: 0 | AL122: =AI122=(AJ122+AK122) -> TRUE
C123: =$C$2 -> 2026092 | F123: =VLOOKUP(E123,'Códigos bancos'!$B$3:$D$29,2,0) -> #N/A | G123: =IFERROR(IF(T123>0,1,""),"") | H123: =VLOOKUP(G123,'Códigos bancos'!$F$3:$G$14,2,0) -> #N/A | I123: =VLOOKUP(E123,'Códigos bancos'!$B$3:$D$29,3,0) -> #N/A | T123: =J123+L123+N123+P123+R123 -> 0 | U123: =K123+M123+O123+Q123+S123 -> 0 | V123: 0 | W123: 0 | X123: =V123-T123 -> 0 | Y123: =W123-U123 -> 0 | AC123: =X123 -> 0 | AD123: 0 | AE123: 0 | AF123: 0 | AG123: =AC123=(AD123+AE123+AF123) -> TRUE | AI123: =Y123 -> 0 | AJ123: 0 | AK123: 0 | AL123: =AI123=(AJ123+AK123) -> TRUE
C124: =$C$2 -> 2026092 | F124: =VLOOKUP(E124,'Códigos bancos'!$B$3:$D$29,2,0) -> #N/A | G124: =IFERROR(IF(T124>0,1,""),"") | H124: =VLOOKUP(G124,'Códigos bancos'!$F$3:$G$14,2,0) -> #N/A | I124: =VLOOKUP(E124,'Códigos bancos'!$B$3:$D$29,3,0) -> #N/A | T124: =J124+L124+N124+P124+R124 -> 0 | U124: =K124+M124+O124+Q124+S124 -> 0 | V124: 0 | W124: 0 | X124: =V124-T124 -> 0 | Y124: =W124-U124 -> 0 | AC124: =X124 -> 0 | AD124: 0 | AE124: 0 | AF124: 0 | AG124: =AC124=(AD124+AE124+AF124) -> TRUE | AI124: =Y124 -> 0 | AJ124: 0 | AK124: 0 | AL124: =AI124=(AJ124+AK124) -> TRUE
C125: =$C$2 -> 2026092 | F125: =VLOOKUP(E125,'Códigos bancos'!$B$3:$D$29,2,0) -> #N/A | G125: =IFERROR(IF(T125>0,1,""),"") | H125: =VLOOKUP(G125,'Códigos bancos'!$F$3:$G$14,2,0) -> #N/A | I125: =VLOOKUP(E125,'Códigos bancos'!$B$3:$D$29,3,0) -> #N/A | T125: =J125+L125+N125+P125+R125 -> 0 | U125: =K125+M125+O125+Q125+S125 -> 0 | V125: 0 | W125: 0 | X125: =V125-T125 -> 0 | Y125: =W125-U125 -> 0 | AC125: =X125 -> 0 | AD125: 0 | AE125: 0 | AF125: 0 | AG125: =AC125=(AD125+AE125+AF125) -> TRUE | AI125: =Y125 -> 0 | AJ125: 0 | AK125: 0 | AL125: =AI125=(AJ125+AK125) -> TRUE
C126: =$C$2 -> 2026092 | F126: =VLOOKUP(E126,'Códigos bancos'!$B$3:$D$29,2,0) -> #N/A | G126: =IFERROR(IF(T126>0,1,""),"") | H126: =VLOOKUP(G126,'Códigos bancos'!$F$3:$G$14,2,0) -> #N/A | I126: =VLOOKUP(E126,'Códigos bancos'!$B$3:$D$29,3,0) -> #N/A | T126: =J126+L126+N126+P126+R126 -> 0 | U126: =K126+M126+O126+Q126+S126 -> 0 | V126: 0 | W126: 0 | X126: =V126-T126 -> 0 | Y126: =W126-U126 -> 0 | AC126: =X126 -> 0 | AD126: 0 | AE126: 0 | AF126: 0 | AG126: =AC126=(AD126+AE126+AF126) -> TRUE | AI126: =Y126 -> 0 | AJ126: 0 | AK126: 0 | AL126: =AI126=(AJ126+AK126) -> TRUE
C127: =$C$2 -> 2026092 | F127: =VLOOKUP(E127,'Códigos bancos'!$B$3:$D$29,2,0) -> #N/A | G127: =IFERROR(IF(T127>0,1,""),"") | H127: =VLOOKUP(G127,'Códigos bancos'!$F$3:$G$14,2,0) -> #N/A | I127: =VLOOKUP(E127,'Códigos bancos'!$B$3:$D$29,3,0) -> #N/A | T127: =J127+L127+N127+P127+R127 -> 0 | U127: =K127+M127+O127+Q127+S127 -> 0 | V127: 0 | W127: 0 | X127: =V127-T127 -> 0 | Y127: =W127-U127 -> 0 | AC127: =X127 -> 0 | AD127: 0 | AE127: 0 | AF127: 0 | AG127: =AC127=(AD127+AE127+AF127) -> TRUE | AI127: =Y127 -> 0 | AJ127: 0 | AK127: 0 | AL127: =AI127=(AJ127+AK127) -> TRUE
C128: =$C$2 -> 2026092 | F128: =VLOOKUP(E128,'Códigos bancos'!$B$3:$D$29,2,0) -> #N/A | G128: =IFERROR(IF(T128>0,1,""),"") | H128: =VLOOKUP(G128,'Códigos bancos'!$F$3:$G$14,2,0) -> #N/A | I128: =VLOOKUP(E128,'Códigos bancos'!$B$3:$D$29,3,0) -> #N/A | T128: =J128+L128+N128+P128+R128 -> 0 | U128: =K128+M128+O128+Q128+S128 -> 0 | V128: 0 | W128: 0 | X128: =V128-T128 -> 0 | Y128: =W128-U128 -> 0 | AC128: =X128 -> 0 | AD128: 0 | AE128: 0 | AF128: 0 | AG128: =AC128=(AD128+AE128+AF128) -> TRUE | AI128: =Y128 -> 0 | AJ128: 0 | AK128: 0 | AL128: =AI128=(AJ128+AK128) -> TRUE
C129: =$C$2 -> 2026092 | F129: =VLOOKUP(E129,'Códigos bancos'!$B$3:$D$29,2,0) -> #N/A | G129: =IFERROR(IF(T129>0,1,""),"") | H129: =VLOOKUP(G129,'Códigos bancos'!$F$3:$G$14,2,0) -> #N/A | I129: =VLOOKUP(E129,'Códigos bancos'!$B$3:$D$29,3,0) -> #N/A | T129: =J129+L129+N129+P129+R129 -> 0 | U129: =K129+M129+O129+Q129+S129 -> 0 | V129: 0 | W129: 0 | X129: =V129-T129 -> 0 | Y129: =W129-U129 -> 0 | AC129: =X129 -> 0 | AD129: 0 | AE129: 0 | AF129: 0 | AG129: =AC129=(AD129+AE129+AF129) -> TRUE | AI129: =Y129 -> 0 | AJ129: 0 | AK129: 0 | AL129: =AI129=(AJ129+AK129) -> TRUE
...

Sheet RESUMEN MES
B2: OPORTUNO | C2: ASE | D2: VALOR 1° Q | E2: NUMERO REG. 1°Q | F2: VALOR 2° Q | G2: NUMERO REG. 2°Q
C3: 1 | D3: =Oportuno!K1 -> 0 | E3: =Oportuno!J1 -> 0 | F3: =Oportuno!K2 -> 0 | G3: =Oportuno!J2 -> 0
C4: 2 | D4: =Oportuno!M1 -> 0 | E4: =Oportuno!L1 -> 0 | F4: =Oportuno!M2 -> 0 | G4: =Oportuno!L2 -> 0
C5: 3 | D5: =Oportuno!O1 -> 0 | E5: =Oportuno!N1 -> 0 | F5: =Oportuno!O2 -> 0 | G5: =Oportuno!N2 -> 0
C6: 4 | D6: =Oportuno!Q1 -> 0 | E6: =Oportuno!P1 -> 0 | F6: =Oportuno!Q2 -> 0 | G6: =Oportuno!P2 -> 0
C7: 5 | D7: =Oportuno!S1 -> 137371512 | E7: =Oportuno!R1 -> 3020 | F7: =Oportuno!S2 -> 33627704 | G7: =Oportuno!R2 -> 521
C8: X
D9: =SUM(D3:D8) -> 137371512 | E9: =SUM(E3:E8) -> 3020 | F9: =SUM(F3:F8) -> 33627704 | G9: =SUM(G3:G8) -> 521
C11: ASE | D11: VALOR 1° Q | E11: NUMERO REG. 1°Q | F11: VALOR 2° Q | G11: NUMERO REG. 2°Q
B12: EXTEMP. | C12: 1 | D12: =EXTEMPORANEO!K1 -> 0 | E12: =EXTEMPORANEO!J1 -> 0 | F12: =EXTEMPORANEO!K2 -> 0 | G12: =EXTEMPORANEO!J2 -> 0
C13: 2 | D13: =EXTEMPORANEO!M1 -> 0 | E13: =EXTEMPORANEO!L1 -> 0 | F13: =EXTEMPORANEO!M2 -> 0 | G13: =EXTEMPORANEO!L2 -> 0
C14: 3 | D14: =EXTEMPORANEO!O1 -> 0 | E14: =EXTEMPORANEO!N1 -> 0 | F14: =EXTEMPORANEO!O2 -> 0 | G14: =EXTEMPORANEO!N2 -> 0
C15: 4 | D15: =EXTEMPORANEO!Q1 -> 0 | E15: =EXTEMPORANEO!P1 -> 0 | F15: =EXTEMPORANEO!Q2 -> 0 | G15: =EXTEMPORANEO!P2 -> 0
C16: 5 | D16: =EXTEMPORANEO!S1 -> 1179300 | E16: =EXTEMPORANEO!R1 -> 6 | F16: =EXTEMPORANEO!S2 -> 5242682 | G16: =EXTEMPORANEO!R2 -> 76
C17: X
D18: =SUM(D12:D17) -> 1179300 | E18: =SUM(E12:E17) -> 6 | F18: =SUM(F12:F17) -> 5242682 | G18: =SUM(G12:G17) -> 76
C20: ASE | D20: VALOR 1° Q | E20: NUMERO REG. 1°Q | F20: VALOR 2° Q | G20: NUMERO REG. 2°Q | I20: VALOR TOTAL MES | J20: NUMERO REGISTROS MES
B21: TOTAL | C21: 1 | D21: =D3+D12 -> 0 | E21: =E3+E12 -> 0 | F21: =F3+F12 -> 0 | G21: =G3+G12 -> 0 | I21: =D21+F21 -> 0 | J21: =E21+G21 -> 0
C22: 2 | D22: =D4+D13 -> 0 | E22: =E4+E13 -> 0 | F22: =F4+F13 -> 0 | G22: =G4+G13 -> 0 | I22: =D22+F22 -> 0 | J22: =E22+G22 -> 0
C23: 3 | D23: =D5+D14 -> 0 | E23: =E5+E14 -> 0 | F23: =F5+F14 -> 0 | G23: =G5+G14 -> 0 | I23: =D23+F23 -> 0 | J23: =E23+G23 -> 0
C24: 4 | D24: =D6+D15 -> 0 | E24: =E6+E15 -> 0 | F24: =F6+F15 -> 0 | G24: =G6+G15 -> 0 | I24: =D24+F24 -> 0 | J24: =E24+G24 -> 0
C25: 5 | D25: =D7+D16 -> 138550812 | E25: =E7+E16 -> 3026 | F25: =F7+F16 -> 38870386 | G25: =G7+G16 -> 597 | I25: =D25+F25 -> 177421198 | J25: =E25+G25 -> 3623
C26: X | I26: =D26+F26 -> 0 | J26: =E26+G26 -> 0
D27: =SUM(D21:D26) -> 138550812 | E27: =SUM(E21:E26) -> 3026 | F27: =SUM(F21:F26) -> 38870386 | G27: =SUM(G21:G26) -> 597 | I27: =SUM(I21:I26) -> 177421198 | J27: =SUM(J21:J26) -> 3623

Sheet Códigos bancos
B3: Código BC | C3: Nombre Banco | D3: Cuenta Bancaria | F3: Código CR | G3: Canal Recaudo
B4: 20 | C4: Bancolombia ENERBIT | F4: 1 | G4: Oficinas

Sheet Reversiones
E3: GESTION DE RECAUDO
E4: CONCILIACION DIARIA DE RECAUDO
D6: NIT: 901 153 639 - 0
E7: =Oportuno!H10 -> SEPTIEMBRE_2026
B8: REVERSIONES -
B9: Fecha de Reversion | C9: Fecha de Recaudo | D9: Entidad que reporto. | E9: ASE 1 Valor | F9: ASE 2 Valor | G9: ASE 3 Valor | H9: ASE 4 Valor | I9: ASE 5 Valor | J9: Valor Reversado | K9: Cuenta Contrato-REVERSION | M9: Cuenta Contrato-NUEVA APLICACIÓN | N9: FECHA NUEVA APLICACIÓN
J10: =SUM(E10:I10) -> 0
J11: =SUM(E11:I11) -> 0
J12: =SUM(E12:I12) -> 0
J13: =SUM(E13:I13) -> 0
J14: =SUM(E14:I14) -> 0
J15: =SUM(E15:I15) -> 0
J16: =SUM(E16:I16) -> 0
J17: =SUM(E17:I17) -> 0
J18: =SUM(E18:I18) -> 0
J19: =SUM(E19:I19) -> 0
J20: =SUM(E20:I20) -> 0
J21: =SUM(E21:I21) -> 0
... J99: =SUM(E99:I99) -> 0
D100: TOTAL | E100: =SUM(E10:E99) -> 0 | F100: =SUM(F10:F99) -> 0 | G100: =SUM(G10:G99) -> 0 | H100: =SUM(H10:H99) -> 0 | I100: =SUM(I10:I99) -> 0 | J100: =SUM(J10:J99) -> 0

Sheet 1_Oportuno ENERBIT
C1: =Oportuno!C1 -> 2026091 | J1: =J38+J66+J94+J122+J150+J178+J206+J234+J262+J290+J318+J346+J374+J402+J430 -> 0 | K1: =K38+K66+K94+K122+K150+K178+K206+K234+K262+K290+K318+K346+K374+K402+K430 -> 0 | L1: =L38+L66+L94+L122+L150+L178+L206+L234+L262+L290+L318+L346+L374+L402+L430 -> 0 | M1: =M38+M66+M94+M122+M150+M178+M206+M234+M262+M290+M318+M346+M374+M402+M430 -> 0 | N1: =N38+N66+N94+N122+N150+N178+N206+N234+N262+N290+N318+N346+N374+N402+N430 -> 0 | O1: =O38+O66+O94+O122+O150+O178+O206+O234+O262+O290+O318+O346+O374+O402+O430 -> 0 | P1: =P38+P66+P94+P122+P150+P178+P206+P234+P262+P290+P318+P346+P374+P402+P430 -> 0 | Q1: =Q38+Q66+Q94+Q122+Q150+Q178+Q206+Q234+Q262+Q290+Q318+Q346+Q374+Q402+Q430 -> 0 | ... Y1: =Y38+Y66+Y94+Y122+Y150+Y178+Y206+Y234+Y262+Y290+Y318+Y346+Y374+Y402+Y430 -> 0 | AC1: =C1=Oportuno!C1 -> TRUE | AD1: =D1=Oportuno!D1 -> TRUE | AE1: =E1=Oportuno!E1 -> TRUE | AF1: =F1=Oportuno!F1 -> TRUE | AG1: =G1=Oportuno!G1 -> TRUE | AH1: =H1=Oportuno!H1 -> TRUE | AI1: =I1=Oportuno!I1 -> TRUE | AJ1: =J1=Oportuno!J1 -> TRUE | ... AY1: =Y1=Oportuno!Y1 -> TRUE
C2: =Oportuno!C2 -> 2026092 | J2: =J458+J486+J514+J542+J570+J598+J626+J654+J682+J710+J738+J766+J794+J822+J850+J878 -> 0 | K2: =K458+K486+K514+K542+K570+K598+K626+K654+K682+K710+K738+K766+K794+K822+K850+K878 -> 0 | L2: =L458+L486+L514+L542+L570+L598+L626+L654+L682+L710+L738+L766+L794+L822+L850+L878 -> 0 | M2: =M458+M486+M514+M542+M570+M598+M626+M654+M682+M710+M738+M766+M794+M822+M850+M878 -> 0 | N2: =N458+N486+N514+N542+N570+N598+N626+N654+N682+N710+N738+N766+N794+N822+N850+N878 -> 0 | O2: =O458+O486+O514+O542+O570+O598+O626+O654+O682+O710+O738+O766+O794+O822+O850+O878 -> 0 | P2: =P458+P486+P514+P542+P570+P598+P626+P654+P682+P710+P738+P766+P794+P822+P850+P878 -> 0 | Q2: =Q458+Q486+Q514+Q542+Q570+Q598+Q626+Q654+Q682+Q710+Q738+Q766+Q794+Q822+Q850+Q878 -> 0 | ... Y2: =Y458+Y486+Y514+Y542+Y570+Y598+Y626+Y654+Y682+Y710+Y738+Y766+Y794+Y822+Y850+Y878 -> 0 | AC2: =C2=Oportuno!C2 -> TRUE | AD2: =D2=Oportuno!D2 -> TRUE | AE2: =E2=Oportuno!E2 -> TRUE | AF2: =F2=Oportuno!F2 -> TRUE | AG2: =G2=Oportuno!G2 -> TRUE | AH2: =H2=Oportuno!H2 -> TRUE | AI2: =I2=Oportuno!I2 -> TRUE | AJ2: =J2=Oportuno!J2 -> TRUE | ... AY2: =Y2=Oportuno!Y2 -> TRUE
C3: =Oportuno!C3 -> 202609 | J3: =SUM(J1:J2) -> 0 | K3: =SUM(K1:K2) -> 0 | L3: =SUM(L1:L2) -> 0 | M3: =SUM(M1:M2) -> 0 | N3: =SUM(N1:N2) -> 0 | O3: =SUM(O1:O2) -> 0 | P3: =SUM(P1:P2) -> 0 | Q3: =SUM(Q1:Q2) -> 0 | ... Y3: =SUM(Y1:Y2) -> 0 | AC3: =C3=Oportuno!C3 -> TRUE | AD3: =D3=Oportuno!D3 -> TRUE | AE3: =E3=Oportuno!E3 -> TRUE | AF3: =F3=Oportuno!F3 -> TRUE | AG3: =G3=Oportuno!G3 -> TRUE | AH3: =H3=Oportuno!H3 -> TRUE | AI3: =I3=Oportuno!I3 -> TRUE | AJ3: =J3=Oportuno!J3 -> TRUE | ... AY3: =Y3=Oportuno!Y3 -> TRUE
H6: 2.5.3. INFORMES DE RECAUDO
H7: R2 - INFORME DE CONCILIACION DE RECAUDOS
H8: CONCILIACION DIARIA DE RECAUDO OPORTUNO
E9: NIT: 901 153 639 - 0
H10: =Oportuno!H10 -> SEPTIEMBRE_2026 | J10: Recaudo Oportuno de las cuentas bancarias de ENEL
B12: FECHA APLICACIÓN | C12: CODIGO REMUNERACIÓN | D12: FECHA RECAUDO | E12: CÓDIGO BC | F12: NOMBRE BANCO | G12: CÓDIGO CR | H12: CANAL RECAUDO | I12: N° CUENTA | J12: ASE 1 N° REGISTROS ARCHIVO | K12: ASE 1 VALOR ARCHIVO | L12: ASE 2 N° REGISTROS ARCHIVO | M12: ASE 2 VALOR ARCHIVO | N12: ASE 3 N° REGISTROS ARCHIVO | O12: ASE 3 VALOR ARCHIVO | P12: ASE 4 N° REGISTROS ARCHIVO | Q12: ASE 4 VALOR ARCHIVO | R12: ASE 5 N° REGISTROS ARCHIVO | S12: ASE 5 VALOR ARCHIVO | T12: TOTAL N° REGISTROS APLICADOS | U12: TOTAL VALOR APLICADO | V12: N° REGISTROS REPORTADOS POR BANCO | W12: VALOR REPORTADO POR BANCO | X12: DIFERENCIA REGISTROS | Y12: DIFERENCIA VALOR
B13: =Oportuno!B13 -> 3/09/2026 | C13: =Oportuno!C13 -> 2026091 | D13: =Oportuno!D13 -> 1 | E13: =Oportuno!E13 -> 20 | F13: =Oportuno!F13 -> Bancolombia ENERBIT | G13: =Oportuno!G13 -> 1 | H13: =Oportuno!H13 -> Oficinas | I13: =Oportuno!I13 -> 0 | ... Y13: =Oportuno!Y13 -> 0
B14: =Oportuno!B14 -> 0 | C14: =Oportuno!C14 -> 2026091 | D14: =Oportuno!D14 -> 1 | E14: =Oportuno!E14 -> 0 | F14: =Oportuno!F14 -> #N/A | G14: =Oportuno!G14 -> 1 | H14: =Oportuno!H14 -> Oficinas | I14: =Oportuno!I14 -> 0 | ... Y14: =Oportuno!Y14 -> 0
B15: =Oportuno!B15 -> 0 | C15: =Oportuno!C15 -> 2026091 | D15: =Oportuno!D15 -> 1 | E15: =Oportuno!E15 -> 0 | F15: =Oportuno!F15 -> #N/A | G15: =Oportuno!G15 -> 1 | H15: =Oportuno!H15 -> Oficinas | I15: =Oportuno!I15 -> 0 | ... Y15: =Oportuno!Y15 -> 0
B16: =Oportuno!B16 -> 0 | C16: =Oportuno!C16 -> 2026091 | D16: =Oportuno!D16 -> 1 | E16: =Oportuno!E16 -> 0 | F16: =Oportuno!F16 -> #N/A | G16: =Oportuno!G16 -> 1 | H16: =Oportuno!H16 -> Oficinas | I16: =Oportuno!I16 -> 0 | ... Y16: =Oportuno!Y16 -> 0
B17: =Oportuno!B17 -> 0 | C17: =Oportuno!C17 -> 2026091 | D17: =Oportuno!D17 -> 1 | E17: =Oportuno!E17 -> 0 | F17: =Oportuno!F17 -> #N/A | G17: =Oportuno!G17 -> 1 | H17: =Oportuno!H17 -> Oficinas | I17: =Oportuno!I17 -> 0 | ... Y17: =Oportuno!Y17 -> 0
B18: =Oportuno!B18 -> 0 | C18: =Oportuno!C18 -> 2026091 | D18: =Oportuno!D18 -> 1 | E18: =Oportuno!E18 -> 0 | F18: =Oportuno!F18 -> #N/A | G18: =Oportuno!G18 -> 1 | H18: =Oportuno!H18 -> Oficinas | I18: =Oportuno!I18 -> 0 | ... Y18: =Oportuno!Y18 -> 0
B19: =Oportuno!B19 -> 0 | C19: =Oportuno!C19 -> 2026091 | D19: =Oportuno!D19 -> 1 | E19: =Oportuno!E19 -> 0 | F19: =Oportuno!F19 -> #N/A | G19: =Oportuno!G19 -> 1 | H19: =Oportuno!H19 -> Oficinas | I19: =Oportuno!I19 -> 0 | ... Y19: =Oportuno!Y19 -> 0
B20: =Oportuno!B20 -> 0 | C20: =Oportuno!C20 -> 2026091 | D20: =Oportuno!D20 -> 1 | E20: =Oportuno!E20 -> 0 | F20: =Oportuno!F20 -> #N/A | G20: =Oportuno!G20 -> 1 | H20: =Oportuno!H20 -> Oficinas | I20: =Oportuno!I20 -> 0 | ... Y20: =Oportuno!Y20 -> 0
B21: =Oportuno!B21 -> 0 | C21: =Oportuno!C21 -> 2026091 | D21: =Oportuno!D21 -> 1 | E21: =Oportuno!E21 -> 0 | F21: =Oportuno!F21 -> #N/A | G21: =Oportuno!G21 -> 1 | H21: =Oportuno!H21 -> Oficinas | I21: =Oportuno!I21 -> 0 | ... Y21: =Oportuno!Y21 -> 0
B22: =Oportuno!B22 -> 0 | C22: =Oportuno!C22 -> 2026091 | D22: =Oportuno!D22 -> 1 | E22: =Oportuno!E22 -> 0 | F22: =Oportuno!F22 -> #N/A | G22: =Oportuno!G22 -> 1 | H22: =Oportuno!H22 -> Oficinas | I22: =Oportuno!I22 -> 0 | ... Y22: =Oportuno!Y22 -> 0
B23: =Oportuno!B23 -> 0 | C23: =Oportuno!C23 -> 2026091 | D23: =Oportuno!D23 -> 1 | E23: =Oportuno!E23 -> 0 | F23: =Oportuno!F23 -> #N/A | G23: =Oportuno!G23 -> 1 | H23: =Oportuno!H23 -> Oficinas | I23: =Oportuno!I23 -> 0 | ... Y23: =Oportuno!Y23 -> 0
B24: =Oportuno!B24 -> 0 | C24: =Oportuno!C24 -> 2026091 | D24: =Oportuno!D24 -> 1 | E24: =Oportuno!E24 -> 0 | F24: =Oportuno!F24 -> #N/A | G24: =Oportuno!G24 -> 1 | H24: =Oportuno!H24 -> Oficinas | I24: =Oportuno!I24 -> 0 | ... Y24: =Oportuno!Y24 -> 0
... B37: =Oportuno!B37 -> 0 | C37: =Oportuno!C37 -> 2026091 | D37: =Oportuno!D37 -> 1 | E37: =Oportuno!E37 -> 0 | F37: =Oportuno!F37 -> #N/A | G37: =Oportuno!G37 -> 1 | H37: =Oportuno!H37 -> Oficinas | I37: =Oportuno!I37 -> 0 | ... Y37: =Oportuno!Y37 -> 0
E38: =Oportuno!E38 | F38: =Oportuno!F38 -> TOTAL RECAUDO | J38: =Oportuno!J38 -> 0 | K38: =Oportuno!K38 -> 0 | L38: =Oportuno!L38 -> 0 | M38: =Oportuno!M38 -> 0 | N38: =Oportuno!N38 -> 0 | O38: =Oportuno!O38 -> 0 | P38: =Oportuno!P38 -> 0 | Q38: =Oportuno!Q38 -> 0 | ... Y38: =Oportuno!Y38 -> 0
B40: FECHA APLICACIÓN | C40: CODIGO REMUNERACIÓN | D40: FECHA RECAUDO | E40: CÓDIGO BC | F40: NOMBRE BANCO | G40: CÓDIGO CR | H40: CANAL RECAUDO | I40: N° CUENTA | J40: ASE 1 N° REGISTROS ARCHIVO | K40: ASE 1 VALOR ARCHIVO | L40: ASE 2 N° REGISTROS ARCHIVO | M40: ASE 2 VALOR ARCHIVO | N40: ASE 3 N° REGISTROS ARCHIVO | O40: ASE 3 VALOR ARCHIVO | P40: ASE 4 N° REGISTROS ARCHIVO | Q40: ASE 4 VALOR ARCHIVO | R40: ASE 5 N° REGISTROS ARCHIVO | S40: ASE 5 VALOR ARCHIVO | T40: TOTAL N° REGISTROS APLICADOS | U40: TOTAL VALOR APLICADO | V40: N° REGISTROS REPORTADOS POR BANCO | W40: VALOR REPORTADO POR BANCO | X40: DIFERENCIA REGISTROS | Y40: DIFERENCIA VALOR
B41: =Oportuno!B41 -> 3/09/2026 | C41: =Oportuno!C41 -> 2026091 | D41: =Oportuno!D41 -> 2 | E41: =Oportuno!E41 -> 20 | F41: =Oportuno!F41 -> Bancolombia ENERBIT | G41: =Oportuno!G41 -> 1 | H41: =Oportuno!H41 -> Oficinas | I41: =Oportuno!I41 -> 0 | ... Y41: =Oportuno!Y41 -> 0
B42: =Oportuno!B42 -> 0 | C42: =Oportuno!C42 -> 2026091 | D42: =Oportuno!D42 -> 2 | E42: =Oportuno!E42 -> 0 | F42: =Oportuno!F42 -> #N/A | G42: =Oportuno!G42 -> 1 | H42: =Oportuno!H42 -> Oficinas | I42: =Oportuno!I42 -> 0 | ... Y42: =Oportuno!Y42 -> 0
B43: =Oportuno!B43 -> 0 | C43: =Oportuno!C43 -> 2026091 | D43: =Oportuno!D43 -> 2 | E43: =Oportuno!E43 -> 0 | F43: =Oportuno!F43 -> #N/A | G43: =Oportuno!G43 -> 1 | H43: =Oportuno!H43 -> Oficinas | I43: =Oportuno!I43 -> 0 | ... Y43: =Oportuno!Y43 -> 0
B44: =Oportuno!B44 -> 0 | C44: =Oportuno!C44 -> 2026091 | D44: =Oportuno!D44 -> 2 | E44: =Oportuno!E44 -> 0 | F44: =Oportuno!F44 -> #N/A | G44: =Oportuno!G44 -> 1 | H44: =Oportuno!H44 -> Oficinas | I44: =Oportuno!I44 -> 0 | ... Y44: =Oportuno!Y44 -> 0
B45: =Oportuno!B45 -> 0 | C45: =Oportuno!C45 -> 2026091 | D45: =Oportuno!D45 -> 2 | E45: =Oportuno!E45 -> 0 | F45: =Oportuno!F45 -> #N/A | G45: =Oportuno!G45 -> 1 | H45: =Oportuno!H45 -> Oficinas | I45: =Oportuno!I45 -> 0 | ... Y45: =Oportuno!Y45 -> 0
B46: =Oportuno!B46 -> 0 | C46: =Oportuno!C46 -> 2026091 | D46: =Oportuno!D46 -> 2 | E46: =Oportuno!E46 -> 0 | F46: =Oportuno!F46 -> #N/A | G46: =Oportuno!G46 -> 1 | H46: =Oportuno!H46 -> Oficinas | I46: =Oportuno!I46 -> 0 | ... Y46: =Oportuno!Y46 -> 0
B47: =Oportuno!B47 -> 0 | C47: =Oportuno!C47 -> 2026091 | D47: =Oportuno!D47 -> 2 | E47: =Oportuno!E47 -> 0 | F47: =Oportuno!F47 -> #N/A | G47: =Oportuno!G47 -> 1 | H47: =Oportuno!H47 -> Oficinas | I47: =Oportuno!I47 -> 0 | ... Y47: =Oportuno!Y47 -> 0
B48: =Oportuno!B48 -> 0 | C48: =Oportuno!C48 -> 2026091 | D48: =Oportuno!D48 -> 2 | E48: =Oportuno!E48 -> 0 | F48: =Oportuno!F48 -> #N/A | G48: =Oportuno!G48 -> 1 | H48: =Oportuno!H48 -> Oficinas | I48: =Oportuno!I48 -> 0 | ... Y48: =Oportuno!Y48 -> 0
B49: =Oportuno!B49 -> 0 | C49: =Oportuno!C49 -> 2026091 | D49: =Oportuno!D49 -> 2 | E49: =Oportuno!E49 -> 0 | F49: =Oportuno!F49 -> #N/A | G49: =Oportuno!G49 -> 1 | H49: =Oportuno!H49 -> Oficinas | I49: =Oportuno!I49 -> 0 | ... Y49: =Oportuno!Y49 -> 0
B50: =Oportuno!B50 -> 0 | C50: =Oportuno!C50 -> 2026091 | D50: =Oportuno!D50 -> 2 | E50: =Oportuno!E50 -> 0 | F50: =Oportuno!F50 -> #N/A | G50: =Oportuno!G50 -> 1 | H50: =Oportuno!H50 -> Oficinas | I50: =Oportuno!I50 -> 0 | ... Y50: =Oportuno!Y50 -> 0
B51: =Oportuno!B51 -> 0 | C51: =Oportuno!C51 -> 2026091 | D51: =Oportuno!D51 -> 2 | E51: =Oportuno!E51 -> 0 | F51: =Oportuno!F51 -> #N/A | G51: =Oportuno!G51 -> 1 | H51: =Oportuno!H51 -> Oficinas | I51: =Oportuno!I51 -> 0 | ... Y51: =Oportuno!Y51 -> 0
B52: =Oportuno!B52 -> 0 | C52: =Oportuno!C52 -> 2026091 | D52: =Oportuno!D52 -> 2 | E52: =Oportuno!E52 -> 0 | F52: =Oportuno!F52 -> #N/A | G52: =Oportuno!G52 -> 1 | H52: =Oportuno!H52 -> Oficinas | I52: =Oportuno!I52 -> 0 | ... Y52: =Oportuno!Y52 -> 0
... B65: =Oportuno!B65 -> 0 | C65: =Oportuno!C65 -> 2026091 | D65: =Oportuno!D65 -> 2 | E65: =Oportuno!E65 -> 0 | F65: =Oportuno!F65 -> #N/A | G65: =Oportuno!G65 -> 1 | H65: =Oportuno!H65 -> Oficinas | I65: =Oportuno!I65 -> 0 | ... Y65: =Oportuno!Y65 -> 0
E66: =Oportuno!E66 | F66: =Oportuno!F66 -> TOTAL RECAUDO | J66: =Oportuno!J66 -> 0 | K66: =Oportuno!K66 -> 0 | L66: =Oportuno!L66 -> 0 | M66: =Oportuno!M66 -> 0 | N66: =Oportuno!N66 -> 0 | O66: =Oportuno!O66 -> 0 | P66: =Oportuno!P66 -> 0 | Q66: =Oportuno!Q66 -> 0 | ... Y66: =Oportuno!Y66 -> 0
B68: FECHA APLICACIÓN | C68: CODIGO REMUNERACIÓN | D68: FECHA RECAUDO | E68: CÓDIGO BC | F68: NOMBRE BANCO | G68: CÓDIGO CR | H68: CANAL RECAUDO | I68: N° CUENTA | J68: ASE 1 N° REGISTROS ARCHIVO | K68: ASE 1 VALOR ARCHIVO | L68: ASE 2 N° REGISTROS ARCHIVO | M68: ASE 2 VALOR ARCHIVO | N68: ASE 3 N° REGISTROS ARCHIVO | O68: ASE 3 VALOR ARCHIVO | P68: ASE 4 N° REGISTROS ARCHIVO | Q68: ASE 4 VALOR ARCHIVO | R68: ASE 5 N° REGISTROS ARCHIVO | S68: ASE 5 VALOR ARCHIVO | T68: TOTAL N° REGISTROS APLICADOS | U68: TOTAL VALOR APLICADO | V68: N° REGISTROS REPORTADOS POR BANCO | W68: VALOR REPORTADO POR BANCO | X68: DIFERENCIA REGISTROS | Y68: DIFERENCIA VALOR
B69: =Oportuno!B69 -> 3/09/2026 | C69: =Oportuno!C69 -> 2026091 | D69: =Oportuno!D69 -> 3 | E69: =Oportuno!E69 -> 20 | F69: =Oportuno!F69 -> Bancolombia ENERBIT | G69: =Oportuno!G69 -> 1 | H69: =Oportuno!H69 -> Oficinas | I69: =Oportuno!I69 -> 0 | ... Y69: =Oportuno!Y69 -> 0
...

Sheet 2_Extemporaneo ENERBIT
C1: =EXTEMPORANEO!C1 -> 2026091 | J1: =SUM(J13:J111) -> 0 | K1: =SUM(K13:K111) -> 0 | L1: =SUM(L13:L111) -> 0 | M1: =SUM(M13:M111) -> 0 | N1: =SUM(N13:N111) -> 0 | O1: =SUM(O13:O111) -> 0 | P1: =SUM(P13:P111) -> 0 | Q1: =SUM(Q13:Q111) -> 0 | ... Y1: =SUM(Y13:Y111) -> 0 | AC1: =C1=EXTEMPORANEO!C1 -> TRUE | AD1: =D1=EXTEMPORANEO!D1 -> TRUE | AE1: =E1=EXTEMPORANEO!E1 -> TRUE | AF1: =F1=EXTEMPORANEO!F1 -> TRUE | AG1: =G1=EXTEMPORANEO!G1 -> TRUE | AH1: =H1=EXTEMPORANEO!H1 -> TRUE | AI1: =I1=EXTEMPORANEO!I1 -> TRUE | AJ1: =J1=EXTEMPORANEO!J1 -> TRUE | ... AY1: =Y1=EXTEMPORANEO!Y1 -> TRUE
