Workbook
Name \0: #REF!
Name _1: #REF!
Name _2: #REF!
Name _A655555: #REF!
Name _CFR1: #REF!
Name _cia1: #REF!
Name _XL250: #REF!
Name A: #REF!
Name ADM: [1]!ADM
Name ADM: [1]!ADM
Name ADM: [1]!ADM
Name ADM: [1]!ADM
Name ADM: [1]!ADM
Name ADM_: [1]!ADM
Name ADM_: [1]!ADM
Name ADM_: [1]!ADM
Name ADM_: [1]!ADM
Name ADM_: [1]!ADM
Name AI: #REF!
Name Air: #REF!
Name AP: '[2]TARIFA no aforos'!$C$12
Name Bancos: [3]Fx!$C$1:$C$23
Name CBL: #REF!
Name CCS: #REF!
Name CDT_p: [4]CDT!$C$3
Name CFR: #REF!
Name cia: #REF!
Name COM: #REF!
Name CRT: #REF!
Name CRT___CTEp___CDTp___CMRv: #REF!
Name CRT_aislados: '[4]COSTOS AJUSTADOS'!$C$13
Name CRT_costas: #REF!
Name CTE_p: [4]CTE!$C$5
Name Denominador: #REF!
Name dg: [1]!ADM
Name dg: [1]!ADM
Name dg: [1]!ADM
Name dg: [1]!ADM
Name dg: [1]!ADM
Name DIAS: [5]CONTRA!#REF!
Name Fmerc: #REF!
Name FPS: #REF!
Name InformacionGeneral: [1]!InformacionGeneral
Name InformacionGeneral: [1]!InformacionGeneral
Name InformacionGeneral: [1]!InformacionGeneral
Name InformacionGeneral: [1]!InformacionGeneral
Name InformacionGeneral: [1]!InformacionGeneral
Name INTFIN: #REF!
Name INV: [1]!INV
Name INV: [1]!INV
Name INV: [1]!INV
Name INV: [1]!INV
Name INV: [1]!INV
Name K: #REF!
Name N: '[4]COSTOS AJUSTADOS'!#REF!
Name Na: '[2]TARIFA no aforos'!$C$39
Name nfc: '[4]COSTOS AJUSTADOS'!#REF!
Name OYM: [1]!OYM
Name OYM: [1]!OYM
Name OYM: [1]!OYM

Sheet Recaudo EAAB Reciprocidad
B2: OPORTUNO | C2: ASE | D2: VALOR 1° Q | E2: NUMERO REG. 1°Q | F2: VALOR 2° Q | G2: NUMERO REG. 2°Q
C3: 1 | D3: 0 | E3: 0 | F3: 0 | G3: 0
C4: 2 | D4: 0 | E4: 0 | F4: 0 | G4: 0
C5: 3 | D5: 0 | E5: 0 | F5: 0 | G5: 0
C6: 4 | D6: 0 | E6: 0 | F6: 0 | G6: 0
C7: 5 | D7: 0 | E7: 0 | F7: 0 | G7: 0
C8: X
D9: 0 | E9: 0 | F9: 0 | G9: 0
C11: ASE | D11: VALOR 1° Q | E11: NUMERO REG. 1°Q | F11: VALOR 2° Q | G11: NUMERO REG. 2°Q
B12: EXTEMP. | C12: 1 | D12: 0 | E12: 0 | F12: 0 | G12: 0
C13: 2 | D13: 0 | E13: 0 | F13: 0 | G13: 0
C14: 3 | D14: 0 | E14: 0 | F14: 0 | G14: 0
C15: 4 | D15: 0 | E15: 0 | F15: 0 | G15: 0
C16: 5 | D16: 0 | E16: 0 | F16: 0 | G16: 0
C17: X
D18: 0 | E18: 0 | F18: 0 | G18: 0
C20: ASE | D20: VALOR 1° Q | E20: NUMERO REG. 1°Q | F20: VALOR 2° Q | G20: NUMERO REG. 2°Q | I20: VALOR TOTAL MES | J20: NUMERO REGISTROS MES
B21: TOTAL | C21: 1 | D21: 0 | E21: 0 | F21: 0 | G21: 0 | I21: 0 | J21: 0
C22: 2 | D22: 0 | E22: 0 | F22: 0 | G22: 0 | I22: 0 | J22: 0
C23: 3 | D23: 0 | E23: 0 | F23: 0 | G23: 0 | I23: 0 | J23: 0
C24: 4 | D24: 0 | E24: 0 | F24: 0 | G24: 0 | I24: 0 | J24: 0
C25: 5 | D25: 0 | E25: 0 | F25: 0 | G25: 0 | I25: 0 | J25: 0
C26: X | I26: 0 | J26: 0
D27: 0 | E27: 0 | F27: 0 | G27: 0 | I27: 0 | J27: 0
B31: OPORTUNO | D31: =D9=SUM(D3:D8) -> TRUE | E31: =E9=SUM(E3:E8) -> TRUE | F31: =F9=SUM(F3:F8) -> TRUE | G31: =G9=SUM(G3:G8) -> TRUE
B33: EXTEMP. | D33: =D18=SUM(D12:D17) -> TRUE | E33: =E18=SUM(E12:E17) -> TRUE | F33: =F18=SUM(F12:F17) -> TRUE | G33: =G18=SUM(G12:G17) -> TRUE
B35: TOTAL | D35: =D27=SUM(D21:D26) -> TRUE | E35: =E27=SUM(E21:E26) -> TRUE | F35: =F27=SUM(F21:F26) -> TRUE | G35: =G27=SUM(G21:G26) -> TRUE | I35: =I27=SUM(I21:I26) -> TRUE | J35: =J27=SUM(J21:J26) -> TRUE
E69: =C69-G17 -> 0

Sheet Recaudo ENEL
B2: OPORTUNO | C2: ASE | D2: VALOR 1° Q | E2: NUMERO REG. 1°Q | F2: VALOR 2° Q | G2: NUMERO REG. 2°Q
C3: 1 | D3: 14382259562 | E3: 305702 | F3: 0 | G3: 0
C4: 2 | D4: 10247752463 | E4: 198695 | F4: 0 | G4: 0
C5: 3 | D5: 8348318512 | E5: 195122 | F5: 0 | G5: 0
C6: 4 | D6: 9859647946 | E6: 172571 | F6: 0 | G6: 0
C7: 5 | D7: 7125653520 | E7: 137028 | F7: 0 | G7: 0
C8: X
D9: 49963632003 | E9: 1009118 | F9: 0 | G9: 0
C11: ASE | D11: VALOR 1° Q | E11: NUMERO REG. 1°Q | F11: VALOR 2° Q | G11: NUMERO REG. 2°Q
B12: EXTEMP. | C12: 1 | D12: 128684600 | E12: 2090 | F12: 0 | G12: 0
C13: 2 | D13: 60162560 | E13: 1233 | F13: 0 | G13: 0
C14: 3 | D14: 58639078 | E14: 1146 | F14: 0 | G14: 0
C15: 4 | D15: 72782190 | E15: 1190 | F15: 0 | G15: 0
C16: 5 | D16: 122557965 | E16: 2207 | F16: 0 | G16: 0
C17: X
D18: 442826393 | E18: 7866 | F18: 0 | G18: 0
C20: ASE | D20: VALOR 1° Q | E20: NUMERO REG. 1°Q | F20: VALOR 2° Q | G20: NUMERO REG. 2°Q | I20: VALOR TOTAL MES | J20: NUMERO REGISTROS MES
B21: TOTAL | C21: 1 | D21: 14510944162 | E21: 307792 | F21: 0 | G21: 0 | I21: 14510944162 | J21: 307792
C22: 2 | D22: 10307915023 | E22: 199928 | F22: 0 | G22: 0 | I22: 10307915023 | J22: 199928
C23: 3 | D23: 8406957590 | E23: 196268 | F23: 0 | G23: 0 | I23: 8406957590 | J23: 196268
C24: 4 | D24: 9932430136 | E24: 173761 | F24: 0 | G24: 0 | I24: 9932430136 | J24: 173761
C25: 5 | D25: 7248211485 | E25: 139235 | F25: 0 | G25: 0 | I25: 7248211485 | J25: 139235
C26: X | I26: 0 | J26: 0
D27: 50406458396 | E27: 1016984 | F27: 0 | G27: 0 | I27: 50406458396 | J27: 1016984
B31: OPORTUNO | D31: =D9=SUM(D3:D8) -> TRUE | E31: =E9=SUM(E3:E8) -> TRUE | F31: =F9=SUM(F3:F8) -> TRUE | G31: =G9=SUM(G3:G8) -> TRUE
B33: EXTEMP. | D33: =D18=SUM(D12:D17) -> TRUE | E33: =E18=SUM(E12:E17) -> TRUE | F33: =F18=SUM(F12:F17) -> TRUE | G33: =G18=SUM(G12:G17) -> TRUE
B35: TOTAL | D35: =D27=SUM(D21:D26) -> TRUE | E35: =E27=SUM(E21:E26) -> TRUE | F35: =F27=SUM(F21:F26) -> TRUE | G35: =G27=SUM(G21:G26) -> TRUE | I35: =I27=SUM(I21:I26) -> TRUE | J35: =J27=SUM(J21:J26) -> TRUE
E69: =C69-G17 -> 0

Sheet Recaudo ENERBIT
B2: OPORTUNO | C2: ASE | D2: VALOR 1° Q | E2: NUMERO REG. 1°Q | F2: VALOR 2° Q | G2: NUMERO REG. 2°Q
C3: 1 | D3: 0 | E3: 0 | F3: 0 | G3: 0
C4: 2 | D4: 0 | E4: 0 | F4: 0 | G4: 0
C5: 3 | D5: 0 | E5: 0 | F5: 0 | G5: 0
C6: 4 | D6: 0 | E6: 0 | F6: 0 | G6: 0
C7: 5 | D7: 140424760 | E7: 2998 | F7: 0 | G7: 0
C8: X
D9: 140424760 | E9: 2998 | F9: 0 | G9: 0
C11: ASE | D11: VALOR 1° Q | E11: NUMERO REG. 1°Q | F11: VALOR 2° Q | G11: NUMERO REG. 2°Q
B12: EXTEMP. | C12: 1 | D12: 0 | E12: 0 | F12: 0 | G12: 0
C13: 2 | D13: 0 | E13: 0 | F13: 0 | G13: 0
C14: 3 | D14: 0 | E14: 0 | F14: 0 | G14: 0
C15: 4 | D15: 0 | E15: 0 | F15: 0 | G15: 0
C16: 5 | D16: 0 | E16: 0 | F16: 0 | G16: 0
C17: X
D18: 0 | E18: 0 | F18: 0 | G18: 0
C20: ASE | D20: VALOR 1° Q | E20: NUMERO REG. 1°Q | F20: VALOR 2° Q | G20: NUMERO REG. 2°Q | I20: VALOR TOTAL MES | J20: NUMERO REGISTROS MES
B21: TOTAL | C21: 1 | D21: 0 | E21: 0 | F21: 0 | G21: 0 | I21: 0 | J21: 0
C22: 2 | D22: 0 | E22: 0 | F22: 0 | G22: 0 | I22: 0 | J22: 0
C23: 3 | D23: 0 | E23: 0 | F23: 0 | G23: 0 | I23: 0 | J23: 0
C24: 4 | D24: 0 | E24: 0 | F24: 0 | G24: 0 | I24: 0 | J24: 0
C25: 5 | D25: 140424760 | E25: 2998 | F25: 0 | G25: 0 | I25: 140424760 | J25: 2998
C26: X | I26: 0 | J26: 0
D27: 140424760 | E27: 2998 | F27: 0 | G27: 0 | I27: 140424760 | J27: 2998
B31: OPORTUNO | D31: =D9=SUM(D3:D8) -> TRUE | E31: =E9=SUM(E3:E8) -> TRUE | F31: =F9=SUM(F3:F8) -> TRUE | G31: =G9=SUM(G3:G8) -> TRUE
B33: EXTEMP. | D33: =D18=SUM(D12:D17) -> TRUE | E33: =E18=SUM(E12:E17) -> TRUE | F33: =F18=SUM(F12:F17) -> TRUE | G33: =G18=SUM(G12:G17) -> TRUE
B35: TOTAL | D35: =D27=SUM(D21:D26) -> TRUE | E35: =E27=SUM(E21:E26) -> TRUE | F35: =F27=SUM(F21:F26) -> TRUE | G35: =G27=SUM(G21:G26) -> TRUE | I35: =I27=SUM(I21:I26) -> TRUE | J35: =J27=SUM(J21:J26) -> TRUE
E69: =C69-G17 -> 0

Sheet Recaudo EAAB + Ciud Limp
B2: Ciudad Limpia - Prestador | C2: ASE | D2: VALOR 1° Q | E2: NUMERO REG. 1°Q | F2: VALOR 2° Q | G2: NUMERO REG. 2°Q
C3: 1 | D3: 0 | E3: 0 | F3: 0 | G3: 0
C4: 2 | D4: 0 | E4: 0 | F4: 0 | G4: 0
C5: 3 | D5: 0 | E5: 0 | F5: 0 | G5: 0
C6: 4 | D6: 0 | E6: 0 | F6: 0 | G6: 0
C7: 5 | D7: 0 | E7: 0 | F7: 0 | G7: 0
C8: X
D9: 0 | E9: 0 | F9: 0 | G9: 0
C11: ASE | D11: VALOR 1° Q | E11: NUMERO REG. 1°Q | F11: VALOR 2° Q | G11: NUMERO REG. 2°Q
B12: EAAB - Prestador | C12: 1 | D12: 0 | E12: 0 | F12: 0 | G12: 0
C13: 2 | D13: 0 | E13: 0 | F13: 0 | G13: 0
C14: 3 | D14: 0 | E14: 0 | F14: 0 | G14: 0
C15: 4 | D15: 0 | E15: 0 | F15: 0 | G15: 0
C16: 5 | D16: 0 | E16: 0 | F16: 0 | G16: 0
C17: X
D18: 0 | E18: 0 | F18: 0 | G18: 0
C20: ASE | D20: VALOR 1° Q | E20: NUMERO REG. 1°Q | F20: VALOR 2° Q | G20: NUMERO REG. 2°Q | I20: VALOR TOTAL MES | J20: NUMERO REGISTROS MES
B21: TOTAL | C21: 1 | D21: 0 | E21: 0 | F21: 0 | G21: 0 | I21: 0 | J21: 0
C22: 2 | D22: 0 | E22: 0 | F22: 0 | G22: 0 | I22: 0 | J22: 0
C23: 3 | D23: 0 | E23: 0 | F23: 0 | G23: 0 | I23: 0 | J23: 0
C24: 4 | D24: 0 | E24: 0 | F24: 0 | G24: 0 | I24: 0 | J24: 0
C25: 5 | D25: 0 | E25: 0 | F25: 0 | G25: 0 | I25: 0 | J25: 0
C26: X | I26: 0 | J26: 0
D27: 0 | E27: 0 | F27: 0 | G27: 0 | I27: 0 | J27: 0
B31: OPORTUNO | D31: =D9=SUM(D3:D8) -> TRUE | E31: =E9=SUM(E3:E8) -> TRUE | F31: =F9=SUM(F3:F8) -> TRUE | G31: =G9=SUM(G3:G8) -> TRUE
B33: EXTEMP. | D33: =D18=SUM(D12:D17) -> TRUE | E33: =E18=SUM(E12:E17) -> TRUE | F33: =F18=SUM(F12:F17) -> TRUE | G33: =G18=SUM(G12:G17) -> TRUE
B35: TOTAL | D35: =D27=SUM(D21:D26) -> TRUE | E35: =E27=SUM(E21:E26) -> TRUE | F35: =F27=SUM(F21:F26) -> TRUE | G35: =G27=SUM(G21:G26) -> TRUE | I35: =I27=SUM(I21:I26) -> TRUE | J35: =J27=SUM(J21:J26) -> TRUE

Sheet Recaudo Directa Occidente
B2: OPORTUNO | C2: ASE | D2: VALOR 1° Q | E2: NUMERO REG. 1°Q | F2: VALOR 2° Q | G2: NUMERO REG. 2°Q
C3: 1 | D3: 322739090 | E3: 1616 | F3: 0 | G3: 0
C4: 2 | D4: 839789795 | E4: 3964 | F4: 0 | G4: 0
C5: 3 | D5: 417500887 | E5: 1376 | F5: 0 | G5: 0
C6: 4 | D6: 481464262 | E6: 2591 | F6: 0 | G6: 0
C7: 5 | D7: 168793421 | E7: 1160 | F7: 0 | G7: 0
C8: X | D8: 0 | E8: 0 | F8: 0 | G8: 0
D9: 2230287455 | E9: 10707 | F9: 0 | G9: 0
C11: ASE | D11: VALOR 1° Q | E11: NUMERO REG. 1°Q | F11: VALOR 2° Q | G11: NUMERO REG. 2°Q
B12: EXTEMP. | C12: 1 | D12: 48127653 | E12: 74 | F12: 0 | G12: 0
C13: 2 | D13: 132160935 | E13: 54 | F13: 0 | G13: 0
C14: 3 | D14: 19609348 | E14: 11 | F14: 0 | G14: 0
C15: 4 | D15: 118198907 | E15: 9 | F15: 0 | G15: 0
C16: 5 | D16: 7112332 | E16: 27 | F16: 0 | G16: 0
C17: X | D17: 0 | E17: 0 | F17: 0 | G17: 0
D18: 325209175 | E18: 175 | F18: 0 | G18: 0
C20: ASE | D20: VALOR 1° Q | E20: NUMERO REG. 1°Q | F20: VALOR 2° Q | G20: NUMERO REG. 2°Q | I20: VALOR TOTAL MES | J20: NUMERO REGISTROS MES
B21: TOTAL | C21: 1 | D21: 370866743 | E21: 1690 | F21: 0 | G21: 0 | I21: 370866743 | J21: 1690
C22: 2 | D22: 971950730 | E22: 4018 | F22: 0 | G22: 0 | I22: 971950730 | J22: 4018
C23: 3 | D23: 437110235 | E23: 1387 | F23: 0 | G23: 0 | I23: 437110235 | J23: 1387
C24: 4 | D24: 599663169 | E24: 2600 | F24: 0 | G24: 0 | I24: 599663169 | J24: 2600
C25: 5 | D25: 175905753 | E25: 1187 | F25: 0 | G25: 0 | I25: 175905753 | J25: 1187
C26: X | D26: 0 | E26: 0 | F26: 0 | G26: 0 | I26: 0 | J26: 0
D27: 2555496630 | E27: 10882 | F27: 0 | G27: 0 | I27: 2555496630 | J27: 10882
B31: OPORTUNO | D31: =D9=SUM(D3:D8) -> TRUE | E31: =E9=SUM(E3:E8) -> TRUE | F31: =F9=SUM(F3:F8) -> TRUE | G31: =G9=SUM(G3:G8) -> TRUE
B33: EXTEMP. | D33: =D18=SUM(D12:D17) -> TRUE | E33: =E18=SUM(E12:E17) -> TRUE | F33: =F18=SUM(F12:F17) -> TRUE | G33: =G18=SUM(G12:G17) -> TRUE
B35: TOTAL | D35: =D27=SUM(D21:D26) -> TRUE | E35: =E27=SUM(E21:E26) -> TRUE | F35: =F27=SUM(F21:F26) -> TRUE | G35: =G27=SUM(G21:G26) -> TRUE | I35: =I27=SUM(I21:I26) -> TRUE | J35: =J27=SUM(J21:J26) -> TRUE
E69: =C69-G17 -> 0

Sheet REPORTE RECAUDO x BANCO
C1: ENEL | D1: CIUDAD LIMPIA | E1: EAB | F1: NUEVO ESQUEMA | G1: ENERBIT | H1: OCCIDENTE | I1: Total
B2: 1-APLICADOS A FACTURACION | C2: =C13+C23+C32+C41+C51 -> 5.0300863e+10 | D2: =D13+D23+D32+D41+D51 -> 0 | E2: =E13+E23+E32+E41+E51 -> 0 | F2: =F13+F23+F32+F41+F51 -> 0 | G2: =G13+G23+G32+G41+G51 -> 139510580 | H2: =H13+H23+H32+H41+H51 -> 2.4480562e+09 | I2: =SUM(C2:H2) -> 5.288843e+10
B3: 2-SALDOS A FAVOR GENERADOS | C3: =C14+C24+C33+C42+C52 -> 1.0831116e+08 | D3: =D14+D24+D33+D42+D52 -> 0 | E3: =E14+E24+E33+E42+E52 -> 0 | F3: =F14+F24+F33+F42+F52 -> 0 | G3: =G14+G24+G33+G42+G52 -> 914180 | H3: =H14+H24+H33+H42+H52 -> 61958868 | I3: =SUM(C3:H3) -> 1.7118421e+08
B4: 3-APLICADOS A FINANCIACIONES NUEVAS | C4: =C15+C25+C34+C43+C53 -> 0 | D4: =D15+D25+D34+D43+D53 -> 0 | E4: =E15+E25+E34+E43+E53 -> 0 | F4: =F15+F25+F34+F43+F53 -> 0 | G4: =G15+G25+G34+G43+G53 -> 0 | H4: =H15+H25+H34+H43+H53 -> 45481533 | I4: =SUM(C4:H4) -> 45481533
B5: 7-APLICADOS A RECIBOS SERVICIOS ESPECIALES | C5: =C16+C26+C35+C44+C54 -> 0 | D5: =D16+D26+D35+D44+D54 -> 0 | E5: =E16+E26+E35+E44+E54 -> 0 | F5: =F16+F26+F35+F44+F54 -> 0 | G5: =G16+G26+G35+G44+G54 -> 0 | H5: =H16+H26+H35+H44+H54 -> 0 | I5: =SUM(C5:H5) -> 0
B6: Total | C6: =SUM(C2:C5) -> 50409174172 | D6: =SUM(D2:D5) -> 0 | E6: =SUM(E2:E5) -> 0 | F6: =SUM(F2:F5) -> 0 | G6: =SUM(G2:G5) -> 140424760 | H6: =SUM(H2:H5) -> 2.5554966e+09 | I6: =SUM(I2:I5) -> 5.3105096e+10
C7: =C6=(C17+C27+C36+C45+C55) -> TRUE | D7: =D6=(D17+D27+D36+D45+D55) -> TRUE | E7: =E6=(E17+E27+E36+E45+E55) -> TRUE | F7: =F6=(F17+F27+F36+F45+F55) -> TRUE | H7: =H6=(H17+H27+H36+H45+H55) -> TRUE | I7: =I6=(I17+I27+I36+I45+I55) -> TRUE
B10: ASE 1
B11: Resumen Recaudo Aplicado Por Servicio
C12: ENEL | D12: CIUDAD LIMPIA | E12: EAB | F12: NUEVO ESQUEMA | G12: ENERBIT | H12: OCCIDENTE | I12: Total
B13: 1-APLICADOS A FACTURACION | C13: 14481337615 | H13: 3.5146605e+08 | I13: =SUM(C13:H13) -> 1.4832804e+10 | J13: =SUM(C13:H13)=I13 -> TRUE
B14: 2-SALDOS A FAVOR GENERADOS | C14: 29606547 | H14: 17250690 | I14: =SUM(C14:H14) -> 46857237 | J14: =SUM(C14:H14)=I14 -> TRUE
B15: 3-APLICADOS A FINANCIACIONES NUEVAS | C15: 0 | H15: 2150000 | I15: =SUM(C15:H15) -> 2150000 | J15: =SUM(C15:H15)=I15 -> TRUE
B16: 7-APLICADOS A RECIBOS SERVICIOS ESPECIALES | C16: 0 | I16: =SUM(C16:H16) -> 0 | J16: =SUM(C16:H16)=I16 -> TRUE
B17: Total | C17: =SUM(C13:C16) -> 14510944162 | D17: =SUM(D13:D16) -> 0 | E17: =SUM(E13:E16) -> 0 | F17: =SUM(F13:F16) -> 0 | G17: =SUM(G13:G16) -> 0 | H17: =SUM(H13:H16) -> 370866743 | I17: =SUM(I13:I16) -> 14881810905 | J17: =SUM(C17:H17)=I17 -> TRUE
B20: ASE 2
B21: Resumen Recaudo Aplicado Por Servicio
C22: ENEL | D22: CIUDAD LIMPIA | E22: EAB | F22: NUEVO ESQUEMA | G22: ENERBIT | H22: OCCIDENTE | I22: Total
B23: 1-APLICADOS A FACTURACION | C23: 1.0286935e+10 | E23: 0 | F23: 0 | H23: 9.240376e+08 | I23: =SUM(C23:H23) -> 1.1210973e+10 | J23: =SUM(C23:H23)=I23 -> TRUE
B24: 2-SALDOS A FAVOR GENERADOS | C24: 22325147 | E24: 0 | F24: 0 | H24: 29950515 | I24: =SUM(C24:H24) -> 52275662 | J24: =SUM(C24:H24)=I24 -> TRUE
B25: 3-APLICADOS A FINANCIACIONES NUEVAS | C25: 0 | E25: 0 | F25: 0 | H25: 17962612 | I25: =SUM(C25:H25) -> 17962612 | J25: =SUM(C25:H25)=I25 -> TRUE
B26: 7-APLICADOS A RECIBOS SERVICIOS ESPECIALES | F26: 0 | H26: 0 | I26: =SUM(C26:H26) -> 0 | J26: =SUM(C26:H26)=I26 -> TRUE
B27: Total | C27: =SUM(C23:C26) -> 10309260573 | D27: =SUM(D23:D26) -> 0 | E27: =SUM(E23:E26) -> 0 | F27: =SUM(F23:F26) -> 0 | G27: =SUM(G23:G26) -> 0 | H27: =SUM(H23:H26) -> 971950730 | I27: =SUM(I23:I26) -> 11281211303 | J27: =SUM(C27:H27)=I27 -> TRUE
B29: ASE 3
B30: Resumen Recaudo Aplicado Por Servicio
C31: ENEL | D31: CIUDAD LIMPIA | E31: EAB | F31: NUEVO ESQUEMA | G31: ENERBIT | H31: OCCIDENTE | I31: Total
B32: 1-APLICADOS A FACTURACION | C32: 8398576932 | F32: 0 | H32: 4.3152163e+08 | I32: =SUM(C32:H32) -> 8.8300986e+09 | J32: =SUM(C32:H32)=I32 -> TRUE
B33: 2-SALDOS A FAVOR GENERADOS | C33: 8845080 | F33: 0 | H33: 4909289 | I33: =SUM(C33:H33) -> 13754369 | J33: =SUM(C33:H33)=I33 -> TRUE
B34: 3-APLICADOS A FINANCIACIONES NUEVAS | C34: 0 | F34: 0 | H34: 679320.71 | I34: =SUM(C34:H34) -> 679320.71 | J34: =SUM(C34:H34)=I34 -> TRUE
B35: 7-APLICADOS A RECIBOS SERVICIOS ESPECIALES | C35: 0 | F35: 0 | I35: =SUM(C35:H35) -> 0 | J35: =SUM(C35:H35)=I35 -> TRUE
B36: Total | C36: =SUM(C32:C35) -> 8407422012 | D36: =SUM(D32:D35) -> 0 | E36: =SUM(E32:E35) -> 0 | F36: =SUM(F32:F35) -> 0 | G36: =SUM(G32:G35) -> 0 | H36: =SUM(H32:H35) -> 437110235 | I36: =SUM(I32:I35) -> 8844532247 | J36: =SUM(C36:H36)=I36 -> TRUE
B38: ASE 4
B39: Resumen Recaudo Aplicado Por Servicio
C40: ENEL | D40: CIUDAD LIMPIA | E40: EAB | F40: NUEVO ESQUEMA | G40: ENERBIT | H40: OCCIDENTE | I40: Total
B41: 1-APLICADOS A FACTURACION | C41: 9890363914 | E41: 0 | F41: 0 | H41: 5.6767788e+08 | I41: =SUM(C41:H41) -> 1.0458042e+10 | J41: =SUM(C41:H41)=I41 -> TRUE
B42: 2-SALDOS A FAVOR GENERADOS | C42: 42284806 | E42: 0 | F42: 0 | H42: 7416134 | I42: =SUM(C42:H42) -> 49700940 | J42: =SUM(C42:H42)=I42 -> TRUE
B43: 3-APLICADOS A FINANCIACIONES NUEVAS | C43: 0 | E43: 0 | F43: 0 | H43: 24569155 | I43: =SUM(C43:H43) -> 24569155 | J43: =SUM(C43:H43)=I43 -> TRUE
B44: 7-APLICADOS A RECIBOS SERVICIOS ESPECIALES | F44: 0 | I44: =SUM(C44:H44) -> 0 | J44: =SUM(C44:H44)=I44 -> TRUE
B45: Total | C45: =SUM(C41:C44) -> 9932648720 | D45: =SUM(D41:D44) -> 0 | E45: =SUM(E41:E44) -> 0 | F45: =SUM(F41:F44) -> 0 | G45: =SUM(G41:G44) -> 0 | H45: =SUM(H41:H44) -> 599663169 | I45: =SUM(I41:I44) -> 10532311889 | J45: =SUM(C45:H45)=I45 -> TRUE
B48: ASE 5
...

Sheet ANT EXT-REV
C1: ASE 1 | E1: ASE 2 | G1: ASE 3 | I1: ASE 4 | K1: ASE 5 | M1: TOTAL
C2: REPORTE 3 | D2: REPORTE 4 | E2: REPORTE 3 | F2: REPORTE 4 | G2: REPORTE 3 | H2: REPORTE 4 | I2: REPORTE 3 | J2: REPORTE 4 | K2: REPORTE 3 | L2: REPORTE 4 | M2: REPORTE 3 | N2: REPORTE 4
B3: APLICADO | C3: =C11+C19+C27+C35+C43 -> 648870 | D3: =D11+D19+D27+D35+D43 -> -3833780 | E3: =E11+E19+E27+E35+E43 -> 9704974 | F3: =F11+F19+F27+F35+F43 -> -21803648 | G3: =G11+G19+G27+G35+G43 -> 0 | H3: =H11+H19+H27+H35+H43 -> -2259272 | I3: =I11+I19+I27+I35+I43 -> 21557177 | J3: =J11+J19+J27+J35+J43 -> -41558585 | ... L3: =L11+L19+L27+L35+L43 -> -3964157 | M3: =C3+E3+G3+I3+K3 -> 31911021 | N3: =D3+F3+H3+J3+L3 -> -73419443 | P3: =N3=(-VALIDACION_TOTAL!M9) -> TRUE
B4: ANTICIPOS | C4: =C12+C20+C28+C36+C44 -> 0 | D4: =D12+D20+D28+D36+D44 -> 0 | E4: =E12+E20+E28+E36+E44 -> 6055989 | F4: =F12+F20+F28+F36+F44 -> -255254.55 | G4: =G12+G20+G28+G36+G44 -> 0 | H4: =H12+H20+H28+H36+H44 -> 0 | I4: =I12+I20+I28+I36+I44 -> 19678542 | J4: =J12+J20+J28+J36+J44 -> -1258817.6 | ... L4: =L12+L20+L28+L36+L44 -> -41240 | M4: =C4+E4+G4+I4+K4 -> 25734531 | N4: =D4+F4+H4+J4+L4 -> -1555312.1 | P4: =N4=(-'CONSOLIDADO_TOTAL RECAUDO'!L131) -> TRUE
B5: TOTAL | C5: =SUM(C3:C4) -> 648870 | D5: =SUM(D3:D4) -> -3833780 | E5: =SUM(E3:E4) -> 15760963 | F5: =SUM(F3:F4) -> -22058903 | G5: =SUM(G3:G4) -> 0 | H5: =SUM(H3:H4) -> -2259272 | I5: =SUM(I3:I4) -> 41235719 | J5: =SUM(J3:J4) -> -42817403 | ... N5: =SUM(N3:N4) -> -74974755
C6: =C5=(C13+C21+C29+C37+C45) -> TRUE | D6: =D5=(D13+D21+D29+D37+D45) -> TRUE | E6: =E5=(E13+E21+E29+E37+E45) -> TRUE | F6: =F5=(F13+F21+F29+F37+F45) -> TRUE | G6: =G5=(G13+G21+G29+G37+G45) -> TRUE | H6: =H5=(H13+H21+H29+H37+H45) -> TRUE | I6: =I5=(I13+I21+I29+I37+I45) -> TRUE | J6: =J5=(J13+J21+J29+J37+J45) -> TRUE | ... N6: =N5=(N13+N21+N29+N37+N45) -> TRUE
B8: BANCO DE OCCIDENTE
C9: ASE 1 | E9: ASE 2 | G9: ASE 3 | I9: ASE 4 | K9: ASE 5 | M9: TOTAL
C10: REPORTE 3 | D10: REPORTE 4 | E10: REPORTE 3 | F10: REPORTE 4 | G10: REPORTE 3 | H10: REPORTE 4 | I10: REPORTE 3 | J10: REPORTE 4 | K10: REPORTE 3 | L10: REPORTE 4 | M10: REPORTE 3 | N10: REPORTE 4
B11: APLICADO | C11: 134910 | D11: -134910 | E11: 464154 | F11: -945063 | G11: 0 | H11: 0 | I11: 850737 | J11: -1371252 | K11: 0 | L11: 0 | M11: =C11+E11+G11+I11+K11 -> 1449801 | N11: =D11+F11+H11+J11+L11 -> -2451225
B12: ANTICIPOS | C12: 0 | D12: 0 | E12: 529459 | F12: -48550 | G12: 0 | H12: 0 | I12: 606286 | J12: -85771 | K12: 0 | L12: 0 | M12: =C12+E12+G12+I12+K12 -> 1135745 | N12: =D12+F12+H12+J12+L12 -> -134321
B13: TOTAL | C13: =SUM(C11:C12) -> 134910 | D13: =SUM(D11:D12) -> -134910 | E13: =SUM(E11:E12) -> 993613 | F13: =SUM(F11:F12) -> -993613 | G13: =SUM(G11:G12) -> 0 | H13: =SUM(H11:H12) -> 0 | I13: =SUM(I11:I12) -> 1457023 | J13: =SUM(J11:J12) -> -1457023 | ... N13: =SUM(N11:N12) -> -2585546
B16: EAAB RECIPROCIDAD
C17: ASE 1 | E17: ASE 2 | G17: ASE 3 | I17: ASE 4 | K17: ASE 5 | M17: TOTAL
C18: REPORTE 3 | D18: REPORTE 4 | E18: REPORTE 3 | F18: REPORTE 4 | G18: REPORTE 3 | H18: REPORTE 4 | I18: REPORTE 3 | J18: REPORTE 4 | K18: REPORTE 3 | L18: REPORTE 4 | M18: REPORTE 3 | N18: REPORTE 4
B19: APLICADO | C19: 0 | D19: 0 | E19: 0 | F19: 0 | G19: 0 | H19: 0 | I19: 309350 | J19: -554080 | K19: 0 | L19: 0 | M19: =C19+E19+G19+I19+K19 -> 309350 | N19: =D19+F19+H19+J19+L19 -> -554080
B20: ANTICIPOS | C20: 0 | D20: 0 | E20: 0 | F20: 0 | G20: 0 | H20: 0 | I20: 244730 | J20: 0 | K20: 0 | L20: 0 | M20: =C20+E20+G20+I20+K20 -> 244730 | N20: =D20+F20+H20+J20+L20 -> 0
B21: TOTAL | C21: =SUM(C19:C20) -> 0 | D21: =SUM(D19:D20) -> 0 | E21: =SUM(E19:E20) -> 0 | F21: =SUM(F19:F20) -> 0 | G21: =SUM(G19:G20) -> 0 | H21: =SUM(H19:H20) -> 0 | I21: =SUM(I19:I20) -> 554080 | J21: =SUM(J19:J20) -> -554080 | ... L21: =SUM(L19:L20) -> 0 | M21: =C21+E21+G21+I21+K21 -> 554080 | N21: =SUM(N19:N20) -> -554080
B24: EAAB CIUDAD LIMPIA
C25: ASE 1 | E25: ASE 2 | G25: ASE 3 | I25: ASE 4 | K25: ASE 5 | M25: TOTAL
C26: REPORTE 3 | D26: REPORTE 4 | E26: REPORTE 3 | F26: REPORTE 4 | G26: REPORTE 3 | H26: REPORTE 4 | I26: REPORTE 3 | J26: REPORTE 4 | K26: REPORTE 3 | L26: REPORTE 4 | M26: REPORTE 3 | N26: REPORTE 4
B27: APLICADO | C27: 0 | D27: 0 | E27: 0 | F27: 0 | G27: 0 | H27: 0 | I27: 0 | J27: 0 | K27: 0 | L27: 0 | M27: =C27+E27+G27+I27+K27 -> 0 | N27: =D27+F27+H27+J27+L27 -> 0
B28: ANTICIPOS | C28: 0 | D28: 0 | E28: 0 | F28: 0 | G28: 0 | H28: 0 | I28: 0 | J28: 0 | K28: 0 | L28: 0 | M28: =C28+E28+G28+I28+K28 -> 0 | N28: =D28+F28+H28+J28+L28 -> 0
B29: TOTAL | C29: =SUM(C27:C28) -> 0 | D29: =SUM(D27:D28) -> 0 | E29: =SUM(E27:E28) -> 0 | F29: =SUM(F27:F28) -> 0 | G29: =SUM(G27:G28) -> 0 | H29: =SUM(H27:H28) -> 0 | I29: =SUM(I27:I28) -> 0 | J29: =SUM(J27:J28) -> 0 | ... N29: =SUM(N27:N28) -> 0
B32: ENEL
C33: ASE 1 | E33: ASE 2 | G33: ASE 3 | I33: ASE 4 | K33: ASE 5 | M33: TOTAL
C34: REPORTE 3 | D34: REPORTE 4 | E34: REPORTE 3 | F34: REPORTE 4 | G34: REPORTE 3 | H34: REPORTE 4 | I34: REPORTE 3 | J34: REPORTE 4 | K34: REPORTE 3 | L34: REPORTE 4 | M34: REPORTE 3 | N34: REPORTE 4
B35: APLICADO | C35: 513960 | D35: -3698870 | E35: 9240820 | F35: -20858585 | G35: 0 | H35: -2259272 | I35: 20397090 | J35: -39633253 | K35: 0 | L35: -3964157 | M35: =C35+E35+G35+I35+K35 -> 30151870 | N35: =D35+F35+H35+J35+L35 -> -70414138
B36: ANTICIPOS | C36: 0 | D36: 0 | E36: 5526530 | F36: -206704.55 | G36: 0 | H36: 0 | I36: 18827526 | J36: -1173046.6 | K36: 0 | L36: -41240 | M36: =C36+E36+G36+I36+K36 -> 24354056 | N36: =D36+F36+H36+J36+L36 -> -1420991.1
B37: TOTAL | C37: =SUM(C35:C36) -> 513960 | D37: =SUM(D35:D36) -> -3698870 | E37: =SUM(E35:E36) -> 14767350 | F37: =SUM(F35:F36) -> -21065290 | G37: =SUM(G35:G36) -> 0 | H37: =SUM(H35:H36) -> -2259272 | I37: =SUM(I35:I36) -> 39224616 | J37: =SUM(J35:J36) -> -40806300 | ... N37: =SUM(N35:N36) -> -71835129
B40: ENERBIT
C41: ASE 1 | E41: ASE 2 | G41: ASE 3 | I41: ASE 4 | K41: ASE 5 | M41: TOTAL
C42: REPORTE 3 | D42: REPORTE 4 | E42: REPORTE 3 | F42: REPORTE 4 | G42: REPORTE 3 | H42: REPORTE 4 | I42: REPORTE 3 | J42: REPORTE 4 | K42: REPORTE 3 | L42: REPORTE 4 | M42: REPORTE 3 | N42: REPORTE 4
B43: APLICADO | C43: 0 | D43: 0 | E43: 0 | F43: 0 | G43: 0 | H43: 0 | I43: 0 | J43: 0 | K43: 0 | L43: 0 | M43: =C43+E43+G43+I43+K43 -> 0 | N43: =D43+F43+H43+J43+L43 -> 0
B44: ANTICIPOS | C44: 0 | D44: 0 | E44: 0 | F44: 0 | G44: 0 | H44: 0 | I44: 0 | J44: 0 | K44: 0 | L44: 0 | M44: =C44+E44+G44+I44+K44 -> 0 | N44: =D44+F44+H44+J44+L44 -> 0
B45: TOTAL | C45: =SUM(C43:C44) -> 0 | D45: =SUM(D43:D44) -> 0 | E45: =SUM(E43:E44) -> 0 | F45: =SUM(F43:F44) -> 0 | G45: =SUM(G43:G44) -> 0 | H45: =SUM(H43:H44) -> 0 | I45: =SUM(I43:I44) -> 0 | J45: =SUM(J43:J44) -> 0 | ... N45: =SUM(N43:N44) -> 0

Sheet ANTICIPOS USUARIOS
B1: TOTAL | E1: RECIPROCIDAD | H1: ENEL | K1: ENERBIT | N1: OCCIDENTE | Q1: EAAB-CIUDADLIMPIA
B2: ASE | C2: ANTICIPOS GENERADOS POR PAGO | E2: ASE | F2: ANTICIPOS GENERADOS POR PAGO | H2: ASE | I2: ANTICIPOS GENERADOS POR PAGO | K2: ASE | L2: ANTICIPOS GENERADOS POR PAGO | N2: ASE | O2: ANTICIPOS GENERADOS POR PAGO | Q2: ASE | R2: ANTICIPOS GENERADOS POR PAGO | T2: Anticipos generados por pago
B3: 1 | C3: ='REPORTE RECAUDO x BANCO'!I14 -> 46857237 | E3: 1 | F3: ='REPORTE RECAUDO x BANCO'!F14 -> 0 | H3: 1 | I3: ='REPORTE RECAUDO x BANCO'!C14 -> 29606547 | K3: 1 | L3: ='REPORTE RECAUDO x BANCO'!G14 -> 0 | N3: 1 | O3: ='REPORTE RECAUDO x BANCO'!H14 -> 17250690 | Q3: 1 | R3: ='REPORTE RECAUDO x BANCO'!D14+'REPORTE RECAUDO x BANCO'!E14 -> 0 | T3: Sale del reporte Recaudo por Bancos.
B4: 2 | C4: ='REPORTE RECAUDO x BANCO'!I24 -> 52275662 | E4: 2 | F4: ='REPORTE RECAUDO x BANCO'!F24 -> 0 | H4: 2 | I4: ='REPORTE RECAUDO x BANCO'!C24 -> 22325147 | K4: 2 | L4: ='REPORTE RECAUDO x BANCO'!G24 -> 0 | N4: 2 | O4: ='REPORTE RECAUDO x BANCO'!H24 -> 29950515 | Q4: 2 | R4: ='REPORTE RECAUDO x BANCO'!D24+'REPORTE RECAUDO x BANCO'!E24 -> 0
B5: 3 | C5: ='REPORTE RECAUDO x BANCO'!I33 -> 13754369 | E5: 3 | F5: ='REPORTE RECAUDO x BANCO'!F33 -> 0 | H5: 3 | I5: ='REPORTE RECAUDO x BANCO'!C33 -> 8845080 | K5: 3 | L5: ='REPORTE RECAUDO x BANCO'!G33 -> 0 | N5: 3 | O5: ='REPORTE RECAUDO x BANCO'!H33 -> 4909289 | Q5: 3 | R5: ='REPORTE RECAUDO x BANCO'!D33+'REPORTE RECAUDO x BANCO'!E33 -> 0
B6: 4 | C6: ='REPORTE RECAUDO x BANCO'!I42 -> 49700940 | E6: 4 | F6: ='REPORTE RECAUDO x BANCO'!F42 -> 0 | H6: 4 | I6: ='REPORTE RECAUDO x BANCO'!C42 -> 42284806 | K6: 4 | L6: ='REPORTE RECAUDO x BANCO'!G42 -> 0 | N6: 4 | O6: ='REPORTE RECAUDO x BANCO'!H42 -> 7416134 | Q6: 4 | R6: ='REPORTE RECAUDO x BANCO'!D42+'REPORTE RECAUDO x BANCO'!E42 -> 0
B7: 5 | C7: ='REPORTE RECAUDO x BANCO'!I52 -> 8596000 | E7: 5 | F7: ='REPORTE RECAUDO x BANCO'!F52 -> 0 | H7: 5 | I7: ='REPORTE RECAUDO x BANCO'!C52 -> 5249580 | K7: 5 | L7: ='REPORTE RECAUDO x BANCO'!G52 -> 914180 | N7: 5 | O7: ='REPORTE RECAUDO x BANCO'!H52 -> 2432240 | Q7: 5 | R7: ='REPORTE RECAUDO x BANCO'!D52+'REPORTE RECAUDO x BANCO'!E52 -> 0
C8: =SUM(C3:C7) -> 1.7118421e+08 | F8: =SUM(F3:F7) -> 0 | I8: =SUM(I3:I7) -> 1.0831116e+08 | L8: =SUM(L3:L7) -> 914180 | O8: =SUM(O3:O7) -> 61958868 | R8: =SUM(R3:R7) -> 0
C9: =C8='REPORTE RECAUDO x BANCO'!I3 -> TRUE | F9: =F8='REPORTE RECAUDO x BANCO'!F3 -> TRUE | I9: =I8='REPORTE RECAUDO x BANCO'!C3 -> TRUE | L9: =L8='REPORTE RECAUDO x BANCO'!G3 -> TRUE | O9: =O8='REPORTE RECAUDO x BANCO'!H3 -> TRUE | R9: =R8='REPORTE RECAUDO x BANCO'!D3+'REPORTE RECAUDO x BANCO'!E3 -> TRUE
B11: ASE | C11: ANTICIPOS GENERADOS POR EXTEMPORANEOS | E11: ASE | F11: ANTICIPOS GENERADOS POR EXTEMPORANEOS | H11: ASE | I11: ANTICIPOS GENERADOS POR EXTEMPORANEOS | K11: ASE | L11: ANTICIPOS GENERADOS POR EXTEMPORANEOS | N11: ASE | O11: ANTICIPOS GENERADOS POR EXTEMPORANEOS | Q11: ASE | R11: ANTICIPOS GENERADOS POR EXTEMPORANEOS | T11: Anticipos generados por pagos aplicados de reversiones
B12: 1 | C12: ='ANT EXT-REV'!C4 -> 0 | E12: 1 | F12: ='ANT EXT-REV'!C20 -> 0 | H12: 1 | I12: ='ANT EXT-REV'!C36 -> 0 | K12: 1 | L12: ='ANT EXT-REV'!A12 -> 0 | N12: 1 | O12: ='ANT EXT-REV'!C12 -> 0 | Q12: 1 | R12: ='ANT EXT-REV'!C28 -> 0 | T12: Sale del reporte Recaudo reversado
B13: 2 | C13: ='ANT EXT-REV'!E4 -> 6055989 | E13: 2 | F13: ='ANT EXT-REV'!E20 -> 0 | H13: 2 | I13: ='ANT EXT-REV'!E36 -> 5526530 | K13: 2 | L13: ='ANT EXT-REV'!E44 -> 0 | N13: 2 | O13: ='ANT EXT-REV'!E12 -> 529459 | Q13: 2 | R13: ='ANT EXT-REV'!E28 -> 0
B14: 3 | C14: ='ANT EXT-REV'!G4 -> 0 | E14: 3 | F14: ='ANT EXT-REV'!G20 -> 0 | H14: 3 | I14: ='ANT EXT-REV'!G36 -> 0 | K14: 3 | L14: ='ANT EXT-REV'!G44 -> 0 | N14: 3 | O14: ='ANT EXT-REV'!G12 -> 0 | Q14: 3 | R14: ='ANT EXT-REV'!G28 -> 0
B15: 4 | C15: ='ANT EXT-REV'!I4 -> 19678542 | E15: 4 | F15: ='ANT EXT-REV'!I20 -> 244730 | H15: 4 | I15: ='ANT EXT-REV'!I36 -> 18827526 | K15: 4 | L15: ='ANT EXT-REV'!I44 -> 0 | N15: 4 | O15: ='ANT EXT-REV'!I12 -> 606286 | Q15: 4 | R15: ='ANT EXT-REV'!I28 -> 0
B16: 5 | C16: ='ANT EXT-REV'!K4 -> 0 | E16: 5 | F16: ='ANT EXT-REV'!K20 -> 0 | H16: 5 | I16: ='ANT EXT-REV'!K36 -> 0 | K16: 5 | L16: ='ANT EXT-REV'!K44 -> 0 | N16: 5 | O16: ='ANT EXT-REV'!K12 -> 0 | Q16: 5 | R16: ='ANT EXT-REV'!K28 -> 0
C17: =SUM(C12:C16) -> 25734531 | F17: =SUM(F12:F16) -> 244730 | I17: =SUM(I12:I16) -> 24354056 | L17: =SUM(L12:L16) -> 0 | O17: =SUM(O12:O16) -> 1135745 | R17: =SUM(R12:R16) -> 0
C18: =C17='ANT EXT-REV'!M4 -> TRUE | F18: =F17='ANT EXT-REV'!M20 -> TRUE | I18: =I17='ANT EXT-REV'!M36 -> TRUE | L18: =L17='ANT EXT-REV'!M44 -> TRUE | O18: =O17='ANT EXT-REV'!M12 -> TRUE | R18: =R17='ANT EXT-REV'!M28 -> TRUE
B20: ASE | C20: ANTICIPOS QUE CARGAN POR REVERSIONES | E20: ASE | F20: ANTICIPOS QUE CARGAN POR REVERSIONES | H20: ASE | I20: ANTICIPOS QUE CARGAN POR REVERSIONES | K20: ASE | L20: ANTICIPOS QUE CARGAN POR REVERSIONES | N20: ASE | O20: ANTICIPOS QUE CARGAN POR REVERSIONES | Q20: ASE | R20: ANTICIPOS QUE CARGAN POR REVERSIONES | T20: Anticipos que cargan de reversiones
B21: 1 | C21: ='ANT EXT-REV'!D4 -> 0 | E21: 1 | F21: ='ANT EXT-REV'!D20 -> 0 | H21: 1 | I21: ='ANT EXT-REV'!D36 -> 0 | K21: 1 | L21: ='ANT EXT-REV'!D44 -> 0 | N21: 1 | O21: ='ANT EXT-REV'!D12 -> 0 | Q21: 1 | R21: ='ANT EXT-REV'!D28 -> 0 | T21: Sale del reporte Recaudo reversado
B22: 2 | C22: ='ANT EXT-REV'!F4 -> -255254.55 | E22: 2 | F22: ='ANT EXT-REV'!F20 -> 0 | H22: 2 | I22: ='ANT EXT-REV'!F36 -> -206704.55 | K22: 2 | L22: ='ANT EXT-REV'!F44 -> 0 | N22: 2 | O22: ='ANT EXT-REV'!F12 -> -48550 | Q22: 2 | R22: ='ANT EXT-REV'!F28 -> 0
B23: 3 | C23: ='ANT EXT-REV'!H4 -> 0 | E23: 3 | F23: ='ANT EXT-REV'!H20 -> 0 | H23: 3 | I23: ='ANT EXT-REV'!H36 -> 0 | K23: 3 | L23: ='ANT EXT-REV'!H44 -> 0 | N23: 3 | O23: ='ANT EXT-REV'!H12 -> 0 | Q23: 3 | R23: ='ANT EXT-REV'!H28 -> 0
B24: 4 | C24: ='ANT EXT-REV'!J4 -> -1258817.6 | E24: 4 | F24: ='ANT EXT-REV'!J20 -> 0 | H24: 4 | I24: ='ANT EXT-REV'!J36 -> -1173046.6 | K24: 4 | L24: ='ANT EXT-REV'!J44 -> 0 | N24: 4 | O24: ='ANT EXT-REV'!J12 -> -85771 | Q24: 4 | R24: ='ANT EXT-REV'!J28 -> 0
B25: 5 | C25: ='ANT EXT-REV'!L4 -> -41240 | E25: 5 | F25: ='ANT EXT-REV'!L20 -> 0 | H25: 5 | I25: ='ANT EXT-REV'!L36 -> -41240 | K25: 5 | L25: ='ANT EXT-REV'!L44 -> 0 | N25: 5 | O25: ='ANT EXT-REV'!L12 -> 0 | Q25: 5 | R25: ='ANT EXT-REV'!L28 -> 0
C26: =SUM(C21:C25) -> -1555312.1 | F26: =SUM(F21:F25) -> 0 | I26: =SUM(I21:I25) -> -1420991.1 | L26: =SUM(L21:L25) -> 0 | O26: =SUM(O21:O25) -> -134321 | R26: =SUM(R21:R25) -> 0
C27: =C26='ANT EXT-REV'!N4 -> TRUE | F27: =F26='ANT EXT-REV'!N20 -> TRUE | I27: =I26='ANT EXT-REV'!N36 -> TRUE | L27: =L26='ANT EXT-REV'!N44 -> TRUE | O27: =O26='ANT EXT-REV'!N12 -> TRUE | R27: =R26='ANT EXT-REV'!N28 -> TRUE

Sheet BCE SC POR FACT.
C2: ASE | D2: SUBSIDIO | E2: CONTRIBUCION | F2: TOTAL BSC | H2: SISTEMA
C3: 1 | D3: -1.3280729e+09 | E3: 3.4820238e+09 | F3: =D3+E3 -> 2.1539508e+09 | H3: =DetRetri2026101!J9 -> 2153950828 | I3: =F3-H3 -> 0.16000032
C4: 2 | D4: -6.051832e+09 | E4: 1.8346864e+09 | F4: =D4+E4 -> -4.2171455e+09 | H4: =DetRetri2026101!J10 -> -4217145527 | I4: =F4-H4 -> 0.090000153
C5: 3 | D5: -3.1050034e+09 | E5: 1.816197e+09 | F5: =D5+E5 -> -1.2888063e+09 | H5: =DetRetri2026101!J11 -> -1288806337 | I5: =F5-H5 -> -0.090000153
C6: 4 | D6: -3.693256e+08 | E6: 4.3085756e+08 | F6: =D6+E6 -> 61531954 | H6: =DetRetri2026101!J12 -> 61531954 | I6: =F6-H6 -> -0.31
C7: 5 | D7: -2.3876069e+09 | E7: 1.1411338e+09 | F7: =D7+E7 -> -1.2464731e+09 | H7: =DetRetri2026101!J13 -> -1246473094 | I7: =F7-H7 -> -0.40999985
F9: =SUM(F3:F7) -> -4.5369422e+09 | H9: =SUM(H3:H7) -> -4536942176 | I9: =F9-H9 -> -0.55999947
H10: =H9=DetRetri2026101!J14 -> TRUE
D11: =SUM(D3:D7) -> -1.3241841e+10 | E11: =SUM(E3:E7) -> 8.7048987e+09 | F11: =SUM(D3:E7) -> -4.5369422e+09
F12: =ROUND(F11,2)=ROUND(F9,2) -> TRUE
F13: =ROUND(F11,2)-ROUND(F9,2) -> 0
D18: ASE | E18: REMUN TOTAL | F18: VALIDA 1 | G18: VALIDA 2 | H18: DIFERENCIA VALIDA 2
D19: 1 | E19: ='CONSOLIDADO_TOTAL RECAUDO'!J104 -> 2.1539508e+09 | F19: =E19=F3 -> TRUE | G19: =E19=H3 -> FALSE | H19: =E19-H3 -> 0.16000032
D20: 2 | E20: ='CONSOLIDADO_TOTAL RECAUDO'!J105 -> -4.2171455e+09 | F20: =E20=F4 -> TRUE | G20: =E20=H4 -> FALSE | H20: =E20-H4 -> 0.090000153
D21: 3 | E21: ='CONSOLIDADO_TOTAL RECAUDO'!J106 -> -1.2888063e+09 | F21: =E21=F5 -> TRUE | G21: =E21=H5 -> FALSE | H21: =E21-H5 -> -0.090000153
D22: 4 | E22: ='CONSOLIDADO_TOTAL RECAUDO'!J107 -> 61531954 | F22: =E22=F6 -> TRUE | G22: =E22=H6 -> FALSE | H22: =E22-H6 -> -0.31
D23: 5 | E23: ='CONSOLIDADO_TOTAL RECAUDO'!J108 -> -1.2464731e+09 | F23: =E23=F7 -> TRUE | G23: =E23=H7 -> FALSE | H23: =E23-H7 -> -0.40999985
E24: =SUM(E19:E23) -> -4.5369422e+09 | F24: =E24=F9 -> TRUE | G24: =E24=H9 -> FALSE | H24: =E24-H9 -> -0.55999947

Sheet Reporte Componentes R1
B4: PROMOAMBIENTAL
F5: Total | G5: Componente TDF | H5: Componente TTL | I5: Componente TVIAT | J5: Aprovechamiento | K5: CCSA Prest.Aprov. | L5: SERVICIO ESPECIALES | M5: Componente TCS | N5: Componente TLU | O5: Componente TBL | P5: Componente TRT | Q5: CCSA Prest. No Aprov. | R5: Ajuste Decena | S5: Ajuste Recargo Aseo | T5: Intereses Cte Financiac. Aseo | U5: Exonera-Recargo Aseo | V5: Exonera-Ajuste Decena Aseo | W5: Exonera-Recargo Aseo | X5: Exonera-Recargo Aseo | Y5: Intereses Cte Financiac. Aseo | Z5: Rec.Intereses
E6: Vlr Servicio | F6: -2015.07 | G6: -122.1 | H6: -51.87 | I6: -22.65 | J6: -369.44 | K6: -23.88 | L6: 0 | M6: -209.4 | N6: -175.25 | O6: -699.55 | P6: -301.98 | Q6: -38.95 | R6: 0 | S6: 0 | T6: 0 | U6: 0 | V6: 0 | W6: 0 | X6: 0 | Y6: 0 | Z6: 0
D7: E | E7: Total | F7: -2015.07 | G7: -122.1 | H7: -51.87 | I7: -22.65 | J7: -369.44 | K7: -23.88 | L7: 0 | M7: -209.4 | N7: -175.25 | O7: -699.55 | P7: -301.98 | Q7: -38.95 | R7: 0 | S7: 0 | T7: 0 | U7: 0 | V7: 0 | W7: 0 | X7: 0 | Y7: 0 | Z7: 0
C8: ENEL | D8: Total | F8: -2015.07 | G8: -122.1 | H8: -51.87 | I8: -22.65 | J8: -369.44 | K8: -23.88 | L8: 0 | M8: -209.4 | N8: -175.25 | O8: -699.55 | P8: -301.98 | Q8: -38.95 | R8: 0 | S8: 0 | T8: 0 | U8: 0 | V8: 0 | W8: 0 | X8: 0 | Y8: 0 | Z8: 0
B9: Mes | C9: Total | F9: -2015.07 | G9: -122.1 | H9: -51.87 | I9: -22.65 | J9: -369.44 | K9: -23.88 | L9: 0 | M9: -209.4 | N9: -175.25 | O9: -699.55 | P9: -301.98 | Q9: -38.95 | R9: 0 | S9: 0 | T9: 0 | U9: 0 | V9: 0 | W9: 0 | X9: 0 | Y9: 0 | Z9: 0
A10: AFaseo | B10: Total | F10: -2015.07 | G10: -122.1 | H10: -51.87 | I10: -22.65 | J10: -369.44 | K10: -23.88 | L10: 0 | M10: -209.4 | N10: -175.25 | O10: -699.55 | P10: -301.98 | Q10: -38.95 | R10: 0 | S10: 0 | T10: 0 | U10: 0 | V10: 0 | W10: 0 | X10: 0 | Y10: 0 | Z10: 0
E11: Vlr Servicio | F11: 543996.54 | G11: 23503.13 | H11: 13266.51 | I11: 6965.01 | J11: 119922.22 | K11: 5285.43 | L11: 0 | M11: 46363.01 | N11: 44625.42 | O11: 211250.82 | P11: 64191.45 | Q11: 8623.46 | R11: 0.08 | S11: 0 | T11: 0 | U11: 0 | V11: 0 | W11: 0 | X11: 0 | Y11: 0 | Z11: 0
E12: Vlr Intereses | F12: 2063.1 | G12: 86.78 | H12: 48.91 | I12: 25.71 | J12: 441.75 | K12: 20.42 | L12: 0 | M12: 179.53 | N12: 172.72 | O12: 816.93 | P12: 236.94 | Q12: 33.41 | R12: 0 | S12: 0 | T12: 0 | U12: 0 | V12: 0 | W12: 0 | X12: 0 | Y12: 0 | Z12: 0
D13: E | E13: Total | F13: 546059.64 | G13: 23589.91 | H13: 13315.42 | I13: 6990.72 | J13: 120363.97 | K13: 5305.85 | L13: 0 | M13: 46542.54 | N13: 44798.14 | O13: 212067.75 | P13: 64428.39 | Q13: 8656.87 | R13: 0.08 | S13: 0 | T13: 0 | U13: 0 | V13: 0 | W13: 0 | X13: 0 | Y13: 0 | Z13: 0
C14: ENEL | D14: Total | F14: 546059.64 | G14: 23589.91 | H14: 13315.42 | I14: 6990.72 | J14: 120363.97 | K14: 5305.85 | L14: 0 | M14: 46542.54 | N14: 44798.14 | O14: 212067.75 | P14: 64428.39 | Q14: 8656.87 | R14: 0.08 | S14: 0 | T14: 0 | U14: 0 | V14: 0 | W14: 0 | X14: 0 | Y14: 0 | Z14: 0
E15: Vlr Servicio | F15: 89870.51 | G15: 5626.37 | H15: 3138.96 | I15: 1667.33 | J15: 21034.12 | K15: 519.02 | L15: 0 | M15: 4552.92 | N15: 6472.07 | O15: 30640.84 | P15: 15366.98 | Q15: 846.86 | R15: 5.04 | S15: 0 | T15: 0 | U15: 0 | V15: 0 | W15: 0 | X15: 0 | Y15: 0 | Z15: 0
E16: Vlr Intereses | F16: 116.92 | G16: 7.31 | H16: 4.09 | I16: 2.17 | J16: 27.38 | K16: 0.67 | L16: 0 | M16: 5.91 | N16: 8.47 | O16: 39.84 | P16: 19.98 | Q16: 1.1 | R16: 0 | S16: 0 | T16: 0 | U16: 0 | V16: 0 | W16: 0 | X16: 0 | Y16: 0 | Z16: 0
D17: T | E17: Total | F17: 89987.43 | G17: 5633.68 | H17: 3143.05 | I17: 1669.5 | J17: 21061.5 | K17: 519.69 | L17: 0 | M17: 4558.83 | N17: 6480.54 | O17: 30680.68 | P17: 15386.96 | Q17: 847.96 | R17: 5.04 | S17: 0 | T17: 0 | U17: 0 | V17: 0 | W17: 0 | X17: 0 | Y17: 0 | Z17: 0
C18: OCCIDENTE | D18: Total | F18: 89987.43 | G18: 5633.68 | H18: 3143.05 | I18: 1669.5 | J18: 21061.5 | K18: 519.69 | L18: 0 | M18: 4558.83 | N18: 6480.54 | O18: 30680.68 | P18: 15386.96 | Q18: 847.96 | R18: 5.04 | S18: 0 | T18: 0 | U18: 0 | V18: 0 | W18: 0 | X18: 0 | Y18: 0 | Z18: 0
B19: Aplicacion nuevos x reversion | C19: Total | F19: 636047.07 | G19: 29223.59 | H19: 16458.47 | I19: 8660.22 | J19: 141425.47 | K19: 5825.54 | L19: 0 | M19: 51101.37 | N19: 51278.68 | O19: 242748.43 | P19: 79815.35 | Q19: 9504.83 | R19: 5.12 | S19: 0 | T19: 0 | U19: 0 | V19: 0 | W19: 0 | X19: 0 | Y19: 0 | Z19: 0
E20: Vlr Servicio | F20: 1.7732826e+10 | G20: 8.0811608e+08 | H20: 4.5018145e+08 | I20: 2.396397e+08 | J20: 4.7172894e+09 | K20: 1.5731653e+08 | L20: 9937432.2 | M20: 1.3814111e+09 | N20: 1.3028635e+09 | O20: 6.2103431e+09 | P20: 2.1989365e+09 | Q20: 2.5681561e+08 | R20: -24243.8 | S20: 0 | T20: 0 | U20: 0 | V20: 0 | W20: 0 | X20: 0 | Y20: 0 | Z20: 0
E21: Vlr Intereses | F21: 2121030.6 | G21: 114429.04 | H21: 59031.07 | I21: 30884.79 | J21: 467332.66 | K21: 20333.36 | L21: 491.86 | M21: 178752.52 | N21: 163509.31 | O21: 744605.58 | P21: 308414.05 | Q21: 33078.85 | R21: 18.46 | S21: 19.47 | T21: 236.47 | U21: 0 | V21: 0 | W21: 0 | X21: 0 | Y21: 0 | Z21: -106.9
D22: E | E22: Total | F22: 1.7734947e+10 | G22: 8.0823051e+08 | H22: 4.5024048e+08 | I22: 2.3967059e+08 | J22: 4.7177568e+09 | K22: 1.5733686e+08 | L22: 9937924.1 | M22: 1.3815898e+09 | N22: 1.303027e+09 | O22: 6.2110877e+09 | P22: 2.1992449e+09 | Q22: 2.5684868e+08 | R22: -24225.34 | S22: 19.47 | T22: 236.47 | U22: 0 | V22: 0 | W22: 0 | X22: 0 | Y22: 0 | Z22: -106.9
C23: ENEL | D23: Total | F23: 1.7734947e+10 | G23: 8.0823051e+08 | H23: 4.5024048e+08 | I23: 2.3967059e+08 | J23: 4.7177568e+09 | K23: 1.5733686e+08 | L23: 9937924.1 | M23: 1.3815898e+09 | N23: 1.303027e+09 | O23: 6.2110877e+09 | P23: 2.1992449e+09 | Q23: 2.5684868e+08 | R23: -24225.34 | S23: 19.47 | T23: 236.47 | U23: 0 | V23: 0 | W23: 0 | X23: 0 | Y23: 0 | Z23: -106.9
E24: Vlr Servicio | F24: 27812534 | G24: 3127682.6 | H24: 1787750.6 | I24: 994482.9 | J24: 3900132.4 | K24: 128394.64 | L24: 65261.43 | M24: 1108739.3 | N24: 1377785.4 | O24: 6585392.2 | P24: 8526230.1 | Q24: 210777.87 | R24: -95.43 | S24: 0 | T24: 0 | U24: 0 | V24: 0 | W24: 0 | X24: 0 | Y24: 0 | Z24: 0
E25: Vlr Intereses | F25: 52627 | G25: 3905.72 | H25: 2108.89 | I25: 1129.02 | J25: 9194.6 | K25: 397.89 | L25: 0 | M25: 3497.21 | N25: 3710.89 | O25: 17365.58 | P25: 10667.02 | Q25: 649.71 | R25: 0.42 | S25: -0.01 | T25: 0.06 | U25: 0 | V25: 0 | W25: 0 | X25: 0 | Y25: 0 | Z25: 0
D26: H | E26: Total | F26: 27865161 | G26: 3131588.3 | H26: 1789859.5 | I26: 995611.92 | J26: 3909327 | K26: 128792.53 | L26: 65261.43 | M26: 1112236.5 | N26: 1381496.3 | O26: 6602757.8 | P26: 8536897.1 | Q26: 211427.58 | R26: -95.01 | S26: -0.01 | T26: 0.06 | U26: 0 | V26: 0 | W26: 0 | X26: 0 | Y26: 0 | Z26: 0
E27: Vlr Servicio | F27: 38733807 | G27: 3039800.2 | H27: 1655044.1 | I27: 884056.68 | J27: 6291646.5 | K27: 298351.07 | L27: 43507.62 | M27: 2623588.8 | N27: 2661210.6 | O27: 12473941 | P27: 8276274 | Q27: 486783.55 | R27: -397.6 | S27: 0 | T27: 0 | U27: 0 | V27: 0 | W27: 0 | X27: 0 | Y27: 0 | Z27: 0
E28: Vlr Intereses | F28: 103423.02 | G28: 5231.83 | H28: 2620.78 | I28: 1432.53 | J28: 22089.08 | K28: 1012.15 | L28: 0 | M28: 8840.42 | N28: 8284.39 | O28: 37991.28 | P28: 14270.12 | Q28: 1651.75 | R28: -1.34 | S28: 0 | T28: 0.03 | U28: 0 | V28: 0 | W28: 0 | X28: 0 | Y28: 0 | Z28: 0
D29: O | E29: Total | F29: 38837230 | G29: 3045032.1 | H29: 1657664.9 | I29: 885489.21 | J29: 6313735.6 | K29: 299363.22 | L29: 43507.62 | M29: 2632429.2 | N29: 2669495 | O29: 12511933 | P29: 8290544.1 | Q29: 488435.3 | R29: -398.94 | S29: 0 | T29: 0.03 | U29: 0 | V29: 0 | W29: 0 | X29: 0 | Y29: 0 | Z29: 0
E30: Vlr Servicio | F30: 2.2289166e+08 | G30: 27345007 | H30: 15201201 | I30: 8089797.9 | J30: 28735246 | K30: 729515.15 | L30: 9878361.2 | M30: 6370953.3 | N30: 8839869.6 | O30: 41844064 | P30: 74669973 | Q30: 1190722.6 | R30: -3045.97 | S30: 0 | T30: 0 | U30: 0 | V30: 0 | W30: 0 | X30: 0 | Y30: 0 | Z30: 0
E31: Vlr Intereses | F31: 650065.1 | G31: 54025.13 | H31: 28815.72 | I31: 15452.4 | J31: 131416.37 | K31: 3462.06 | L31: 6638.64 | M31: 30369.24 | N31: 40871.66 | O31: 186410.2 | P31: 147007.48 | Q31: 5632.59 | R31: -36.4 | S31: 0.01 | T31: 0 | U31: 0 | V31: 0 | W31: 0 | X31: 0 | Y31: 0 | Z31: 0
D32: T | E32: Total | F32: 2.2354173e+08 | G32: 27399032 | H32: 15230017 | I32: 8105250.3 | J32: 28866662 | K32: 732977.21 | L32: 9884999.9 | M32: 6401322.6 | N32: 8880741.2 | O32: 42030474 | P32: 74816980 | Q32: 1196355.2 | R32: -3082.37 | S32: 0.01 | T32: 0 | U32: 0 | V32: 0 | W32: 0 | X32: 0 | Y32: 0 | Z32: 0
C33: OCCIDENTE | D33: Total | F33: 2.9024412e+08 | G33: 33575652 | H33: 18677541 | I33: 9986351.4 | J33: 39089725 | K33: 1161133 | L33: 9993768.9 | M33: 10145988 | N33: 12931733 | O33: 61145165 | P33: 91644422 | Q33: 1896218.1 | R33: -3576.32 | S33: 0 | T33: 0.09 | U33: 0 | V33: 0 | W33: 0 | X33: 0 | Y33: 0 | Z33: 0
B34: Mes | C34: Total | F34: 1.8025191e+10 | G34: 8.4180616e+08 | H34: 4.6891802e+08 | I34: 2.4965694e+08 | J34: 4.7568465e+09 | K34: 1.58498e+08 | L34: 19931693 | M34: 1.3917358e+09 | N34: 1.3159588e+09 | O34: 6.2722329e+09 | P34: 2.2908894e+09 | Q34: 2.587449e+08 | R34: -27801.66 | S34: 19.47 | T34: 236.56 | U34: 0 | V34: 0 | W34: 0 | X34: 0 | Y34: 0 | Z34: -106.9
A35: Componente | B35: Total | F35: 1.8025827e+10 | G35: 8.4183538e+08 | H35: 4.6893448e+08 | I35: 2.496656e+08 | J35: 4.7569879e+09 | K35: 1.5850382e+08 | L35: 19931693 | M35: 1391786912 | N35: 1.3160101e+09 | O35: 6.2724756e+09 | P35: 2.2909692e+09 | Q35: 2.5875441e+08 | R35: -27796.54 | S35: 19.47 | T35: 236.56 | U35: 0 | V35: 0 | W35: 0 | X35: 0 | Y35: 0 | Z35: -106.9
E36: Subsidio(-)/Contribucion(+) | F36: -32099.64 | G36: -1182.8 | H36: -661.02 | I36: -350.52 | J36: -6245.62 | K36: -344.7 | L36: 0 | M36: -3023.82 | N36: -2892.68 | O36: -13605.48 | P36: -3230.56 | Q36: -562.44 | R36: 0 | S36: 0 | T36: 0 | U36: 0 | V36: 0 | W36: 0 | X36: 0 | Y36: 0 | Z36: 0
D37: E | E37: Total | F37: -32099.64 | G37: -1182.8 | H37: -661.02 | I37: -350.52 | J37: -6245.62 | K37: -344.7 | L37: 0 | M37: -3023.82 | N37: -2892.68 | O37: -13605.48 | P37: -3230.56 | Q37: -562.44 | R37: 0 | S37: 0 | T37: 0 | U37: 0 | V37: 0 | W37: 0 | X37: 0 | Y37: 0 | Z37: 0
C38: ENEL | D38: Total | F38: -32099.64 | G38: -1182.8 | H38: -661.02 | I38: -350.52 | J38: -6245.62 | K38: -344.7 | L38: 0 | M38: -3023.82 | N38: -2892.68 | O38: -13605.48 | P38: -3230.56 | Q38: -562.44 | R38: 0 | S38: 0 | T38: 0 | U38: 0 | V38: 0 | W38: 0 | X38: 0 | Y38: 0 | Z38: 0
E39: Subsidio(-)/Contribucion(+) | F39: 44922.57 | G39: 2812.56 | H39: 1569.13 | I39: 833.5 | J39: 10514.48 | K39: 259.46 | L39: 0 | M39: 2275.96 | N39: 3235.33 | O39: 15317.02 | P39: 7681.79 | Q39: 423.34 | R39: 0 | S39: 0 | T39: 0 | U39: 0 | V39: 0 | W39: 0 | X39: 0 | Y39: 0 | Z39: 0
D40: T | E40: Total | F40: 44922.57 | G40: 2812.56 | H40: 1569.13 | I40: 833.5 | J40: 10514.48 | K40: 259.46 | L40: 0 | M40: 2275.96 | N40: 3235.33 | O40: 15317.02 | P40: 7681.79 | Q40: 423.34 | R40: 0 | S40: 0 | T40: 0 | U40: 0 | V40: 0 | W40: 0 | X40: 0 | Y40: 0 | Z40: 0
C41: OCCIDENTE | D41: Total | F41: 44922.57 | G41: 2812.56 | H41: 1569.13 | I41: 833.5 | J41: 10514.48 | K41: 259.46 | L41: 0 | M41: 2275.96 | N41: 3235.33 | O41: 15317.02 | P41: 7681.79 | Q41: 423.34 | R41: 0 | S41: 0 | T41: 0 | U41: 0 | V41: 0 | W41: 0 | X41: 0 | Y41: 0 | Z41: 0
B42: Aplicacion nuevos x reversion | C42: Total | F42: 12822.93 | G42: 1629.76 | H42: 908.11 | I42: 482.98 | J42: 4268.86 | K42: -85.24 | L42: 0 | M42: -747.86 | N42: 342.65 | O42: 1711.54 | P42: 4451.23 | Q42: -139.1 | R42: 0 | S42: 0 | T42: 0 | U42: 0 | V42: 0 | W42: 0 | X42: 0 | Y42: 0 | Z42: 0
E43: Subsidio(-)/Contribucion(+) | F43: -3.2536076e+09 | G43: -91345711 | H43: -50905404 | I43: -27078429 | J43: -9.643413e+08 | K43: -31681533 | L43: 0 | M43: -2.7807169e+08 | N43: -2.6199779e+08 | O43: -1.2502637e+09 | P43: -2.4623216e+08 | Q43: -51689935 | R43: 0 | S43: 0 | T43: 0 | U43: 0 | V43: 0 | W43: 0 | X43: 0 | Y43: 0 | Z43: 0
...

Sheet Rem. Anticipos R2
B1: PROMOAMBIENTAL
E2: Total | F2: Componente TDF | G2: Componente TTL | H2: Componente TVIAT | I2: Aprovechamiento | J2: CCSA Prest.Aprov. | K2: Especiales | L2: Componente TCS | M2: Componente TLU | N2: Componente TBL | O2: Componente TRT | P2: CCSA Prest. No Aprov. | Q2: Deb/Cred | R2: Deb/Cred-otros
D3: Vlr Servicio | E3: 28276858 | F3: 1878439.3 | G3: 985949.48 | H3: 400118.84 | I3: 6330266.9 | J3: 223633.39 | K3: 0 | L3: 2828219.3 | M3: 1761600.2 | N3: 8194935.5 | O3: 5327754.2 | P3: 345780.7 | Q3: 159.95 | R3: 0
D4: Vlr Intereses | E4: 4361.05 | F4: 174.89 | G4: 94.31 | H4: 51.05 | I4: 867.88 | J4: 42.71 | K4: 0 | L4: 386.27 | M4: 363.74 | N4: 1826.85 | O4: 483.6 | P4: 69.65 | Q4: 0.1 | R4: 0
C5: E | D5: Total | E5: 28281219 | F5: 1878614.2 | G5: 986043.79 | H5: 400169.89 | I5: 6331134.8 | J5: 223676.1 | K5: 0 | L5: 2828605.6 | M5: 1761964 | N5: 8196762.3 | O5: 5328237.8 | P5: 345850.35 | Q5: 160.05 | R5: 0
B6: ENEL | C6: Total | E6: 28281219 | F6: 1878614.2 | G6: 986043.79 | H6: 400169.89 | I6: 6331134.8 | J6: 223676.1 | K6: 0 | L6: 2828605.6 | M6: 1761964 | N6: 8196762.3 | O6: 5328237.8 | P6: 345850.35 | Q6: 160.05 | R6: 0
D7: Vlr Servicio | E7: 603814.81 | F7: 22956.62 | G7: 13137.59 | H7: 7524.92 | I7: 152984.36 | J7: 6128.32 | K7: 0 | L7: 63509.52 | M7: 47408.1 | N7: 220781.98 | O7: 58741.12 | P7: 10623.64 | Q7: 18.64 | R7: 0
D8: Vlr Intereses | E8: 360.62 | F8: 3.45 | G8: 1.78 | H8: 0.98 | I8: 52.98 | J8: 5.18 | K8: 0 | L8: 45.52 | M8: 41 | N8: 191.87 | O8: 9.4 | P8: 8.46 | Q8: 0 | R8: 0
C9: H | D9: Total | E9: 604175.43 | F9: 22960.07 | G9: 13139.37 | H9: 7525.9 | I9: 153037.34 | J9: 6133.5 | K9: 0 | L9: 63555.04 | M9: 47449.1 | N9: 220973.85 | O9: 58750.52 | P9: 10632.1 | Q9: 18.64 | R9: 0
D10: Vlr Servicio | E10: 448565.61 | F10: 11179.62 | G10: 6229.22 | H10: 3290.21 | I10: 128320.56 | J10: 16086.84 | K10: 0 | L10: 61274.39 | M10: 33671.14 | N10: 131140.71 | O10: 34633.76 | P10: 22652.26 | Q10: 86.9 | R10: 0
D11: Vlr Intereses | E11: 11.93 | F11: 0.08 | G11: 0.04 | H11: 0.02 | I11: -0.02 | J11: 0.2 | K11: 0 | L11: 1.72 | M11: 1.64 | N11: 7.71 | O11: 0.22 | P11: 0.32 | Q11: 0 | R11: 0
C12: O | D12: Total | E12: 448577.54 | F12: 11179.7 | G12: 6229.26 | H12: 3290.23 | I12: 128320.54 | J12: 16087.04 | K12: 0 | L12: 61276.11 | M12: 33672.78 | N12: 131148.42 | O12: 34633.98 | P12: 22652.58 | Q12: 86.9 | R12: 0
D13: Vlr Servicio | E13: 1942713.6 | F13: 100160.14 | G13: 100233.78 | H13: 28448.06 | I13: 472285.73 | J13: 14554.76 | K13: 0 | L13: 137745.27 | M13: 129582.14 | N13: 604849.23 | O13: 331094.18 | P13: 23746.96 | Q13: 13.38 | R13: 0
D14: Vlr Intereses | E14: 57.05 | F14: 3.33 | G14: 1.86 | H14: 0.99 | I14: 12.38 | J14: 0.53 | K14: 0 | L14: 4.57 | M14: 4.38 | N14: 19.07 | O14: 9.09 | P14: 0.85 | Q14: 0 | R14: 0
C15: T | D15: Total | E15: 1942770.7 | F15: 100163.47 | G15: 100235.64 | H15: 28449.05 | I15: 472298.11 | J15: 14555.29 | K15: 0 | L15: 137749.84 | M15: 129586.52 | N15: 604868.3 | O15: 331103.27 | P15: 23747.81 | Q15: 13.38 | R15: 0
B16: OCCIDENTE | C16: Total | E16: 2995523.6 | F16: 134303.24 | G16: 119604.27 | H16: 39265.18 | I16: 753655.99 | J16: 36775.83 | K16: 0 | L16: 262580.99 | M16: 210708.4 | N16: 956990.57 | O16: 424487.77 | P16: 57032.49 | Q16: 118.92 | R16: 0
A17: Componente | B17: Total | E17: 31276742 | F17: 2012917.5 | G17: 1105648.1 | H17: 439435.07 | I17: 7084790.8 | J17: 260451.93 | K17: 0 | L17: 3091186.5 | M17: 1972672.4 | N17: 9153752.9 | O17: 5752725.5 | P17: 402882.84 | Q17: 278.97 | R17: 0
D18: Subsidio(-)/Contribucion(+) | E18: -1549869.4 | F18: 185823.17 | G18: 103275.64 | H18: 53808.19 | I18: -1128778.2 | J18: -31133.11 | K18: 0 | L18: -258857.59 | M18: -225710.03 | N18: -698982.91 | O18: 501335.93 | P18: -50650.46 | Q18: 0 | R18: 0
C19: E | D19: Total | E19: -1549869.4 | F19: 185823.17 | G19: 103275.64 | H19: 53808.19 | I19: -1128778.2 | J19: -31133.11 | K19: 0 | L19: -258857.59 | M19: -225710.03 | N19: -698982.91 | O19: 501335.93 | P19: -50650.46 | Q19: 0 | R19: 0
B20: ENEL | C20: Total | E20: -1549869.4 | F20: 185823.17 | G20: 103275.64 | H20: 53808.19 | I20: -1128778.2 | J20: -31133.11 | K20: 0 | L20: -258857.59 | M20: -225710.03 | N20: -698982.91 | O20: 501335.93 | P20: -50650.46 | Q20: 0 | R20: 0
D21: Subsidio(-)/Contribucion(+) | E21: 111513.88 | F21: 6336.61 | G21: 2760.73 | H21: 1928.26 | I21: 26391.68 | J21: 1378.86 | K21: 0 | L21: 10415.46 | M21: 9797.65 | N21: 32948.04 | O21: 17306.89 | P21: 2249.7 | Q21: 0 | R21: 0
C22: H | D22: Total | E22: 111513.88 | F22: 6336.61 | G22: 2760.73 | H22: 1928.26 | I22: 26391.68 | J22: 1378.86 | K22: 0 | L22: 10415.46 | M22: 9797.65 | N22: 32948.04 | O22: 17306.89 | P22: 2249.7 | Q22: 0 | R22: 0
D23: Subsidio(-)/Contribucion(+) | E23: 95516.58 | F23: 4186.32 | G23: 2332.6 | H23: 1240.6 | I23: 21396.66 | J23: 900.1 | K23: 0 | L23: 7895.59 | M23: 5846.99 | N23: 38815.29 | O23: 11433.88 | P23: 1468.55 | Q23: 0 | R23: 0
C24: O | D24: Total | E24: 95516.58 | F24: 4186.32 | G24: 2332.6 | H24: 1240.6 | I24: 21396.66 | J24: 900.1 | K24: 0 | L24: 7895.59 | M24: 5846.99 | N24: 38815.29 | O24: 11433.88 | P24: 1468.55 | Q24: 0 | R24: 0
D25: Subsidio(-)/Contribucion(+) | E25: 654167.52 | F25: 41222.62 | G25: 22968.96 | H25: 12216.06 | I25: 166867.65 | J25: 4462.16 | K25: 0 | L25: 47541.46 | M25: 44721.58 | N25: 194297.55 | O25: 112589.19 | P25: 7280.29 | Q25: 0 | R25: 0
C26: T | D26: Total | E26: 654167.52 | F26: 41222.62 | G26: 22968.96 | H26: 12216.06 | I26: 166867.65 | J26: 4462.16 | K26: 0 | L26: 47541.46 | M26: 44721.58 | N26: 194297.55 | O26: 112589.19 | P26: 7280.29 | Q26: 0 | R26: 0
B27: OCCIDENTE | C27: Total | E27: 861197.98 | F27: 51745.55 | G27: 28062.29 | H27: 15384.92 | I27: 214655.99 | J27: 6741.12 | K27: 0 | L27: 65852.51 | M27: 60366.22 | N27: 266060.88 | O27: 141329.96 | P27: 10998.54 | Q27: 0 | R27: 0
A28: Subs/Cont | B28: Total | E28: -688671.4 | F28: 237568.72 | G28: 131337.93 | H28: 69193.11 | I28: -914122.22 | J28: -24391.99 | K28: 0 | L28: -193005.08 | M28: -165343.81 | N28: -432922.03 | O28: 642665.89 | P28: -39651.92 | Q28: 0 | R28: 0
A29: Total | E29: 30588071 | F29: 2250486.2 | G29: 1236986 | H29: 508628.18 | I29: 6170668.5 | J29: 236059.94 | K29: 0 | L29: 2898181.5 | M29: 1807328.6 | N29: 8720830.8 | O29: 6395391.4 | P29: 363230.92 | Q29: 278.97 | R29: 0
B43: TOTAL | C43: OPORTUNO | D43: Total | E43: =E17+E28-K17 -> 30588071 | F43: =F17 -> 2012917.5 | G43: =G17 -> 1105648.1 | H43: =H17 -> 439435.07 | I43: =I17 -> 7084790.8 | J43: =J17 -> 260451.93 | K43: =K17 -> 0 | L43: =L17 -> 3091186.5 | M43: =M17 -> 1972672.4 | ... S43: =S17 -> 0
D44: Subsidio(-)/Contribucion(+) | E44: =E28 -> -688671.4
B46: RECIPROCIDAD | C46: OPORTUNO | D46: Total | E46: 0 | F46: 0 | G46: 0 | H46: 0 | I46: 0 | J46: 0 | K46: 0 | L46: 0 | M46: 0 | N46: 0 | O46: 0 | P46: 0 | Q46: 0 | R46: 0 | S46: 0
D47: Subsidio(-)/Contribucion(+) | E47: 0
B49: ENEL | C49: OPORTUNO | D49: Total | E49: =E20+E6-K6 -> 26731349 | F49: =F6 -> 1878614.2 | G49: =G6 -> 986043.79 | H49: =H6 -> 400169.89 | I49: =I6 -> 6331134.8 | J49: =J6 -> 223676.1 | K49: =K6 -> 0 | L49: =L6 -> 2828605.6 | M49: =M6 -> 1761964 | ... S49: =S6 -> 0
D50: Subsidio(-)/Contribucion(+) | E50: =E20 -> -1549869.4
B52: ENERBIT | C52: OPORTUNO | D52: Total | E52: 0 | F52: 0 | G52: 0 | H52: 0 | I52: 0 | J52: 0 | K52: 0 | L52: 0 | M52: 0 | N52: 0 | O52: 0 | P52: 0 | Q52: 0 | R52: 0
D53: Subsidio(-)/Contribucion(+) | E53: 0
B55: OCCIDENTE | C55: OPORTUNO | D55: Total | E55: =E16+E27-K16 -> 3856721.6 | F55: =F16 -> 134303.24 | G55: =G16 -> 119604.27 | H55: =H16 -> 39265.18 | I55: =I16 -> 753655.99 | J55: =J16 -> 36775.83 | K55: =K16 -> 0 | L55: =L16 -> 262580.99 | M55: =M16 -> 210708.4 | ... S55: =S16 -> 0
D56: Subsidio(-)/Contribucion(+) | E56: =E27 -> 861197.98
B58: CIUDAD LIMPIA-ACUEDUCTO | C58: OPORTUNO | D58: Total | E58: 0 | F58: 0 | G58: 0 | H58: 0 | I58: 0 | J58: 0 | K58: 0 | L58: 0 | M58: 0 | N58: 0 | O58: 0 | P58: 0 | Q58: 0 | R58: 0 | S58: 0
...

Sheet Reversion Pagos R4
B1: PROMOAMBIENTAL
D2: Total | E2: Componente TDF | F2: Componente TTL | G2: Componente TVIAT | H2: Aprovechamiento | I2: CCSA Prest.Aprov. | J2: Componente TCS | K2: Componente TLU | L2: Componente TBL | M2: Componente TRT | N2: CCSA Prest. No Aprov. | O2: Ajuste Decena | P2: SERVICIO ESPECIALES | Q2: Ajuste Recargo Aseo | R2: Otros
C3: Vlr Servicio | D3: -4304657 | E3: -204234.44 | F3: -114903.02 | G3: -58910.61 | H3: -1052437.8 | I3: -38840.3 | J3: -350782.23 | K3: -326414.03 | L3: -1541278.5 | M3: -553450.68 | N3: -63370.25 | O3: -35.1 | P3: 0 | Q3: 0 | R3: 0
C4: Vlr Intereses | D4: -437.51 | E4: -20.61 | F4: -11.62 | G4: -6.13 | H4: -99.06 | I4: -4.11 | J4: -35.82 | K4: -34.53 | L4: -162.79 | M4: -56.17 | N4: -6.66 | O4: -0.01 | P4: 0 | Q4: 0 | R4: 0
B5: Componente | C5: Total | D5: -4305094.5 | E5: -204255.05 | F5: -114914.64 | G5: -58916.74 | H5: -1052536.9 | I5: -38844.41 | J5: -350818.05 | K5: -326448.56 | L5: -1541441.3 | M5: -553506.85 | N5: -63376.91 | O5: -35.11 | P5: 0 | Q5: 0 | R5: 0
C6: Subsidio(-)/Contribucion(+) | D6: 606224.47 | E6: 20070.35 | F6: 11288.32 | G6: 5947.61 | H6: 174148.52 | I6: 5843.46 | J6: 51257.62 | K6: 49095.51 | L6: 225712.61 | M6: 53326.47 | N6: 9534 | O6: 0 | P6: 0 | Q6: 0 | R6: 0
B7: Subs/Cont | C7: Total | D7: 606224.47 | E7: 20070.35 | F7: 11288.32 | G7: 5947.61 | H7: 174148.52 | I7: 5843.46 | J7: 51257.62 | K7: 49095.51 | L7: 225712.61 | M7: 53326.47 | N7: 9534 | O7: 0 | P7: 0 | Q7: 0 | R7: 0
A8: ENEL | B8: Total | D8: -3698870 | E8: -184184.7 | F8: -103626.32 | G8: -52969.13 | H8: -878388.36 | I8: -33000.95 | J8: -299560.43 | K8: -277353.05 | L8: -1315728.7 | M8: -500180.38 | N8: -53842.91 | O8: -35.11 | P8: 0 | Q8: 0 | R8: 0
C9: Vlr Servicio | D9: -90290.21 | E9: -5787.72 | F9: -3267.74 | G9: -1715.14 | H9: -21117.15 | I9: -503.05 | J9: -4412.75 | K9: -6447.78 | L9: -30412.84 | M9: -15807.14 | N9: -820.77 | O9: 1.87 | P9: 0 | Q9: 0 | R9: 0
C10: Vlr Intereses | D10: -230.5 | E10: -14.77 | F10: -8.34 | G10: -4.37 | H10: -53.93 | I10: -1.28 | J10: -11.27 | K10: -16.46 | L10: -77.62 | M10: -40.36 | N10: -2.1 | O10: 0 | P10: 0 | Q10: 0 | R10: 0
B11: Componente | C11: Total | D11: -90520.71 | E11: -5802.49 | F11: -3276.08 | G11: -1719.51 | H11: -21171.08 | I11: -504.33 | J11: -4424.02 | K11: -6464.24 | L11: -30490.46 | M11: -15847.5 | N11: -822.87 | O11: 1.87 | P11: 0 | Q11: 0 | R11: 0
C12: Subsidio(-)/Contribucion(+) | D12: -44389.29 | E12: -2901.74 | F12: -1638.32 | G12: -2.33 | H12: -10566.74 | I12: -252.21 | J12: -2212.3 | K12: -3232.7 | L12: -15246.38 | M12: -7925.08 | N12: -411.49 | O12: 0 | P12: 0 | Q12: 0 | R12: 0
B13: Subs/Cont | C13: Total | D13: -44389.29 | E13: -2901.74 | F13: -1638.32 | G13: -2.33 | H13: -10566.74 | I13: -252.21 | J13: -2212.3 | K13: -3232.7 | L13: -15246.38 | M13: -7925.08 | N13: -411.49 | O13: 0 | P13: 0 | Q13: 0 | R13: 0
A14: OCCIDENTE | B14: Total | D14: -134910 | E14: -8704.23 | F14: -4914.4 | G14: -1721.84 | H14: -31737.82 | I14: -756.54 | J14: -6636.32 | K14: -9696.94 | L14: -45736.84 | M14: -23772.58 | N14: -1234.36 | O14: 1.87 | P14: 0 | Q14: 0 | R14: 0
A15: Total | D15: -3833780 | E15: -192888.93 | F15: -108540.72 | G15: -54690.97 | H15: -910126.18 | I15: -33757.49 | J15: -306196.75 | K15: -287049.99 | L15: -1361465.5 | M15: -523952.96 | N15: -55077.27 | O15: -33.24 | P15: 0 | Q15: 0 | R15: 0
A73: TOTAL | B73: OPORTUNO | C73: Total | D73: =D15-P15 -> -3833780 | E73: =E11+E5 -> -210057.54 | F73: =F11+F5 -> -118190.72 | G73: =G11+G5 -> -60636.25 | H73: =H11+H5 -> -1073708 | I73: =I11+I5 -> -39348.74 | J73: =J11+J5 -> -355242.07 | K73: =K11+K5 -> -332912.8 | L73: =L11+L5 -> -1571931.7 | ... R73: =R11+R5 -> 0
C74: Subsidio(-)/Contribucion(+) | D74: =D7+D13 -> 561835.18
A76: RECIPROCIDAD | B76: OPORTUNO | C76: Total | D76: 0 | E76: 0 | F76: 0 | G76: 0 | H76: 0 | I76: 0 | J76: 0 | K76: 0 | L76: 0 | M76: 0 | N76: 0 | O76: 0 | P76: 0 | Q76: 0 | R76: 0
C77: Subsidio(-)/Contribucion(+) | D77: 0
A79: ENEL | B79: OPORTUNO | C79: Total | D79: =D8-P8 -> -3698870 | E79: =E5 -> -204255.05 | F79: =F5 -> -114914.64 | G79: =G5 -> -58916.74 | H79: =H5 -> -1052536.9 | I79: =I5 -> -38844.41 | J79: =J5 -> -350818.05 | K79: =K5 -> -326448.56 | L79: =L5 -> -1541441.3 | ... R79: =R5 -> 0
C80: Subsidio(-)/Contribucion(+) | D80: =D7 -> 606224.47
A82: ENERBIT | B82: OPORTUNO | C82: Total | D82: 0 | E82: 0 | F82: 0 | G82: 0 | H82: 0 | I82: 0 | J82: 0 | K82: 0 | L82: 0 | M82: 0 | N82: 0 | O82: 0 | P82: 0 | Q82: 0 | R82: 0
C83: Subsidio(-)/Contribucion(+) | D83: 0
A85: OCCIDENTE | B85: OPORTUNO | C85: Total | D85: =D14-P14 -> -134910 | E85: =E11 -> -5802.49 | F85: =F11 -> -3276.08 | G85: =G11 -> -1719.51 | H85: =H11 -> -21171.08 | I85: =I11 -> -504.33 | J85: =J11 -> -4424.02 | K85: =K11 -> -6464.24 | L85: =L11 -> -30490.46 | ... R85: =R11 -> 0
C86: Subsidio(-)/Contribucion(+) | D86: =D13 -> -44389.29
A88: CIUDAD LIMPIA-ACUEDUCTO | B88: OPORTUNO | C88: Total | D88: 0 | E88: 0 | F88: 0 | G88: 0 | H88: 0 | I88: 0 | J88: 0 | K88: 0 | L88: 0 | M88: 0 | N88: 0 | O88: 0 | P88: 0 | Q88: 0 | R88: 0
C89: Subsidio(-)/Contribucion(+) | D89: 0
B91: LIME
D92: Total | E92: Componente TDF | F92: Componente TTL | G92: Componente TVIAT | H92: Aprovechamiento | I92: CCSA Prest.Aprov. | J92: Componente TCS | K92: Componente TLU | L92: Componente TBL | M92: Componente TRT | N92: CCSA Prest. No Aprov. | O92: Ajuste Decena | P92: SERVICIO ESPECIALES | Q92: Ajuste Recargo Aseo | R92: Otros
C93: Vlr Servicio | D93: -26888437 | E93: -1660901.3 | F93: -899968.47 | G93: -460891.41 | H93: -6488857 | I93: -230262.37 | J93: -2029454.6 | K93: -2051952.9 | L93: -9182422.9 | M93: -3507972.9 | N93: -375690.45 | O93: -62.47 | P93: 0 | Q93: 0 | R93: 0
C94: Vlr Intereses | D94: -508997.86 | E94: -53684.14 | F94: -25853.97 | G94: -10930.09 | H94: -103686.96 | I94: -3626.84 | J94: -32144.78 | K94: -39085.05 | L94: -127629.69 | M94: -106438.52 | N94: -5916.12 | O94: -1.89 | P94: 0 | Q94: 0 | R94: 0.19
B95: Componente | C95: Total | D95: -27397435 | E95: -1714585.5 | F95: -925822.44 | G95: -471821.5 | H95: -6592544 | I95: -233889.21 | J95: -2061599.4 | K95: -2091038 | L95: -9310052.6 | M95: -3614411.4 | N95: -381606.57 | O95: -64.36 | P95: 0 | Q95: 0 | R95: 0.19
C96: Subsidio(-)/Contribucion(+) | D96: 6538849.3 | E96: 226514.95 | F96: 99793.49 | G96: 42188.77 | H96: 1862301.5 | I96: 64413.78 | J96: 565028 | K96: 610776.83 | L96: 2539725 | M96: 423011.57 | N96: 105095.33 | O96: 0 | P96: 0 | Q96: 0 | R96: 0
B97: Subs/Cont | C97: Total | D97: 6538849.3 | E97: 226514.95 | F97: 99793.49 | G97: 42188.77 | H97: 1862301.5 | I97: 64413.78 | J97: 565028 | K97: 610776.83 | L97: 2539725 | M97: 423011.57 | N97: 105095.33 | O97: 0 | P97: 0 | Q97: 0 | R97: 0
A98: ENEL | B98: Total | D98: -20858585 | E98: -1488070.5 | F98: -826028.95 | G98: -429632.73 | H98: -4730242.5 | I98: -169475.43 | J98: -1496571.4 | K98: -1480261.2 | L98: -6770327.5 | M98: -3191399.8 | N98: -276511.24 | O98: -64.36 | P98: 0 | Q98: 0 | R98: 0.19
C99: Vlr Servicio | D99: -3980237.6 | E99: -286462.52 | F99: -142022.56 | G99: -63580.64 | H99: -969928.29 | I99: -33251.02 | J99: -289558.91 | K99: -349827.6 | L99: -1253345.6 | M99: -538054.56 | N99: -54251.66 | O99: 45.81 | P99: 0 | Q99: 0 | R99: 0
C100: Vlr Intereses | D100: -18211.28 | E100: -1812.96 | F100: -926.34 | G100: -486.28 | H100: -4026.88 | I100: -107.04 | J100: -911.93 | K100: -1140.23 | L100: -4993.66 | M100: -3631.56 | N100: -174.64 | O100: 0.08 | P100: 0 | Q100: 0.16 | R100: 0
B101: Componente | C101: Total | D101: -3998448.9 | E101: -288275.48 | F101: -142948.9 | G101: -64066.92 | H101: -973955.17 | I101: -33358.06 | J101: -290470.84 | K101: -350967.83 | L101: -1258339.3 | M101: -541686.12 | N101: -54426.3 | O101: 45.89 | P101: 0 | Q101: 0.16 | R101: 0
C102: Subsidio(-)/Contribucion(+) | D102: 3053385.9 | E102: 191175.93 | F102: 90448.03 | G102: 40403.45 | H102: 788542.93 | I102: 25367.94 | J102: 222523.7 | K102: 271617.33 | L102: 1010650.4 | M102: 371266.58 | N102: 41389.52 | O102: 0 | P102: 0 | Q102: 0 | R102: 0
